Workbook

Sheet 総括
B1: 事業計画書チェック結果
B2: 株式会社トンボ飲料 様 中小企業省力化投資補助金（一般型）第8回 ｜ 作成日：2026年10月1日
B4: 1. チェック対象
B5: その１その２ | C5: 20261001【更新版】作成中【参考様式】事業計画書（その１その２）第8回フォーマット.docx（Dropbox、2026/10/01 08:34更新）
B6: その３ | C6: 20261001【更新版】作成中【指定様式】事業計画書（その３）第8回フォーマット.xlsx（Dropbox、2026/10/01 08:36更新）
B7: 審査項目 | C7: 【更新版】省力化投資補助金_審査項目分析表.xlsx（Dropbox、2026/09/29更新）
B8: 照合に使った資料 | C8: 第8回公募要領（更新版）、応募申請の手引き（第8回）、よくあるご質問（第5〜8回、2026/08/18更新）、事業計画書作成の参考ガイド、ヒアリングリストv5、20260930ヒアリングMTGメモ、市場・労働統計の調査メモ（market_data.md／labor_data.md）、図の元データ（★0930Gライン_レイアウト工程ビフォーアフター_v3.pptx）、20261001【更新版】スケジュール.xlsx、参照用収支計画.xlsx
B10: 2. チェックの方法と制約
B11: ①ファイル内 | C11: 矛盾・ロジック、説得力、審査上不利な記載、誤字脱字を全文で確認。統計値は出典の調査メモと照合。
B12: ②ファイル間 | C12: その１その２・その３・図・スケジュールの数値と記載を照合し、主要な数値は元データから数式で再計算（「数値照合」シート）。
B13: ③審査項目 | C13: 審査項目分析表の全項目（必須・技術面・計画面・政策面・特例・口頭審査・加点・減点）への対応を評価（「審査項目カバレッジ」シート）。
B14: 制約（画像） | C14: 本体ファイルのダウンロードがこの環境のネットワーク設定（dl.dropboxusercontent.com）で拒否されたため、本文はDropbox経由の抽出テキストで確認し、図は元データ（pptx v3）を画像化して図中の文字・数値を確認した。フジシール図面・当社の歴史・末尾スケジュール等の貼付画像そのものは未確認（「画像確認状況」シート）。
B16: 3. 総評
B17: 良い点 | C17: 数値はその１その２とその３で全て一致し、計算も再計算と合っている。SWOT→クロスSWOT→課題（B1〜B3）→設備→創出時間の配分（配分率・人時・KPI・3段階）→賃上げまでの因果が一貫しており、オーダーメイド性（3観点・打合せ経緯・代替案の棄却）とリスク対策も採択事例の水準にある。
B18: 優先して直す点 | C18: (1) 投資回収期間：手引きの記入例は「1年あたりの付加価値増加額」→主値を0.93年に（No.1） (2) 補助対象経費：既設SPM機の改造費・改造工事は対象外の可能性（No.2）、運搬費は機械装置費に計上（No.3） (3) 増収の根拠：能力を上げない装置で年800万袋を追加生産できる理由が示されていない（No.4） (4) 省力化指数の説明：「無くなる作業」と「詰めにほぐし等を集約」が矛盾（No.5） (5) 末尾スケジュール画像：旧版に他社案件の記載があるため版を確認（No.6） (6) 足下の賃上げ：実施済みの約5%と計画3.02%・進行期人件費+0.7%の整合（No.7）
B20: 4. 指摘件数（「指摘一覧」から自動集計）
B21: 重要度 | C21: ①ファイル内 | D21: ②ファイル間 | E21: ③審査項目 | F21: 合計 | G21: 対応済
B22: A：要修正 | C22: =COUNTIFS(指摘一覧!$B$5:$B$65,"A",指摘一覧!$C$5:$C$65,"*①*") -> 6 | D22: =COUNTIFS(指摘一覧!$B$5:$B$65,"A",指摘一覧!$C$5:$C$65,"*②*") -> 4 | E22: =COUNTIFS(指摘一覧!$B$5:$B$65,"A",指摘一覧!$C$5:$C$65,"*③*") -> 5 | F22: =COUNTIF(指摘一覧!$B$5:$B$65,"A") -> 7 | G22: =COUNTIFS(指摘一覧!$B$5:$B$65,"A",指摘一覧!$L$5:$L$65,"対応済") -> 0
B23: B：修正推奨 | C23: =COUNTIFS(指摘一覧!$B$5:$B$65,"B",指摘一覧!$C$5:$C$65,"*①*") -> 7 | D23: =COUNTIFS(指摘一覧!$B$5:$B$65,"B",指摘一覧!$C$5:$C$65,"*②*") -> 6 | E23: =COUNTIFS(指摘一覧!$B$5:$B$65,"B",指摘一覧!$C$5:$C$65,"*③*") -> 8 | F23: =COUNTIF(指摘一覧!$B$5:$B$65,"B") -> 17 | G23: =COUNTIFS(指摘一覧!$B$5:$B$65,"B",指摘一覧!$L$5:$L$65,"対応済") -> 0
B24: C：軽微 | C24: =COUNTIFS(指摘一覧!$B$5:$B$65,"C",指摘一覧!$C$5:$C$65,"*①*") -> 24 | D24: =COUNTIFS(指摘一覧!$B$5:$B$65,"C",指摘一覧!$C$5:$C$65,"*②*") -> 4 | E24: =COUNTIFS(指摘一覧!$B$5:$B$65,"C",指摘一覧!$C$5:$C$65,"*③*") -> 0 | F24: =COUNTIF(指摘一覧!$B$5:$B$65,"C") -> 27 | G24: =COUNTIFS(指摘一覧!$B$5:$B$65,"C",指摘一覧!$L$5:$L$65,"対応済") -> 0
B25: 確認 | C25: =COUNTIFS(指摘一覧!$B$5:$B$65,"確認",指摘一覧!$C$5:$C$65,"*①*") -> 1 | D25: =COUNTIFS(指摘一覧!$B$5:$B$65,"確認",指摘一覧!$C$5:$C$65,"*②*") -> 2 | E25: =COUNTIFS(指摘一覧!$B$5:$B$65,"確認",指摘一覧!$C$5:$C$65,"*③*") -> 7 | F25: =COUNTIF(指摘一覧!$B$5:$B$65,"確認") -> 10 | G25: =COUNTIFS(指摘一覧!$B$5:$B$65,"確認",指摘一覧!$L$5:$L$65,"対応済") -> 0
B26: 合計 | C26: =SUM(C22:C25) -> 38 | D26: =SUM(D22:D25) -> 16 | E26: =SUM(E22:E25) -> 20 | F26: =SUM(F22:F25) -> 61 | G26: =SUM(G22:G25) -> 0
B27: ※1件の指摘が複数の観点に該当する場合は、観点別の列で重複して数えています（合計列は件数そのもの）。
B29: 5. 凡例
B30: A：要修正 | C30: 要件・補助対象経費・審査の主要数値に直接影響するもの、または明確な矛盾。
B31: B：修正推奨 | C31: 整合性・説得力の改善、出典の正確性。
B32: C：軽微 | C32: 誤字脱字・表記ゆれ・体裁。
B33: 確認 | C33: クライアント・事務局への事実確認や、申請手続きの確認が必要なもの。
B34: シート構成 | C34: 指摘一覧（全指摘）／数値照合（記載値と再計算の照合、能力検証、文字数）／審査項目カバレッジ（審査項目分析表との対応）／画像確認状況（貼付図ごとの確認状況）

Sheet 指摘一覧
A1: 指摘一覧（重要度順：A→B→C→確認、同じ重要度の中は計画書の掲載順）
A2: 観点：①ファイル内の矛盾・ロジック・説得力・不利な記載・誤字脱字／②ファイル間・本文と図の整合／③審査項目への対応。対応状況はプルダウンで選択できます。
A4: No | B4: 重要度 | C4: 観点 | D4: 分類 | E4: 対象ファイル | F4: 該当箇所 | G4: 現状の記載（抜粋） | H4: 指摘内容（問題点・根拠） | I4: 修正案 | J4: 関連審査項目 | K4: 根拠資料・確認元 | L4: 対応状況 | M4: メモ
A5: 1 | B5: A | C5: ①②③ | D5: 数値・計算／要件 | E5: その１その２／その３ | F5: その１その２：2-2②「投資回収期間（0.33年）」本文・要素表、6章①リスク② その３：【３】投資回収期間、（別紙３） | G5: 「＝101,200,000円÷（9,047,144円＋297,960,717円）＝0.33年」 「増加した付加価値額 297,960,717円（3年目−基準年度）」 「▶保守ケース：…＝0.93年」 | H5: 応募申請の手引き（第8回）p.60の（別紙３）記入例は、増加した付加価値額を「（円/年）」とし「１年あたりの付加価値増加額を入力 例）5年計画の場合、（５年後の付加価値額－基準年度の付加価値額）÷5」と説明している（例：110,000,000÷(6.5×260×2,480＋8,250,000)＝8.85年）。公募要領の算式も「削減工数×年間稼働日数×人件費単価（＝年額）＋増加した付加価値額」で、年額同士の合算が前提。 本計画は3年間の増加総額297,960,717円をそのまま加えており、手引きの方法では0.93年になる。様式シート内の注記は「最終年度－基準年度」（÷なし）のため公式資料間で不一致があるが、手引きの方法で検算されると「回収期間を過小に見せている」と受け取られるリスクがある（審査項目2-b「算出根拠が妥当か」）。審査項目分析表2-bも「÷計画年数」と整理している。 | I5: 主値を手引き方式の0.93年に変更する（別紙３の「増加した付加価値額」に99,320,239円＝297,960,717÷3を入力→その３【３】も自動で0.93年）。0.93年でも1年未満で、採択事例（0.17〜0.76年）と遜色はない。 0.33年は記載しないか「（参考）様式注記の方法では0.33年」程度にとどめる。2-2②の見出し・本文・要素表、6章①リスク②、その３（別紙３）【算定根拠】を連動して修正。Gライン単独（1.59年）は増加額が既に年額なので変更不要。 | J5: 2-b | K5: 手引き（第8回）7-2 p.60（別紙３）記入例／公募要領1-4(7)／その３様式（別紙３）注記／審査項目分析表2-b | L5: 未対応
A6: 2 | B6: A | C6: ①③ | D6: 要件（補助対象経費） | E6: その１その２／その３ | F6: その１その２：（４）経費一覧No.5・No.6、2章②表No.5・No.6、2章④「既設機を活かす改造で投資額も抑えている」、2章⑤、4章① その３：（別紙３）投資総額の根拠 | G6: 「No.5 機械装置・システム構築費 既設SPM機（製袋機）改造部品・設計変更費 1式 3,600,000円」 「No.6 機械装置・システム構築費 現地改造工事費（工事〜調整〜生産立会 約11日） 4,100,000円」 | H6: よくあるご質問（第5〜8回、2026/08/18更新）「応募・交付申請」No.17は、改良・据付けが補助対象となるのは「本補助金で新たに購入・製作（構築）・借用した機械装置・システム」の改良・据付けに限られ、「既存の機械装置・システムの改良又は据付けに要する経費は対象外」と明記している。手引き5-3でも「改良＝本事業で新たに購入する機械装置・システムの機能を高める又は耐久性を増すもの」「据付け＝新たに購入する機械装置の設置と一体の軽微なもの（設置場所の整備工事・基礎工事は含まない）」とされる。 No.5は既設機（SPM機）の改造費そのもの、No.6も既設機の改造工事を含むため、補助対象外と判断されるリスクが高い（最大770万円、補助金換算で約385万円）。対象外の経費を補助対象に計上していると、交付申請時の減額だけでなく、審査で経費の妥当性に疑義を持たれる要因にもなる。 | I6: ①No.5は補助対象外経費として補助対象から外し、自己資金で実施する経費として別記する（税込の投資総額には含める）。 ②No.6はフジシールに「新設装置（ロボット・U字型コンベア）の据付・試運転調整・立会」と「既設SPM機の改造工事」に見積を分けてもらい、前者のみ計上する。 ③値引▲4,790,000円の配分も見積上で明確にする。 ④補助対象経費・補助金額・自己資金を再計算する（（４）表、2章⑤、4章①の調達表、その３（別紙３））。 ⑤判断に迷う場合は、事務局に「新設装置と接続するための既設機側の改造費」の扱いを事前に確認する。 | J6: 1-a、必須7 | K6: FAQ「応募・交付申請」No.17／公募要領3-2 機械装置・システム構築費③※4・※5／手引き5-3 p.43 | L6: 未対応
A7: 3 | B7: A | C7: ①③ | D7: 要件（経費区分） | E7: その１その２／申請システム | F7: （４）経費一覧No.4 | G7: 「No.4 運搬費 装置輸送費（車上渡し） 1式 300,000円」 | H7: 公募要領3-2・手引き5-3「２．運搬費」に「※購入時の機械装置の運搬料については、機械装置費に含めてください」とある。装置輸送費は購入する機械装置の運搬料なので、経費区分は「機械装置・システム構築費」が正しい。 | I7: （４）表No.4の経費区分を「機械装置・システム構築費」に変更する（申請システムの経費入力も同様）。 | J7: 1-a | K7: 公募要領3-2 運搬費の※／手引き5-3 p.44 | L7: 未対応
A8: 4 | B8: A | C8: ①②③ | D8: 論理・整合／説得力 | E8: その１その２／その３ | F8: その１その２：1-2①、2-2①「受注」行、2-2②Gライン部門単独、3章③、4章②各年度サマリ・【1】①顧客（断った案件）、6章①② その３：【算定根拠】①(1)、（別紙３）Gライン部門 | G8: 「本装置は製袋機の能力（150袋／分）を上げない。この規模の案件は、遅番を社員1名で回せることで生まれる稼働の余地で受ける」（4章【1】） 「キャパ不足で断っていた約4億円規模の案件（年800万袋×50円）を取り込み、1年目は前年比＋4.0％（＋460百万円）」（その３①） | H8: 1年目の増収（＋460百万円）の主な根拠は「生産能力不足で断った年800万袋（約4億円）の案件の取込み」だが、計画書自身が①装置は製袋機の能力を上げない、②稼働は17.5時間のまま（現状もカバー出勤で17.5時間稼働を維持）と明記しており、追加の800万袋をどの稼働で生産するのかが示されていない。 試算：現状のGライン生産量は（15万袋＋10万袋）÷2×245日≒3,063万袋/年で、800万袋はその約26%。追加後の必要日産は約15.77万袋となり、製袋機の理論上の最大能力（150袋/分×1,050分＝15.75万袋/日、段取り・停止ゼロ）を上回る。「遅番を社員1名で回せることで生まれる稼働の余地」が何袋分かの定量化もない。 審査（2-c・3-d・3-g）や口頭審査で「能力を上げないのになぜ増産できるのか」と問われるリスクが高い。1年目の全社増収460百万円はGライン売上（約14億円）の約33%に当たり、Gラインの寄与だけで説明するのは過大に見える。Gライン単独の投資回収期間（1.59年）も同じ前提に依存している。 | I8: 次のいずれか（または組合せ）で論理と数値を補強し、各所の表現を一貫させる。 (a) 現状の機会損失を定量化：派遣・カバー不足による遅番の短縮・停止日数、供給待ち・欠員による停止時間（○分/日）→導入後に回復する生産量（年○万袋）。 (b) 稼働日数の増加：投入担当の確保に左右されなくなることで土曜稼働等を月○日追加できる（年○万袋）なら計画に明記。 (c) 断った案件は既存顧客の増量・新アイテムとして段階的に受注（1年目は一部）と表現を改め、1年目＋4.0%の残りは全社の価格転嫁や他ライン（Eライン等）で説明。 修正箇所：2-2①受注行、2-2②Gライン部門単独、3章③、4章②・【1】、6章①②、その３①(1)・（別紙３）。数値はクライアント（生産部）に確認。 | J8: 2-c、3-d、3-g、口頭審査 | K8: その１その２ 2-2①・4章【1】／ヒアリングリストv5（生産量15万袋・10万袋、稼働8:30〜26:00）／数値照合シート「能力検証」 | L8: 未対応
A9: 5 | B9: A | C9: ①② | D9: 論理・整合（省力化指数の根拠） | E9: その１その２／その３／図 | F9: その１その２：1-3「▶1,050分のうち②〜⑦の1,030分は、本投資で無くなる作業」、2-1①「左の現状のうちオレンジの②〜⑦（1,030分）が無くなり」「・無くなる作業：開梱・片付け・ほぐし…計1,030分」、2-1④注記「現状の時間は…実作業を1日約131回のサイクルで積算」 図「パウチ供給工程のビフォーアフター」④「無くなる（投入の合間に継続）」 | G9: 上記に対し、2章②表「導入後②詰め…（現状②③は詰めに集約）」、その３（別紙２）「専用パレット（1,200袋）へ開梱・ほぐし・片付け込みで約2分／枚」 | H9: 開梱・片付け・ほぐしは導入後も「詰め」作業の中で行う（その３（別紙２）・2章②表・ヒアリング「ほぐしを含む」）のに、1-3・2-1・図では「無くなる作業」と書いており、計画書内・ファイル間で矛盾している。 特にほぐし563分は削減時間1,030分の約55%を占める省力化指数の中核だが、①563分の算定根拠（約8分サイクルのうち空になるまでの約5分×約131回≒656分から、搬入・開梱・片付け・切替の93分を除いた拘束時間）と、②導入後は2分/枚に含まれるほど短くなる理由が本文にない。 さらに131回×1,200袋≒15.7万袋/日は1品種の日・フル稼働相当で、2品種の日（10万袋）には当てはまらないため、「実作業を131回で積算した実績ベース」という注記とも整合しない。審査員に「待ち時間を作業時間として計上し、省力化指数を高く見せている」と受け取られるおそれがある（2-a「算出根拠の妥当性」）。 | I9: ①表現を統一：「削減される作業（②〜⑦、1,030分）のうち、開梱・片付け・ほぐしは導入後の『詰め』（2分/枚）に集約されて大幅に短縮し、踏み台の昇降・手投入・品種切替は無くなる」（1-3、2-1①、図の注記）。 ②ほぐしの根拠を追記：「投入担当は5分おきの投入に備えて持ち場を離れられず、投入間隔（約5分×約131回）のうち搬入・開梱等以外の時間はほぐしを続けている（ヒアリングで確認した実態）」。 ③2-1④の注記を「現状の時間は、投入担当の拘束時間（1,050分）を工程別に分解した値（1品種の日・フル稼働ベース）」に修正。 ④導入後に短くなる理由：「床の作業スペースで束単位にまとめてほぐしながら詰めるため、5分おきの小分け作業と待機がなくなる（フジシール資料・試作で2分/枚を確認）」。 | J9: 2-a | K9: その１その２ 1-3・2-1・2章②表／その３（別紙２）／ヒアリングリストv5／図元データ（pptx v3 p.7） | L9: 未対応
A10: 6 | B10: A | C10: ② | D10: 画像・図（要目視確認） | E10: その１その２（末尾の別紙スケジュール画像） | F10: 5章④末尾「全体スケジュールは別紙（次ページ）に示す」、最終ページの補助事業スケジュール | G10: （画像のため本文テキストでは確認できない） | H10: スケジュールの元ファイル「★20260930スケジュール（トンボ飲料様）.xlsx」の旧版（GitHubリポジトリ内・Dropboxのold/）には、別案件の内容（㈱HOPEE JAPAN、㈱Oyraa、CSチーム6名、AI判定（対応漏れ検知）、2027年12月本稼働、創出年約3,994時間 等）が残っている。 Dropboxの「20261001【更新版】★20260930スケジュール」はトンボ飲料様向けに修正済みだが、計画書に貼付された画像がどの版から作成されたかは確認できていない。他社名・他案件の内容が残っていると、計画書の使い回しと見なされ致命的になる。 | I10: 貼付画像を目視で確認し、更新版（2026/10/01 08:34版）から作成されていることを確認する。 あわせて画像内の日程（発注2027年5月、製作7〜9か月、納入・据付2027年12月〜2028年1月、検収2028年1月、実績報告2028年2月、決算日3月20日）と5章④表の一致、支払条件（契約時1/3・納入時1/3・検収後1/3）、「Eライン横展開の準備」（スケジュールのみに記載）の扱いを確認する。 | J10: 3-b、必須8 | K10: GitHubリポジトリ ★20260930スケジュール（トンボ飲料様）.xlsx（旧版）／Dropbox 20261001【更新版】スケジュール | L10: 未対応
A11: 7 | B11: A | C11: ①③ | D11: 論理・整合／審査上不利 | E11: その１その２／その３ | F11: その１その２：1-1 S4、3-1②、4章②表（人件費）・【3】人件費 その３：【算定根拠】③、（別紙４） | G11: 「2026年4月に総額約5%の賃上げを実施済みである。計画では保守的に、足下は年3%を上回る水準（年平均3.02%…）」（3-1②） 「進行期の+3%は、2026年4月に実施済みの賃上げ（総額約5%）より控えめに見込んだ」（4章【3】） 人件費：2026年3月期1,021,940,577円→2027年3月期1,028,861,760円 | H11: ①ヒアリングでは「2026年4月に人件費総額ベースで約5%の賃上げを実施」だが、計画の進行期（2027年3月期）は人件費総額+0.68%、1人当たり給与支給総額+3.02%で、既に実施した賃上げより低い。実施済みの賃上げを「保守的に見込む」という説明は不自然で、数表を見た審査員に整合しないと受け取られるおそれがある。 ②同じ進行期で給与支給総額は+9.85%（全月分支給者166名→177名）なのに人件費総額は+0.68%で、伸び率が大きく乖離して見える（母集団の変化が理由と推測されるが説明がない）。 ③第8回公募要領は「足下の賃上げ」を評価し、直近決算期→基準年度の年平均成長率が物価上昇率を上回る程度に達しない計画は「審査上大幅に不利」と明記している。3.02%は目安の3.0%をわずかに上回るだけで、実績（約5%）を反映すれば足下の評価を高められる余地がある。 | I11: クライアントに2026年4月改定の内容（定昇・ベア・賞与・手当、パート時給、対象者、1人当たりの改定率）を確認し、次のどちらかで整合させる。 (a) 進行期の1人当たり給与・人件費に実績を反映する（例：進行期+4〜5%→足下の年平均約3.5〜4%）。 (b) 3.02%とする理由（例：総額5%は賞与・法定福利費を含む人件費総額ベースで、新卒・中途の入替により全月分支給者の平均が下がる等）を3-1②に明記する。 あわせて給与支給総額+9.85%と人件費+0.68%の差の理由（全月分支給者166名→177名）を注記する。 ※本計画のモデル（原価率を売上比で固定）では人件費を増やしても付加価値額・労働生産性は下がらないが、営業利益は販管費の人件費分だけ減るため再計算が必要。ヒアリングメモでは「足下は3%で作成」の指示があるため、最終判断はクライアント確認のうえで行う。 | J11: 必須3、3-e、3-g | K11: 第8回公募要領5-1(3)（足下の賃上げ）／ヒアリングリストv5「5.賃上げの予定」／20260930ヒアリングMTGメモ／その３（別紙４）／数値照合シート | L11: 未対応
A12: 8 | B12: B | C12: ① | D12: 数値・出典 | E12: その１その２ | F12: 1-1 SWOT T3〔調達・物価〕 | G12: 「2025年の食品値上げは20,609品目、要因は原材料高90.7%・包装資材81.3%（帝国データバンク）」 | H12: 調査メモ（market_data.md A-5）では、20,609品目は「2025年通年」（帝国データバンク 2025/12/26）、原材料高90.7%は「2026年（9月時点）の値上げ要因」（同 2026/8/31）、包装・資材81.3%は「2026年1〜4月判明分の要因」（同 2025/12/26）で、年も調査も異なる数値を「2025年の要因」として混在させている。 | I12: 例：「2025年の食品値上げは20,609品目に達し、2026年も1〜4月判明分の値上げ要因の81.3%が包装・資材、66.0%が人件費である（帝国データバンク、2025年12月）」のように、年・調査を揃える。 | J12: 3-a | K12: market_data.md A-5（帝国データバンク 2025/12/26・2026/8/31） | L12: 未対応
A13: 9 | B13: B | C13: ① | D13: 数値・出典 | E13: その１その２ | F13: 1-1 SWOT T1〔労働市場〕、3章⑥地域雇用 | G13: 「県の製造業の労働力は2040年に▲23.1%と推計される（富山県）」 「製造業の労働力が2040年に▲23.1%と推計される中（T1）」 | H13: 出典（富山県「富山県独自の労働需給シミュレーション」2026年2月）の▲23.12%は、2040年の製造業の労働需要135,012人に対する供給不足▲31,213人の割合であり、「労働力が23.1%減る」という意味ではない。 | I13: 「県内製造業では2040年に需要の約23%（約3.1万人）の人手不足が見込まれる（富山県、2026年2月）」に修正する（2か所）。 | J13: 3-a、4-a | K13: labor_data.md（富山県 労働需給シミュレーション 2026/2/20） | L13: 未対応
A14: 10 | B14: B | C14: ①② | D14: 論理・整合 | E14: その１その２ | F14: 1-1 SWOT W1、1-2課題①（図の説明文） | G14: 「製袋機より後ろは機械化済みで、投入だけが手作業で残る」 「②以降のスパウトの圧着・検査・充填は、すでに機械が行っている」 | H14: その３（別紙１）・2-1では、充填（1名・1,050分）、包装・箱詰め（2〜3名・2,625分）を人手作業として計上しており、「製袋機より後ろは機械化済み」「投入だけが手作業」と矛盾して読める。 | I14: 「製袋室内では、製袋機（スパウトの熱圧着）・リークチェッカ・搬送は機械化済みで、空パウチの投入だけが手作業で残る」のように範囲を限定する。課題①の説明も「②以降の圧着・検査は機械が行っている（充填・包装の工程と人員は本事業で変わらない）」に修正。 | J14: 3-g | K14: その３（別紙１）／その１その２ 2-1 | L14: 未対応
A15: 11 | B15: B | C15: ③ | D15: 説得力 | E15: その１その２ | F15: 1-1 W3、1-2課題②、2-2①人員行、3章① | G15: 「遅番の投入担当は派遣で賄う想定だが確保できず、日勤社員のカバー出勤が常態化している」 | H15: 人手不足の中核である夜勤（遅番）の派遣不足・カバー出勤について、頻度（月○日）、カバーした社員の時間外・連続勤務、派遣の充足率・単価などの定量情報がない（ヒアリングでも回数は定性的な回答）。審査項目3-a「現に人手不足であることが説明されているか」では、採択事例も欠員数・残業時間等を数値で示している。 また派遣が来た日の遅番420分は社内人員の再配置ではなく派遣費の削減になるため、3章の配分（社員を品質管理・ODMへ）の原資の実在性にも関わる。 | I15: 直近1年の遅番の派遣充足状況を追記する（例：月○日は派遣不在→日勤社員がカバー、年○時間の時間外）。派遣費の削減見込みがあれば2-2①の効果にも加える。 | J15: 3-a、3-f | K15: ヒアリングリストv5「2.夜勤の担当者が確保できないとき」 | L15: 未対応
A16: 12 | B16: B | C16: ①② | D16: 数値・計算／論理・整合 | E16: その１その２／その３／図 | F16: （４）注記・2章主要仕様「24,000袋（約2時間分）」、1-3「約2時間に1回・約3分のパレット入替」、2-2①稼働行、その３（別紙２）「約2時間に1回」、図（投入作業のサイクル）「入替は約3分×4時間で2回」 | G16: 「ストック量 5段×4列＝20パレット＝24,000袋（約2時間分）」「約2時間に1回」 入替の計算は「1品種の日6回＝18分、2品種の日4回＝12分」 | H16: 24,000袋÷150袋/分＝160分（約2時間40分）で、1品種の日の平均消費（15万袋÷1,050分≒143袋/分）では約168分。入替回数の計算（1品種の日6回・2品種の日4回）とも「約2時間に1回」（1日約8.75回）は整合しない。 仮に2時間ごとなら入替は約26分/日となり、省力化指数は0.76〜0.77に下がる計算になるため、表現の不一致が省力化指数の信頼性に響く。 | I16: 「24,000袋（製袋機の最大能力150袋/分で約2時間40分分）」「約2.5〜3時間に1回（1品種の日6回・2品種の日4回）」等に統一する（本文・その３（別紙２）・図）。フジシール資料の「約2時間分」を残す場合は「余裕を見た目安」と注記し、入替回数の算定根拠（生産量÷24,000袋）を明記する。 | J16: 2-a | K16: 数値照合シート（ストック持続時間・入替間隔）／図元データ（pptx v3 p.6） | L16: 未対応
... A65: 61 | B65: 確認 | C65: ③ | D65: 画像（個人情報・数値） | E65: 図（当社の歴史と事業内容） | F65: 1．当社概要【当社の歴史と事業内容】の画像 | G65: （画像のため未確認） | H65: 公募要領4-5「事業内容に直接関係のない不必要な個人情報（社長・役員・従業員・顧客の顔写真等）は掲載しない」。画像に人物の顔写真が含まれていないか、画像内の数値（創業1896年、設立昭和37年、売上、拠点等）が本文と一致しているかを目視で確認する（本体ファイルを取得できていないため未確認）。 | I65: 顔写真があれば削除・差し替え。数値は本文と統一。 | J65: — | K65: 公募要領4-5 | L65: 未対応

Sheet 数値照合
A1: 数値照合（その１その２の記載値・その３の記載値を、元データから数式で再計算して照合）
A2: 青字＝計画書・その３からの転記値（入力値）、黒字＝再計算の数式。判定：再計算値との差が許容差以内なら「一致」、超えれば「不一致」、記載値がない行は「参考」。
A4: No | B4: 区分 | C4: 項目 | D4: その１その２の記載値 | E4: その３の記載値 | F4: 再計算値（数式） | G4: 単位 | H4: 許容差 | I4: 判定 | J4: 再計算の内容・備考 | K4: 関連指摘No.
A5: 1 | B5: 工程時間 | C5: 削減される業務（現状②〜⑦） | D5: 1030 | E5: 1030 | F5: =43+22+563+79+315+8 -> 1030 | G5: 分/日 | H5: 0.5 | I5: =IF(F5="","—",IF(COUNT(D5,E5)=0,"参考",IF(OR(AND(ISNUMBER(D5),ABS(N(D5)-F5)>H5),AND(ISNUMBER(E5),ABS(N(E5)-F5)>H5)),"不一致","一致"))) -> 一致 | J5: 開梱43＋片付け22＋ほぐし563＋昇降79＋手投入315＋品種切替8 | K5: —
A6: 2 | B6: 工程時間 | C6: 導入後に発生する業務（導入後②〜④） | D6: 231 | E6: 231 | F6: =209+15+7 -> 231 | G6: 分/日 | H6: 0.5 | I6: =IF(F6="","—",IF(COUNT(D6,E6)=0,"参考",IF(OR(AND(ISNUMBER(D6),ABS(N(D6)-F6)>H6),AND(ISNUMBER(E6),ABS(N(E6)-F6)>H6)),"不一致","一致"))) -> 一致 | J6: 詰め209＋装填・入替15＋型替え7 | K6: —
A7: 3 | B7: 工程時間 | C7: 削減時間（時間換算） | D7: 17.2 | E7: 17.2 | F7: =ROUND(F5/60,1) -> 17.2 | G7: 時間/日 | H7: 0.05 | I7: =IF(F7="","—",IF(COUNT(D7,E7)=0,"参考",IF(OR(AND(ISNUMBER(D7),ABS(N(D7)-F7)>H7),AND(ISNUMBER(E7),ABS(N(E7)-F7)>H7)),"不一致","一致"))) -> 一致 | J7: 1,030÷60 | K7: —
A8: 4 | B8: 工程時間 | C8: 発生時間（時間換算） | D8: 3.9 | E8: 3.9 | F8: =ROUND(F6/60,1) -> 3.9 | G8: 時間/日 | H8: 0.05 | I8: =IF(F8="","—",IF(COUNT(D8,E8)=0,"参考",IF(OR(AND(ISNUMBER(D8),ABS(N(D8)-F8)>H8),AND(ISNUMBER(E8),ABS(N(E8)-F8)>H8)),"不一致","一致"))) -> 一致 | J8: 231÷60 | K8: —
A9: 5 | B9: 工程時間 | C9: 省力化指数 | D9: 0.78 | E9: 0.78 | F9: =ROUND((F5-F6)/F5,2) -> 0.78 | G9: — | H9: 0.001 | I9: =IF(F9="","—",IF(COUNT(D9,E9)=0,"参考",IF(OR(AND(ISNUMBER(D9),ABS(N(D9)-F9)>H9),AND(ISNUMBER(E9),ABS(N(E9)-F9)>H9)),"不一致","一致"))) -> 一致 | J9: （1,030−231）÷1,030 | K9: —
A10: 6 | B10: 工程時間 | C10: 投入担当の拘束時間（早番＋中番＋遅番） | D10: 1050 | F10: =150+480+420 -> 1050 | G10: 分/日 | H10: 0 | I10: =IF(F10="","—",IF(COUNT(D10,E10)=0,"参考",IF(OR(AND(ISNUMBER(D10),ABS(N(D10)-F10)>H10),AND(ISNUMBER(E10),ABS(N(E10)-F10)>H10)),"不一致","一致"))) -> 一致 | J10: 8:30〜11:00＋11:00〜19:00＋19:00〜26:00 | K10: —
A11: 7 | B11: 工程時間 | C11: 現状①〜⑦の合計 | D11: 1050 | F11: =20+F5 -> 1050 | G11: 分/日 | H11: 0 | I11: =IF(F11="","—",IF(COUNT(D11,E11)=0,"参考",IF(OR(AND(ISNUMBER(D11),ABS(N(D11)-F11)>H11),AND(ISNUMBER(E11),ABS(N(E11)-F11)>H11)),"不一致","一致"))) -> 一致 | J11: 搬入20＋削減1,030 | K11: —
A12: 8 | B12: 工程時間 | C12: 導入後①〜④の合計 | D12: 251 | F12: =20+F6 -> 251 | G12: 分/日 | H12: 0 | I12: =IF(F12="","—",IF(COUNT(D12,E12)=0,"参考",IF(OR(AND(ISNUMBER(D12),ABS(N(D12)-F12)>H12),AND(ISNUMBER(E12),ABS(N(E12)-F12)>H12)),"不一致","一致"))) -> 一致 | J12: 搬入20＋新規231 | K12: —
A13: 9 | B13: 工程時間 | C13: 創出時間 | D13: 799 | F13: =F11-F12 -> 799 | G13: 分/日 | H13: 0 | I13: =IF(F13="","—",IF(COUNT(D13,E13)=0,"参考",IF(OR(AND(ISNUMBER(D13),ABS(N(D13)-F13)>H13),AND(ISNUMBER(E13),ABS(N(E13)-F13)>H13)),"不一致","一致"))) -> 一致 | J13: 1,050−251 | K13: —
A14: 10 | B14: 工程時間 | C14: 創出時間（年間） | D14: 3262 | F14: =ROUNDDOWN(F13/60*245,0) -> 3262 | G14: 人時/年 | H14: 1 | I14: =IF(F14="","—",IF(COUNT(D14,E14)=0,"参考",IF(OR(AND(ISNUMBER(D14),ABS(N(D14)-F14)>H14),AND(ISNUMBER(E14),ABS(N(E14)-F14)>H14)),"不一致","一致"))) -> 一致 | J14: 799÷60×245日（計画書は約3,262） | K14: —
A15: 11 | B15: 工程時間 | C15: 設備導入前の作業時間合計（別紙１） | E15: 96.3 | F15: =ROUND((1050+1050+1050+2625)/60,1) -> 96.3 | G15: 時間/日 | H15: 0.05 | I15: =IF(F15="","—",IF(COUNT(D15,E15)=0,"参考",IF(OR(AND(ISNUMBER(D15),ABS(N(D15)-F15)>H15),AND(ISNUMBER(E15),ABS(N(E15)-F15)>H15)),"不一致","一致"))) -> 一致 | J15: 投入1,050＋製袋機1,050＋充填1,050＋包装2,625 | K15: —
A16: 12 | B16: 工程時間 | C16: 設備導入後の作業時間合計（別紙１） | E16: 82.9 | F16: =ROUND((20+209+15+7+1050+1050+2625)/60,1) -> 82.9 | G16: 時間/日 | H16: 0.05 | I16: =IF(F16="","—",IF(COUNT(D16,E16)=0,"参考",IF(OR(AND(ISNUMBER(D16),ABS(N(D16)-F16)>H16),AND(ISNUMBER(E16),ABS(N(E16)-F16)>H16)),"不一致","一致"))) -> 一致 | J16: 搬入20＋新規231＋変化しない作業4,725 | K16: —
A17: 13 | B17: 工程時間 | C17: 投入サイクル回数 | D17: 131 | F17: =1050/8 -> 131.25 | G17: 回/日 | H17: 0.5 | I17: =IF(F17="","—",IF(COUNT(D17,E17)=0,"参考",IF(OR(AND(ISNUMBER(D17),ABS(N(D17)-F17)>H17),AND(ISNUMBER(E17),ABS(N(E17)-F17)>H17)),"不一致","一致"))) -> 一致 | J17: 1,050分÷8分＝131.25回 | K17: —
A18: 14 | B18: 工程時間 | C18: ⑤踏み台の昇降（0.6分×131回） | D18: 79 | E18: 79 | F18: =ROUND(0.6*131,0) -> 79 | G18: 分/日 | H18: 0 | I18: =IF(F18="","—",IF(COUNT(D18,E18)=0,"参考",IF(OR(AND(ISNUMBER(D18),ABS(N(D18)-F18)>H18),AND(ISNUMBER(E18),ABS(N(E18)-F18)>H18)),"不一致","一致"))) -> 一致 | J18: 0.6×131＝78.6→79 | K18: —
A19: 15 | B19: 工程時間 | C19: ⑥手投入（2.4分×131回） | D19: 315 | E19: 315 | F19: =2.4*131 -> 314.4 | G19: 分/日 | H19: 0.5 | I19: =IF(F19="","—",IF(COUNT(D19,E19)=0,"参考",IF(OR(AND(ISNUMBER(D19),ABS(N(D19)-F19)>H19),AND(ISNUMBER(E19),ABS(N(E19)-F19)>H19)),"不一致","一致"))) -> 不一致 | J19: 2.4×131＝314.4（315は131.25回で計算した値） | K19: No.34
A20: 16 | B20: 工程時間 | C20: ③空段ボールの片付け（43箱×0.5分） | D20: 22 | F20: =ROUND(43*0.5,0) -> 22 | G20: 分/日 | H20: 0 | I20: =IF(F20="","—",IF(COUNT(D20,E20)=0,"参考",IF(OR(AND(ISNUMBER(D20),ABS(N(D20)-F20)>H20),AND(ISNUMBER(E20),ABS(N(E20)-F20)>H20)),"不一致","一致"))) -> 一致 | J20: 21.5→22 | K20: —
A21: 17 | B21: 工程時間 | C21: ④ほぐし（投入間隔の残余） | D21: 563 | E21: 563 | F21: =ROUND(1050/8*5-(20+43+22+8),0) -> 563 | G21: 分/日 | H21: 0 | I21: =IF(F21="","—",IF(COUNT(D21,E21)=0,"参考",IF(OR(AND(ISNUMBER(D21),ABS(N(D21)-F21)>H21),AND(ISNUMBER(E21),ABS(N(E21)-F21)>H21)),"不一致","一致"))) -> 一致 | J21: 5分×131.25回−（搬入20＋開梱43＋片付け22＋切替8） | K21: No.5
A22: 18 | B22: 工程時間 | C22: 詰め：1品種の日 | D22: 250 | F22: =150000/1200*2 -> 250 | G22: 分/日 | H22: 0 | I22: =IF(F22="","—",IF(COUNT(D22,E22)=0,"参考",IF(OR(AND(ISNUMBER(D22),ABS(N(D22)-F22)>H22),AND(ISNUMBER(E22),ABS(N(E22)-F22)>H22)),"不一致","一致"))) -> 一致 | J22: 15万袋÷1,200袋×2分 | K22: —
A23: 19 | B23: 工程時間 | C23: 詰め：2品種の日 | D23: 168 | F23: =ROUNDUP(100000/1200,0)*2 -> 168 | G23: 分/日 | H23: 0 | I23: =IF(F23="","—",IF(COUNT(D23,E23)=0,"参考",IF(OR(AND(ISNUMBER(D23),ABS(N(D23)-F23)>H23),AND(ISNUMBER(E23),ABS(N(E23)-F23)>H23)),"不一致","一致"))) -> 一致 | J23: 10万袋÷1,200袋＝84枚×2分 | K23: —
A24: 20 | B24: 工程時間 | C24: 詰め：平均 | D24: 209 | E24: 209 | F24: =(F22+F23)/2 -> 209 | G24: 分/日 | H24: 0 | I24: =IF(F24="","—",IF(COUNT(D24,E24)=0,"参考",IF(OR(AND(ISNUMBER(D24),ABS(N(D24)-F24)>H24),AND(ISNUMBER(E24),ABS(N(E24)-F24)>H24)),"不一致","一致"))) -> 一致 | J24: （250＋168）÷2 | K24: —
A25: 21 | B25: 工程時間 | C25: 入替：1品種の日 | D25: 18 | F25: =ROUNDDOWN(150000/24000,0)*3 -> 18 | G25: 分/日 | H25: 0 | I25: =IF(F25="","—",IF(COUNT(D25,E25)=0,"参考",IF(OR(AND(ISNUMBER(D25),ABS(N(D25)-F25)>H25),AND(ISNUMBER(E25),ABS(N(E25)-F25)>H25)),"不一致","一致"))) -> 一致 | J25: 15万袋÷24,000袋＝6回×3分 | K25: —
A26: 22 | B26: 工程時間 | C26: 入替：2品種の日 | D26: 12 | F26: =ROUNDDOWN(100000/24000,0)*3 -> 12 | G26: 分/日 | H26: 0 | I26: =IF(F26="","—",IF(COUNT(D26,E26)=0,"参考",IF(OR(AND(ISNUMBER(D26),ABS(N(D26)-F26)>H26),AND(ISNUMBER(E26),ABS(N(E26)-F26)>H26)),"不一致","一致"))) -> 一致 | J26: 10万袋÷24,000袋＝4回×3分 | K26: —
A27: 23 | B27: 工程時間 | C27: 入替：平均 | D27: 15 | E27: 15 | F27: =(F25+F26)/2 -> 15 | G27: 分/日 | H27: 0 | I27: =IF(F27="","—",IF(COUNT(D27,E27)=0,"参考",IF(OR(AND(ISNUMBER(D27),ABS(N(D27)-F27)>H27),AND(ISNUMBER(E27),ABS(N(E27)-F27)>H27)),"不一致","一致"))) -> 一致 | J27: （18＋12）÷2 | K27: —
A28: 24 | B28: 工程時間 | C28: 型替え：月平均 | D28: 7 | E28: 7 | F28: =ROUND(25*1.1,0)/4 -> 7 | G28: 分/日 | H28: 0 | I28: =IF(F28="","—",IF(COUNT(D28,E28)=0,"参考",IF(OR(AND(ISNUMBER(D28),ABS(N(D28)-F28)>H28),AND(ISNUMBER(E28),ABS(N(E28)-F28)>H28)),"不一致","一致"))) -> 一致 | J28: 25枚×1.1分≒28分×（2品種の日の半数＝全稼働日の1/4） | K28: No.13
A29: 25 | B29: 工程時間 | C29: ストック24,000袋の持続時間（記載「約2時間分」＝120分） | D29: 120 | E29: 120 | F29: =24000/150 -> 160 | G29: 分 | H29: 15 | I29: =IF(F29="","—",IF(COUNT(D29,E29)=0,"参考",IF(OR(AND(ISNUMBER(D29),ABS(N(D29)-F29)>H29),AND(ISNUMBER(E29),ABS(N(E29)-F29)>H29)),"不一致","一致"))) -> 不一致 | J29: 最大能力150袋/分で160分（約2時間40分） | K29: No.12
A30: 26 | B30: 工程時間 | C30: 1品種の日の入替間隔（記載「約2時間に1回」＝120分） | D30: 120 | E30: 120 | F30: =1050/ROUNDDOWN(150000/24000,0) -> 175 | G30: 分 | H30: 15 | I30: =IF(F30="","—",IF(COUNT(D30,E30)=0,"参考",IF(OR(AND(ISNUMBER(D30),ABS(N(D30)-F30)>H30),AND(ISNUMBER(E30),ABS(N(E30)-F30)>H30)),"不一致","一致"))) -> 不一致 | J30: 1,050分÷6回＝175分 | K30: No.12
A31: 27 | B31: 工程時間 | C31: 遅番で使うパレット（1品種の日） | D31: 50 | F31: =150000/1050*420/1200 -> 50 | G31: 枚 | H31: 0.5 | I31: =IF(F31="","—",IF(COUNT(D31,E31)=0,"参考",IF(OR(AND(ISNUMBER(D31),ABS(N(D31)-F31)>H31),AND(ISNUMBER(E31),ABS(N(E31)-F31)>H31)),"不一致","一致"))) -> 一致 | J31: 15万袋÷1,050分×420分÷1,200袋 | K31: —
A32: 28 | B32: 投資・回収 | C32: 補助対象経費の小計 | D32: 96790000 | F32: =55250000+31500000+2040000+300000+3600000+4100000 -> 96790000 | G32: 円 | H32: 0 | I32: =IF(F32="","—",IF(COUNT(D32,E32)=0,"参考",IF(OR(AND(ISNUMBER(D32),ABS(N(D32)-F32)>H32),AND(ISNUMBER(E32),ABS(N(E32)-F32)>H32)),"不一致","一致"))) -> 一致 | J32: No.1〜6の合計 | K32: —
A33: 29 | B33: 投資・回収 | C33: 補助対象経費（値引後） | D33: 92000000 | F33: =F32-4790000 -> 92000000 | G33: 円 | H33: 0 | I33: =IF(F33="","—",IF(COUNT(D33,E33)=0,"参考",IF(OR(AND(ISNUMBER(D33),ABS(N(D33)-F33)>H33),AND(ISNUMBER(E33),ABS(N(E33)-F33)>H33)),"不一致","一致"))) -> 一致 | J33: 小計−値引4,790,000 | K33: —
A34: 30 | B34: 投資・回収 | C34: 補助金額（補助率1/2） | D34: 46000000 | F34: =F33/2 -> 46000000 | G34: 円 | H34: 0 | I34: =IF(F34="","—",IF(COUNT(D34,E34)=0,"参考",IF(OR(AND(ISNUMBER(D34),ABS(N(D34)-F34)>H34),AND(ISNUMBER(E34),ABS(N(E34)-F34)>H34)),"不一致","一致"))) -> 一致 | J34: 上限8,000万円（101人以上）以内 | K34: No.2
A35: 31 | B35: 投資・回収 | C35: 投資総額（税込） | D35: 101200000 | E35: 101200000 | F35: =F33*1.1 -> 101200000 | G35: 円 | H35: 0 | I35: =IF(F35="","—",IF(COUNT(D35,E35)=0,"参考",IF(OR(AND(ISNUMBER(D35),ABS(N(D35)-F35)>H35),AND(ISNUMBER(E35),ABS(N(E35)-F35)>H35)),"不一致","一致"))) -> 一致 | J35: 92,000,000×1.1（ユーティリティ工事等は未計上） | K35: No.15
A36: 32 | B36: 投資・回収 | C36: 自己資金（投資総額−補助金） | D36: 55200000 | F36: =F35-F34 -> 55200000 | G36: 円 | H36: 0 | I36: =IF(F36="","—",IF(COUNT(D36,E36)=0,"参考",IF(OR(AND(ISNUMBER(D36),ABS(N(D36)-F36)>H36),AND(ISNUMBER(E36),ABS(N(E36)-F36)>H36)),"不一致","一致"))) -> 一致 | J36: 4章①の自己資金 | K36: —
A37: 33 | B37: 投資・回収 | C37: 人件費単価 | D37: 2773 | E37: 2773 | F37: =ROUNDDOWN(1021940577/(188*245*8),0) -> 2773 | G37: 円/時 | H37: 0 | I37: =IF(F37="","—",IF(COUNT(D37,E37)=0,"参考",IF(OR(AND(ISNUMBER(D37),ABS(N(D37)-F37)>H37),AND(ISNUMBER(E37),ABS(N(E37)-F37)>H37)),"不一致","一致"))) -> 一致 | J37: 総人件費÷（188名×245日×8時間） | K37: —
A38: 34 | B38: 投資・回収 | C38: 労働時間削減額 | D38: 9047144 | E38: 9047144 | F38: =ROUND(799/60*245*F37,0) -> 9047144 | G38: 円/年 | H38: 1 | I38: =IF(F38="","—",IF(COUNT(D38,E38)=0,"参考",IF(OR(AND(ISNUMBER(D38),ABS(N(D38)-F38)>H38),AND(ISNUMBER(E38),ABS(N(E38)-F38)>H38)),"不一致","一致"))) -> 一致 | J38: 799÷60×245×2,773 | K38: —
A39: 35 | B39: 投資・回収 | C39: 増加した付加価値額（3年間の総額） | D39: 297960717 | E39: 297960717 | F39: =1891288147-1593327430 -> 297960717 | G39: 円 | H39: 0 | I39: =IF(F39="","—",IF(COUNT(D39,E39)=0,"参考",IF(OR(AND(ISNUMBER(D39),ABS(N(D39)-F39)>H39),AND(ISNUMBER(E39),ABS(N(E39)-F39)>H39)),"不一致","一致"))) -> 一致 | J39: 3年目−基準年度 | K39: —
A40: 36 | B40: 投資・回収 | C40: 投資回収期間（計画の主値：3年間の総額で計算） | D40: 0.33 | E40: 0.33 | F40: =ROUND(F35/(F38+F39),2) -> 0.33 | G40: 年 | H40: 0.001 | I40: =IF(F40="","—",IF(COUNT(D40,E40)=0,"参考",IF(OR(AND(ISNUMBER(D40),ABS(N(D40)-F40)>H40),AND(ISNUMBER(E40),ABS(N(E40)-F40)>H40)),"不一致","一致"))) -> 一致 | J40: 101,200,000÷（9,047,144＋297,960,717） | K40: No.1
A41: 37 | B41: 投資・回収 | C41: 投資回収期間（手引き方式：1年あたりで計算） | D41: 0.93 | E41: 0.93 | F41: =ROUND(F35/(F38+F39/3),2) -> 0.93 | G41: 年 | H41: 0.001 | I41: =IF(F41="","—",IF(COUNT(D41,E41)=0,"参考",IF(OR(AND(ISNUMBER(D41),ABS(N(D41)-F41)>H41),AND(ISNUMBER(E41),ABS(N(E41)-F41)>H41)),"不一致","一致"))) -> 一致 | J41: 101,200,000÷（9,047,144＋297,960,717÷3）※手引きp.60記入例の方法 | K41: No.1
...

Sheet 審査項目カバレッジ
A1: 審査項目カバレッジ（【更新版】省力化投資補助金_審査項目分析表の全項目と計画書の対応）
A2: 評価：◎十分に対応／○概ね対応（軽微な補強余地）／△補強が必要／×未対応／確認＝手続き・事実の確認が必要／対象外
A4: 審査大分類 | B4: No | C4: 審査項目（要約） | D4: 重要度（分析表） | E4: 計画書の対応箇所 | F4: 評価 | G4: 評価コメント | H4: 関連指摘No.
A5: 前提・必須要件 | B5: 必須1 | C5: 事業計画名（30字程度）・概要（100字程度） | D5: ★★★ | E5: （２）事業計画名、（３）概要 | F5: ◎ | G5: 名称31字・概要108字で「課題→解決策→効果」の構成。概要の「1日」重複のみ表現の改善余地。 | H5: No.25
A6: 前提・必須要件 | B6: 必須2 | C6: 労働生産性の年平均成長率4.0%以上（毎年） | D6: ★★★ | E6: 3-1①、4章②、その３②・（別紙４） | F6: ○ | G6: 4.53%／4.10%／4.06%（4・5年目4.07%／4.13%）で毎年要件を満たす。3年目の余裕が小さく、原価率改善の根拠補強が望ましい。 | H6: No.18
A7: 前提・必須要件 | B7: 必須3 | C7: 1人当たり給与支給総額の年平均成長率3.5%以上 | D7: ★★★ | E7: 3-1②、その３③・（別紙４） | F7: ○ | G7: 3.52%で要件を充足、足下3.02%。実施済み賃上げ（約5%）との整合、足下の評価向上の余地あり。 | H7: No.7、No.19
A8: 前提・必須要件 | B8: 必須4 | C8: 事業場内最低賃金が県最低賃金＋30円以上 | D8: ★★★ | E8: 3-1③ | F8: ○ | G8: 現状1,140円（県1,119円＋21円）→2027年3月までに1,150円以上へ引上げ。判定時点（毎年3月末）も正しく記載。 | H8: —
A9: 前提・必須要件 | B9: 必須5 | C9: 一般事業主行動計画の公表（21名以上） | D9: ★★★ | E9: 計画書に記載なし（申請システムで公表URL／宣誓） | F9: 確認 | G9: 交付申請時点で有効な計画の公表が必要。 | H9: No.58
A10: 前提・必須要件 | B10: 必須6 | C10: 3〜5年の事業計画 | D10: ★★ | E10: 4章、その３【事業計画年数】 | F10: ◎ | G10: 3年（2029年3月期〜2031年3月期）、基準年度2028年3月期（完了日を含む決算期）と正しく設定。 | H10: —
A11: 前提・必須要件 | B11: 必須7 | C11: 見積書等（仕様・積算根拠）の添付 | D11: ★★★ | E11: （４）、2章②③ | F11: ○ | G11: フジシール見積（2026/9/24）取得済み。最終版見積との一致、補助対象外経費の切り分けが必要。 | H11: No.2、No.17、No.52
A12: 前提・必須要件 | B12: 必須8 | C12: 作成支援者の記載 | D12: ★★★ | E12: 5章② | F12: ○ | G12: ライズウィルを記載し、口頭審査は事業者自身が対応と明記。申請システムへの報酬・契約期間の入力を確認。 | H12: No.56
A13: 1.適格性 | B13: 1-a | C13: 対象事業・対象者・申請要件の充足 | D13: ★★★ | E13: 全体 | F13: ○ | G13: 人手不足の解消が主目的であることが明確。ただし補助対象外となり得る経費（既設機の改造、運搬費の区分、台車）がある。 | H13: No.2、No.3、No.16
A14: 2.技術面 | B14: 2-a | C14: 省力化指数（高さ・算出根拠の妥当性） | D14: ★★★ | E14: 1-3、2-1④、その３（別紙１・２） | F14: ○ | G14: 0.78で、工程別表・図・別紙が一貫。「無くなる作業」の表現の矛盾、ほぐし563分の根拠、入替間隔・型替えの前提の補強が必要。 | H14: No.5、No.12、No.13
A15: 2.技術面 | B15: 2-b | C15: 投資回収期間（短さ・算出根拠の妥当性） | D15: ★★★ | E15: 2-2②、その３（別紙３） | F15: △ | G15: 0.33年は手引きの記入例（1年あたりの付加価値増加額）と算定方法が異なる。手引きの方法でも0.93年で1年未満。 | H15: No.1、No.15
... A44: 減点項目 | B44: 減点2 | C44: 過剰投資の抑制（他の助成制度の利用実績） | D44: — | E44: 6章③ | F44: 確認 | G44: 他の助成制度の利用実績確認書に、ものづくり補助金21次（グローバル枠）の採択実績を記載。 | H44: No.58

Sheet 画像確認状況
A1: 画像確認状況（その１その２に貼付された図・写真）
A2: 本体ファイル（docx）のダウンロードがこの環境のネットワーク設定で拒否されたため、図の元データ（★0930Gライン_レイアウト工程ビフォーアフター_トンボ飲料様_v3.pptx）を画像化して図中の文字・数値を確認しました。貼付画像そのものの最終確認は、本体ファイル取得後に実施が必要です。
A4: No | B4: 貼付位置（その１その２） | C4: 図・画像の内容（見出し） | D4: 元データ | E4: 確認状況 | F4: 確認結果・指摘 | G4: 関連指摘No.
A5: 1 | B5: （４）経費一覧の下 | C5: パウチ自動供給装置 平面図（生産開始時：5段積×4列＋予備1列） | D5: フジシール提案資料（推定） | E5: 未確認 | F5: 本体ファイル取得後に確認：段数・列数・袋数（24,000袋）・寸法の表記が本文と一致しているか。 | G5: —
A6: 2 | B6: （４）経費一覧の下 | C6: 同 側面図（ロボットアームとパレット搬送） | D6: フジシール提案資料（推定） | E6: 未確認 | F6: 同上。 | G6: —
A7: 3 | B7: 1．当社概要 | C7: 当社の歴史と事業内容 | D7: 不明 | E7: 未確認 | F7: 顔写真等の不要な個人情報がないか、年号・数値（創業1896年、設立昭和37年、売上等）が本文と一致しているか。 | G7: No.61
A8: 4 | B8: 1-2 課題① | C8: パウチとスパウト（ストロー）、製袋機で行う工程 | D8: pptx v3 p.3 | E8: 元データで確認済 | F8: 工程（①空パウチ→②熱圧着→③リークチェッカ→④充填）と150袋／分は本文と一致。「①」が左右に2つある、他社Webサイトの写真の転載、用語欄の重なり（描画時）。 | G8: No.36、No.59、No.60
A9: 5 | B9: 1-3 冒頭 | C9: 本事業の対象範囲：Gライン全体の流れと人の配置 | D9: pptx v3 p.2 | E9: 元データで確認済 | F9: 人数（製袋室2名・充填1名・包装2〜3名）、稼働8:30〜26:00、シフト、15万／10万袋、150袋／分、売上約14億円・約13%は本文と一致。創出時間の再配分先が3章（5領域）と一部不一致。 | G9: No.44
A10: 6 | B10: 1-3 ① | C10: 投入作業のサイクル：3分詰めて5分で空、の繰り返し | D10: pptx v3 p.6 | E10: 元データで確認済 | F10: 131回、150／480／420分、250／168／209分、18／12分、799分、0.78は本文・別紙1と一致。「約2時間分」「4時間で2回」が入替6回／4回の計算と不一致。「1,050分→251分／日」の改行崩れ（描画時）。 | G10: No.12、No.60
A11: 7 | B11: 2-1 ① | C11: パウチ供給工程のビフォーアフター（1日あたりの人手作業時間） | D11: pptx v3 p.7 | E11: 元データで確認済 | F11: 各工程の分数は別紙1と一致。④ほぐし「無くなる」が、導入後の詰め（ほぐし込み）と矛盾。2.4分×131回の表記。 | G11: No.5、No.34
A12: 8 | B12: 2-1 ② | C12: 製袋室のレイアウト ビフォーアフター | D12: pptx v3 p.4 | E12: 元データで確認済 | F12: 記号a〜i、工程番号（②③⑤）は本文と一致。「h.専用パレット」の文字とパレット図形の重なり、凡例の改行（描画時）。 | G12: No.60
A13: 9 | B13: 2-1 ③ | C13: シフト別の人の配置と作業時間の変化 | D13: pptx v3 p.8 | E13: 元データで確認済 | F13: 150／480／420、100／18、380／462、288／214、762／836は本文と一致。遅番の現状担当「派遣1名」の表現、380／462分の定義、合計行と注記の重なり（描画時）。 | G13: No.21、No.40、No.60
A14: 10 | B14: 5章①（図がある場合） | C14: 社内の実施体制 | D14: 不明 | E14: 未確認 | F14: 氏名・役職が表と一致しているか、代表者の位置付け。 | G14: No.22
A15: 11 | B15: 末尾（別紙） | C15: 補助事業のスケジュール | D15: スケジュール.xlsx | E15: 未確認（最重要） | F15: 旧版に他社案件の内容（㈱HOPEE JAPAN等）が残っている。更新版（2026/10/01版）から作成されているかを必ず確認。 | G15: No.6
A16: 12 | B16: （貼付していれば） | C16: 各機械の役割（pptx p.5）／設備の概要と見積の構成（pptx p.9） | D16: pptx v3 p.5・p.9 | E16: 元データで確認済 | F16: 本文に同等の表があるため貼付していない想定。p.9を貼付している場合は「見積は値引き行の削除と名称の修正を依頼中」等の社内向けの記載が残らないよう注意。 | G16: No.17
... A18: 14 | B18: — | C18: 上記以外に貼付された図・写真 | D18: — | E18: 未確認 | F18: 本体ファイル取得後に全図を確認。 | G18: —
