Workbook

Sheet Sheet1
A1: 【前提①】売上高 成長率（対前年） | C1: 0.015 | D1: 0.015 | E1: 0.04 | F1: 0.04 | G1: 0.04 | H1: 0.04 | I1: 0.04
A2: 【前提②】売上原価率（対売上高） | B2: =B8/B7 -> 0.90588833 | C2: 0.9057 | D2: 0.905 | E2: 0.9025 | F2: 0.9 | G2: 0.8975 | H2: 0.8945 | I2: 0.8915
A3: 【前提③】その他販管費率（対売上高） | B3: =B28/B7 -> 0.047702148 | C3: 0.0477 | D3: 0.0477 | E3: 0.0477 | F3: 0.0477 | G3: 0.0477 | H3: 0.0477 | I3: 0.0477
A4: 【前提④】1人当たり賃上げ率（対前年） | C4: 0.03 | D4: 0.03 | E4: 0.035 | F4: 0.035 | G4: 0.035 | H4: 0.035 | I4: 0.035
A5: 【前提⑤】本事業設備の減価償却費 | C5: 0 | D5: 0 | E5: 9200000 | F5: 9200000 | G5: 9200000 | H5: 9200000 | I5: 9200000
A6: 収支詳細 | B6: 直近年度 2026年3月 | C6: 進行期 2027年3月 | D6: 基準年度 2028年3月 | E6: 1年目 2029年3月 | F6: 2年目 2030年3月 | G6: 3年目 2031年3月 | H6: 4年目（目標値） 2032年3月 | I6: 5年目（目標値） 2033年3月 | J6: ※事業計画期間は3年。4・5年目は目標値として策定（よくあるご質問No.8：目標値は5年目まで必要）。別紙４のJ・K列へ転記。
A7: ①売上高 | B7: =人件費・給与支給総額!J4 -> 11168904537 | C7: =ROUND(B7*(1+C$1),0) -> 11336438105 | D7: =ROUND(C7*(1+D$1),0) -> 11506484677 | E7: =ROUND(D7*(1+E$1),0) -> 11966744064 | F7: =ROUND(E7*(1+F$1),0) -> 12445413827 | G7: =ROUND(F7*(1+G$1),0) -> 12943230380 | H7: =ROUND(G7*(1+H$1),0) -> 13460959595 | I7: =ROUND(H7*(1+I$1),0) -> 13999397979
A8: 売上原価 | B8: =人件費・給与支給総額!J6 -> 10117780260 | C8: =ROUND(C7*C$2,0) -> 10267411992 | D8: =ROUND(D7*D$2,0) -> 10413368633 | E8: =ROUND(E7*E$2,0) -> 10799986518 | F8: =ROUND(F7*F$2,0) -> 11200872444 | G8: =ROUND(G7*G$2,0) -> 11616549266 | H8: =ROUND(H7*H$2,0) -> 12040828358 | I8: =ROUND(I7*I$2,0) -> 12480463298
A9: （原価率） | B9: =B8/B7 -> 0.90588833 | C9: =C8/C7 -> 0.9057 | D9: =D8/D7 -> 0.905 | E9: =E8/E7 -> 0.9025 | F9: =F8/F7 -> 0.9 | G9: =G8/G7 -> 0.8975 | H9: =H8/H7 -> 0.8945 | I9: =I8/I7 -> 0.8915
A10: └うち人件費 | B10: =人件費・給与支給総額!C10 -> 733251723 | C10: =ROUND(C33*$B$10/$B$33,0) -> 738217735 | D10: =ROUND(D33*$B$10/$B$33,0) -> 775037872 | E10: =ROUND(E33*$B$10/$B$33,0) -> 813002830 | F10: =ROUND(F33*$B$10/$B$33,0) -> 857041779 | G10: =ROUND(G33*$B$10/$B$33,0) -> 898766289 | H10: =ROUND(H33*$B$10/$B$33,0) -> 947034354 | I10: =ROUND(I33*$B$10/$B$33,0) -> 992861369
A11: └うち役員給与支給総額 | B11: =人件費・給与支給総額!C11 -> 0 | C11: =C12+C13 -> 0 | D11: =D12+D13 -> 0 | E11: =E12+E13 -> 0 | F11: =F12+F13 -> 0 | G11: =G12+G13 -> 0 | H11: =H12+H13 -> 0 | I11: =I12+I13 -> 0
A12: └うち賞与 | B12: =人件費・給与支給総額!C12 -> 0 | C12: =B12 -> 0 | D12: =C12 -> 0 | E12: =D12 -> 0 | F12: =E12 -> 0 | G12: =F12 -> 0 | H12: =G12 -> 0 | I12: =H12 -> 0
A13: └うち給与・賃金 | B13: =人件費・給与支給総額!C13 -> 0 | C13: =B13 -> 0 | D13: =C13 -> 0 | E13: =D13 -> 0 | F13: =E13 -> 0 | G13: =F13 -> 0 | H13: =G13 -> 0 | I13: =H13 -> 0
A14: └うち従業員給与支給総額 | B14: =人件費・給与支給総額!C14 -> 620349460 | C14: =C15+C16 -> 624839282 | D14: =D15+D16 -> 658128742 | E14: =E15+E16 -> 692453246 | F14: =F15+F16 -> 732269307 | G14: =G15+G16 -> 769992862 | H14: =H15+H16 -> 813632509 | I14: =I15+I16 -> 855065180
A15: └うち賞与 | B15: =人件費・給与支給総額!C15 -> 153907318 | C15: =ROUND(B15*(1+C$4)*C$42/B$42,0) -> 155021233 | D15: =ROUND(C15*(1+D$4)*D$42/C$42,0) -> 163280274 | E15: =ROUND(D15*(1+E$4)*E$42/D$42,0) -> 171796107 | F15: =ROUND(E15*(1+F$4)*F$42/E$42,0) -> 181674383 | G15: =ROUND(F15*(1+G$4)*G$42/F$42,0) -> 191033513 | H15: =ROUND(G15*(1+H$4)*H$42/G$42,0) -> 201860412 | I15: =ROUND(H15*(1+I$4)*I$42/H$42,0) -> 212139765
A16: └うち給与・賃金 | B16: =人件費・給与支給総額!C16 -> 466442142 | C16: =ROUND(B16*(1+C$4)*C$42/B$42,0) -> 469818049 | D16: =ROUND(C16*(1+D$4)*D$42/C$42,0) -> 494848468 | E16: =ROUND(D16*(1+E$4)*E$42/D$42,0) -> 520657139 | F16: =ROUND(E16*(1+F$4)*F$42/E$42,0) -> 550594924 | G16: =ROUND(F16*(1+G$4)*G$42/F$42,0) -> 578959349 | H16: =ROUND(G16*(1+H$4)*H$42/G$42,0) -> 611772097 | I16: =ROUND(H16*(1+I$4)*I$42/H$42,0) -> 642925415
A17: └うち減価償却費 | B17: =人件費・給与支給総額!J11 -> 274032833 | C17: =$B$17+C5 -> 274032833 | D17: =$B$17+D5 -> 274032833 | E17: =$B$17+E5 -> 283232833 | F17: =$B$17+F5 -> 283232833 | G17: =$B$17+G5 -> 283232833 | H17: =$B$17+H5 -> 283232833 | I17: =$B$17+I5 -> 283232833
A18: 粗利 | B18: =B7-B8 -> 1051124277 | C18: =C7-C8 -> 1069026113 | D18: =D7-D8 -> 1093116044 | E18: =E7-E8 -> 1166757546 | F18: =F7-F8 -> 1244541383 | G18: =G7-G8 -> 1326681114 | H18: =H7-H8 -> 1420131237 | I18: =I7-I8 -> 1518934681
A19: 販管費 | B19: 846301227 | C19: =C20+C27+C28 -> 856223758 | D19: =D20+D27+D28 -> 878831451 | E19: =E20+E27+E28 -> 915733024 | F19: =F20+F27+F28 -> 955904165 | G19: =G20+G27+G28 -> 996077390 | H19: =H20+H27+H28 -> 1039776714 | I19: =I20+I27+I28 -> 1083502800
A20: └うち人件費 | B20: =人件費・給与支給総額!C28 -> 288688854 | C20: =C33-C10 -> 290644025 | D20: =D33-D10 -> 305140497 | E20: =E33-E10 -> 320087697 | F20: =F33-F10 -> 337426290 | G20: =G33-G10 -> 353853666 | H20: =H33-H10 -> 372857306 | I20: =I33-I10 -> 390899881
A21: └うち役員給与支給総額 | B21: =人件費・給与支給総額!C29 -> 65655000 | C21: =C22+C23 -> 65655000 | D21: =D22+D23 -> 65655000 | E21: =E22+E23 -> 65655000 | F21: =F22+F23 -> 65655000 | G21: =G22+G23 -> 65655000 | H21: =H22+H23 -> 65655000 | I21: =I22+I23 -> 65655000
A22: └うち賞与 | B22: =人件費・給与支給総額!C30 -> 0 | C22: =B22 -> 0 | D22: =C22 -> 0 | E22: =D22 -> 0 | F22: =E22 -> 0 | G22: =F22 -> 0 | H22: =G22 -> 0 | I22: =H22 -> 0
A23: └うち給与・賃金 | B23: =人件費・給与支給総額!C31 -> 65655000 | C23: =B23 -> 65655000 | D23: =C23 -> 65655000 | E23: =D23 -> 65655000 | F23: =E23 -> 65655000 | G23: =F23 -> 65655000 | H23: =G23 -> 65655000 | I23: =H23 -> 65655000
A24: └うち従業員給与支給総額 | B24: =人件費・給与支給総額!C32 -> 173507534 | C24: =C25+C26 -> 174763306 | D24: =D25+D26 -> 184074142 | E24: =E25+E26 -> 193674473 | F24: =F25+F26 -> 204810756 | G24: =G25+G26 -> 215361778 | H24: =H25+H26 -> 227567492 | I24: =I25+I26 -> 239155929
A25: └うち賞与 | B25: =人件費・給与支給総額!C33 -> 50163729 | C25: =ROUND(B25*(1+C$4)*C$42/B$42,0) -> 50526792 | D25: =ROUND(C25*(1+D$4)*D$42/C$42,0) -> 53218700 | E25: =ROUND(D25*(1+E$4)*E$42/D$42,0) -> 55994305 | F25: =ROUND(E25*(1+F$4)*F$42/E$42,0) -> 59213978 | G25: =ROUND(F25*(1+G$4)*G$42/F$42,0) -> 62264443 | H25: =ROUND(G25*(1+H$4)*H$42/G$42,0) -> 65793305 | I25: =ROUND(H25*(1+I$4)*I$42/H$42,0) -> 69143703
A26: └うち給与・賃金 | B26: =人件費・給与支給総額!C34 -> 123343805 | C26: =ROUND(B26*(1+C$4)*C$42/B$42,0) -> 124236514 | D26: =ROUND(C26*(1+D$4)*D$42/C$42,0) -> 130855442 | E26: =ROUND(D26*(1+E$4)*E$42/D$42,0) -> 137680168 | F26: =ROUND(E26*(1+F$4)*F$42/E$42,0) -> 145596778 | G26: =ROUND(F26*(1+G$4)*G$42/F$42,0) -> 153097335 | H26: =ROUND(G26*(1+H$4)*H$42/G$42,0) -> 161774187 | I26: =ROUND(H26*(1+I$4)*I$42/H$42,0) -> 170012226
A27: └うち減価償却費 | B27: =人件費・給与支給総額!J12 -> 24831635 | C27: =$B$27 -> 24831635 | D27: =$B$27 -> 24831635 | E27: =$B$27 -> 24831635 | F27: =$B$27 -> 24831635 | G27: =$B$27 -> 24831635 | H27: =$B$27 -> 24831635 | I27: =$B$27 -> 24831635
A28: └その他販管費 | B28: =B19-B20-B27 -> 532780738 | C28: =ROUND(C7*C$3,0) -> 540748098 | D28: =ROUND(D7*D$3,0) -> 548859319 | E28: =ROUND(E7*E$3,0) -> 570813692 | F28: =ROUND(F7*F$3,0) -> 593646240 | G28: =ROUND(G7*G$3,0) -> 617392089 | H28: =ROUND(H7*H$3,0) -> 642087773 | I28: =ROUND(I7*I$3,0) -> 667771284
A29: （その他販管費率：対売上） | B29: =B28/B7 -> 0.047702148 | C29: =C28/C7 -> 0.0477 | D29: =D28/D7 -> 0.0477 | E29: =E28/E7 -> 0.0477 | F29: =F28/F7 -> 0.0477 | G29: =G28/G7 -> 0.0477 | H29: =H28/H7 -> 0.0477 | I29: =I28/I7 -> 0.0477
A30: ②営業利益 | B30: =B18-B19 -> 204823050 | C30: =C18-C19 -> 212802355 | D30: =D18-D19 -> 214284593 | E30: =E18-E19 -> 251024522 | F30: =F18-F19 -> 288637218 | G30: =G18-G19 -> 330603724 | H30: =H18-H19 -> 380354523 | I30: =I18-I19 -> 435431881
A31: （営業利益率） | B31: =B30/B7 -> 0.018338687 | C31: =C30/C7 -> 0.018771536 | D31: =D30/D7 -> 0.018622942 | E31: =E30/E7 -> 0.020976844 | F31: =F30/F7 -> 0.023192256 | G31: =G30/G7 -> 0.025542598 | H31: =H30/H7 -> 0.028256122 | I31: =I30/I7 -> 0.031103615
A32: ③経常利益 | B32: 205886748 | C32: =C30+($B$32-$B$30) -> 213866053 | D32: =D30+($B$32-$B$30) -> 215348291 | E32: =E30+($B$32-$B$30) -> 252088220 | F32: =F30+($B$32-$B$30) -> 289700916 | G32: =G30+($B$32-$B$30) -> 331667422 | H32: =H30+($B$32-$B$30) -> 381418221 | I32: =I30+($B$32-$B$30) -> 436495579
A33: ④人件費計 | B33: =B10+B20 -> 1021940577 | C33: =ROUND(C48*C42+C34,0) -> 1028861760 | D33: =ROUND(D48*D42+D34,0) -> 1080178369 | E33: =ROUND(E48*E42+E34,0) -> 1133090527 | F33: =ROUND(F48*F42+F34,0) -> 1194468069 | G33: =ROUND(G48*G42+G34,0) -> 1252619955 | H33: =ROUND(H48*H42+H34,0) -> 1319891660 | I33: =ROUND(I48*I42+I34,0) -> 1383761250
A34: └役員報酬給与支給総額 | B34: =B11+B21 -> 65655000 | C34: =C11+C21 -> 65655000 | D34: =D11+D21 -> 65655000 | E34: =E11+E21 -> 65655000 | F34: =F11+F21 -> 65655000 | G34: =G11+G21 -> 65655000 | H34: =H11+H21 -> 65655000 | I34: =I11+I21 -> 65655000
A35: └うち賞与 | B35: =B12+B22 -> 0 | C35: =C12+C22 -> 0 | D35: =D12+D22 -> 0 | E35: =E12+E22 -> 0 | F35: =F12+F22 -> 0 | G35: =G12+G22 -> 0 | H35: =H12+H22 -> 0 | I35: =I12+I22 -> 0
A36: └うち給与・賃金 | B36: =B13+B23 -> 65655000 | C36: =C13+C23 -> 65655000 | D36: =D13+D23 -> 65655000 | E36: =E13+E23 -> 65655000 | F36: =F13+F23 -> 65655000 | G36: =G13+G23 -> 65655000 | H36: =H13+H23 -> 65655000 | I36: =I13+I23 -> 65655000
A37: └従業員給与支給総額 | B37: =B14+B24 -> 793856994 | C37: =C14+C24 -> 799602588 | D37: =D14+D24 -> 842202884 | E37: =E14+E24 -> 886127719 | F37: =F14+F24 -> 937080063 | G37: =G14+G24 -> 985354640 | H37: =H14+H24 -> 1041200001 | I37: =I14+I24 -> 1094221109
A38: └うち賞与 | B38: =B15+B25 -> 204071047 | C38: =C15+C25 -> 205548025 | D38: =D15+D25 -> 216498974 | E38: =E15+E25 -> 227790412 | F38: =F15+F25 -> 240888361 | G38: =G15+G25 -> 253297956 | H38: =H15+H25 -> 267653717 | I38: =I15+I25 -> 281283468
A39: └うち給与・賃金 | B39: =B16+B26 -> 589785947 | C39: =C16+C26 -> 594054563 | D39: =D16+D26 -> 625703910 | E39: =E16+E26 -> 658337307 | F39: =F16+F26 -> 696191702 | G39: =G16+G26 -> 732056684 | H39: =H16+H26 -> 773546284 | I39: =I16+I26 -> 812937641
A40: ⑤減価償却費 | B40: =B17+B27 -> 298864468 | C40: =C17+C27 -> 298864468 | D40: =D17+D27 -> 298864468 | E40: =E17+E27 -> 308064468 | F40: =F17+F27 -> 308064468 | G40: =G17+G27 -> 308064468 | H40: =H17+H27 -> 308064468 | I40: =I17+I27 -> 308064468
...

Sheet 人件費・給与支給総額
C1: 2026年3月期
A3: 原価内 | B3: 賃金（労務費内） | C3: 376769793 | J3: 2026年3月期
B4: 雑給 | C4: 61352644 | I4: ①売上高 | J4: 11168904537
B5: 賞与 | C5: 153907318
B6: 研究開発労務費 | C6: 28319705 | I6: 売上原価 | J6: 10117780260 | K6: =J6/J4 -> 0.90588833
B7: 法定福利費 | C7: 91831558 | I7: 内減価償却費 | J7: =J11 -> 274032833
B8: 厚生費 | C8: 21070705 | I8: 減価償却費を除いた売上原価 | J8: =J6-J7 -> 9843747427 | K8: =J8/$J$4 -> 0.88135299
I9: 売上原価内人件費と売上原価内減価償却を除いた売上原価 | J9: =J6-J11-C10 -> 9110495704 | K9: =J9/$J$4 -> 0.81570182
B10: 売上原価内人件費 | C10: =C3+C4+C5+C6+C7+C8 -> 733251723
B11: └うち役員給与支給総額 | C11: =C12+C13 -> 0 | I11: 売上原価内減価償却費 | J11: 274032833
B12: └うち賞与 | C12: 0 | I12: 販管費内減価償却費 | J12: 24831635
B13: └うち給料・賃金 | C13: 0 | I13: 減価償却費計 | J13: =J11+J12 -> 298864468
B14: └うち従業員給与支給総額 | C14: =C15+C16 -> 620349460
B15: └うち賞与 | C15: =C5 -> 153907318
B16: └うち給料・賃金 | C16: =C3+C4+C6 -> 466442142
C18: 人件費 | D18: 給与支給総額
A19: 販管費 | B19: 給与手当 | C19: 120356805 | D19: 120356805
B20: 雑給 | C20: 2987000 | D20: 2987000
B21: 役員報酬 | C21: 65655000 | D21: 65655000
B22: 役員賞与 | C22: 0 | D22: 0
B23: 従業員賞与 | C23: 50163729 | D23: 50163729
B24: 法定福利費 | C24: 35845218
B25: 厚生費 | C25: 11607582
B26: 退職金 | C26: 2073520
B28: 販管費内人件費 | C28: =C19+C20+C21+C22+C23+C24+C25+C26 -> 288688854
B29: └うち役員給与支給総額 | C29: =C30+C31 -> 65655000 | D29: =D30+D31 -> 65655000
B30: └うち賞与 | C30: =C22 -> 0 | D30: =D22 -> 0
B31: └うち給料・賃金 | C31: =C21 -> 65655000 | D31: =D21 -> 65655000
B32: └うち従業員給与支給総額 | C32: =C33+C34 -> 173507534 | D32: =D33+D34 -> 173507534
B33: └うち賞与 | C33: =C23 -> 50163729 | D33: =D23 -> 50163729
B34: └うち給料・賃金 | C34: =C19+C20 -> 123343805 | D34: =D19+D20 -> 123343805
B36: 売上原価＋販管費人件費合計 | C36: =C28+C10 -> 1021940577
B37: └うち役員給与支給総額 | C37: =C29+C11 -> 65655000 | D37: =D29+D11 -> 65655000
B38: └うち賞与 | C38: =C30+C12 -> 0 | D38: =D30+D12 -> 0
B39: └うち給料・賃金 | C39: =C31+C13 -> 65655000 | D39: =D31+D13 -> 65655000
B40: └うち従業員給与支給総額 | C40: =C32+C14 -> 793856994 | D40: =D32+D14 -> 173507534
B41: └うち賞与 | C41: =C33+C15 -> 204071047 | D41: =D33+D15 -> 50163729
B42: └うち給料・賃金 | C42: =C34+C16 -> 589785947 | D42: =D34+D16 -> 123343805
