Workbook
Name サブタイトル: [1]更新履歴!$L$3
Name タイトル: [1]更新履歴!$D$3
Name 決算期: 選択肢!$O$3:$O$18
Name 作成日: [1]更新履歴!$U$2
Name 所属: #REF!
Name 変更決算期: 選択肢!$N$4:$N$18
Name 変更前決算期: 選択肢!$N$3:$N$18

Sheet 【指定様式】事業計画書（その3）
A1: 【指定様式】事業計画書（その３）
B2: 事業者名
B3: 株式会社トンボ飲料
B4: 本事業計画における会社全体の事業計画（数値計画）を記載してください。
A5: 記載数値：「省力化指数」「付加価値額」「労働生産性」「1人当たり給与支給総額」「投資回収期間」
B7: 【１】省力化指数
B8: ='（別紙１）省力化計算シート'!M3 -> 0.77572816
B9: ※「（別紙１）省力化計算シート」より算出。
B10: ※「（別紙２）省力化業務プロセス図」も作成し省力化指数の詳細を説明してください。
B13: 【事業計画年数（３～５年）】
B14: 3 | D14: 年
B16: 【算定根拠】算定の根拠となる計算式等をそれぞれ記載ください。
B17: また、計画最終年の年平均成長率を転記してください。（事業者の目標値となります。）
B19: ①付加価値額 | H19: 最終年の年平均成長率 | I19: 5.88 | J19: ％
B20: 付加価値額（営業利益＋人件費＋減価償却費）は、基準年度（2028年3月期）1,593,327,430円→1年目1,692,179,517円→2年目1,791,169,755円→3年目（2031年3月期）1,891,288,147円（基準年度比＋297,960,717円、年平均成長率5.88％）と推移する。 （1）売上高：本装置は製袋機の能力を上げないが、供給待ちによる停止（1日約30分）の解消と土曜稼働（月2日）で年約470万袋の余地が生まれる。生産能力の不足で断った案件（年800万袋×50円）の約半分（約2億円）を受注し、価格転嫁（＋1.5％）と既存顧客の増量を加えて1年目は前年比＋4.0％（＋460百万円）とする。2年目は日勤へ戻った社員による提案型ODMの獲得、3年目はその定着で各＋4.0％とし、売上高は11,506百万円→12,943百万円となる。年＋4.0％は清涼飲料の生産者販売金額の伸び（2025年＋5.3％）を下回る保守的な水準である。 （2）売上原価率：ODM売上比率を約10％→3年目約14.5％に高め（年＋0.30pt）、価格転嫁（＋0.05pt）と労務費の抑制（1年目＋0.07pt）で賃上げによる労務費率の上昇を吸収し、保守的に年0.25pt改善して、90.50％→89.75％とする。その他販管費は売上高比4.77％を維持し、営業利益は214百万円→330百万円となる。 （3）人件費：1人当たり年3.5％の賃上げと年3〜4名の新卒採用により、1,080百万円→1,252百万円とする（役員報酬は据え置き）。 （4）減価償却費：既存分298,864,468円に本設備（92,000,000円・定額法10年）の9,200,000円／年を加え、308,064,468円とする。 目標値として策定する4・5年目は、ODM比率の上昇が定着して原価率を年0.30pt改善し、付加価値額は2,008,310,651円→2,127,257,599円（年平均成長率5.95％）とする。
B25: ②労働生産性 | H25: 最終年の年平均成長率 | I25: 4.06 | J25: ％
B26: 労働生産性＝付加価値額÷（役員7名＋常勤従業員数）。省力化で創出する799分／日（約3,262時間／年）は人員削減に充てず、多能工化・品質管理・提案型ODMへ再配分する。 新卒採用（年3〜4名）を続けるため、常勤従業員数は基準年度181名→1年目184名→2年目188名→3年目191名（労働者数188名→198名）と増えるが、付加価値額の伸び（年平均5.88％）が人員の伸びを上回る。 労働生産性は基準年度8,475,145円→1年目8,859,578円（＋4.53％）→2年目9,185,485円（年平均4.10％）→3年目9,551,960円（年平均4.06％）と推移し、毎年、必須要件（年平均成長率4.0％以上）を満たす。目標値として策定する4・5年目も、年平均4.07％・4.13％と4.0％以上を維持する。
B32: ③1人当たり給与支給総額 | H32: 最終年の年平均成長率 | I32: 3.52 | J32: ％
B33: 1人当たり給与支給総額＝全月分の給与等の支給を受けた従業員の給与支給総額（給料・賞与・課税対象の手当。法定福利費・退職金は除く）÷同従業員数。直近の2026年3月期は4,319,298円（717,003,483円÷166名）である。 2026年4月に人件費総額ベースで約5％の賃上げを実施済みであるが、1人当たりの平均は新卒・中途の入替で伸びが小さくなるため、計画では保守的に、足下は年3％を上回る水準（年平均成長率3.02％）で基準年度4,584,175円（829,735,675円÷181名）とする。 基準年度以降は既存従業員を年約4％引き上げ（新卒入社による平均の引下げ約−0.5pt）、1年目4,745,570円（184名）→2年目4,912,647円（188名）→3年目5,085,606円（191名、給与支給総額971,350,746円）となり、年平均成長率3.52％で必須要件（3.5％以上）を満たす。目標値として策定する4・5年目も同じ水準を続け、5年目は5,450,006円（年平均3.52％）とする。 原資は安定稼働とODM比率向上による収益の拡大と労務費の抑制であり、給与支給総額の増加（基準年度比141,615,071円）を織り込んでも、営業利益は116,319,131円増加する。役員報酬は据え置き、従業員へ厚く配分する。賃上げ目標は従業員へ表明し、確実に実行する。
B38: 【３】投資回収期間
B39: ='（別紙３）投資回収期間計算シート'!C3 -> 0.32963325 | D39: 年
B40: ※「（別紙３）投資回収期間計算シート」より算出（自動反映）。

Sheet （別紙１）省力化計算シート
B1: （別紙１）省力化計算シート
C3: 設備導入により削減される 業務に要していた時間 | D3: =(SUMIF(C11:C40,"<>",D11:D40)-SUMIF(E11:E40,"<>-",D11:D40)-SUMIF(F11:F40,"<0"))/60 -> 17.166667 | G3: 時間 | I3: 設備導入後に発生する 業務に要する時間 | J3: =(SUMIF(I11:I40,"<>",J11:J40)-SUMIF(N11:N40,"<>-",J11:J40)+SUMIF(N11:N40,">0"))/60 -> 3.85 | K3: 時間 | L3: 省力化指数 | M3: =IF(D3=0,0,IF((D3-J3)/D3<0,0,(D3-J3)/D3)) -> 0.77572816
B5: ■設備導入前の業務プロセス・作業工程 | H5: ■設備導入後の業務プロセス・作業工程
C7: 設備導入前の作業時間合計 | D7: =SUMIF(C11:C40,"<>",D11:D40)/60 -> 96.25 | G7: 時間 | I7: 設備導入後の作業時間合計 | J7: =SUMIF(I11:I40,"<>",J11:J40)/60 -> 82.933333 | K7: 時間
B10: No. | C10: 工程名・作業名 | D10: 作業時間（分） | E10: 対応する導入後の 業務プロセスNo | F10: 同工程差分時間（分） | H10: No. | I10: 工程名・作業名 | J10: 作業時間（分） | K10: 作業種別 | L10: 対応する設備導入前の 業務プロセスNo. | N10: 同工程差分時間（分） | P10: 作業種別選択肢
B11: 1 | C11: 空パウチの搬入 | D11: 20 | E11: =IF(OR(C11="",D11=""),"-",IF(IFERROR(MATCH(B11,L$11:L$40,0),"")="","-",IF(OR(INDEX(I$11:I$40,MATCH(B11,L$11:L$40,0))="",INDEX(J$11:J$40,MATCH(B11,L$11:L$40,0))="",INDEX(K$11:K$40,MATCH(B11,L$11:L$40,0))<>"内容は変化しない作業"),"-",MATCH(B11,L$11:L$40,0)))) -> 1 | F11: {=IF(E11="-","-",IF(AND(C11<>"",D11>0,INDEX(K$11:K$40,E11)="内容は変化しない作業",AND(E11<>"-",E11<>""),INDEX(I$11:I$40,E11)<>"",INDEX(J$11:J$40,E11)<>""),INDEX(J$11:J$40,E11)-D11,"-"))} -> 0 | H11: 1 | I11: 空パウチの搬入 | J11: 20 | K11: 内容は変化しない作業 | L11: 1 | N11: {=IF(AND(I11<>"",J11>0,K11="内容は変化しない作業",L11>0,INDEX(C$11:C$40,L11)<>"",INDEX(D$11:D$40,L11)<>""),J11-INDEX(D$11:D$40,L11),"-")} -> 0 | P11: 新たに追加される作業
B12: 2 | C12: 段ボールの開梱・束の取り出し | D12: 43 | E12: =IF(OR(C12="",D12=""),"-",IF(IFERROR(MATCH(B12,L$11:L$40,0),"")="","-",IF(OR(INDEX(I$11:I$40,MATCH(B12,L$11:L$40,0))="",INDEX(J$11:J$40,MATCH(B12,L$11:L$40,0))="",INDEX(K$11:K$40,MATCH(B12,L$11:L$40,0))<>"内容は変化しない作業"),"-",MATCH(B12,L$11:L$40,0)))) -> - | F12: {=IF(E12="-","-",IF(AND(C12<>"",D12>0,INDEX(K$11:K$40,E12)="内容は変化しない作業",AND(E12<>"-",E12<>""),INDEX(I$11:I$40,E12)<>"",INDEX(J$11:J$40,E12)<>""),INDEX(J$11:J$40,E12)-D12,"-"))} -> - | H12: 2 | I12: 専用パレットへの詰め | J12: 209 | K12: 新たに追加される作業 | N12: {=IF(AND(I12<>"",J12>0,K12="内容は変化しない作業",L12>0,INDEX(C$11:C$40,L12)<>"",INDEX(D$11:D$40,L12)<>""),J12-INDEX(D$11:D$40,L12),"-")} -> - | P12: 内容は変化しない作業
B13: 3 | C13: 空段ボールの片付け | D13: 22 | E13: =IF(OR(C13="",D13=""),"-",IF(IFERROR(MATCH(B13,L$11:L$40,0),"")="","-",IF(OR(INDEX(I$11:I$40,MATCH(B13,L$11:L$40,0))="",INDEX(J$11:J$40,MATCH(B13,L$11:L$40,0))="",INDEX(K$11:K$40,MATCH(B13,L$11:L$40,0))<>"内容は変化しない作業"),"-",MATCH(B13,L$11:L$40,0)))) -> - | F13: {=IF(E13="-","-",IF(AND(C13<>"",D13>0,INDEX(K$11:K$40,E13)="内容は変化しない作業",AND(E13<>"-",E13<>""),INDEX(I$11:I$40,E13)<>"",INDEX(J$11:J$40,E13)<>""),INDEX(J$11:J$40,E13)-D13,"-"))} -> - | H13: 3 | I13: パレットの装填・入替 | J13: 15 | K13: 新たに追加される作業 | N13: {=IF(AND(I13<>"",J13>0,K13="内容は変化しない作業",L13>0,INDEX(C$11:C$40,L13)<>"",INDEX(D$11:D$40,L13)<>""),J13-INDEX(D$11:D$40,L13),"-")} -> -
B14: 4 | C14: パウチのほぐし | D14: 563 | E14: =IF(OR(C14="",D14=""),"-",IF(IFERROR(MATCH(B14,L$11:L$40,0),"")="","-",IF(OR(INDEX(I$11:I$40,MATCH(B14,L$11:L$40,0))="",INDEX(J$11:J$40,MATCH(B14,L$11:L$40,0))="",INDEX(K$11:K$40,MATCH(B14,L$11:L$40,0))<>"内容は変化しない作業"),"-",MATCH(B14,L$11:L$40,0)))) -> - | F14: {=IF(E14="-","-",IF(AND(C14<>"",D14>0,INDEX(K$11:K$40,E14)="内容は変化しない作業",AND(E14<>"-",E14<>""),INDEX(I$11:I$40,E14)<>"",INDEX(J$11:J$40,E14)<>""),INDEX(J$11:J$40,E14)-D14,"-"))} -> - | H14: 4 | I14: 専用パレットの型替え | J14: 7 | K14: 新たに追加される作業 | N14: {=IF(AND(I14<>"",J14>0,K14="内容は変化しない作業",L14>0,INDEX(C$11:C$40,L14)<>"",INDEX(D$11:D$40,L14)<>""),J14-INDEX(D$11:D$40,L14),"-")} -> -
B15: 5 | C15: 踏み台の昇降・マガジン残量確認 | D15: 79 | E15: =IF(OR(C15="",D15=""),"-",IF(IFERROR(MATCH(B15,L$11:L$40,0),"")="","-",IF(OR(INDEX(I$11:I$40,MATCH(B15,L$11:L$40,0))="",INDEX(J$11:J$40,MATCH(B15,L$11:L$40,0))="",INDEX(K$11:K$40,MATCH(B15,L$11:L$40,0))<>"内容は変化しない作業"),"-",MATCH(B15,L$11:L$40,0)))) -> - | F15: {=IF(E15="-","-",IF(AND(C15<>"",D15>0,INDEX(K$11:K$40,E15)="内容は変化しない作業",AND(E15<>"-",E15<>""),INDEX(I$11:I$40,E15)<>"",INDEX(J$11:J$40,E15)<>""),INDEX(J$11:J$40,E15)-D15,"-"))} -> - | H15: 5 | I15: 製袋機の運転・監視 | J15: 1050 | K15: 内容は変化しない作業 | L15: 8 | N15: {=IF(AND(I15<>"",J15>0,K15="内容は変化しない作業",L15>0,INDEX(C$11:C$40,L15)<>"",INDEX(D$11:D$40,L15)<>""),J15-INDEX(D$11:D$40,L15),"-")} -> 0
B16: 6 | C16: マガジンへの束の手投入 | D16: 315 | E16: =IF(OR(C16="",D16=""),"-",IF(IFERROR(MATCH(B16,L$11:L$40,0),"")="","-",IF(OR(INDEX(I$11:I$40,MATCH(B16,L$11:L$40,0))="",INDEX(J$11:J$40,MATCH(B16,L$11:L$40,0))="",INDEX(K$11:K$40,MATCH(B16,L$11:L$40,0))<>"内容は変化しない作業"),"-",MATCH(B16,L$11:L$40,0)))) -> - | F16: {=IF(E16="-","-",IF(AND(C16<>"",D16>0,INDEX(K$11:K$40,E16)="内容は変化しない作業",AND(E16<>"-",E16<>""),INDEX(I$11:I$40,E16)<>"",INDEX(J$11:J$40,E16)<>""),INDEX(J$11:J$40,E16)-D16,"-"))} -> - | H16: 6 | I16: 充填（充填室） | J16: 1050 | K16: 内容は変化しない作業 | L16: 9 | N16: {=IF(AND(I16<>"",J16>0,K16="内容は変化しない作業",L16>0,INDEX(C$11:C$40,L16)<>"",INDEX(D$11:D$40,L16)<>""),J16-INDEX(D$11:D$40,L16),"-")} -> 0
B17: 7 | C17: 品種切替時のパウチ切替 | D17: 8 | E17: =IF(OR(C17="",D17=""),"-",IF(IFERROR(MATCH(B17,L$11:L$40,0),"")="","-",IF(OR(INDEX(I$11:I$40,MATCH(B17,L$11:L$40,0))="",INDEX(J$11:J$40,MATCH(B17,L$11:L$40,0))="",INDEX(K$11:K$40,MATCH(B17,L$11:L$40,0))<>"内容は変化しない作業"),"-",MATCH(B17,L$11:L$40,0)))) -> - | F17: {=IF(E17="-","-",IF(AND(C17<>"",D17>0,INDEX(K$11:K$40,E17)="内容は変化しない作業",AND(E17<>"-",E17<>""),INDEX(I$11:I$40,E17)<>"",INDEX(J$11:J$40,E17)<>""),INDEX(J$11:J$40,E17)-D17,"-"))} -> - | H17: 7 | I17: 包装・箱詰め | J17: 2625 | K17: 内容は変化しない作業 | L17: 10 | N17: {=IF(AND(I17<>"",J17>0,K17="内容は変化しない作業",L17>0,INDEX(C$11:C$40,L17)<>"",INDEX(D$11:D$40,L17)<>""),J17-INDEX(D$11:D$40,L17),"-")} -> 0
B18: 8 | C18: 製袋機の運転・監視 | D18: 1050 | E18: =IF(OR(C18="",D18=""),"-",IF(IFERROR(MATCH(B18,L$11:L$40,0),"")="","-",IF(OR(INDEX(I$11:I$40,MATCH(B18,L$11:L$40,0))="",INDEX(J$11:J$40,MATCH(B18,L$11:L$40,0))="",INDEX(K$11:K$40,MATCH(B18,L$11:L$40,0))<>"内容は変化しない作業"),"-",MATCH(B18,L$11:L$40,0)))) -> 5 | F18: {=IF(E18="-","-",IF(AND(C18<>"",D18>0,INDEX(K$11:K$40,E18)="内容は変化しない作業",AND(E18<>"-",E18<>""),INDEX(I$11:I$40,E18)<>"",INDEX(J$11:J$40,E18)<>""),INDEX(J$11:J$40,E18)-D18,"-"))} -> 0 | H18: 8 | N18: {=IF(AND(I18<>"",J18>0,K18="内容は変化しない作業",L18>0,INDEX(C$11:C$40,L18)<>"",INDEX(D$11:D$40,L18)<>""),J18-INDEX(D$11:D$40,L18),"-")} -> -
B19: 9 | C19: 充填（充填室） | D19: 1050 | E19: =IF(OR(C19="",D19=""),"-",IF(IFERROR(MATCH(B19,L$11:L$40,0),"")="","-",IF(OR(INDEX(I$11:I$40,MATCH(B19,L$11:L$40,0))="",INDEX(J$11:J$40,MATCH(B19,L$11:L$40,0))="",INDEX(K$11:K$40,MATCH(B19,L$11:L$40,0))<>"内容は変化しない作業"),"-",MATCH(B19,L$11:L$40,0)))) -> 6 | F19: {=IF(E19="-","-",IF(AND(C19<>"",D19>0,INDEX(K$11:K$40,E19)="内容は変化しない作業",AND(E19<>"-",E19<>""),INDEX(I$11:I$40,E19)<>"",INDEX(J$11:J$40,E19)<>""),INDEX(J$11:J$40,E19)-D19,"-"))} -> 0 | H19: 9 | N19: {=IF(AND(I19<>"",J19>0,K19="内容は変化しない作業",L19>0,INDEX(C$11:C$40,L19)<>"",INDEX(D$11:D$40,L19)<>""),J19-INDEX(D$11:D$40,L19),"-")} -> -
B20: 10 | C20: 包装・箱詰め | D20: 2625 | E20: =IF(OR(C20="",D20=""),"-",IF(IFERROR(MATCH(B20,L$11:L$40,0),"")="","-",IF(OR(INDEX(I$11:I$40,MATCH(B20,L$11:L$40,0))="",INDEX(J$11:J$40,MATCH(B20,L$11:L$40,0))="",INDEX(K$11:K$40,MATCH(B20,L$11:L$40,0))<>"内容は変化しない作業"),"-",MATCH(B20,L$11:L$40,0)))) -> 7 | F20: {=IF(E20="-","-",IF(AND(C20<>"",D20>0,INDEX(K$11:K$40,E20)="内容は変化しない作業",AND(E20<>"-",E20<>""),INDEX(I$11:I$40,E20)<>"",INDEX(J$11:J$40,E20)<>""),INDEX(J$11:J$40,E20)-D20,"-"))} -> 0 | H20: 10 | N20: {=IF(AND(I20<>"",J20>0,K20="内容は変化しない作業",L20>0,INDEX(C$11:C$40,L20)<>"",INDEX(D$11:D$40,L20)<>""),J20-INDEX(D$11:D$40,L20),"-")} -> -
B21: 11 | E21: =IF(OR(C21="",D21=""),"-",IF(IFERROR(MATCH(B21,L$11:L$40,0),"")="","-",IF(OR(INDEX(I$11:I$40,MATCH(B21,L$11:L$40,0))="",INDEX(J$11:J$40,MATCH(B21,L$11:L$40,0))="",INDEX(K$11:K$40,MATCH(B21,L$11:L$40,0))<>"内容は変化しない作業"),"-",MATCH(B21,L$11:L$40,0)))) -> - | F21: {=IF(E21="-","-",IF(AND(C21<>"",D21>0,INDEX(K$11:K$40,E21)="内容は変化しない作業",AND(E21<>"-",E21<>""),INDEX(I$11:I$40,E21)<>"",INDEX(J$11:J$40,E21)<>""),INDEX(J$11:J$40,E21)-D21,"-"))} -> - | H21: 11 | N21: {=IF(AND(I21<>"",J21>0,K21="内容は変化しない作業",L21>0,INDEX(C$11:C$40,L21)<>"",INDEX(D$11:D$40,L21)<>""),J21-INDEX(D$11:D$40,L21),"-")} -> -
B22: 12 | E22: =IF(OR(C22="",D22=""),"-",IF(IFERROR(MATCH(B22,L$11:L$40,0),"")="","-",IF(OR(INDEX(I$11:I$40,MATCH(B22,L$11:L$40,0))="",INDEX(J$11:J$40,MATCH(B22,L$11:L$40,0))="",INDEX(K$11:K$40,MATCH(B22,L$11:L$40,0))<>"内容は変化しない作業"),"-",MATCH(B22,L$11:L$40,0)))) -> - | F22: {=IF(E22="-","-",IF(AND(C22<>"",D22>0,INDEX(K$11:K$40,E22)="内容は変化しない作業",AND(E22<>"-",E22<>""),INDEX(I$11:I$40,E22)<>"",INDEX(J$11:J$40,E22)<>""),INDEX(J$11:J$40,E22)-D22,"-"))} -> - | H22: 12 | N22: {=IF(AND(I22<>"",J22>0,K22="内容は変化しない作業",L22>0,INDEX(C$11:C$40,L22)<>"",INDEX(D$11:D$40,L22)<>""),J22-INDEX(D$11:D$40,L22),"-")} -> -
B23: 13 | E23: =IF(OR(C23="",D23=""),"-",IF(IFERROR(MATCH(B23,L$11:L$40,0),"")="","-",IF(OR(INDEX(I$11:I$40,MATCH(B23,L$11:L$40,0))="",INDEX(J$11:J$40,MATCH(B23,L$11:L$40,0))="",INDEX(K$11:K$40,MATCH(B23,L$11:L$40,0))<>"内容は変化しない作業"),"-",MATCH(B23,L$11:L$40,0)))) -> - | F23: {=IF(E23="-","-",IF(AND(C23<>"",D23>0,INDEX(K$11:K$40,E23)="内容は変化しない作業",AND(E23<>"-",E23<>""),INDEX(I$11:I$40,E23)<>"",INDEX(J$11:J$40,E23)<>""),INDEX(J$11:J$40,E23)-D23,"-"))} -> - | H23: 13 | N23: {=IF(AND(I23<>"",J23>0,K23="内容は変化しない作業",L23>0,INDEX(C$11:C$40,L23)<>"",INDEX(D$11:D$40,L23)<>""),J23-INDEX(D$11:D$40,L23),"-")} -> -
B24: 14 | E24: =IF(OR(C24="",D24=""),"-",IF(IFERROR(MATCH(B24,L$11:L$40,0),"")="","-",IF(OR(INDEX(I$11:I$40,MATCH(B24,L$11:L$40,0))="",INDEX(J$11:J$40,MATCH(B24,L$11:L$40,0))="",INDEX(K$11:K$40,MATCH(B24,L$11:L$40,0))<>"内容は変化しない作業"),"-",MATCH(B24,L$11:L$40,0)))) -> - | F24: {=IF(E24="-","-",IF(AND(C24<>"",D24>0,INDEX(K$11:K$40,E24)="内容は変化しない作業",AND(E24<>"-",E24<>""),INDEX(I$11:I$40,E24)<>"",INDEX(J$11:J$40,E24)<>""),INDEX(J$11:J$40,E24)-D24,"-"))} -> - | H24: 14 | N24: {=IF(AND(I24<>"",J24>0,K24="内容は変化しない作業",L24>0,INDEX(C$11:C$40,L24)<>"",INDEX(D$11:D$40,L24)<>""),J24-INDEX(D$11:D$40,L24),"-")} -> -
B25: 15 | E25: =IF(OR(C25="",D25=""),"-",IF(IFERROR(MATCH(B25,L$11:L$40,0),"")="","-",IF(OR(INDEX(I$11:I$40,MATCH(B25,L$11:L$40,0))="",INDEX(J$11:J$40,MATCH(B25,L$11:L$40,0))="",INDEX(K$11:K$40,MATCH(B25,L$11:L$40,0))<>"内容は変化しない作業"),"-",MATCH(B25,L$11:L$40,0)))) -> - | F25: {=IF(E25="-","-",IF(AND(C25<>"",D25>0,INDEX(K$11:K$40,E25)="内容は変化しない作業",AND(E25<>"-",E25<>""),INDEX(I$11:I$40,E25)<>"",INDEX(J$11:J$40,E25)<>""),INDEX(J$11:J$40,E25)-D25,"-"))} -> - | H25: 15 | N25: {=IF(AND(I25<>"",J25>0,K25="内容は変化しない作業",L25>0,INDEX(C$11:C$40,L25)<>"",INDEX(D$11:D$40,L25)<>""),J25-INDEX(D$11:D$40,L25),"-")} -> -
B26: 16 | E26: =IF(OR(C26="",D26=""),"-",IF(IFERROR(MATCH(B26,L$11:L$40,0),"")="","-",IF(OR(INDEX(I$11:I$40,MATCH(B26,L$11:L$40,0))="",INDEX(J$11:J$40,MATCH(B26,L$11:L$40,0))="",INDEX(K$11:K$40,MATCH(B26,L$11:L$40,0))<>"内容は変化しない作業"),"-",MATCH(B26,L$11:L$40,0)))) -> - | F26: {=IF(E26="-","-",IF(AND(C26<>"",D26>0,INDEX(K$11:K$40,E26)="内容は変化しない作業",AND(E26<>"-",E26<>""),INDEX(I$11:I$40,E26)<>"",INDEX(J$11:J$40,E26)<>""),INDEX(J$11:J$40,E26)-D26,"-"))} -> - | H26: 16 | N26: {=IF(AND(I26<>"",J26>0,K26="内容は変化しない作業",L26>0,INDEX(C$11:C$40,L26)<>"",INDEX(D$11:D$40,L26)<>""),J26-INDEX(D$11:D$40,L26),"-")} -> -
B27: 17 | E27: =IF(OR(C27="",D27=""),"-",IF(IFERROR(MATCH(B27,L$11:L$40,0),"")="","-",IF(OR(INDEX(I$11:I$40,MATCH(B27,L$11:L$40,0))="",INDEX(J$11:J$40,MATCH(B27,L$11:L$40,0))="",INDEX(K$11:K$40,MATCH(B27,L$11:L$40,0))<>"内容は変化しない作業"),"-",MATCH(B27,L$11:L$40,0)))) -> - | F27: {=IF(E27="-","-",IF(AND(C27<>"",D27>0,INDEX(K$11:K$40,E27)="内容は変化しない作業",AND(E27<>"-",E27<>""),INDEX(I$11:I$40,E27)<>"",INDEX(J$11:J$40,E27)<>""),INDEX(J$11:J$40,E27)-D27,"-"))} -> - | H27: 17 | N27: {=IF(AND(I27<>"",J27>0,K27="内容は変化しない作業",L27>0,INDEX(C$11:C$40,L27)<>"",INDEX(D$11:D$40,L27)<>""),J27-INDEX(D$11:D$40,L27),"-")} -> -
B28: 18 | E28: =IF(OR(C28="",D28=""),"-",IF(IFERROR(MATCH(B28,L$11:L$40,0),"")="","-",IF(OR(INDEX(I$11:I$40,MATCH(B28,L$11:L$40,0))="",INDEX(J$11:J$40,MATCH(B28,L$11:L$40,0))="",INDEX(K$11:K$40,MATCH(B28,L$11:L$40,0))<>"内容は変化しない作業"),"-",MATCH(B28,L$11:L$40,0)))) -> - | F28: {=IF(E28="-","-",IF(AND(C28<>"",D28>0,INDEX(K$11:K$40,E28)="内容は変化しない作業",AND(E28<>"-",E28<>""),INDEX(I$11:I$40,E28)<>"",INDEX(J$11:J$40,E28)<>""),INDEX(J$11:J$40,E28)-D28,"-"))} -> - | H28: 18 | N28: {=IF(AND(I28<>"",J28>0,K28="内容は変化しない作業",L28>0,INDEX(C$11:C$40,L28)<>"",INDEX(D$11:D$40,L28)<>""),J28-INDEX(D$11:D$40,L28),"-")} -> -
B29: 19 | E29: =IF(OR(C29="",D29=""),"-",IF(IFERROR(MATCH(B29,L$11:L$40,0),"")="","-",IF(OR(INDEX(I$11:I$40,MATCH(B29,L$11:L$40,0))="",INDEX(J$11:J$40,MATCH(B29,L$11:L$40,0))="",INDEX(K$11:K$40,MATCH(B29,L$11:L$40,0))<>"内容は変化しない作業"),"-",MATCH(B29,L$11:L$40,0)))) -> - | F29: {=IF(E29="-","-",IF(AND(C29<>"",D29>0,INDEX(K$11:K$40,E29)="内容は変化しない作業",AND(E29<>"-",E29<>""),INDEX(I$11:I$40,E29)<>"",INDEX(J$11:J$40,E29)<>""),INDEX(J$11:J$40,E29)-D29,"-"))} -> - | H29: 19 | N29: {=IF(AND(I29<>"",J29>0,K29="内容は変化しない作業",L29>0,INDEX(C$11:C$40,L29)<>"",INDEX(D$11:D$40,L29)<>""),J29-INDEX(D$11:D$40,L29),"-")} -> -
B30: 20 | E30: =IF(OR(C30="",D30=""),"-",IF(IFERROR(MATCH(B30,L$11:L$40,0),"")="","-",IF(OR(INDEX(I$11:I$40,MATCH(B30,L$11:L$40,0))="",INDEX(J$11:J$40,MATCH(B30,L$11:L$40,0))="",INDEX(K$11:K$40,MATCH(B30,L$11:L$40,0))<>"内容は変化しない作業"),"-",MATCH(B30,L$11:L$40,0)))) -> - | F30: {=IF(E30="-","-",IF(AND(C30<>"",D30>0,INDEX(K$11:K$40,E30)="内容は変化しない作業",AND(E30<>"-",E30<>""),INDEX(I$11:I$40,E30)<>"",INDEX(J$11:J$40,E30)<>""),INDEX(J$11:J$40,E30)-D30,"-"))} -> - | H30: 20 | N30: {=IF(AND(I30<>"",J30>0,K30="内容は変化しない作業",L30>0,INDEX(C$11:C$40,L30)<>"",INDEX(D$11:D$40,L30)<>""),J30-INDEX(D$11:D$40,L30),"-")} -> -
B31: 21 | E31: =IF(OR(C31="",D31=""),"-",IF(IFERROR(MATCH(B31,L$11:L$40,0),"")="","-",IF(OR(INDEX(I$11:I$40,MATCH(B31,L$11:L$40,0))="",INDEX(J$11:J$40,MATCH(B31,L$11:L$40,0))="",INDEX(K$11:K$40,MATCH(B31,L$11:L$40,0))<>"内容は変化しない作業"),"-",MATCH(B31,L$11:L$40,0)))) -> - | F31: {=IF(E31="-","-",IF(AND(C31<>"",D31>0,INDEX(K$11:K$40,E31)="内容は変化しない作業",AND(E31<>"-",E31<>""),INDEX(I$11:I$40,E31)<>"",INDEX(J$11:J$40,E31)<>""),INDEX(J$11:J$40,E31)-D31,"-"))} -> - | H31: 21 | N31: {=IF(AND(I31<>"",J31>0,K31="内容は変化しない作業",L31>0,INDEX(C$11:C$40,L31)<>"",INDEX(D$11:D$40,L31)<>""),J31-INDEX(D$11:D$40,L31),"-")} -> -
B32: 22 | E32: =IF(OR(C32="",D32=""),"-",IF(IFERROR(MATCH(B32,L$11:L$40,0),"")="","-",IF(OR(INDEX(I$11:I$40,MATCH(B32,L$11:L$40,0))="",INDEX(J$11:J$40,MATCH(B32,L$11:L$40,0))="",INDEX(K$11:K$40,MATCH(B32,L$11:L$40,0))<>"内容は変化しない作業"),"-",MATCH(B32,L$11:L$40,0)))) -> - | F32: {=IF(E32="-","-",IF(AND(C32<>"",D32>0,INDEX(K$11:K$40,E32)="内容は変化しない作業",AND(E32<>"-",E32<>""),INDEX(I$11:I$40,E32)<>"",INDEX(J$11:J$40,E32)<>""),INDEX(J$11:J$40,E32)-D32,"-"))} -> - | H32: 22 | N32: {=IF(AND(I32<>"",J32>0,K32="内容は変化しない作業",L32>0,INDEX(C$11:C$40,L32)<>"",INDEX(D$11:D$40,L32)<>""),J32-INDEX(D$11:D$40,L32),"-")} -> -
... B40: 30 | E40: =IF(OR(C40="",D40=""),"-",IF(IFERROR(MATCH(B40,L$11:L$40,0),"")="","-",IF(OR(INDEX(I$11:I$40,MATCH(B40,L$11:L$40,0))="",INDEX(J$11:J$40,MATCH(B40,L$11:L$40,0))="",INDEX(K$11:K$40,MATCH(B40,L$11:L$40,0))<>"内容は変化しない作業"),"-",MATCH(B40,L$11:L$40,0)))) -> - | F40: {=IF(E40="-","-",IF(AND(C40<>"",D40>0,INDEX(K$11:K$40,E40)="内容は変化しない作業",AND(E40<>"-",E40<>""),INDEX(I$11:I$40,E40)<>"",INDEX(J$11:J$40,E40)<>""),INDEX(J$11:J$40,E40)-D40,"-"))} -> - | H40: 30 | N40: {=IF(AND(I40<>"",J40>0,K40="内容は変化しない作業",L40>0,INDEX(C$11:C$40,L40)<>"",INDEX(D$11:D$40,L40)<>""),J40-INDEX(D$11:D$40,L40),"-")} -> -

Sheet （別紙２）省力化業務プロセス図
B1: （別紙２）省力化業務プロセス図 ※（別紙1）で入れた業務プロセス・作業工程がフロー図として表示されます。
O3: 省力化指数 | S3: ='（別紙１）省力化計算シート'!M3 -> 0.77572816
C5: ■設備導入前の業務プロセス・作業工程 （BEFORE） | O5: 設備導入による削減時間 | S5: ='（別紙１）省力化計算シート'!D3 -> 17.166667 | T5: 時間
C8: ='（別紙１）省力化計算シート'!C11 -> 空パウチの搬入 | E8: > | G8: ='（別紙１）省力化計算シート'!C12 -> 段ボールの開梱・束の取り出し | I8: > | K8: ='（別紙１）省力化計算シート'!C13 -> 空段ボールの片付け | M8: > | O8: ='（別紙１）省力化計算シート'!C14 -> パウチのほぐし | Q8: > | S8: ='（別紙１）省力化計算シート'!C15 -> 踏み台の昇降・マガジン残量確認 | U8: > | X8: 削減される作業
C9: =IF('（別紙１）省力化計算シート'!D11="","",IF(OR('（別紙１）省力化計算シート'!F11="-",'（別紙１）省力化計算シート'!F11=0),'（別紙１）省力化計算シート'!D11&"分",'（別紙１）省力化計算シート'!D11&"分"&" (→"&'（別紙１）省力化計算シート'!D11+'（別紙１）省力化計算シート'!F11&"分）")) -> 20分 | G9: =IF('（別紙１）省力化計算シート'!D12="","",IF(OR('（別紙１）省力化計算シート'!F12="-",'（別紙１）省力化計算シート'!F12=0),'（別紙１）省力化計算シート'!D12&"分",'（別紙１）省力化計算シート'!D12&"分"&" (→"&'（別紙１）省力化計算シート'!D12+'（別紙１）省力化計算シート'!F12&"分）")) -> 43分 | K9: =IF('（別紙１）省力化計算シート'!D13="","",IF(OR('（別紙１）省力化計算シート'!F13="-",'（別紙１）省力化計算シート'!F13=0),'（別紙１）省力化計算シート'!D13&"分",'（別紙１）省力化計算シート'!D13&"分"&" (→"&'（別紙１）省力化計算シート'!D13+'（別紙１）省力化計算シート'!F13&"分）")) -> 22分 | O9: =IF('（別紙１）省力化計算シート'!D14="","",IF(OR('（別紙１）省力化計算シート'!F14="-",'（別紙１）省力化計算シート'!F14=0),'（別紙１）省力化計算シート'!D14&"分",'（別紙１）省力化計算シート'!D14&"分"&" (→"&'（別紙１）省力化計算シート'!D14+'（別紙１）省力化計算シート'!F14&"分）")) -> 563分 | S9: =IF('（別紙１）省力化計算シート'!D15="","",IF(OR('（別紙１）省力化計算シート'!F15="-",'（別紙１）省力化計算シート'!F15=0),'（別紙１）省力化計算シート'!D15&"分",'（別紙１）省力化計算シート'!D15&"分"&" (→"&'（別紙１）省力化計算シート'!D15+'（別紙１）省力化計算シート'!F15&"分）")) -> 79分
C10: 投入担当が資材保管室から数箱ずつ運び、踏み台の脇に置く。1日約43箱を5〜6回 | G10: 段ボールを開けて束（1束50袋）を取り出す。1日約43箱、1箱1分 | K10: 空になった段ボールを折りたたんで片付ける。1箱0.5分 | O10: 袋同士のくっつきによる2枚取りを防ぐため手でほぐす。投入の合間（約5分）も継続 | S10: 投入のたびに踏み台を昇り降りし、マガジンの残量を確認する（供給3分のうち0.6分）
X11: 時間が削減される作業
C15: ='（別紙１）省力化計算シート'!C16 -> マガジンへの束の手投入 | E15: > | G15: ='（別紙１）省力化計算シート'!C17 -> 品種切替時のパウチ切替 | I15: > | K15: ='（別紙１）省力化計算シート'!C18 -> 製袋機の運転・監視 | M15: > | O15: ='（別紙１）省力化計算シート'!C19 -> 充填（充填室） | Q15: > | S15: ='（別紙１）省力化計算シート'!C20 -> 包装・箱詰め | U15: > | X15: 導入前後で同様の作業
C16: =IF('（別紙１）省力化計算シート'!D16="","",IF(OR('（別紙１）省力化計算シート'!F16="-",'（別紙１）省力化計算シート'!F16=0),'（別紙１）省力化計算シート'!D16&"分",'（別紙１）省力化計算シート'!D16&"分"&" (→"&'（別紙１）省力化計算シート'!D16+'（別紙１）省力化計算シート'!F16&"分）")) -> 315分 | G16: =IF('（別紙１）省力化計算シート'!D17="","",IF(OR('（別紙１）省力化計算シート'!F17="-",'（別紙１）省力化計算シート'!F17=0),'（別紙１）省力化計算シート'!D17&"分",'（別紙１）省力化計算シート'!D17&"分"&" (→"&'（別紙１）省力化計算シート'!D17+'（別紙１）省力化計算シート'!F17&"分）")) -> 8分 | K16: =IF('（別紙１）省力化計算シート'!D18="","",IF(OR('（別紙１）省力化計算シート'!F18="-",'（別紙１）省力化計算シート'!F18=0),'（別紙１）省力化計算シート'!D18&"分",'（別紙１）省力化計算シート'!D18&"分"&" (→"&'（別紙１）省力化計算シート'!D18+'（別紙１）省力化計算シート'!F18&"分）")) -> 1050分 | O16: =IF('（別紙１）省力化計算シート'!D19="","",IF(OR('（別紙１）省力化計算シート'!F19="-",'（別紙１）省力化計算シート'!F19=0),'（別紙１）省力化計算シート'!D19&"分",'（別紙１）省力化計算シート'!D19&"分"&" (→"&'（別紙１）省力化計算シート'!D19+'（別紙１）省力化計算シート'!F19&"分）")) -> 1050分 | S16: =IF('（別紙１）省力化計算シート'!D20="","",IF(OR('（別紙１）省力化計算シート'!F20="-",'（別紙１）省力化計算シート'!F20=0),'（別紙１）省力化計算シート'!D20&"分",'（別紙１）省力化計算シート'!D20&"分"&" (→"&'（別紙１）省力化計算シート'!D20+'（別紙１）省力化計算シート'!F20&"分）")) -> 2625分
C17: 踏み台に立ちマガジンへ束を手投入（約2.4分×約131回）。5分で空になり繰り返すため離れられない | G17: 2品種の日に、残ったパウチの回収と次品種の段ボール・束の準備を行う（1回約15分、月平均） | K17: オペレーター1名が製袋機（スパウト熱圧着）の運転・監視を行う | O17: 充填室1名。調合液の殺菌、充填、容器ごとの殺菌（本事業で作業は変わらない） | S17: 2階包装室2〜3名（平均2.5名）。包装・箱詰めののち1階へ下ろす（作業は変わらない） | X17: 作業内容の説明 入力欄
C22: ='（別紙１）省力化計算シート'!C21 -> 0 | E22: > | G22: ='（別紙１）省力化計算シート'!C22 -> 0 | I22: > | K22: ='（別紙１）省力化計算シート'!C23 -> 0 | M22: > | O22: ='（別紙１）省力化計算シート'!C24 -> 0 | Q22: > | S22: ='（別紙１）省力化計算シート'!C25 -> 0 | U22: >
C23: =IF('（別紙１）省力化計算シート'!D21="","",IF(OR('（別紙１）省力化計算シート'!F21="-",'（別紙１）省力化計算シート'!F21=0),'（別紙１）省力化計算シート'!D21&"分",'（別紙１）省力化計算シート'!D21&"分"&" (→"&'（別紙１）省力化計算シート'!D21+'（別紙１）省力化計算シート'!F21&"分）")) | G23: =IF('（別紙１）省力化計算シート'!D22="","",IF(OR('（別紙１）省力化計算シート'!F22="-",'（別紙１）省力化計算シート'!F22=0),'（別紙１）省力化計算シート'!D22&"分",'（別紙１）省力化計算シート'!D22&"分"&" (→"&'（別紙１）省力化計算シート'!D22+'（別紙１）省力化計算シート'!F22&"分）")) | K23: =IF('（別紙１）省力化計算シート'!D23="","",IF(OR('（別紙１）省力化計算シート'!F23="-",'（別紙１）省力化計算シート'!F23=0),'（別紙１）省力化計算シート'!D23&"分",'（別紙１）省力化計算シート'!D23&"分"&" (→"&'（別紙１）省力化計算シート'!D23+'（別紙１）省力化計算シート'!F23&"分）")) | O23: =IF('（別紙１）省力化計算シート'!D24="","",IF(OR('（別紙１）省力化計算シート'!F24="-",'（別紙１）省力化計算シート'!F24=0),'（別紙１）省力化計算シート'!D24&"分",'（別紙１）省力化計算シート'!D24&"分"&" (→"&'（別紙１）省力化計算シート'!D24+'（別紙１）省力化計算シート'!F24&"分）")) | S23: =IF('（別紙１）省力化計算シート'!D25="","",IF(OR('（別紙１）省力化計算シート'!F25="-",'（別紙１）省力化計算シート'!F25=0),'（別紙１）省力化計算シート'!D25&"分",'（別紙１）省力化計算シート'!D25&"分"&" (→"&'（別紙１）省力化計算シート'!D25+'（別紙１）省力化計算シート'!F25&"分）"))
C29: ='（別紙１）省力化計算シート'!C26 -> 0 | E29: > | G29: ='（別紙１）省力化計算シート'!C27 -> 0 | I29: > | K29: ='（別紙１）省力化計算シート'!C28 -> 0 | M29: > | O29: ='（別紙１）省力化計算シート'!C29 -> 0 | Q29: > | S29: ='（別紙１）省力化計算シート'!C30 -> 0 | U29: >
C30: =IF('（別紙１）省力化計算シート'!D26="","",IF(OR('（別紙１）省力化計算シート'!F26="-",'（別紙１）省力化計算シート'!F26=0),'（別紙１）省力化計算シート'!D26&"分",'（別紙１）省力化計算シート'!D26&"分"&" (→"&'（別紙１）省力化計算シート'!D26+'（別紙１）省力化計算シート'!F26&"分）")) | G30: =IF('（別紙１）省力化計算シート'!D27="","",IF(OR('（別紙１）省力化計算シート'!F27="-",'（別紙１）省力化計算シート'!F27=0),'（別紙１）省力化計算シート'!D27&"分",'（別紙１）省力化計算シート'!D27&"分"&" (→"&'（別紙１）省力化計算シート'!D27+'（別紙１）省力化計算シート'!F27&"分）")) | K30: =IF('（別紙１）省力化計算シート'!D28="","",IF(OR('（別紙１）省力化計算シート'!F28="-",'（別紙１）省力化計算シート'!F28=0),'（別紙１）省力化計算シート'!D28&"分",'（別紙１）省力化計算シート'!D28&"分"&" (→"&'（別紙１）省力化計算シート'!D28+'（別紙１）省力化計算シート'!F28&"分）")) | O30: =IF('（別紙１）省力化計算シート'!D29="","",IF(OR('（別紙１）省力化計算シート'!F29="-",'（別紙１）省力化計算シート'!F29=0),'（別紙１）省力化計算シート'!D29&"分",'（別紙１）省力化計算シート'!D29&"分"&" (→"&'（別紙１）省力化計算シート'!D29+'（別紙１）省力化計算シート'!F29&"分）")) | S30: =IF('（別紙１）省力化計算シート'!D30="","",IF(OR('（別紙１）省力化計算シート'!F30="-",'（別紙１）省力化計算シート'!F30=0),'（別紙１）省力化計算シート'!D30&"分",'（別紙１）省力化計算シート'!D30&"分"&" (→"&'（別紙１）省力化計算シート'!D30+'（別紙１）省力化計算シート'!F30&"分）"))
C36: ='（別紙１）省力化計算シート'!C31 -> 0 | E36: > | G36: ='（別紙１）省力化計算シート'!C32 -> 0 | I36: > | K36: ='（別紙１）省力化計算シート'!C33 -> 0 | M36: > | O36: ='（別紙１）省力化計算シート'!C34 -> 0 | Q36: > | S36: ='（別紙１）省力化計算シート'!C35 -> 0 | U36: >
C37: =IF('（別紙１）省力化計算シート'!D31="","",IF(OR('（別紙１）省力化計算シート'!F31="-",'（別紙１）省力化計算シート'!F31=0),'（別紙１）省力化計算シート'!D31&"分",'（別紙１）省力化計算シート'!D31&"分"&" (→"&'（別紙１）省力化計算シート'!D31+'（別紙１）省力化計算シート'!F31&"分）")) | G37: =IF('（別紙１）省力化計算シート'!D32="","",IF(OR('（別紙１）省力化計算シート'!F32="-",'（別紙１）省力化計算シート'!F32=0),'（別紙１）省力化計算シート'!D32&"分",'（別紙１）省力化計算シート'!D32&"分"&" (→"&'（別紙１）省力化計算シート'!D32+'（別紙１）省力化計算シート'!F32&"分）")) | K37: =IF('（別紙１）省力化計算シート'!D33="","",IF(OR('（別紙１）省力化計算シート'!F33="-",'（別紙１）省力化計算シート'!F33=0),'（別紙１）省力化計算シート'!D33&"分",'（別紙１）省力化計算シート'!D33&"分"&" (→"&'（別紙１）省力化計算シート'!D33+'（別紙１）省力化計算シート'!F33&"分）")) | O37: =IF('（別紙１）省力化計算シート'!D34="","",IF(OR('（別紙１）省力化計算シート'!F34="-",'（別紙１）省力化計算シート'!F34=0),'（別紙１）省力化計算シート'!D34&"分",'（別紙１）省力化計算シート'!D34&"分"&" (→"&'（別紙１）省力化計算シート'!D34+'（別紙１）省力化計算シート'!F34&"分）")) | S37: =IF('（別紙１）省力化計算シート'!D35="","",IF(OR('（別紙１）省力化計算シート'!F35="-",'（別紙１）省力化計算シート'!F35=0),'（別紙１）省力化計算シート'!D35&"分",'（別紙１）省力化計算シート'!D35&"分"&" (→"&'（別紙１）省力化計算シート'!D35+'（別紙１）省力化計算シート'!F35&"分）"))
C43: ='（別紙１）省力化計算シート'!C36 -> 0 | E43: > | G43: ='（別紙１）省力化計算シート'!C37 -> 0 | I43: > | K43: ='（別紙１）省力化計算シート'!C38 -> 0 | M43: > | O43: ='（別紙１）省力化計算シート'!C39 -> 0 | Q43: > | S43: ='（別紙１）省力化計算シート'!C40 -> 0
C44: =IF('（別紙１）省力化計算シート'!D36="","",IF(OR('（別紙１）省力化計算シート'!F36="-",'（別紙１）省力化計算シート'!F36=0),'（別紙１）省力化計算シート'!D36&"分",'（別紙１）省力化計算シート'!D36&"分"&" (→"&'（別紙１）省力化計算シート'!D36+'（別紙１）省力化計算シート'!F36&"分）")) | G44: =IF('（別紙１）省力化計算シート'!D37="","",IF(OR('（別紙１）省力化計算シート'!F37="-",'（別紙１）省力化計算シート'!F37=0),'（別紙１）省力化計算シート'!D37&"分",'（別紙１）省力化計算シート'!D37&"分"&" (→"&'（別紙１）省力化計算シート'!D37+'（別紙１）省力化計算シート'!F37&"分）")) | K44: =IF('（別紙１）省力化計算シート'!D38="","",IF(OR('（別紙１）省力化計算シート'!F38="-",'（別紙１）省力化計算シート'!F38=0),'（別紙１）省力化計算シート'!D38&"分",'（別紙１）省力化計算シート'!D38&"分"&" (→"&'（別紙１）省力化計算シート'!D38+'（別紙１）省力化計算シート'!F38&"分）")) | O44: =IF('（別紙１）省力化計算シート'!D39="","",IF(OR('（別紙１）省力化計算シート'!F39="-",'（別紙１）省力化計算シート'!F39=0),'（別紙１）省力化計算シート'!D39&"分",'（別紙１）省力化計算シート'!D39&"分"&" (→"&'（別紙１）省力化計算シート'!D39+'（別紙１）省力化計算シート'!F39&"分）")) | S44: =IF('（別紙１）省力化計算シート'!D40="","",IF(OR('（別紙１）省力化計算シート'!F40="-",'（別紙１）省力化計算シート'!F40=0),'（別紙１）省力化計算シート'!D40&"分",'（別紙１）省力化計算シート'!D40&"分"&" (→"&'（別紙１）省力化計算シート'!D40+'（別紙１）省力化計算シート'!F40&"分）"))
A48: =IF(COUNTA('（別紙１）省力化計算シート'!C26:C40)<>0,"← 非表示エリアに記載があります。[＋]をクリックして表示してください。[-]の場合は、すべて表示されています。","")
C50: ■設備導入後の業務プロセス・作業工程 （AFTER） | O50: 設備導入による増加時間 | S50: ='（別紙１）省力化計算シート'!J3 -> 3.85 | T50: 時間
C53: ='（別紙１）省力化計算シート'!I11 -> 空パウチの搬入 | E53: > | G53: ='（別紙１）省力化計算シート'!I12 -> 専用パレットへの詰め | I53: > | K53: ='（別紙１）省力化計算シート'!I13 -> パレットの装填・入替 | M53: > | O53: ='（別紙１）省力化計算シート'!I14 -> 専用パレットの型替え | Q53: > | S53: ='（別紙１）省力化計算シート'!I15 -> 製袋機の運転・監視 | U53: > | X53: 新たに追加される作業
C54: =IF('（別紙１）省力化計算シート'!J11="","",IF(OR('（別紙１）省力化計算シート'!N11="-",'（別紙１）省力化計算シート'!N11=0),'（別紙１）省力化計算シート'!J11&"分","("&'（別紙１）省力化計算シート'!J11-'（別紙１）省力化計算シート'!N11&"分→）"&'（別紙１）省力化計算シート'!J11&"分")) -> 20分 | G54: =IF('（別紙１）省力化計算シート'!J12="","",IF(OR('（別紙１）省力化計算シート'!N12="-",'（別紙１）省力化計算シート'!N12=0),'（別紙１）省力化計算シート'!J12&"分","("&'（別紙１）省力化計算シート'!J12-'（別紙１）省力化計算シート'!N12&"分→）"&'（別紙１）省力化計算シート'!J12&"分")) -> 209分 | K54: =IF('（別紙１）省力化計算シート'!J13="","",IF(OR('（別紙１）省力化計算シート'!N13="-",'（別紙１）省力化計算シート'!N13=0),'（別紙１）省力化計算シート'!J13&"分","("&'（別紙１）省力化計算シート'!J13-'（別紙１）省力化計算シート'!N13&"分→）"&'（別紙１）省力化計算シート'!J13&"分")) -> 15分 | O54: =IF('（別紙１）省力化計算シート'!J14="","",IF(OR('（別紙１）省力化計算シート'!N14="-",'（別紙１）省力化計算シート'!N14=0),'（別紙１）省力化計算シート'!J14&"分","("&'（別紙１）省力化計算シート'!J14-'（別紙１）省力化計算シート'!N14&"分→）"&'（別紙１）省力化計算シート'!J14&"分")) -> 7分 | S54: =IF('（別紙１）省力化計算シート'!J15="","",IF(OR('（別紙１）省力化計算シート'!N15="-",'（別紙１）省力化計算シート'!N15=0),'（別紙１）省力化計算シート'!J15&"分","("&'（別紙１）省力化計算シート'!J15-'（別紙１）省力化計算シート'!N15&"分→）"&'（別紙１）省力化計算シート'!J15&"分")) -> 1050分
C55: 詰め担当が資材保管室から数箱ずつ運ぶ。回数・時間は変わらない | G55: 専用パレット（1,200袋）へ開梱・ほぐし・片付け込みで約2分／枚。125枚と84枚の日の月平均 | K55: 約2.5〜3時間に1回（1日4〜6回）、パレットを装填し空パレットを取り出す（約3分／回）。遅番はオペレーターが兼務 | O55: パウチ形状が変わる品種切替時に、機内25枚のガイド幅を替える（約1.1分／枚≒28分）。月平均 | S55: 運転・監視は変わらない。マガジンへの供給はロボットが自動で行い、供給待ちや欠員カバーがなくなる
X56: 時間が増加する作業
C60: ='（別紙１）省力化計算シート'!I16 -> 充填（充填室） | E60: > | G60: ='（別紙１）省力化計算シート'!I17 -> 包装・箱詰め | I60: > | K60: ='（別紙１）省力化計算シート'!I18 -> 0 | M60: > | O60: ='（別紙１）省力化計算シート'!I19 -> 0 | Q60: > | S60: ='（別紙１）省力化計算シート'!I20 -> 0 | U60: > | X60: 導入前後で同様の作業
C61: =IF('（別紙１）省力化計算シート'!J16="","",IF(OR('（別紙１）省力化計算シート'!N16="-",'（別紙１）省力化計算シート'!N16=0),'（別紙１）省力化計算シート'!J16&"分","("&'（別紙１）省力化計算シート'!J16-'（別紙１）省力化計算シート'!N16&"分→）"&'（別紙１）省力化計算シート'!J16&"分")) -> 1050分 | G61: =IF('（別紙１）省力化計算シート'!J17="","",IF(OR('（別紙１）省力化計算シート'!N17="-",'（別紙１）省力化計算シート'!N17=0),'（別紙１）省力化計算シート'!J17&"分","("&'（別紙１）省力化計算シート'!J17-'（別紙１）省力化計算シート'!N17&"分→）"&'（別紙１）省力化計算シート'!J17&"分")) -> 2625分 | K61: =IF('（別紙１）省力化計算シート'!J18="","",IF(OR('（別紙１）省力化計算シート'!N18="-",'（別紙１）省力化計算シート'!N18=0),'（別紙１）省力化計算シート'!J18&"分","("&'（別紙１）省力化計算シート'!J18-'（別紙１）省力化計算シート'!N18&"分→）"&'（別紙１）省力化計算シート'!J18&"分")) | O61: =IF('（別紙１）省力化計算シート'!J19="","",IF(OR('（別紙１）省力化計算シート'!N19="-",'（別紙１）省力化計算シート'!N19=0),'（別紙１）省力化計算シート'!J19&"分","("&'（別紙１）省力化計算シート'!J19-'（別紙１）省力化計算シート'!N19&"分→）"&'（別紙１）省力化計算シート'!J19&"分")) | S61: =IF('（別紙１）省力化計算シート'!J20="","",IF(OR('（別紙１）省力化計算シート'!N20="-",'（別紙１）省力化計算シート'!N20=0),'（別紙１）省力化計算シート'!J20&"分","("&'（別紙１）省力化計算シート'!J20-'（別紙１）省力化計算シート'!N20&"分→）"&'（別紙１）省力化計算シート'!J20&"分"))
C62: 作業は変わらない。パウチ供給が途切れず、投入担当の確保に左右されない安定稼働になる | G62: 作業は変わらない。安定稼働により受注の取りこぼしを防ぐ余力が生まれる | X62: 作業内容の説明 入力欄
C67: ='（別紙１）省力化計算シート'!I21 -> 0 | E67: > | G67: ='（別紙１）省力化計算シート'!I22 -> 0 | I67: > | K67: ='（別紙１）省力化計算シート'!I23 -> 0 | M67: > | O67: ='（別紙１）省力化計算シート'!I24 -> 0 | Q67: > | S67: ='（別紙１）省力化計算シート'!I25 -> 0 | U67: >
C68: =IF('（別紙１）省力化計算シート'!J21="","",IF(OR('（別紙１）省力化計算シート'!N21="-",'（別紙１）省力化計算シート'!N21=0),'（別紙１）省力化計算シート'!J21&"分","("&'（別紙１）省力化計算シート'!J21-'（別紙１）省力化計算シート'!N21&"分→）"&'（別紙１）省力化計算シート'!J21&"分")) | G68: =IF('（別紙１）省力化計算シート'!J22="","",IF(OR('（別紙１）省力化計算シート'!N22="-",'（別紙１）省力化計算シート'!N22=0),'（別紙１）省力化計算シート'!J22&"分","("&'（別紙１）省力化計算シート'!J22-'（別紙１）省力化計算シート'!N22&"分→）"&'（別紙１）省力化計算シート'!J22&"分")) | K68: =IF('（別紙１）省力化計算シート'!J23="","",IF(OR('（別紙１）省力化計算シート'!N23="-",'（別紙１）省力化計算シート'!N23=0),'（別紙１）省力化計算シート'!J23&"分","("&'（別紙１）省力化計算シート'!J23-'（別紙１）省力化計算シート'!N23&"分→）"&'（別紙１）省力化計算シート'!J23&"分")) | O68: =IF('（別紙１）省力化計算シート'!J24="","",IF(OR('（別紙１）省力化計算シート'!N24="-",'（別紙１）省力化計算シート'!N24=0),'（別紙１）省力化計算シート'!J24&"分","("&'（別紙１）省力化計算シート'!J24-'（別紙１）省力化計算シート'!N24&"分→）"&'（別紙１）省力化計算シート'!J24&"分")) | S68: =IF('（別紙１）省力化計算シート'!J25="","",IF(OR('（別紙１）省力化計算シート'!N25="-",'（別紙１）省力化計算シート'!N25=0),'（別紙１）省力化計算シート'!J25&"分","("&'（別紙１）省力化計算シート'!J25-'（別紙１）省力化計算シート'!N25&"分→）"&'（別紙１）省力化計算シート'!J25&"分"))
C74: ='（別紙１）省力化計算シート'!I26 -> 0 | E74: > | G74: ='（別紙１）省力化計算シート'!I27 -> 0 | I74: > | K74: ='（別紙１）省力化計算シート'!I28 -> 0 | M74: > | O74: ='（別紙１）省力化計算シート'!I29 -> 0 | Q74: > | S74: ='（別紙１）省力化計算シート'!I30 -> 0 | U74: >
C75: =IF('（別紙１）省力化計算シート'!J26="","",IF(OR('（別紙１）省力化計算シート'!N26="-",'（別紙１）省力化計算シート'!N26=0),'（別紙１）省力化計算シート'!J26&"分","("&'（別紙１）省力化計算シート'!J26-'（別紙１）省力化計算シート'!N26&"分→）"&'（別紙１）省力化計算シート'!J26&"分")) | G75: =IF('（別紙１）省力化計算シート'!J27="","",IF(OR('（別紙１）省力化計算シート'!N27="-",'（別紙１）省力化計算シート'!N27=0),'（別紙１）省力化計算シート'!J27&"分","("&'（別紙１）省力化計算シート'!J27-'（別紙１）省力化計算シート'!N27&"分→）"&'（別紙１）省力化計算シート'!J27&"分")) | K75: =IF('（別紙１）省力化計算シート'!J28="","",IF(OR('（別紙１）省力化計算シート'!N28="-",'（別紙１）省力化計算シート'!N28=0),'（別紙１）省力化計算シート'!J28&"分","("&'（別紙１）省力化計算シート'!J28-'（別紙１）省力化計算シート'!N28&"分→）"&'（別紙１）省力化計算シート'!J28&"分")) | O75: =IF('（別紙１）省力化計算シート'!J29="","",IF(OR('（別紙１）省力化計算シート'!N29="-",'（別紙１）省力化計算シート'!N29=0),'（別紙１）省力化計算シート'!J29&"分","("&'（別紙１）省力化計算シート'!J29-'（別紙１）省力化計算シート'!N29&"分→）"&'（別紙１）省力化計算シート'!J29&"分")) | S75: =IF('（別紙１）省力化計算シート'!J30="","",IF(OR('（別紙１）省力化計算シート'!N30="-",'（別紙１）省力化計算シート'!N30=0),'（別紙１）省力化計算シート'!J30&"分","("&'（別紙１）省力化計算シート'!J30-'（別紙１）省力化計算シート'!N30&"分→）"&'（別紙１）省力化計算シート'!J30&"分"))
C81: ='（別紙１）省力化計算シート'!I31 -> 0 | E81: > | G81: ='（別紙１）省力化計算シート'!I32 -> 0 | I81: > | K81: ='（別紙１）省力化計算シート'!I33 -> 0 | M81: > | O81: ='（別紙１）省力化計算シート'!I34 -> 0 | Q81: > | S81: ='（別紙１）省力化計算シート'!I35 -> 0 | U81: >
C82: =IF('（別紙１）省力化計算シート'!J31="","",IF(OR('（別紙１）省力化計算シート'!N31="-",'（別紙１）省力化計算シート'!N31=0),'（別紙１）省力化計算シート'!J31&"分","("&'（別紙１）省力化計算シート'!J31-'（別紙１）省力化計算シート'!N31&"分→）"&'（別紙１）省力化計算シート'!J31&"分")) | G82: =IF('（別紙１）省力化計算シート'!J32="","",IF(OR('（別紙１）省力化計算シート'!N32="-",'（別紙１）省力化計算シート'!N32=0),'（別紙１）省力化計算シート'!J32&"分","("&'（別紙１）省力化計算シート'!J32-'（別紙１）省力化計算シート'!N32&"分→）"&'（別紙１）省力化計算シート'!J32&"分")) | K82: =IF('（別紙１）省力化計算シート'!J33="","",IF(OR('（別紙１）省力化計算シート'!N33="-",'（別紙１）省力化計算シート'!N33=0),'（別紙１）省力化計算シート'!J33&"分","("&'（別紙１）省力化計算シート'!J33-'（別紙１）省力化計算シート'!N33&"分→）"&'（別紙１）省力化計算シート'!J33&"分")) | O82: =IF('（別紙１）省力化計算シート'!J34="","",IF(OR('（別紙１）省力化計算シート'!N34="-",'（別紙１）省力化計算シート'!N34=0),'（別紙１）省力化計算シート'!J34&"分","("&'（別紙１）省力化計算シート'!J34-'（別紙１）省力化計算シート'!N34&"分→）"&'（別紙１）省力化計算シート'!J34&"分")) | S82: =IF('（別紙１）省力化計算シート'!J35="","",IF(OR('（別紙１）省力化計算シート'!N35="-",'（別紙１）省力化計算シート'!N35=0),'（別紙１）省力化計算シート'!J35&"分","("&'（別紙１）省力化計算シート'!J35-'（別紙１）省力化計算シート'!N35&"分→）"&'（別紙１）省力化計算シート'!J35&"分"))
C88: ='（別紙１）省力化計算シート'!I36 -> 0 | E88: > | G88: ='（別紙１）省力化計算シート'!I37 -> 0 | I88: > | K88: ='（別紙１）省力化計算シート'!I38 -> 0 | M88: > | O88: ='（別紙１）省力化計算シート'!I39 -> 0 | Q88: > | S88: ='（別紙１）省力化計算シート'!I40 -> 0
C89: =IF('（別紙１）省力化計算シート'!J36="","",IF(OR('（別紙１）省力化計算シート'!N36="-",'（別紙１）省力化計算シート'!N36=0),'（別紙１）省力化計算シート'!J36&"分","("&'（別紙１）省力化計算シート'!J36-'（別紙１）省力化計算シート'!N36&"分→）"&'（別紙１）省力化計算シート'!J36&"分")) | G89: =IF('（別紙１）省力化計算シート'!J37="","",IF(OR('（別紙１）省力化計算シート'!N37="-",'（別紙１）省力化計算シート'!N37=0),'（別紙１）省力化計算シート'!J37&"分","("&'（別紙１）省力化計算シート'!J37-'（別紙１）省力化計算シート'!N37&"分→）"&'（別紙１）省力化計算シート'!J37&"分")) | K89: =IF('（別紙１）省力化計算シート'!J38="","",IF(OR('（別紙１）省力化計算シート'!N38="-",'（別紙１）省力化計算シート'!N38=0),'（別紙１）省力化計算シート'!J38&"分","("&'（別紙１）省力化計算シート'!J38-'（別紙１）省力化計算シート'!N38&"分→）"&'（別紙１）省力化計算シート'!J38&"分")) | O89: =IF('（別紙１）省力化計算シート'!J39="","",IF(OR('（別紙１）省力化計算シート'!N39="-",'（別紙１）省力化計算シート'!N39=0),'（別紙１）省力化計算シート'!J39&"分","("&'（別紙１）省力化計算シート'!J39-'（別紙１）省力化計算シート'!N39&"分→）"&'（別紙１）省力化計算シート'!J39&"分")) | S89: =IF('（別紙１）省力化計算シート'!J40="","",IF(OR('（別紙１）省力化計算シート'!N40="-",'（別紙１）省力化計算シート'!N40=0),'（別紙１）省力化計算シート'!J40&"分","("&'（別紙１）省力化計算シート'!J40-'（別紙１）省力化計算シート'!N40&"分→）"&'（別紙１）省力化計算シート'!J40&"分"))
A93: =IF(COUNTA('（別紙１）省力化計算シート'!I26:I40)<>0,"← 非表示エリアに記載があります。[＋]をクリックして表示してください。[-]の場合は、すべて表示されています。","")

Sheet （別紙３）投資回収期間計算シート
B1: （別紙３）投資回収期間計算シート
B3: 投資回収期間 | C3: =IF(AND(O4=FALSE,OR(C6="",H6="",J6="",L6="")),"",IF(AND(O4=TRUE,OR(C6="",L6="")),"",IF(C6/(F6*H6*J6+L6)<=0,"",C6/(F6*H6*J6+L6)))) -> 0.32963325 | D3: 年 | O3: パラメータ（公開時に非表示）
O4: FALSE
C5: 投資総額（円） | F5: 削減工数(時間) | H5: 年間稼働日数（日） | J5: 人件費単価（円/時） | L5: 増加した付加価値額（円） | O5: =IF($O$4=TRUE,"※新規事業の場合、削減工数（時間）は0と見なします。","※ 省力化計算シートより自動入力されます。") -> ※ 省力化計算シートより自動入力されます。
C6: 101200000 | D6: / | E6: （ | F6: =IF($O$4=TRUE,0,'（別紙１）省力化計算シート'!D3-'（別紙１）省力化計算シート'!J3) -> 13.316667 | G6: × | H6: 245 | I6: × | J6: 2773 | K6: ＋ | L6: 297960717 | M6: ）
C12: 【算定根拠】算定の根拠となる計算式等の説明があれば記載してください。
C13: ・投資総額101,200,000円＝株式会社フジシールの見積による補助対象経費92,000,000円（税抜）×1.1（消費税10％）。 ・削減工数13.3時間／日＝別紙１の削減時間1,030分−導入後に発生する時間231分＝799分（÷60）。 ・年間稼働日数245日＝本事業を行うGライン（製袋室）の年間稼働日数。 ・人件費単価2,773円／時＝従業員・役員の時給平均額（2026年3月期の人件費1,021,940,577円÷総労働時間368,480時間（188名×245日×8時間））。 ・増加した付加価値額297,960,717円＝3年目1,891,288,147円−基準年度1,593,327,430円（別紙４）。 ・労働時間削減額9,047,144円／年＝799/60×245×2,773。 →投資回収期間＝101,200,000÷（9,047,144＋297,960,717）≒0.33年。 ・増加した付加価値額を1年あたり（297,960,717÷3＝99,320,239円）とした場合も、101,200,000÷（9,047,144＋99,320,239）≒0.93年で、1年未満で回収できる。 ・Gライン部門のみで見た場合：1年目に受注する断った案件の約半分（約2億円）に、全社の付加価値率13.66％（2026年3月期：1,525,628,095円÷11,168,904,537円）を当てはめると付加価値額は年約2,732万円となり、101,200,000÷（9,047,144＋27,320,000）≒2.78年で、耐用年数（10年）の範囲内で回収できる。

Sheet 【（別紙４）の入力について】
B1: （別紙４）の入力について
B2: （別紙４）事業計画目標値算出シートについて
B3: 労働生産性、1人当たり給与支給総額の年平均成長率算出のためのシートです。全事業者提出が必要になりますので、入力のうえ応募申請時にご提出ください。
B4: 事業計画の策定にあたり、以下の機構ツールをぜひご活用ください。
B5: 「経営自己診断システム」 | C5: 「価格転嫁検討ツール」 | D5: 「儲かる経営キヅク君」
B7: ■注意点
B8: 〇事業計画期間（基準年度～事業計画期間）の計画値
B9: ・申請システムへの入力はこの表の入力値を転記していただきます。ただし、入力値(営業利益が大幅にマイナスの場合など)によっては、申請システムの計算値と異なる可能性があります。
B10: システムへの入力値を正しいものとして審査しますので、申請システムにて数値をよくご確認ください。
B12: 〇１人当たり給与支給総額の足下の賃上げ計画値
B13: ・申請システムへの入力はありません。こちらのシートに入力された計画値を基に審査を行いますのでよくご確認ください。計画が策定されていない場合や、目標を下回る計画の場合審査で不利となります。
B15: ※申請にあたっての要件等は、公募要領にてご確認ください。
B18: シートの利用方法
B19: 事業年度はいずれも事業者自身における決算年度になります。 | H19: （別紙4）事業計画目標値算出シートの該当箇所
B20: １． 決算月をプルダウンから選択してください。 | H20: C列4行目
B21: 応募申請の直近決算期、応募申請締切（10月）を含む決算期が自動表示されます。 | H21: D列12行目
B22: ２． 補助事業の完了予定年月をプルダウンから選択してください。事業計画に沿った補助事業完了予定日にてご判断ください。 | H22: C列5行目
B23: 基準年度及び1年目以降の決算期が自動表示されます。 | H23: E列12行目～K列12行目
B24: ３． 労働生産性の基準年度～５年目までの計画を策定してください。 | H24: F列14行目～K列29行目
B25: ４． 1人当たり給与支給総額の直近の事業年度～基準年度までの足下の賃上げ計画を策定してください。 | H25: C列32行目～E列39行目
B26: ５． ４で策定した基準年度の数値を基に、1人当たり給与支給総額の事業計画期間1年目～5年目の計画を策定してください。 | H26: F列32行目～K列39行目
B28: 凡例 （別紙4）の入力セルについて
B29: 入力項目 | C29: 入力項目です。
B31: 自動計算・自動表示 | C31: 入力値から自動で計算、表示しています。
B33: 達成するための目標値 | C33: 目標を達成するための数値を参考として表示しています。
B35: 策定された目標値（％） | C35: 入力された値から策定された目標値です。

Sheet (別紙4）事業計画目標値算出シート
B1: （別紙４）事業計画目標値算出シート 全事業者提出必須 | D1: 本シートの利用については【（別紙４）の入力について】シートにてご確認ください。
B4: 決算月 | C4: 3月 | D4: 自社の決算月を選択してください。
B5: 補助事業完了予定年月 | C5: 46753 | D5: 補助事業を完了する予定年月を選択してください。
B6: 応募申請の直近から基準年度までの経過年数 | C6: =IF(OR(C12="",E12=""),"",YEAR(E12)-YEAR(C12)) -> 2
D9: 1 | E9: =IF(OR(C4="",C5=""),"",((YEAR(C5)+(MONTH(C5)>VALUE(SUBSTITUTE(C4,"月",""))))-IF(VALUE(SUBSTITUTE(C4,"月",""))<=9,2026,2025))) -> 2 | G9: 1 | H9: 2 | I9: 3 | J9: 4 | K9: 5
C10: 足下の賃上げ 計画目標 | F10: 事業計画期間の計画目標
C11: 応募申請の 直近の決算期（注５） | D11: 応募申請締切日（10月） を含む決算期 | E11: 基準年度 （補助事業の完了日を含む決算期） | G11: １年目計画 | H11: ２年目計画 | I11: ３年目計画 | J11: ４年目計画 | K11: ５年目計画
C12: =IF(D12="","",EDATE(D12,-12)) -> 46082 | D12: =IF(C4="","",DATE(IF(VALUE(SUBSTITUTE(C4,"月",""))<=9,2027,2026),VALUE(SUBSTITUTE(C4,"月","")),1)) -> 46447 | E12: =IF(OR(C5="",C4=""),"",DATE(YEAR(C5)+(MONTH(C5)>VALUE(SUBSTITUTE(C4,"月",""))),VALUE(SUBSTITUTE(C4,"月","")),1)) -> 46813 | F12: =E12 -> 46813 | G12: =IF(F12="","",EDATE(F12,12)) -> 47178 | H12: =IF(G12="","",EDATE(G12,12)) -> 47543 | I12: =IF(H12="","",EDATE(H12,12)) -> 47908 | J12: =IF(I12="","",EDATE(I12,12)) -> 48274 | K12: =IF(J12="","",EDATE(J12,12)) -> 48639
B13: 労働生産性の年平均成長率算定シート
B14: 売上高 | F14: 11506484677 | G14: 11966744064 | H14: 12445413827 | I14: 12943230380 | J14: 13460959595 | K14: 13999397979
B15: 売上原価 | F15: 10413368633 | G15: 10799986518 | H15: 11200872444 | I15: 11616549266 | J15: 12040828358 | K15: 12480463298
B16: 売上総利益 | F16: =F14-F15 -> 1093116044 | G16: =G14-G15 -> 1166757546 | H16: =H14-H15 -> 1244541383 | I16: =I14-I15 -> 1326681114 | J16: =J14-J15 -> 1420131237 | K16: =K14-K15 -> 1518934681
B17: 販売費及び一般管理費 | F17: 878831451 | G17: 915733024 | H17: 955904165 | I17: 996077390 | J17: 1039776714 | K17: 1083502800
B18: ① 営業利益 | F18: =F16-F17 -> 214284593 | G18: =G16-G17 -> 251024522 | H18: =H16-H17 -> 288637218 | I18: =I16-I17 -> 330603724 | J18: =J16-J17 -> 380354523 | K18: =K16-K17 -> 435431881
B19: ② 人件費 （注1） | F19: 1080178369 | G19: 1133090527 | H19: 1194468069 | I19: 1252619955 | J19: 1319891660 | K19: 1383761250
B20: ③ 減価償却費 | F20: =F21+F22 -> 298864468 | G20: =G21+G22 -> 308064468 | H20: =H21+H22 -> 308064468 | I20: =I21+I22 -> 308064468 | J20: =J21+J22 -> 308064468 | K20: =K21+K22 -> 308064468
B21: （内訳）既存設備の減価償却費 | F21: 298864468 | G21: 298864468 | H21: 298864468 | I21: 298864468 | J21: 298864468 | K21: 298864468
B22: 本補助金で導入する設備の減価償却費 | G22: 9200000 | H22: 9200000 | I22: 9200000 | J22: 9200000 | K22: 9200000
B23: ④付加価値額（①+②+③） | F23: =F18+F19+F20 -> 1593327430 | G23: =G18+G19+G20 -> 1692179517 | H23: =H18+H19+H20 -> 1791169755 | I23: =I18+I19+I20 -> 1891288147 | J23: =J18+J19+J20 -> 2008310651 | K23: =K18+K19+K20 -> 2127257599
B24: 付加価値額の年平均成長率（％） | G24: =ROUNDDOWN(((G23/$F$23)^(1/G9)-1)*100,2) -> 6.2 | H24: =ROUNDDOWN(((H23/$F$23)^(1/H9)-1)*100,2) -> 6.02 | I24: =ROUNDDOWN(((I23/$F$23)^(1/I9)-1)*100,2) -> 5.88 | J24: =ROUNDDOWN(((J23/$F$23)^(1/J9)-1)*100,2) -> 5.95 | K24: =ROUNDDOWN(((K23/$F$23)^(1/K9)-1)*100,2) -> 5.95
B25: ⑤労働者数のうち役員数（人） | F25: 7 | G25: 7 | H25: 7 | I25: 7 | J25: 7 | K25: 7
B26: ⑥労働者数のうち常勤従業員数（人） （注2） | F26: 181 | G26: 184 | H26: 188 | I26: 191 | J26: 195 | K26: 198
B27: 労働生産性(＝１人あたり付加価値額)（④÷(⑤＋⑥)） | F27: =IF(F23<0,ROUNDUP((F23/(F25+F26)),2),ROUNDDOWN((F23/(F25+F26)),2)) -> 8475145.9 | G27: =IF(G23<0,ROUNDUP((G23/(G25+G26)),2),ROUNDDOWN((G23/(G25+G26)),2)) -> 8859578.6 | H27: =IF(H23<0,ROUNDUP((H23/(H25+H26)),2),ROUNDDOWN((H23/(H25+H26)),2)) -> 9185485.9 | I27: =IF(I23<0,ROUNDUP((I23/(I25+I26)),2),ROUNDDOWN((I23/(I25+I26)),2)) -> 9551960.3 | J27: =IF(J23<0,ROUNDUP((J23/(J25+J26)),2),ROUNDDOWN((J23/(J25+J26)),2)) -> 9942131.9 | K27: =IF(K23<0,ROUNDUP((K23/(K25+K26)),2),ROUNDDOWN((K23/(K25+K26)),2)) -> 10376866
B28: 労働生産性の目標値 （年平均成長率４％ずつ上げる場合） | G28: =IFERROR(IF($F$23>=0,ROUNDUP(((ABS($F$23)*1.04^G9-(ABS($F$23)))+$F$23)/($F$25+$F$26),2),ROUNDDOWN(((ABS($F$23)*1.04^G9-(ABS($F$23)))+$F$23)/($F$25+$F$26),2)),0) -> 8814151.8 | H28: =IFERROR(IF($F$23>=0,ROUNDUP(((ABS($F$23)*1.04^H9-(ABS($F$23)))+$F$23)/($F$25+$F$26),2),ROUNDDOWN(((ABS($F$23)*1.04^H9-(ABS($F$23)))+$F$23)/($F$25+$F$26),2)),0) -> 9166717.8 | I28: =IFERROR(IF($F$23>=0,ROUNDUP(((ABS($F$23)*1.04^I9-(ABS($F$23)))+$F$23)/($F$25+$F$26),2),ROUNDDOWN(((ABS($F$23)*1.04^I9-(ABS($F$23)))+$F$23)/($F$25+$F$26),2)),0) -> 9533386.5 | J28: =IFERROR(IF($F$23>=0,ROUNDUP(((ABS($F$23)*1.04^J9-(ABS($F$23)))+$F$23)/($F$25+$F$26),2),ROUNDDOWN(((ABS($F$23)*1.04^J9-(ABS($F$23)))+$F$23)/($F$25+$F$26),2)),0) -> 9914722 | K28: =IFERROR(IF($F$23>=0,ROUNDUP(((ABS($F$23)*1.04^K9-(ABS($F$23)))+$F$23)/($F$25+$F$26),2),ROUNDDOWN(((ABS($F$23)*1.04^K9-(ABS($F$23)))+$F$23)/($F$25+$F$26),2)),0) -> 10311311
B29: 労働生産性の年平均成長率（％）（注3） | G29: =ROUNDDOWN(((G27/$F$27)^(1/G9)-1)*100,2) -> 4.53 | H29: =ROUNDDOWN(((H27/$F$27)^(1/H9)-1)*100,2) -> 4.1 | I29: =ROUNDDOWN(((I27/$F$27)^(1/I9)-1)*100,2) -> 4.06 | J29: =ROUNDDOWN(((J27/$F$27)^(1/J9)-1)*100,2) -> 4.07 | K29: =ROUNDDOWN(((K27/$F$27)^(1/K9)-1)*100,2) -> 4.13
B32: １人当たり給与支給総額の年平均成長率算定シート
B33: ⑦全月分の給与等の支給を受けた従業員の給与支給総額 （注4） | C33: 717003483 | D33: 787608582 | E33: 829735675 | F33: =E33 -> 829735675 | G33: 873184880 | H33: 923577636 | I33: 971350746 | J33: 1026607530 | K33: 1079101188
B34: ⑧全月分の給与等の支給を受けた従業員数（人）（注4） | C34: 166 | D34: 177 | E34: 181 | F34: =E34 -> 181 | G34: 184 | H34: 188 | I34: 191 | J34: 195 | K34: 198
B35: １人当たり給与支給総額 （⑦÷⑧） | C35: =ROUNDDOWN(C33/C34,2) -> 4319298.1 | D35: =ROUNDDOWN(D33/D34,2) -> 4449766 | E35: =ROUNDDOWN(E33/E34,2) -> 4584175 | F35: =E35 -> 4584175 | G35: =ROUNDDOWN(G33/G34,2) -> 4745570 | H35: =ROUNDDOWN(H33/H34,2) -> 4912647 | I35: =ROUNDDOWN(I33/I34,2) -> 5085606 | J35: =ROUNDDOWN(J33/J34,2) -> 5264654 | K35: =ROUNDDOWN(K33/K34,2) -> 5450006
B36: 従業員1人当たり給与支給総額の目標値 | E36: 年平均成長率(3.0%)を達成するための目標値 | G36: 【特例なし】年平均成長率(3.5%）を達成するための目標値
E37: =ROUNDUP(($C$33+(ABS($C$33)*1.03^E9-ABS($C$33)))/($C$34),0) -> 4582344 | G37: =ROUNDUP(($F$33+(ABS($F$33)*1.035^G9-ABS($F$33)))/($F$34),0) -> 4744622 | H37: =ROUNDUP(($F$33+(ABS($F$33)*1.035^H9-ABS($F$33)))/($F$34),0) -> 4910683 | I37: =ROUNDUP(($F$33+(ABS($F$33)*1.035^I9-ABS($F$33)))/($F$34),0) -> 5082557 | J37: =ROUNDUP(($F$33+(ABS($F$33)*1.035^J9-ABS($F$33)))/($F$34),0) -> 5260447 | K37: =ROUNDUP(($F$33+(ABS($F$33)*1.035^K9-ABS($F$33)))/($F$34),0) -> 5444562
G38: 【特例あり】年平均成長率(6.0%）を達成するための目標値
G39: =ROUNDUP(($F$33+(ABS($F$33)*1.06^G9-ABS($F$33)))/($F$34),0) -> 4859226 | H39: =ROUNDUP(($F$33+(ABS($F$33)*1.06^H9-ABS($F$33)))/($F$34),0) -> 5150780 | I39: =ROUNDUP(($F$33+(ABS($F$33)*1.06^I9-ABS($F$33)))/($F$34),0) -> 5459826 | J39: =ROUNDUP(($F$33+(ABS($F$33)*1.06^J9-ABS($F$33)))/($F$34),0) -> 5787416 | K39: =ROUNDUP(($F$33+(ABS($F$33)*1.06^K9-ABS($F$33)))/($F$34),0) -> 6134661
B40: 1人当たり給与支給総額の年平均成長率（％）（注3） | E40: =IFERROR(IF(E$35>=$C$35,ROUNDDOWN(((E35/$C$35)^(1/C6)-1)*100,2),ROUNDUP(((E35/$C$35)^(1/C6)-1)*100,2)),0) -> 3.02 | G40: =IFERROR(IF(G$35>=$F$35,ROUNDDOWN(((G35/$F$35)^(1/G9)-1)*100,2),ROUNDUP(((G35/$F$35)^(1/G9)-1)*100,2)),0) -> 3.52 | H40: =IFERROR(IF(H$35>=$F$35,ROUNDDOWN(((H35/$F$35)^(1/H9)-1)*100,2),ROUNDUP(((H35/$F$35)^(1/H9)-1)*100,2)),0) -> 3.52 | I40: =IFERROR(IF(I$35>=$F$35,ROUNDDOWN(((I35/$F$35)^(1/I9)-1)*100,2),ROUNDUP(((I35/$F$35)^(1/I9)-1)*100,2)),0) -> 3.52 | J40: =IFERROR(IF(J$35>=$F$35,ROUNDDOWN(((J35/$F$35)^(1/J9)-1)*100,2),ROUNDUP(((J35/$F$35)^(1/J9)-1)*100,2)),0) -> 3.52 | K40: =IFERROR(IF(K$35>=$F$35,ROUNDDOWN(((K35/$F$35)^(1/K9)-1)*100,2),ROUNDUP(((K35/$F$35)^(1/K9)-1)*100,2)),0) -> 3.52
E41: ↑（足下の賃上げ）基準年度における1人当たり給与支給総額年平均成長率の目標値
B43: （注１）人件費は、給与支給総額に加えて福利厚生費、法定福利費、退職金を含みます。具体的には以下の通りです。
B44: ・売上原価に含まれる労務費（福利厚生費、退職金等を含んだもの）
B45: ・一般管理費に含まれる役員給与、従業員給与、賞与及び賞与引当金繰入れ、福利厚生 費、退職金及び退職給与引当金繰入れ
B47: （注２）常勤従業員数には、パート、アルバイト、契約社員、非正規社員、出向者等も含まれます。
B48: 次の人は含まれません。
...

Sheet 【参考書式】達成すべき目標値の算出ツール（参考）
C1: (参考)
D3: 基準年 | E3: 1 | F3: 2 | G3: 3 | H3: 4 | I3: 5
C4: 増加率 | E4: 0.02 | F4: =(1+$E4)^$F3-1 -> 0.0404 | G4: =(1+$E4)^G3-1 -> 0.061208 | H4: =(1+$E4)^H3-1 -> 0.08243216 | I4: =(1+$E4)^I3-1 -> 0.1040808
D5: 1000 | E5: =$D5*((1+$E4)^E3) -> 1020 | F5: =$D5*((1+$E4)^F3) -> 1040.4 | G5: =$D5*((1+$E4)^G3) -> 1061.208 | H5: =$D5*((1+$E4)^H3) -> 1082.4322 | I5: =$D5*((1+$E4)^I3) -> 1104.0808
E6: 0.04 | F6: =(1+$E6)^F3-1 -> 0.0816 | G6: =(1+$E6)^G3-1 -> 0.124864 | H6: =(1+$E6)^H3-1 -> 0.16985856 | I6: =(1+$E6)^I3-1 -> 0.2166529
E7: 0.05 | F7: =(1+$E7)^F3-1 -> 0.1025 | G7: =(1+$E7)^G3-1 -> 0.157625 | H7: =(1+$E7)^H3-1 -> 0.21550625 | I7: =(1+$E7)^I3-1 -> 0.27628156
E8: 0.06 | F8: =(1+$E8)^F3-1 -> 0.1236 | G8: =(1+$E8)^G3-1 -> 0.191016 | H8: =(1+$E8)^H3-1 -> 0.26247696 | I8: =(1+$E8)^I3-1 -> 0.33822558
E9: 0.07 | F9: =(1+$E9)^F3-1 -> 0.1449 | G9: =(1+$E9)^G3-1 -> 0.225043 | H9: =(1+$E9)^H3-1 -> 0.31079601 | I9: =(1+$E9)^I3-1 -> 0.40255173
E10: 0.08 | F10: =(1+$E10)^F3-1 -> 0.1664 | G10: =(1+$E10)^G3-1 -> 0.259712 | H10: =(1+$E10)^H3-1 -> 0.36048896 | I10: =(1+$E10)^I3-1 -> 0.46932808
E11: 0.09 | F11: =(1+$E11)^F3-1 -> 0.1881 | G11: =(1+$E11)^G3-1 -> 0.295029 | H11: =(1+$E11)^H3-1 -> 0.41158161 | I11: =(1+$E11)^I3-1 -> 0.53862395
D13: 基準年 | E13: １年目 | F13: ２年目 | G13: ３年目 | H13: ４年目 | I13: ５年目
C14: 増加率 | E14: 0.0352 | F14: =(1+$E14)^F3-1 -> 0.07163904 | G14: =(1+$E14)^G3-1 -> 0.10936073 | H14: =(1+$E14)^H3-1 -> 0.14841023 | I14: =(1+$E14)^I3-1 -> 0.18883427
C15: 目標値 | D15: 4584175 | E15: =ROUNDUP($D$15*((1+$E14)^E3),3) -> 4745538 | F15: =$D$15*((1+$E14)^F3) -> 4912580.9 | G15: =$D15*((1+$E14)^G3) -> 5085503.7 | H15: =$D15*((1+$E14)^H3) -> 5264513.5 | I15: =$D15*((1+$E14)^I3) -> 5449824.3
C16: 年平均成長率 | E16: =ROUNDDOWN(((E15/$D$15)^(1/E3)-1),5) -> 0.03519 | F16: =ROUNDDOWN(((F15/$D$15)^(1/F3)-1),5) -> 0.03519 | G16: =ROUNDDOWN(((G15/$D$15)^(1/G3)-1),5) -> 0.03519 | H16: =ROUNDDOWN(((H15/$D$15)^(1/H3)-1),5) -> 0.03519 | I16: =ROUNDDOWN(((I15/$D$15)^(1/I3)-1),5) -> 0.03519

Sheet 選択肢
N2: 直近決算期 | P2: 応募申請の決算期 | R2: 決算月 | S2: 補助事業完了年月
L3: 未選択 | N3: 未選択 | O3: =IF(#REF!="変更あり",N3,"") -> #REF! | P3: 未選択 | R3: 未選択 | S3: 未選択 | T3: 未選択
L4: 変更あり | N4: 2025年7月期 | O4: =IF(#REF!="変更あり",N4,"") -> #REF! | P4: 2026年10月期 | R4: 1月 | S4: 46508 | T4: 2027年5月期
L5: 変更なし | N5: 2025年8月期 | O5: =IF(#REF!="変更あり",N5,"") -> #REF! | P5: 2026年11月期 | R5: 2月 | S5: 46539 | T5: 2027年6月期
N6: 2025年9月期 | O6: =IF(#REF!="変更あり",N6,"") -> #REF! | P6: 2026年12月期 | R6: 3月 | S6: 46569 | T6: 2027年7月期
N7: 2025年10月期 | O7: =IF(#REF!="変更あり",N7,"") -> #REF! | P7: 2027年1月期 | R7: 4月 | S7: 46600 | T7: 2027年8月期
N8: 2025年11月期 | O8: =IF(#REF!="変更あり",N8,"") -> #REF! | P8: 2027年2月期 | R8: 5月 | S8: 46631 | T8: 2027年9月期
N9: 2025年12月期 | O9: =IF(#REF!="変更あり",N9,"") -> #REF! | P9: 2027年3月期 | R9: 6月 | S9: 46661 | T9: 2027年10月期
N10: 2026年1月期 | O10: =IF(#REF!="変更あり",N10,"") -> #REF! | P10: 2027年4月期 | R10: 7月 | S10: 46692 | T10: 2027年11月期
N11: 2026年2月期 | O11: =IF(#REF!="変更あり",N11,"") -> #REF! | P11: 2027年5月期 | R11: 8月 | S11: 46722 | T11: 2027年12月期
N12: 2026年3月期 | O12: =IF(#REF!="変更あり",N12,"") -> #REF! | P12: 2027年6月期 | R12: 9月 | S12: 46753 | T12: 2028年1月期
N13: 2026年4月期 | O13: =IF(#REF!="変更あり",N13,"") -> #REF! | P13: 2027年7月期 | R13: 10月 | S13: 46784 | T13: 2028年2月期
N14: 2026年5月期 | O14: =IF(#REF!="変更あり",N14,"") -> #REF! | P14: 2027年8月期 | R14: 11月 | S14: 46813 | T14: 2028年3月期
N15: 2026年6月期 | O15: =IF(#REF!="変更あり",N15,"") -> #REF! | P15: 2027年9月期 | R15: 12月 | S15: 46844 | T15: 2028年4月期
N16: 2026年7月期 | O16: =IF(#REF!="変更あり",N16,"") -> #REF! | S16: 46874 | T16: 2028年5月期
N17: 2026年8月期 | O17: =IF(#REF!="変更あり",N17,"") -> #REF! | S17: 46905 | T17: 2028年6月期
N18: 2026年9月期 | O18: =IF(#REF!="変更あり",N18,"") -> #REF! | S18: 46935 | T18: 2028年7月期
S19: 46966 | T19: 2028年8月期
S20: 46997 | T20: 2028年9月期
T21: 2028年10月期
T22: 2028年11月期
T23: 2028年12月期
T24: 2029年1月期
T25: 2029年2月期
T26: 2029年3月期
T27: 2029年4月期
T28: 2029年5月期
T29: 2029年6月期
T30: 2029年7月期
T31: 2029年8月期
