Workbook
Name サブタイトル: [1]更新履歴!$L$3
Name タイトル: [1]更新履歴!$D$3
Name 作成日: [1]更新履歴!$U$2
Name 所属: #REF!

Sheet 【指定様式】事業計画書（その3） 
A1: 【指定様式】事業計画書（その３）
B2: 事業者名
B3: 株式会社TURN Technology
B4: 本事業計画における会社全体の事業計画（数値計画）を記載してください。
A5: 記載数値：「省力化指数」「付加価値額」「労働生産性」「給与支給総額」「一人当たり給与支給総額」「投資回収期間」
B7: 【１】省力化指数
B8: ='（別紙１）省力化計算シート'!M3 -> 0.91580712
B9: ※「（別紙１）省力化計算シート」より算出。
B10: ※「（別紙２）省力化業務プロセス図」も作成し省力化指数の詳細を説明してください。
B12: 【２】会社全体の事業計画（表）
B48: 【事業計画年数（３～５年）】
B49: 5 | D49: 年
B51: 【算定根拠】算定の根拠となる計算式等をそれぞれ記載ください。
B52: また、計画最終年の年平均成長率を転記してください。（事業者の目標値となります。）
B54: ①付加価値額 | H54: 最終年の年平均成長率 | I54: 7.57 | J54: ％
B55: 省力化設備により、1年目は5ヵ月分、2年目以降は1年分、下記の製造コストが低減される。 ①不良品分の製造コストの削減：現状のコスト2,000円×（6,000個/月÷良品率75%－6,000個/月）×12月=48,000千円 ②外注加工費の削減：補助事業にて生まれる6名×2直の工数を内製化し、年間51,480千円 また、技術者の工数余力と生産スペースの拡大により、今後の増産対応、新規受注活動が促進でき、1年目は5ヵ月分、2年目以降は1年分として、売上高成長率6.5%/年を見込むことで、営業利益率の増加に寄与する。
B60: ②労働生産性 | H60: 最終年の年平均成長率 | I60: 7.57 | J60: ％
B61: 省力化設備により、約6名/直の工数を他の業務に回すことができることから、直近年度末の36名体制で計画する生産量に対応することが可能となる。 「①付加価値額」の増加に対し、従業員の増員を必要としないため、上記の成長率となる。
B66: ③給与支給総額 | H66: 最終年の年平均成長率 | I66: 4.1 | J66: ％
B67: 省力化投資の効果によって得られる営業利益の一部（28%）を賃上げの原資とすることで、4.10%の高い給与支給総額の年平均成長率とすることができる。 当社の強みの源泉は長く働いていただいている優秀な技術者たちにあり、高い賃上げと労働環境の向上により、離職のリスクを下げる必要があることから、高い目標を設定している。
B72: ④一人当たり給与支給総額 | H72: 最終年の年平均成長率 | I72: 4.1 | J72: ％
B73: 省力化投資により、約6名/直（全体の約30%）にあたる内製工数の余力を創出できる。これにより、今後の売上高成長や収益性の向上といった取組みを推進することができることから、4.10%という高い水準での陳影が可能となる。
B78: 【３】投資回収期間
B79: ='（別紙３）投資回収期間計算シート'!C3 -> 0.29117512 | D79: 年
B80: ※「（別紙３）投資回収期間計算シート」より算出（自動反映）。

Sheet （別紙１）省力化計算シート
B1: （別紙１）省力化計算シート
C3: 設備導入により削減される 業務に要していた時間 | D3: =(SUMIF(C11:C40,"<>",D11:D40)-SUMIF(E11:E40,"<>-",D11:D40)-SUMIF(F11:F40,"<0"))/60 -> 155.12 | G3: 時間 | I3: 設備導入後に発生する 業務に要する時間 | J3: =(SUMIF(I11:I40,"<>",J11:J40)-SUMIF(N11:N40,"<>-",J11:J40)+SUMIF(N11:N40,">0"))/60 -> 13.06 | K3: 時間 | L3: 省力化指数 | M3: =IF(D3=0,0,IF((D3-J3)/D3<0,0,(D3-J3)/D3)) -> 0.91580712
B5: ■設備導入前の業務プロセス・作業工程 | H5: ■設備導入後の業務プロセス・作業工程
C7: 設備導入前の作業時間合計 | D7: =SUMIF(C11:C40,"<>",D11:D40)/60 -> 158.16 | G7: 時間 | I7: 設備導入後の作業時間合計 | J7: =SUMIF(I11:I40,"<>",J11:J40)/60 -> 16.1 | K7: 時間
B10: No. | C10: 工程名・作業名 | D10: 作業時間（分） | E10: 対応する導入後の 業務プロセスNo | F10: 同工程差分時間（分） | H10: No. | I10: 工程名・作業名 | J10: 作業時間（分） | K10: 作業種別 | L10: 対応する設備導入前の 業務プロセスNo. | N10: 同工程差分時間（分） | P10: 作業種別選択肢
B11: 1 | C11: 資材供給 | D11: 182.4 | E11: =IF(OR(C11="",D11=""),"-",IF(IFERROR(MATCH(B11,L$11:L$40,0),"")="","-",IF(OR(INDEX(I$11:I$40,MATCH(B11,L$11:L$40,0))="",INDEX(J$11:J$40,MATCH(B11,L$11:L$40,0))="",INDEX(K$11:K$40,MATCH(B11,L$11:L$40,0))<>"内容は変化しない作業"),"-",MATCH(B11,L$11:L$40,0)))) -> 1 | F11: {=IF(E11="-","-",IF(AND(C11<>"",D11>0,INDEX(K$11:K$40,E11)="内容は変化しない作業",AND(E11<>"-",E11<>""),INDEX(I$11:I$40,E11)<>"",INDEX(J$11:J$40,E11)<>""),INDEX(J$11:J$40,E11)-D11,"-"))} -> 9.6 | H11: 1 | I11: 資材供給 | J11: 192 | K11: 内容は変化しない作業 | L11: 1 | N11: {=IF(AND(I11<>"",J11>0,K11="内容は変化しない作業",L11>0,INDEX(C$11:C$40,L11)<>"",INDEX(D$11:D$40,L11)<>""),J11-INDEX(D$11:D$40,L11),"-")} -> 9.6 | P11: 新たに追加される作業
B12: 2 | C12: バー材切断 | D12: 91.2 | E12: =IF(OR(C12="",D12=""),"-",IF(IFERROR(MATCH(B12,L$11:L$40,0),"")="","-",IF(OR(INDEX(I$11:I$40,MATCH(B12,L$11:L$40,0))="",INDEX(J$11:J$40,MATCH(B12,L$11:L$40,0))="",INDEX(K$11:K$40,MATCH(B12,L$11:L$40,0))<>"内容は変化しない作業"),"-",MATCH(B12,L$11:L$40,0)))) -> - | F12: {=IF(E12="-","-",IF(AND(C12<>"",D12>0,INDEX(K$11:K$40,E12)="内容は変化しない作業",AND(E12<>"-",E12<>""),INDEX(I$11:I$40,E12)<>"",INDEX(J$11:J$40,E12)<>""),INDEX(J$11:J$40,E12)-D12,"-"))} -> - | H12: 2 | I12: L1加工 | J12: 288 | K12: 新たに追加される作業 | N12: {=IF(AND(I12<>"",J12>0,K12="内容は変化しない作業",L12>0,INDEX(C$11:C$40,L12)<>"",INDEX(D$11:D$40,L12)<>""),J12-INDEX(D$11:D$40,L12),"-")} -> - | P12: 内容は変化しない作業
B13: 3 | C13: L1加工 | D13: 228 | E13: =IF(OR(C13="",D13=""),"-",IF(IFERROR(MATCH(B13,L$11:L$40,0),"")="","-",IF(OR(INDEX(I$11:I$40,MATCH(B13,L$11:L$40,0))="",INDEX(J$11:J$40,MATCH(B13,L$11:L$40,0))="",INDEX(K$11:K$40,MATCH(B13,L$11:L$40,0))<>"内容は変化しない作業"),"-",MATCH(B13,L$11:L$40,0)))) -> - | F13: {=IF(E13="-","-",IF(AND(C13<>"",D13>0,INDEX(K$11:K$40,E13)="内容は変化しない作業",AND(E13<>"-",E13<>""),INDEX(I$11:I$40,E13)<>"",INDEX(J$11:J$40,E13)<>""),INDEX(J$11:J$40,E13)-D13,"-"))} -> - | H13: 3 | I13: L2加工 | J13: 480 | K13: 新たに追加される作業 | N13: {=IF(AND(I13<>"",J13>0,K13="内容は変化しない作業",L13>0,INDEX(C$11:C$40,L13)<>"",INDEX(D$11:D$40,L13)<>""),J13-INDEX(D$11:D$40,L13),"-")} -> -
B14: 4 | C14: L2加工 | D14: 456 | E14: =IF(OR(C14="",D14=""),"-",IF(IFERROR(MATCH(B14,L$11:L$40,0),"")="","-",IF(OR(INDEX(I$11:I$40,MATCH(B14,L$11:L$40,0))="",INDEX(J$11:J$40,MATCH(B14,L$11:L$40,0))="",INDEX(K$11:K$40,MATCH(B14,L$11:L$40,0))<>"内容は変化しない作業"),"-",MATCH(B14,L$11:L$40,0)))) -> - | F14: {=IF(E14="-","-",IF(AND(C14<>"",D14>0,INDEX(K$11:K$40,E14)="内容は変化しない作業",AND(E14<>"-",E14<>""),INDEX(I$11:I$40,E14)<>"",INDEX(J$11:J$40,E14)<>""),INDEX(J$11:J$40,E14)-D14,"-"))} -> - | H14: 4 | I14: 寸法精度検査 | J14: 6 | K14: 新たに追加される作業 | N14: {=IF(AND(I14<>"",J14>0,K14="内容は変化しない作業",L14>0,INDEX(C$11:C$40,L14)<>"",INDEX(D$11:D$40,L14)<>""),J14-INDEX(D$11:D$40,L14),"-")} -> -
B15: 5 | C15: MC1加工 | D15: 547.2 | E15: =IF(OR(C15="",D15=""),"-",IF(IFERROR(MATCH(B15,L$11:L$40,0),"")="","-",IF(OR(INDEX(I$11:I$40,MATCH(B15,L$11:L$40,0))="",INDEX(J$11:J$40,MATCH(B15,L$11:L$40,0))="",INDEX(K$11:K$40,MATCH(B15,L$11:L$40,0))<>"内容は変化しない作業"),"-",MATCH(B15,L$11:L$40,0)))) -> - | F15: {=IF(E15="-","-",IF(AND(C15<>"",D15>0,INDEX(K$11:K$40,E15)="内容は変化しない作業",AND(E15<>"-",E15<>""),INDEX(I$11:I$40,E15)<>"",INDEX(J$11:J$40,E15)<>""),INDEX(J$11:J$40,E15)-D15,"-"))} -> - | H15: 5 | N15: {=IF(AND(I15<>"",J15>0,K15="内容は変化しない作業",L15>0,INDEX(C$11:C$40,L15)<>"",INDEX(D$11:D$40,L15)<>""),J15-INDEX(D$11:D$40,L15),"-")} -> -
B16: 6 | C16: MC2加工 | D16: 273.6 | E16: =IF(OR(C16="",D16=""),"-",IF(IFERROR(MATCH(B16,L$11:L$40,0),"")="","-",IF(OR(INDEX(I$11:I$40,MATCH(B16,L$11:L$40,0))="",INDEX(J$11:J$40,MATCH(B16,L$11:L$40,0))="",INDEX(K$11:K$40,MATCH(B16,L$11:L$40,0))<>"内容は変化しない作業"),"-",MATCH(B16,L$11:L$40,0)))) -> - | F16: {=IF(E16="-","-",IF(AND(C16<>"",D16>0,INDEX(K$11:K$40,E16)="内容は変化しない作業",AND(E16<>"-",E16<>""),INDEX(I$11:I$40,E16)<>"",INDEX(J$11:J$40,E16)<>""),INDEX(J$11:J$40,E16)-D16,"-"))} -> - | H16: 6 | N16: {=IF(AND(I16<>"",J16>0,K16="内容は変化しない作業",L16>0,INDEX(C$11:C$40,L16)<>"",INDEX(D$11:D$40,L16)<>""),J16-INDEX(D$11:D$40,L16),"-")} -> -
B17: 7 | C17: MC3加工 | D17: 547.2 | E17: =IF(OR(C17="",D17=""),"-",IF(IFERROR(MATCH(B17,L$11:L$40,0),"")="","-",IF(OR(INDEX(I$11:I$40,MATCH(B17,L$11:L$40,0))="",INDEX(J$11:J$40,MATCH(B17,L$11:L$40,0))="",INDEX(K$11:K$40,MATCH(B17,L$11:L$40,0))<>"内容は変化しない作業"),"-",MATCH(B17,L$11:L$40,0)))) -> - | F17: {=IF(E17="-","-",IF(AND(C17<>"",D17>0,INDEX(K$11:K$40,E17)="内容は変化しない作業",AND(E17<>"-",E17<>""),INDEX(I$11:I$40,E17)<>"",INDEX(J$11:J$40,E17)<>""),INDEX(J$11:J$40,E17)-D17,"-"))} -> - | H17: 7 | N17: {=IF(AND(I17<>"",J17>0,K17="内容は変化しない作業",L17>0,INDEX(C$11:C$40,L17)<>"",INDEX(D$11:D$40,L17)<>""),J17-INDEX(D$11:D$40,L17),"-")} -> -
B18: 8 | C18: MC4加工 | D18: 684 | E18: =IF(OR(C18="",D18=""),"-",IF(IFERROR(MATCH(B18,L$11:L$40,0),"")="","-",IF(OR(INDEX(I$11:I$40,MATCH(B18,L$11:L$40,0))="",INDEX(J$11:J$40,MATCH(B18,L$11:L$40,0))="",INDEX(K$11:K$40,MATCH(B18,L$11:L$40,0))<>"内容は変化しない作業"),"-",MATCH(B18,L$11:L$40,0)))) -> - | F18: {=IF(E18="-","-",IF(AND(C18<>"",D18>0,INDEX(K$11:K$40,E18)="内容は変化しない作業",AND(E18<>"-",E18<>""),INDEX(I$11:I$40,E18)<>"",INDEX(J$11:J$40,E18)<>""),INDEX(J$11:J$40,E18)-D18,"-"))} -> - | H18: 8 | N18: {=IF(AND(I18<>"",J18>0,K18="内容は変化しない作業",L18>0,INDEX(C$11:C$40,L18)<>"",INDEX(D$11:D$40,L18)<>""),J18-INDEX(D$11:D$40,L18),"-")} -> -
B19: 9 | C19: GD加工 | D19: 1368 | E19: =IF(OR(C19="",D19=""),"-",IF(IFERROR(MATCH(B19,L$11:L$40,0),"")="","-",IF(OR(INDEX(I$11:I$40,MATCH(B19,L$11:L$40,0))="",INDEX(J$11:J$40,MATCH(B19,L$11:L$40,0))="",INDEX(K$11:K$40,MATCH(B19,L$11:L$40,0))<>"内容は変化しない作業"),"-",MATCH(B19,L$11:L$40,0)))) -> - | F19: {=IF(E19="-","-",IF(AND(C19<>"",D19>0,INDEX(K$11:K$40,E19)="内容は変化しない作業",AND(E19<>"-",E19<>""),INDEX(I$11:I$40,E19)<>"",INDEX(J$11:J$40,E19)<>""),INDEX(J$11:J$40,E19)-D19,"-"))} -> - | H19: 9 | N19: {=IF(AND(I19<>"",J19>0,K19="内容は変化しない作業",L19>0,INDEX(C$11:C$40,L19)<>"",INDEX(D$11:D$40,L19)<>""),J19-INDEX(D$11:D$40,L19),"-")} -> -
B20: 10 | C20: 交差穴バリ取り | D20: 2376 | E20: =IF(OR(C20="",D20=""),"-",IF(IFERROR(MATCH(B20,L$11:L$40,0),"")="","-",IF(OR(INDEX(I$11:I$40,MATCH(B20,L$11:L$40,0))="",INDEX(J$11:J$40,MATCH(B20,L$11:L$40,0))="",INDEX(K$11:K$40,MATCH(B20,L$11:L$40,0))<>"内容は変化しない作業"),"-",MATCH(B20,L$11:L$40,0)))) -> - | F20: {=IF(E20="-","-",IF(AND(C20<>"",D20>0,INDEX(K$11:K$40,E20)="内容は変化しない作業",AND(E20<>"-",E20<>""),INDEX(I$11:I$40,E20)<>"",INDEX(J$11:J$40,E20)<>""),INDEX(J$11:J$40,E20)-D20,"-"))} -> - | H20: 10 | N20: {=IF(AND(I20<>"",J20>0,K20="内容は変化しない作業",L20>0,INDEX(C$11:C$40,L20)<>"",INDEX(D$11:D$40,L20)<>""),J20-INDEX(D$11:D$40,L20),"-")} -> -
B21: 11 | C21: 内視鏡検査 | D21: 2736 | E21: =IF(OR(C21="",D21=""),"-",IF(IFERROR(MATCH(B21,L$11:L$40,0),"")="","-",IF(OR(INDEX(I$11:I$40,MATCH(B21,L$11:L$40,0))="",INDEX(J$11:J$40,MATCH(B21,L$11:L$40,0))="",INDEX(K$11:K$40,MATCH(B21,L$11:L$40,0))<>"内容は変化しない作業"),"-",MATCH(B21,L$11:L$40,0)))) -> - | F21: {=IF(E21="-","-",IF(AND(C21<>"",D21>0,INDEX(K$11:K$40,E21)="内容は変化しない作業",AND(E21<>"-",E21<>""),INDEX(I$11:I$40,E21)<>"",INDEX(J$11:J$40,E21)<>""),INDEX(J$11:J$40,E21)-D21,"-"))} -> - | H21: 11 | N21: {=IF(AND(I21<>"",J21>0,K21="内容は変化しない作業",L21>0,INDEX(C$11:C$40,L21)<>"",INDEX(D$11:D$40,L21)<>""),J21-INDEX(D$11:D$40,L21),"-")} -> -
B22: 12 | E22: =IF(OR(C22="",D22=""),"-",IF(IFERROR(MATCH(B22,L$11:L$40,0),"")="","-",IF(OR(INDEX(I$11:I$40,MATCH(B22,L$11:L$40,0))="",INDEX(J$11:J$40,MATCH(B22,L$11:L$40,0))="",INDEX(K$11:K$40,MATCH(B22,L$11:L$40,0))<>"内容は変化しない作業"),"-",MATCH(B22,L$11:L$40,0)))) -> - | F22: {=IF(E22="-","-",IF(AND(C22<>"",D22>0,INDEX(K$11:K$40,E22)="内容は変化しない作業",AND(E22<>"-",E22<>""),INDEX(I$11:I$40,E22)<>"",INDEX(J$11:J$40,E22)<>""),INDEX(J$11:J$40,E22)-D22,"-"))} -> - | H22: 12 | N22: {=IF(AND(I22<>"",J22>0,K22="内容は変化しない作業",L22>0,INDEX(C$11:C$40,L22)<>"",INDEX(D$11:D$40,L22)<>""),J22-INDEX(D$11:D$40,L22),"-")} -> -
B23: 13 | E23: =IF(OR(C23="",D23=""),"-",IF(IFERROR(MATCH(B23,L$11:L$40,0),"")="","-",IF(OR(INDEX(I$11:I$40,MATCH(B23,L$11:L$40,0))="",INDEX(J$11:J$40,MATCH(B23,L$11:L$40,0))="",INDEX(K$11:K$40,MATCH(B23,L$11:L$40,0))<>"内容は変化しない作業"),"-",MATCH(B23,L$11:L$40,0)))) -> - | F23: {=IF(E23="-","-",IF(AND(C23<>"",D23>0,INDEX(K$11:K$40,E23)="内容は変化しない作業",AND(E23<>"-",E23<>""),INDEX(I$11:I$40,E23)<>"",INDEX(J$11:J$40,E23)<>""),INDEX(J$11:J$40,E23)-D23,"-"))} -> - | H23: 13 | N23: {=IF(AND(I23<>"",J23>0,K23="内容は変化しない作業",L23>0,INDEX(C$11:C$40,L23)<>"",INDEX(D$11:D$40,L23)<>""),J23-INDEX(D$11:D$40,L23),"-")} -> -
B24: 14 | E24: =IF(OR(C24="",D24=""),"-",IF(IFERROR(MATCH(B24,L$11:L$40,0),"")="","-",IF(OR(INDEX(I$11:I$40,MATCH(B24,L$11:L$40,0))="",INDEX(J$11:J$40,MATCH(B24,L$11:L$40,0))="",INDEX(K$11:K$40,MATCH(B24,L$11:L$40,0))<>"内容は変化しない作業"),"-",MATCH(B24,L$11:L$40,0)))) -> - | F24: {=IF(E24="-","-",IF(AND(C24<>"",D24>0,INDEX(K$11:K$40,E24)="内容は変化しない作業",AND(E24<>"-",E24<>""),INDEX(I$11:I$40,E24)<>"",INDEX(J$11:J$40,E24)<>""),INDEX(J$11:J$40,E24)-D24,"-"))} -> - | H24: 14 | N24: {=IF(AND(I24<>"",J24>0,K24="内容は変化しない作業",L24>0,INDEX(C$11:C$40,L24)<>"",INDEX(D$11:D$40,L24)<>""),J24-INDEX(D$11:D$40,L24),"-")} -> -
B25: 15 | E25: =IF(OR(C25="",D25=""),"-",IF(IFERROR(MATCH(B25,L$11:L$40,0),"")="","-",IF(OR(INDEX(I$11:I$40,MATCH(B25,L$11:L$40,0))="",INDEX(J$11:J$40,MATCH(B25,L$11:L$40,0))="",INDEX(K$11:K$40,MATCH(B25,L$11:L$40,0))<>"内容は変化しない作業"),"-",MATCH(B25,L$11:L$40,0)))) -> - | F25: {=IF(E25="-","-",IF(AND(C25<>"",D25>0,INDEX(K$11:K$40,E25)="内容は変化しない作業",AND(E25<>"-",E25<>""),INDEX(I$11:I$40,E25)<>"",INDEX(J$11:J$40,E25)<>""),INDEX(J$11:J$40,E25)-D25,"-"))} -> - | H25: 15 | N25: {=IF(AND(I25<>"",J25>0,K25="内容は変化しない作業",L25>0,INDEX(C$11:C$40,L25)<>"",INDEX(D$11:D$40,L25)<>""),J25-INDEX(D$11:D$40,L25),"-")} -> -
B26: 16 | E26: =IF(OR(C26="",D26=""),"-",IF(IFERROR(MATCH(B26,L$11:L$40,0),"")="","-",IF(OR(INDEX(I$11:I$40,MATCH(B26,L$11:L$40,0))="",INDEX(J$11:J$40,MATCH(B26,L$11:L$40,0))="",INDEX(K$11:K$40,MATCH(B26,L$11:L$40,0))<>"内容は変化しない作業"),"-",MATCH(B26,L$11:L$40,0)))) -> - | F26: {=IF(E26="-","-",IF(AND(C26<>"",D26>0,INDEX(K$11:K$40,E26)="内容は変化しない作業",AND(E26<>"-",E26<>""),INDEX(I$11:I$40,E26)<>"",INDEX(J$11:J$40,E26)<>""),INDEX(J$11:J$40,E26)-D26,"-"))} -> - | H26: 16 | N26: {=IF(AND(I26<>"",J26>0,K26="内容は変化しない作業",L26>0,INDEX(C$11:C$40,L26)<>"",INDEX(D$11:D$40,L26)<>""),J26-INDEX(D$11:D$40,L26),"-")} -> -
B27: 17 | E27: =IF(OR(C27="",D27=""),"-",IF(IFERROR(MATCH(B27,L$11:L$40,0),"")="","-",IF(OR(INDEX(I$11:I$40,MATCH(B27,L$11:L$40,0))="",INDEX(J$11:J$40,MATCH(B27,L$11:L$40,0))="",INDEX(K$11:K$40,MATCH(B27,L$11:L$40,0))<>"内容は変化しない作業"),"-",MATCH(B27,L$11:L$40,0)))) -> - | F27: {=IF(E27="-","-",IF(AND(C27<>"",D27>0,INDEX(K$11:K$40,E27)="内容は変化しない作業",AND(E27<>"-",E27<>""),INDEX(I$11:I$40,E27)<>"",INDEX(J$11:J$40,E27)<>""),INDEX(J$11:J$40,E27)-D27,"-"))} -> - | H27: 17 | N27: {=IF(AND(I27<>"",J27>0,K27="内容は変化しない作業",L27>0,INDEX(C$11:C$40,L27)<>"",INDEX(D$11:D$40,L27)<>""),J27-INDEX(D$11:D$40,L27),"-")} -> -
B28: 18 | E28: =IF(OR(C28="",D28=""),"-",IF(IFERROR(MATCH(B28,L$11:L$40,0),"")="","-",IF(OR(INDEX(I$11:I$40,MATCH(B28,L$11:L$40,0))="",INDEX(J$11:J$40,MATCH(B28,L$11:L$40,0))="",INDEX(K$11:K$40,MATCH(B28,L$11:L$40,0))<>"内容は変化しない作業"),"-",MATCH(B28,L$11:L$40,0)))) -> - | F28: {=IF(E28="-","-",IF(AND(C28<>"",D28>0,INDEX(K$11:K$40,E28)="内容は変化しない作業",AND(E28<>"-",E28<>""),INDEX(I$11:I$40,E28)<>"",INDEX(J$11:J$40,E28)<>""),INDEX(J$11:J$40,E28)-D28,"-"))} -> - | H28: 18 | N28: {=IF(AND(I28<>"",J28>0,K28="内容は変化しない作業",L28>0,INDEX(C$11:C$40,L28)<>"",INDEX(D$11:D$40,L28)<>""),J28-INDEX(D$11:D$40,L28),"-")} -> -
B29: 19 | E29: =IF(OR(C29="",D29=""),"-",IF(IFERROR(MATCH(B29,L$11:L$40,0),"")="","-",IF(OR(INDEX(I$11:I$40,MATCH(B29,L$11:L$40,0))="",INDEX(J$11:J$40,MATCH(B29,L$11:L$40,0))="",INDEX(K$11:K$40,MATCH(B29,L$11:L$40,0))<>"内容は変化しない作業"),"-",MATCH(B29,L$11:L$40,0)))) -> - | F29: {=IF(E29="-","-",IF(AND(C29<>"",D29>0,INDEX(K$11:K$40,E29)="内容は変化しない作業",AND(E29<>"-",E29<>""),INDEX(I$11:I$40,E29)<>"",INDEX(J$11:J$40,E29)<>""),INDEX(J$11:J$40,E29)-D29,"-"))} -> - | H29: 19 | N29: {=IF(AND(I29<>"",J29>0,K29="内容は変化しない作業",L29>0,INDEX(C$11:C$40,L29)<>"",INDEX(D$11:D$40,L29)<>""),J29-INDEX(D$11:D$40,L29),"-")} -> -
B30: 20 | E30: =IF(OR(C30="",D30=""),"-",IF(IFERROR(MATCH(B30,L$11:L$40,0),"")="","-",IF(OR(INDEX(I$11:I$40,MATCH(B30,L$11:L$40,0))="",INDEX(J$11:J$40,MATCH(B30,L$11:L$40,0))="",INDEX(K$11:K$40,MATCH(B30,L$11:L$40,0))<>"内容は変化しない作業"),"-",MATCH(B30,L$11:L$40,0)))) -> - | F30: {=IF(E30="-","-",IF(AND(C30<>"",D30>0,INDEX(K$11:K$40,E30)="内容は変化しない作業",AND(E30<>"-",E30<>""),INDEX(I$11:I$40,E30)<>"",INDEX(J$11:J$40,E30)<>""),INDEX(J$11:J$40,E30)-D30,"-"))} -> - | H30: 20 | N30: {=IF(AND(I30<>"",J30>0,K30="内容は変化しない作業",L30>0,INDEX(C$11:C$40,L30)<>"",INDEX(D$11:D$40,L30)<>""),J30-INDEX(D$11:D$40,L30),"-")} -> -
B31: 21 | E31: =IF(OR(C31="",D31=""),"-",IF(IFERROR(MATCH(B31,L$11:L$40,0),"")="","-",IF(OR(INDEX(I$11:I$40,MATCH(B31,L$11:L$40,0))="",INDEX(J$11:J$40,MATCH(B31,L$11:L$40,0))="",INDEX(K$11:K$40,MATCH(B31,L$11:L$40,0))<>"内容は変化しない作業"),"-",MATCH(B31,L$11:L$40,0)))) -> - | F31: {=IF(E31="-","-",IF(AND(C31<>"",D31>0,INDEX(K$11:K$40,E31)="内容は変化しない作業",AND(E31<>"-",E31<>""),INDEX(I$11:I$40,E31)<>"",INDEX(J$11:J$40,E31)<>""),INDEX(J$11:J$40,E31)-D31,"-"))} -> - | H31: 21 | N31: {=IF(AND(I31<>"",J31>0,K31="内容は変化しない作業",L31>0,INDEX(C$11:C$40,L31)<>"",INDEX(D$11:D$40,L31)<>""),J31-INDEX(D$11:D$40,L31),"-")} -> -
B32: 22 | E32: =IF(OR(C32="",D32=""),"-",IF(IFERROR(MATCH(B32,L$11:L$40,0),"")="","-",IF(OR(INDEX(I$11:I$40,MATCH(B32,L$11:L$40,0))="",INDEX(J$11:J$40,MATCH(B32,L$11:L$40,0))="",INDEX(K$11:K$40,MATCH(B32,L$11:L$40,0))<>"内容は変化しない作業"),"-",MATCH(B32,L$11:L$40,0)))) -> - | F32: {=IF(E32="-","-",IF(AND(C32<>"",D32>0,INDEX(K$11:K$40,E32)="内容は変化しない作業",AND(E32<>"-",E32<>""),INDEX(I$11:I$40,E32)<>"",INDEX(J$11:J$40,E32)<>""),INDEX(J$11:J$40,E32)-D32,"-"))} -> - | H32: 22 | N32: {=IF(AND(I32<>"",J32>0,K32="内容は変化しない作業",L32>0,INDEX(C$11:C$40,L32)<>"",INDEX(D$11:D$40,L32)<>""),J32-INDEX(D$11:D$40,L32),"-")} -> -
B33: 23 | E33: =IF(OR(C33="",D33=""),"-",IF(IFERROR(MATCH(B33,L$11:L$40,0),"")="","-",IF(OR(INDEX(I$11:I$40,MATCH(B33,L$11:L$40,0))="",INDEX(J$11:J$40,MATCH(B33,L$11:L$40,0))="",INDEX(K$11:K$40,MATCH(B33,L$11:L$40,0))<>"内容は変化しない作業"),"-",MATCH(B33,L$11:L$40,0)))) -> - | F33: {=IF(E33="-","-",IF(AND(C33<>"",D33>0,INDEX(K$11:K$40,E33)="内容は変化しない作業",AND(E33<>"-",E33<>""),INDEX(I$11:I$40,E33)<>"",INDEX(J$11:J$40,E33)<>""),INDEX(J$11:J$40,E33)-D33,"-"))} -> - | H33: 23 | N33: {=IF(AND(I33<>"",J33>0,K33="内容は変化しない作業",L33>0,INDEX(C$11:C$40,L33)<>"",INDEX(D$11:D$40,L33)<>""),J33-INDEX(D$11:D$40,L33),"-")} -> -
... B40: 30 | E40: =IF(OR(C40="",D40=""),"-",IF(IFERROR(MATCH(B40,L$11:L$40,0),"")="","-",IF(OR(INDEX(I$11:I$40,MATCH(B40,L$11:L$40,0))="",INDEX(J$11:J$40,MATCH(B40,L$11:L$40,0))="",INDEX(K$11:K$40,MATCH(B40,L$11:L$40,0))<>"内容は変化しない作業"),"-",MATCH(B40,L$11:L$40,0)))) -> - | F40: {=IF(E40="-","-",IF(AND(C40<>"",D40>0,INDEX(K$11:K$40,E40)="内容は変化しない作業",AND(E40<>"-",E40<>""),INDEX(I$11:I$40,E40)<>"",INDEX(J$11:J$40,E40)<>""),INDEX(J$11:J$40,E40)-D40,"-"))} -> - | H40: 30 | N40: {=IF(AND(I40<>"",J40>0,K40="内容は変化しない作業",L40>0,INDEX(C$11:C$40,L40)<>"",INDEX(D$11:D$40,L40)<>""),J40-INDEX(D$11:D$40,L40),"-")} -> -

Sheet （別紙２）省力化業務プロセス図
B1: （別紙２）省力化業務プロセス図 ※（別紙1）で入れた業務プロセス・作業工程がフロー図として表示されます。
O3: 省力化指数 | S3: ='（別紙１）省力化計算シート'!M3 -> 0.91580712
C5: ■設備導入前の業務プロセス・作業工程 （BEFORE） | O5: 設備導入による削減時間 | S5: ='（別紙１）省力化計算シート'!D3 -> 155.12 | T5: 時間
C8: ='（別紙１）省力化計算シート'!C11 -> 資材供給 | E8: > | G8: ='（別紙１）省力化計算シート'!C12 -> バー材切断 | I8: > | K8: ='（別紙１）省力化計算シート'!C13 -> L1加工 | M8: > | O8: ='（別紙１）省力化計算シート'!C14 -> L2加工 | Q8: > | S8: ='（別紙１）省力化計算シート'!C15 -> MC1加工 | U8: > | X8: 削減される作業
C9: =IF('（別紙１）省力化計算シート'!D11="","",IF(OR('（別紙１）省力化計算シート'!F11="-",'（別紙１）省力化計算シート'!F11=0),'（別紙１）省力化計算シート'!D11&"分",'（別紙１）省力化計算シート'!D11&"分"&" (→"&'（別紙１）省力化計算シート'!D11+'（別紙１）省力化計算シート'!F11&"分）")) -> 182.4分 (→192分） | G9: =IF('（別紙１）省力化計算シート'!D12="","",IF(OR('（別紙１）省力化計算シート'!F12="-",'（別紙１）省力化計算シート'!F12=0),'（別紙１）省力化計算シート'!D12&"分",'（別紙１）省力化計算シート'!D12&"分"&" (→"&'（別紙１）省力化計算シート'!D12+'（別紙１）省力化計算シート'!F12&"分）")) -> 91.2分 | K9: =IF('（別紙１）省力化計算シート'!D13="","",IF(OR('（別紙１）省力化計算シート'!F13="-",'（別紙１）省力化計算シート'!F13=0),'（別紙１）省力化計算シート'!D13&"分",'（別紙１）省力化計算シート'!D13&"分"&" (→"&'（別紙１）省力化計算シート'!D13+'（別紙１）省力化計算シート'!F13&"分）")) -> 228分 | O9: =IF('（別紙１）省力化計算シート'!D14="","",IF(OR('（別紙１）省力化計算シート'!F14="-",'（別紙１）省力化計算シート'!F14=0),'（別紙１）省力化計算シート'!D14&"分",'（別紙１）省力化計算シート'!D14&"分"&" (→"&'（別紙１）省力化計算シート'!D14+'（別紙１）省力化計算シート'!F14&"分）")) -> 456分 | S9: =IF('（別紙１）省力化計算シート'!D15="","",IF(OR('（別紙１）省力化計算シート'!F15="-",'（別紙１）省力化計算シート'!F15=0),'（別紙１）省力化計算シート'!D15&"分",'（別紙１）省力化計算シート'!D15&"分"&" (→"&'（別紙１）省力化計算シート'!D15+'（別紙１）省力化計算シート'!F15&"分）")) -> 547.2分
X11: 時間が削減される作業
C15: ='（別紙１）省力化計算シート'!C16 -> MC2加工 | E15: > | G15: ='（別紙１）省力化計算シート'!C17 -> MC3加工 | I15: > | K15: ='（別紙１）省力化計算シート'!C18 -> MC4加工 | M15: > | O15: ='（別紙１）省力化計算シート'!C19 -> GD加工 | Q15: > | S15: ='（別紙１）省力化計算シート'!C20 -> 交差穴バリ取り | U15: > | X15: 導入前後で同様の作業
C16: =IF('（別紙１）省力化計算シート'!D16="","",IF(OR('（別紙１）省力化計算シート'!F16="-",'（別紙１）省力化計算シート'!F16=0),'（別紙１）省力化計算シート'!D16&"分",'（別紙１）省力化計算シート'!D16&"分"&" (→"&'（別紙１）省力化計算シート'!D16+'（別紙１）省力化計算シート'!F16&"分）")) -> 273.6分 | G16: =IF('（別紙１）省力化計算シート'!D17="","",IF(OR('（別紙１）省力化計算シート'!F17="-",'（別紙１）省力化計算シート'!F17=0),'（別紙１）省力化計算シート'!D17&"分",'（別紙１）省力化計算シート'!D17&"分"&" (→"&'（別紙１）省力化計算シート'!D17+'（別紙１）省力化計算シート'!F17&"分）")) -> 547.2分 | K16: =IF('（別紙１）省力化計算シート'!D18="","",IF(OR('（別紙１）省力化計算シート'!F18="-",'（別紙１）省力化計算シート'!F18=0),'（別紙１）省力化計算シート'!D18&"分",'（別紙１）省力化計算シート'!D18&"分"&" (→"&'（別紙１）省力化計算シート'!D18+'（別紙１）省力化計算シート'!F18&"分）")) -> 684分 | O16: =IF('（別紙１）省力化計算シート'!D19="","",IF(OR('（別紙１）省力化計算シート'!F19="-",'（別紙１）省力化計算シート'!F19=0),'（別紙１）省力化計算シート'!D19&"分",'（別紙１）省力化計算シート'!D19&"分"&" (→"&'（別紙１）省力化計算シート'!D19+'（別紙１）省力化計算シート'!F19&"分）")) -> 1368分 | S16: =IF('（別紙１）省力化計算シート'!D20="","",IF(OR('（別紙１）省力化計算シート'!F20="-",'（別紙１）省力化計算シート'!F20=0),'（別紙１）省力化計算シート'!D20&"分",'（別紙１）省力化計算シート'!D20&"分"&" (→"&'（別紙１）省力化計算シート'!D20+'（別紙１）省力化計算シート'!F20&"分）")) -> 2376分
X17: 作業内容の説明 入力欄
C22: ='（別紙１）省力化計算シート'!C21 -> 内視鏡検査 | E22: > | G22: ='（別紙１）省力化計算シート'!C22 -> 0 | I22: > | K22: ='（別紙１）省力化計算シート'!C23 -> 0 | M22: > | O22: ='（別紙１）省力化計算シート'!C24 -> 0 | Q22: > | S22: ='（別紙１）省力化計算シート'!C25 -> 0 | U22: >
C23: =IF('（別紙１）省力化計算シート'!D21="","",IF(OR('（別紙１）省力化計算シート'!F21="-",'（別紙１）省力化計算シート'!F21=0),'（別紙１）省力化計算シート'!D21&"分",'（別紙１）省力化計算シート'!D21&"分"&" (→"&'（別紙１）省力化計算シート'!D21+'（別紙１）省力化計算シート'!F21&"分）")) -> 2736分 | G23: =IF('（別紙１）省力化計算シート'!D22="","",IF(OR('（別紙１）省力化計算シート'!F22="-",'（別紙１）省力化計算シート'!F22=0),'（別紙１）省力化計算シート'!D22&"分",'（別紙１）省力化計算シート'!D22&"分"&" (→"&'（別紙１）省力化計算シート'!D22+'（別紙１）省力化計算シート'!F22&"分）")) | K23: =IF('（別紙１）省力化計算シート'!D23="","",IF(OR('（別紙１）省力化計算シート'!F23="-",'（別紙１）省力化計算シート'!F23=0),'（別紙１）省力化計算シート'!D23&"分",'（別紙１）省力化計算シート'!D23&"分"&" (→"&'（別紙１）省力化計算シート'!D23+'（別紙１）省力化計算シート'!F23&"分）")) | O23: =IF('（別紙１）省力化計算シート'!D24="","",IF(OR('（別紙１）省力化計算シート'!F24="-",'（別紙１）省力化計算シート'!F24=0),'（別紙１）省力化計算シート'!D24&"分",'（別紙１）省力化計算シート'!D24&"分"&" (→"&'（別紙１）省力化計算シート'!D24+'（別紙１）省力化計算シート'!F24&"分）")) | S23: =IF('（別紙１）省力化計算シート'!D25="","",IF(OR('（別紙１）省力化計算シート'!F25="-",'（別紙１）省力化計算シート'!F25=0),'（別紙１）省力化計算シート'!D25&"分",'（別紙１）省力化計算シート'!D25&"分"&" (→"&'（別紙１）省力化計算シート'!D25+'（別紙１）省力化計算シート'!F25&"分）"))
C29: ='（別紙１）省力化計算シート'!C26 -> 0 | E29: > | G29: ='（別紙１）省力化計算シート'!C27 -> 0 | I29: > | K29: ='（別紙１）省力化計算シート'!C28 -> 0 | M29: > | O29: ='（別紙１）省力化計算シート'!C29 -> 0 | Q29: > | S29: ='（別紙１）省力化計算シート'!C30 -> 0 | U29: >
C30: =IF('（別紙１）省力化計算シート'!D26="","",IF(OR('（別紙１）省力化計算シート'!F26="-",'（別紙１）省力化計算シート'!F26=0),'（別紙１）省力化計算シート'!D26&"分",'（別紙１）省力化計算シート'!D26&"分"&" (→"&'（別紙１）省力化計算シート'!D26+'（別紙１）省力化計算シート'!F26&"分）")) | G30: =IF('（別紙１）省力化計算シート'!D27="","",IF(OR('（別紙１）省力化計算シート'!F27="-",'（別紙１）省力化計算シート'!F27=0),'（別紙１）省力化計算シート'!D27&"分",'（別紙１）省力化計算シート'!D27&"分"&" (→"&'（別紙１）省力化計算シート'!D27+'（別紙１）省力化計算シート'!F27&"分）")) | K30: =IF('（別紙１）省力化計算シート'!D28="","",IF(OR('（別紙１）省力化計算シート'!F28="-",'（別紙１）省力化計算シート'!F28=0),'（別紙１）省力化計算シート'!D28&"分",'（別紙１）省力化計算シート'!D28&"分"&" (→"&'（別紙１）省力化計算シート'!D28+'（別紙１）省力化計算シート'!F28&"分）")) | O30: =IF('（別紙１）省力化計算シート'!D29="","",IF(OR('（別紙１）省力化計算シート'!F29="-",'（別紙１）省力化計算シート'!F29=0),'（別紙１）省力化計算シート'!D29&"分",'（別紙１）省力化計算シート'!D29&"分"&" (→"&'（別紙１）省力化計算シート'!D29+'（別紙１）省力化計算シート'!F29&"分）")) | S30: =IF('（別紙１）省力化計算シート'!D30="","",IF(OR('（別紙１）省力化計算シート'!F30="-",'（別紙１）省力化計算シート'!F30=0),'（別紙１）省力化計算シート'!D30&"分",'（別紙１）省力化計算シート'!D30&"分"&" (→"&'（別紙１）省力化計算シート'!D30+'（別紙１）省力化計算シート'!F30&"分）"))
C36: ='（別紙１）省力化計算シート'!C31 -> 0 | E36: > | G36: ='（別紙１）省力化計算シート'!C32 -> 0 | I36: > | K36: ='（別紙１）省力化計算シート'!C33 -> 0 | M36: > | O36: ='（別紙１）省力化計算シート'!C34 -> 0 | Q36: > | S36: ='（別紙１）省力化計算シート'!C35 -> 0 | U36: >
C37: =IF('（別紙１）省力化計算シート'!D31="","",IF(OR('（別紙１）省力化計算シート'!F31="-",'（別紙１）省力化計算シート'!F31=0),'（別紙１）省力化計算シート'!D31&"分",'（別紙１）省力化計算シート'!D31&"分"&" (→"&'（別紙１）省力化計算シート'!D31+'（別紙１）省力化計算シート'!F31&"分）")) | G37: =IF('（別紙１）省力化計算シート'!D32="","",IF(OR('（別紙１）省力化計算シート'!F32="-",'（別紙１）省力化計算シート'!F32=0),'（別紙１）省力化計算シート'!D32&"分",'（別紙１）省力化計算シート'!D32&"分"&" (→"&'（別紙１）省力化計算シート'!D32+'（別紙１）省力化計算シート'!F32&"分）")) | K37: =IF('（別紙１）省力化計算シート'!D33="","",IF(OR('（別紙１）省力化計算シート'!F33="-",'（別紙１）省力化計算シート'!F33=0),'（別紙１）省力化計算シート'!D33&"分",'（別紙１）省力化計算シート'!D33&"分"&" (→"&'（別紙１）省力化計算シート'!D33+'（別紙１）省力化計算シート'!F33&"分）")) | O37: =IF('（別紙１）省力化計算シート'!D34="","",IF(OR('（別紙１）省力化計算シート'!F34="-",'（別紙１）省力化計算シート'!F34=0),'（別紙１）省力化計算シート'!D34&"分",'（別紙１）省力化計算シート'!D34&"分"&" (→"&'（別紙１）省力化計算シート'!D34+'（別紙１）省力化計算シート'!F34&"分）")) | S37: =IF('（別紙１）省力化計算シート'!D35="","",IF(OR('（別紙１）省力化計算シート'!F35="-",'（別紙１）省力化計算シート'!F35=0),'（別紙１）省力化計算シート'!D35&"分",'（別紙１）省力化計算シート'!D35&"分"&" (→"&'（別紙１）省力化計算シート'!D35+'（別紙１）省力化計算シート'!F35&"分）"))
C43: ='（別紙１）省力化計算シート'!C36 -> 0 | E43: > | G43: ='（別紙１）省力化計算シート'!C37 -> 0 | I43: > | K43: ='（別紙１）省力化計算シート'!C38 -> 0 | M43: > | O43: ='（別紙１）省力化計算シート'!C39 -> 0 | Q43: > | S43: ='（別紙１）省力化計算シート'!C40 -> 0
C44: =IF('（別紙１）省力化計算シート'!D36="","",IF(OR('（別紙１）省力化計算シート'!F36="-",'（別紙１）省力化計算シート'!F36=0),'（別紙１）省力化計算シート'!D36&"分",'（別紙１）省力化計算シート'!D36&"分"&" (→"&'（別紙１）省力化計算シート'!D36+'（別紙１）省力化計算シート'!F36&"分）")) | G44: =IF('（別紙１）省力化計算シート'!D37="","",IF(OR('（別紙１）省力化計算シート'!F37="-",'（別紙１）省力化計算シート'!F37=0),'（別紙１）省力化計算シート'!D37&"分",'（別紙１）省力化計算シート'!D37&"分"&" (→"&'（別紙１）省力化計算シート'!D37+'（別紙１）省力化計算シート'!F37&"分）")) | K44: =IF('（別紙１）省力化計算シート'!D38="","",IF(OR('（別紙１）省力化計算シート'!F38="-",'（別紙１）省力化計算シート'!F38=0),'（別紙１）省力化計算シート'!D38&"分",'（別紙１）省力化計算シート'!D38&"分"&" (→"&'（別紙１）省力化計算シート'!D38+'（別紙１）省力化計算シート'!F38&"分）")) | O44: =IF('（別紙１）省力化計算シート'!D39="","",IF(OR('（別紙１）省力化計算シート'!F39="-",'（別紙１）省力化計算シート'!F39=0),'（別紙１）省力化計算シート'!D39&"分",'（別紙１）省力化計算シート'!D39&"分"&" (→"&'（別紙１）省力化計算シート'!D39+'（別紙１）省力化計算シート'!F39&"分）")) | S44: =IF('（別紙１）省力化計算シート'!D40="","",IF(OR('（別紙１）省力化計算シート'!F40="-",'（別紙１）省力化計算シート'!F40=0),'（別紙１）省力化計算シート'!D40&"分",'（別紙１）省力化計算シート'!D40&"分"&" (→"&'（別紙１）省力化計算シート'!D40+'（別紙１）省力化計算シート'!F40&"分）"))
A48: =IF(COUNTA('（別紙１）省力化計算シート'!C26:C40)<>0,"← 非表示エリアに記載があります。[＋]をクリックして表示してください。[-]の場合は、すべて表示されています。","")
C50: ■設備導入後の業務プロセス・作業工程 （AFTER） | O50: 設備導入による増加時間 | S50: ='（別紙１）省力化計算シート'!J3 -> 13.06 | T50: 時間
C53: ='（別紙１）省力化計算シート'!I11 -> 資材供給 | E53: > | G53: ='（別紙１）省力化計算シート'!I12 -> L1加工 | I53: > | K53: ='（別紙１）省力化計算シート'!I13 -> L2加工 | M53: > | O53: ='（別紙１）省力化計算シート'!I14 -> 寸法精度検査 | Q53: > | S53: ='（別紙１）省力化計算シート'!I15 -> 0 | U53: > | X53: 新たに追加される作業
C54: =IF('（別紙１）省力化計算シート'!J11="","",IF(OR('（別紙１）省力化計算シート'!N11="-",'（別紙１）省力化計算シート'!N11=0),'（別紙１）省力化計算シート'!J11&"分","("&'（別紙１）省力化計算シート'!J11-'（別紙１）省力化計算シート'!N11&"分→）"&'（別紙１）省力化計算シート'!J11&"分")) -> (182.4分→）192分 | G54: =IF('（別紙１）省力化計算シート'!J12="","",IF(OR('（別紙１）省力化計算シート'!N12="-",'（別紙１）省力化計算シート'!N12=0),'（別紙１）省力化計算シート'!J12&"分","("&'（別紙１）省力化計算シート'!J12-'（別紙１）省力化計算シート'!N12&"分→）"&'（別紙１）省力化計算シート'!J12&"分")) -> 288分 | K54: =IF('（別紙１）省力化計算シート'!J13="","",IF(OR('（別紙１）省力化計算シート'!N13="-",'（別紙１）省力化計算シート'!N13=0),'（別紙１）省力化計算シート'!J13&"分","("&'（別紙１）省力化計算シート'!J13-'（別紙１）省力化計算シート'!N13&"分→）"&'（別紙１）省力化計算シート'!J13&"分")) -> 480分 | O54: =IF('（別紙１）省力化計算シート'!J14="","",IF(OR('（別紙１）省力化計算シート'!N14="-",'（別紙１）省力化計算シート'!N14=0),'（別紙１）省力化計算シート'!J14&"分","("&'（別紙１）省力化計算シート'!J14-'（別紙１）省力化計算シート'!N14&"分→）"&'（別紙１）省力化計算シート'!J14&"分")) -> 6分 | S54: =IF('（別紙１）省力化計算シート'!J15="","",IF(OR('（別紙１）省力化計算シート'!N15="-",'（別紙１）省力化計算シート'!N15=0),'（別紙１）省力化計算シート'!J15&"分","("&'（別紙１）省力化計算シート'!J15-'（別紙１）省力化計算シート'!N15&"分→）"&'（別紙１）省力化計算シート'!J15&"分"))
X56: 時間が増加する作業
C60: ='（別紙１）省力化計算シート'!I16 -> 0 | E60: > | G60: ='（別紙１）省力化計算シート'!I17 -> 0 | I60: > | K60: ='（別紙１）省力化計算シート'!I18 -> 0 | M60: > | O60: ='（別紙１）省力化計算シート'!I19 -> 0 | Q60: > | S60: ='（別紙１）省力化計算シート'!I20 -> 0 | U60: > | X60: 導入前後で同様の作業
C61: =IF('（別紙１）省力化計算シート'!J16="","",IF(OR('（別紙１）省力化計算シート'!N16="-",'（別紙１）省力化計算シート'!N16=0),'（別紙１）省力化計算シート'!J16&"分","("&'（別紙１）省力化計算シート'!J16-'（別紙１）省力化計算シート'!N16&"分→）"&'（別紙１）省力化計算シート'!J16&"分")) | G61: =IF('（別紙１）省力化計算シート'!J17="","",IF(OR('（別紙１）省力化計算シート'!N17="-",'（別紙１）省力化計算シート'!N17=0),'（別紙１）省力化計算シート'!J17&"分","("&'（別紙１）省力化計算シート'!J17-'（別紙１）省力化計算シート'!N17&"分→）"&'（別紙１）省力化計算シート'!J17&"分")) | K61: =IF('（別紙１）省力化計算シート'!J18="","",IF(OR('（別紙１）省力化計算シート'!N18="-",'（別紙１）省力化計算シート'!N18=0),'（別紙１）省力化計算シート'!J18&"分","("&'（別紙１）省力化計算シート'!J18-'（別紙１）省力化計算シート'!N18&"分→）"&'（別紙１）省力化計算シート'!J18&"分")) | O61: =IF('（別紙１）省力化計算シート'!J19="","",IF(OR('（別紙１）省力化計算シート'!N19="-",'（別紙１）省力化計算シート'!N19=0),'（別紙１）省力化計算シート'!J19&"分","("&'（別紙１）省力化計算シート'!J19-'（別紙１）省力化計算シート'!N19&"分→）"&'（別紙１）省力化計算シート'!J19&"分")) | S61: =IF('（別紙１）省力化計算シート'!J20="","",IF(OR('（別紙１）省力化計算シート'!N20="-",'（別紙１）省力化計算シート'!N20=0),'（別紙１）省力化計算シート'!J20&"分","("&'（別紙１）省力化計算シート'!J20-'（別紙１）省力化計算シート'!N20&"分→）"&'（別紙１）省力化計算シート'!J20&"分"))
X62: 作業内容の説明 入力欄
C67: ='（別紙１）省力化計算シート'!I21 -> 0 | E67: > | G67: ='（別紙１）省力化計算シート'!I22 -> 0 | I67: > | K67: ='（別紙１）省力化計算シート'!I23 -> 0 | M67: > | O67: ='（別紙１）省力化計算シート'!I24 -> 0 | Q67: > | S67: ='（別紙１）省力化計算シート'!I25 -> 0 | U67: >
C68: =IF('（別紙１）省力化計算シート'!J21="","",IF(OR('（別紙１）省力化計算シート'!N21="-",'（別紙１）省力化計算シート'!N21=0),'（別紙１）省力化計算シート'!J21&"分","("&'（別紙１）省力化計算シート'!J21-'（別紙１）省力化計算シート'!N21&"分→）"&'（別紙１）省力化計算シート'!J21&"分")) | G68: =IF('（別紙１）省力化計算シート'!J22="","",IF(OR('（別紙１）省力化計算シート'!N22="-",'（別紙１）省力化計算シート'!N22=0),'（別紙１）省力化計算シート'!J22&"分","("&'（別紙１）省力化計算シート'!J22-'（別紙１）省力化計算シート'!N22&"分→）"&'（別紙１）省力化計算シート'!J22&"分")) | K68: =IF('（別紙１）省力化計算シート'!J23="","",IF(OR('（別紙１）省力化計算シート'!N23="-",'（別紙１）省力化計算シート'!N23=0),'（別紙１）省力化計算シート'!J23&"分","("&'（別紙１）省力化計算シート'!J23-'（別紙１）省力化計算シート'!N23&"分→）"&'（別紙１）省力化計算シート'!J23&"分")) | O68: =IF('（別紙１）省力化計算シート'!J24="","",IF(OR('（別紙１）省力化計算シート'!N24="-",'（別紙１）省力化計算シート'!N24=0),'（別紙１）省力化計算シート'!J24&"分","("&'（別紙１）省力化計算シート'!J24-'（別紙１）省力化計算シート'!N24&"分→）"&'（別紙１）省力化計算シート'!J24&"分")) | S68: =IF('（別紙１）省力化計算シート'!J25="","",IF(OR('（別紙１）省力化計算シート'!N25="-",'（別紙１）省力化計算シート'!N25=0),'（別紙１）省力化計算シート'!J25&"分","("&'（別紙１）省力化計算シート'!J25-'（別紙１）省力化計算シート'!N25&"分→）"&'（別紙１）省力化計算シート'!J25&"分"))
C74: ='（別紙１）省力化計算シート'!I26 -> 0 | E74: > | G74: ='（別紙１）省力化計算シート'!I27 -> 0 | I74: > | K74: ='（別紙１）省力化計算シート'!I28 -> 0 | M74: > | O74: ='（別紙１）省力化計算シート'!I29 -> 0 | Q74: > | S74: ='（別紙１）省力化計算シート'!I30 -> 0 | U74: >
C75: =IF('（別紙１）省力化計算シート'!J26="","",IF(OR('（別紙１）省力化計算シート'!N26="-",'（別紙１）省力化計算シート'!N26=0),'（別紙１）省力化計算シート'!J26&"分","("&'（別紙１）省力化計算シート'!J26-'（別紙１）省力化計算シート'!N26&"分→）"&'（別紙１）省力化計算シート'!J26&"分")) | G75: =IF('（別紙１）省力化計算シート'!J27="","",IF(OR('（別紙１）省力化計算シート'!N27="-",'（別紙１）省力化計算シート'!N27=0),'（別紙１）省力化計算シート'!J27&"分","("&'（別紙１）省力化計算シート'!J27-'（別紙１）省力化計算シート'!N27&"分→）"&'（別紙１）省力化計算シート'!J27&"分")) | K75: =IF('（別紙１）省力化計算シート'!J28="","",IF(OR('（別紙１）省力化計算シート'!N28="-",'（別紙１）省力化計算シート'!N28=0),'（別紙１）省力化計算シート'!J28&"分","("&'（別紙１）省力化計算シート'!J28-'（別紙１）省力化計算シート'!N28&"分→）"&'（別紙１）省力化計算シート'!J28&"分")) | O75: =IF('（別紙１）省力化計算シート'!J29="","",IF(OR('（別紙１）省力化計算シート'!N29="-",'（別紙１）省力化計算シート'!N29=0),'（別紙１）省力化計算シート'!J29&"分","("&'（別紙１）省力化計算シート'!J29-'（別紙１）省力化計算シート'!N29&"分→）"&'（別紙１）省力化計算シート'!J29&"分")) | S75: =IF('（別紙１）省力化計算シート'!J30="","",IF(OR('（別紙１）省力化計算シート'!N30="-",'（別紙１）省力化計算シート'!N30=0),'（別紙１）省力化計算シート'!J30&"分","("&'（別紙１）省力化計算シート'!J30-'（別紙１）省力化計算シート'!N30&"分→）"&'（別紙１）省力化計算シート'!J30&"分"))
C81: ='（別紙１）省力化計算シート'!I31 -> 0 | E81: > | G81: ='（別紙１）省力化計算シート'!I32 -> 0 | I81: > | K81: ='（別紙１）省力化計算シート'!I33 -> 0 | M81: > | O81: ='（別紙１）省力化計算シート'!I34 -> 0 | Q81: > | S81: ='（別紙１）省力化計算シート'!I35 -> 0 | U81: >
C82: =IF('（別紙１）省力化計算シート'!J31="","",IF(OR('（別紙１）省力化計算シート'!N31="-",'（別紙１）省力化計算シート'!N31=0),'（別紙１）省力化計算シート'!J31&"分","("&'（別紙１）省力化計算シート'!J31-'（別紙１）省力化計算シート'!N31&"分→）"&'（別紙１）省力化計算シート'!J31&"分")) | G82: =IF('（別紙１）省力化計算シート'!J32="","",IF(OR('（別紙１）省力化計算シート'!N32="-",'（別紙１）省力化計算シート'!N32=0),'（別紙１）省力化計算シート'!J32&"分","("&'（別紙１）省力化計算シート'!J32-'（別紙１）省力化計算シート'!N32&"分→）"&'（別紙１）省力化計算シート'!J32&"分")) | K82: =IF('（別紙１）省力化計算シート'!J33="","",IF(OR('（別紙１）省力化計算シート'!N33="-",'（別紙１）省力化計算シート'!N33=0),'（別紙１）省力化計算シート'!J33&"分","("&'（別紙１）省力化計算シート'!J33-'（別紙１）省力化計算シート'!N33&"分→）"&'（別紙１）省力化計算シート'!J33&"分")) | O82: =IF('（別紙１）省力化計算シート'!J34="","",IF(OR('（別紙１）省力化計算シート'!N34="-",'（別紙１）省力化計算シート'!N34=0),'（別紙１）省力化計算シート'!J34&"分","("&'（別紙１）省力化計算シート'!J34-'（別紙１）省力化計算シート'!N34&"分→）"&'（別紙１）省力化計算シート'!J34&"分")) | S82: =IF('（別紙１）省力化計算シート'!J35="","",IF(OR('（別紙１）省力化計算シート'!N35="-",'（別紙１）省力化計算シート'!N35=0),'（別紙１）省力化計算シート'!J35&"分","("&'（別紙１）省力化計算シート'!J35-'（別紙１）省力化計算シート'!N35&"分→）"&'（別紙１）省力化計算シート'!J35&"分"))
C88: ='（別紙１）省力化計算シート'!I36 -> 0 | E88: > | G88: ='（別紙１）省力化計算シート'!I37 -> 0 | I88: > | K88: ='（別紙１）省力化計算シート'!I38 -> 0 | M88: > | O88: ='（別紙１）省力化計算シート'!I39 -> 0 | Q88: > | S88: ='（別紙１）省力化計算シート'!I40 -> 0
C89: =IF('（別紙１）省力化計算シート'!J36="","",IF(OR('（別紙１）省力化計算シート'!N36="-",'（別紙１）省力化計算シート'!N36=0),'（別紙１）省力化計算シート'!J36&"分","("&'（別紙１）省力化計算シート'!J36-'（別紙１）省力化計算シート'!N36&"分→）"&'（別紙１）省力化計算シート'!J36&"分")) | G89: =IF('（別紙１）省力化計算シート'!J37="","",IF(OR('（別紙１）省力化計算シート'!N37="-",'（別紙１）省力化計算シート'!N37=0),'（別紙１）省力化計算シート'!J37&"分","("&'（別紙１）省力化計算シート'!J37-'（別紙１）省力化計算シート'!N37&"分→）"&'（別紙１）省力化計算シート'!J37&"分")) | K89: =IF('（別紙１）省力化計算シート'!J38="","",IF(OR('（別紙１）省力化計算シート'!N38="-",'（別紙１）省力化計算シート'!N38=0),'（別紙１）省力化計算シート'!J38&"分","("&'（別紙１）省力化計算シート'!J38-'（別紙１）省力化計算シート'!N38&"分→）"&'（別紙１）省力化計算シート'!J38&"分")) | O89: =IF('（別紙１）省力化計算シート'!J39="","",IF(OR('（別紙１）省力化計算シート'!N39="-",'（別紙１）省力化計算シート'!N39=0),'（別紙１）省力化計算シート'!J39&"分","("&'（別紙１）省力化計算シート'!J39-'（別紙１）省力化計算シート'!N39&"分→）"&'（別紙１）省力化計算シート'!J39&"分")) | S89: =IF('（別紙１）省力化計算シート'!J40="","",IF(OR('（別紙１）省力化計算シート'!N40="-",'（別紙１）省力化計算シート'!N40=0),'（別紙１）省力化計算シート'!J40&"分","("&'（別紙１）省力化計算シート'!J40-'（別紙１）省力化計算シート'!N40&"分→）"&'（別紙１）省力化計算シート'!J40&"分"))
A93: =IF(COUNTA('（別紙１）省力化計算シート'!I26:I40)<>0,"← 非表示エリアに記載があります。[＋]をクリックして表示してください。[-]の場合は、すべて表示されています。","")

Sheet （別紙３）投資回収期間計算シート
B1: （別紙３）投資回収期間計算シート
B3: 投資回収期間 | C3: =IF(AND(O4=FALSE,OR(C6="",H6="",J6="",L6="")),"",IF(AND(O4=TRUE,OR(C6="",L6="")),"",IF(C6/(F6*H6*J6+L6)<=0,"",C6/(F6*H6*J6+L6)))) -> 0.29117512 | D3: 年 | O3: パラメータ（公開時に非表示）
O4: FALSE
C5: 投資総額（円） | F5: 削減工数(時間) | H5: 年間稼働日数（日） | J5: 人件費単価（円/時） | L5: 増加した付加価値額（円） | O5: =IF($O$4=TRUE,"※新規事業の場合、削減工数（時間）は0と見なします。","※ 省力化計算シートより自動入力されます。") -> ※ 省力化計算シートより自動入力されます。
C6: 73500000 | D6: / | E6: （ | F6: =IF($O$4=TRUE,0,'（別紙１）省力化計算シート'!D3-'（別紙１）省力化計算シート'!J3) -> 142.06 | G6: × | H6: 250 | I6: × | J6: 1884 | K6: ＋ | L6: 185515151 | M6: ）
C12: 【算定根拠】算定の根拠となる計算式等の説明があれば記載してください。
C13: 【投資総額】Cincom M32 : 43,500,000円（税抜き）＋QTN 200 MSY : 30,000,000円（税抜き）＝73,500,000円（税抜き） 【年間稼働日数（日）】休日出勤を除く当社稼働日数 【人件費単価（円/時）】当該工程従業員平均給与 5,500,000円÷（250日×8時間＋残業1.5時間/日×250日×割り増し1.2＋休日出勤38日×9.5時間×割り増し1.3）＝1,884円/時

Sheet 【参考書式】事業計画目標値算出シート（参考） 
B1: ◆◆◆ 参考書式をご利用になる際のご注意点 ◆◆◆
B2: ・自動計算項目については、参考値となります。 | N2: （参考サイト：写真をタッチでリンクに飛びます）
B3: ・入力値(営業利益が大幅にマイナスの場合など)によっては、申請システムの計算値と異なる可能性があります。
B4: ・イメージがわかるよう入力値に数値をいれてありますが、上書きしてご活用ください。また、以下の機構ツールもぜひご活用ください。
B5: 「経営自己診断システム」「価格転嫁検討ツール」「儲かる経営キヅク君」→印刷枠外にリンクあります。
B6: ・申請システムへの入力は、この表の一部（黄色のセル）を転記していただくことになりますが、本事業における売上・収益計画等
B7: を立てるにあたっての参考にお使いください。（初めに直近決算書の実績数値を入れて、数値シミュレーションにもお使いください。）
B8: ・あくまでシステムに入力いただいた数値を正しいものとして審査します。（提出時に本シートは削除しなくて結構です。）
B9: ・労働生産性および給与支給総額の計画値が、目標額を上回っていることの確認、
B10: および、事業実施都道府県における最低賃金の直近5年間の年平均成長率の要件を充たしていることの確認 等、
B11: 申請に係る要件の確認は、必ず申請システム上でご確認ください。
F13: 申請システムへ転記する数字
E15: 緑字 | F15: 入力するとシミュレーションできます
E17: 青字 | F17: 成長率 | H17: 紫字 | I17: 計算式が不適当な場合適宜直接手入力してください
E19: その他 | F19: 自動計算 | I19: （基準年の販管費に人件費増加分と新設備減価償却費を加味）
B22: 【参考書式】事業計画目標値算出シート
E24: 基準年度 | G24: 1 | H24: 2 | I24: 3 | J24: 4 | K24: 5
E25: 直近の決算年月 | G25: 年目計画 | H25: 年目計画 | I25: 年目計画 | J25: 年目計画 | K25: 年目計画
E26: 2025年 3月期 | G26: 2027年 3月期 | H26: 2028年 3月期 | I26: 2029年 3月期 | J26: 2030年 3月期 | K26: 2031年 3月期
B28: 売上高 | E28: 9.5781039e+08 | G28: 1027083000 | H28: 1093843000 | I28: 1164942000 | J28: 1240663000 | K28: 1321306000
B29: 売上原価 | E29: 6.2402145e+08 | G29: 620608000 | H29: 670689000 | I29: 708956000 | J29: 747986000 | K29: 792505000
B30: 売上総利益 | E30: =E28-E29 -> 3.3378894e+08 | G30: =G28-G29 -> 406475000 | H30: =H28-H29 -> 423154000 | I30: =I28-I29 -> 455986000 | J30: =J28-J29 -> 492677000 | K30: =K28-K29 -> 528801000
B31: 販売費及び一般管理費 | E31: 1.0176276e+08 | G31: =$E$31+G36+(G42-$E$42) -> 1.1558216e+08 | H31: =$E$31+H36+(H42-$E$42) -> 1.3093416e+08 | I31: =$E$31+I36+(I42-$E$42) -> 1.3628116e+08 | J31: =$E$31+J36+(J42-$E$42) -> 1.4254216e+08 | K31: =$E$31+K36+(K42-$E$42) -> 1.4961316e+08
B32: ① 営業利益 | E32: =E30-E31 -> 2.3202618e+08 | G32: =G30-G31 -> 2.9089284e+08 | H32: =H30-H31 -> 2.9221984e+08 | I32: =I30-I31 -> 3.1970484e+08 | J32: =J30-J31 -> 3.5013484e+08 | K32: =K30-K31 -> 3.7918784e+08
B33: ② 人件費 （注１） | E33: 2.3256557e+08 | G33: 242029000 | H33: 251879000 | I33: 262134000 | J33: 272810000 | K33: 283923000
B34: ③ 減価償却費 | E34: =E35+E36 -> 13150.386 | G34: =G35+G36 -> 6292150.4 | H34: =H35+H36 -> 13794150 | I34: =I35+I36 -> 10969150 | J34: =J35+J36 -> 8723150.4 | K34: =K35+K36 -> 6938150.4
B35: （内訳）既存設備の減価償却費 | E35: 13150.386 | G35: 13150.386 | H35: 13150.386 | I35: 13150.386 | J35: 13150.386 | K35: 13150.386
B36: 本補助金で導入する設備の減価償却費 | E36: 0 | G36: 6279000 | H36: 13781000 | I36: 10956000 | J36: 8710000 | K36: 6925000
B37: ④付加価値額（①+②+③） | E37: =E32+E33+E34 -> 4.646049e+08 | G37: =G32+G33+G34 -> 5.3921399e+08 | H37: =H32+H33+H34 -> 5.5789299e+08 | I37: =I32+I33+I34 -> 5.9280799e+08 | J37: =J32+J33+J34 -> 6.3166799e+08 | K37: =K32+K33+K34 -> 6.7004899e+08
B38: 付加価値額の年平均成長率（％） | G38: =ROUNDDOWN(((G37/$E$37)^(1/G24)-1)*100,2) -> 16.05 | H38: =ROUNDDOWN(((H37/$E$37)^(1/H24)-1)*100,2) -> 9.58 | I38: =ROUNDDOWN(((I37/$E$37)^(1/I24)-1)*100,2) -> 8.46 | J38: =ROUNDDOWN(((J37/$E$37)^(1/J24)-1)*100,2) -> 7.98 | K38: =ROUNDDOWN(((K37/$E$37)^(1/K24)-1)*100,2) -> 7.59
B39: 労働生産性(＝１人あたり付加価値額) | E39: =ROUNDUP((E37/(E49+E50)),2) -> 11615123 | G39: =ROUNDUP((G37/(G49+G50)),2) -> 13480350 | H39: =ROUNDUP((H37/(H49+H50)),2) -> 13947325 | I39: =ROUNDUP((I37/(I49+I50)),2) -> 14820200 | J39: =ROUNDUP((J37/(J49+J50)),2) -> 15791700 | K39: =ROUNDUP((K37/(K49+K50)),2) -> 16751225
B40: 労働生産性の目標値 （年平均成長率４％ずつ上げる場合） | G40: =ROUNDUP(($E$37+(ABS($E$37)*1.04^G24-ABS($E$37)))/($E$49+$E$50),0) -> 12079728 | H40: =ROUNDUP(($E$37+(ABS($E$37)*1.04^H24-ABS($E$37)))/($E$49+$E$50),0) -> 12562917 | I40: =ROUNDUP(($E$37+(ABS($E$37)*1.04^I24-ABS($E$37)))/($E$49+$E$50),0) -> 13065434 | J40: =ROUNDUP(($E$37+(ABS($E$37)*1.04^J24-ABS($E$37)))/($E$49+$E$50),0) -> 13588051 | K40: =ROUNDUP(($E$37+(ABS($E$37)*1.04^K24-ABS($E$37)))/($E$49+$E$50),0) -> 14131573
B41: 労働生産性の年平均成長率（％） | G41: =ROUNDDOWN(((G39/$E$39)^(1/G24)-1)*100,2) -> 16.05 | H41: =ROUNDDOWN(((H39/$E$39)^(1/H24)-1)*100,2) -> 9.58 | I41: =ROUNDDOWN(((I39/$E$39)^(1/I24)-1)*100,2) -> 8.46 | J41: =ROUNDDOWN(((J39/$E$39)^(1/J24)-1)*100,2) -> 7.98 | K41: =ROUNDDOWN(((K39/$E$39)^(1/K24)-1)*100,2) -> 7.59
B42: ⑤給与支給総額（⑥+⑦） (注２)（※５） | E42: =E43+E44 -> 1.838946e+08 | G42: =G43+G44 -> 191435000 | H42: =H43+H44 -> 199285000 | I42: =I43+I44 -> 207457000 | J42: =J43+J44 -> 215964000 | K42: =K43+K44 -> 224820000
B43: ⑥ ⑤のうち、役員報酬 | E43: 20994919 | G43: 21856000 | H43: 22753000 | I43: 23686000 | J43: 24658000 | K43: 25669000
B44: ⑦ ⑤のうち、従業員の給与支給総額 | E44: 1.6289968e+08 | G44: 169579000 | H44: 176532000 | I44: 183771000 | J44: 191306000 | K44: 199151000
B45: 給与支給総額の年平均成長率（％）（※５） | G45: =ROUNDDOWN(((G42/$E$42)^(1/G24)-1)*100,2) -> 4.1 | H45: =ROUNDDOWN(((H42/$E$42)^(1/H24)-1)*100,2) -> 4.1 | I45: =ROUNDDOWN(((I42/$E$42)^(1/I24)-1)*100,2) -> 4.1 | J45: =ROUNDDOWN(((J42/$E$42)^(1/J24)-1)*100,2) -> 4.1 | K45: =ROUNDDOWN(((K42/$E$42)^(1/K24)-1)*100,2) -> 4.1
B46: 給与支給総額の目標額 | C46: (※1)特例なし、加点なし：2% | D46: 0.02 | G46: =$E$42*(1+$D46)^G$24 -> 1.8757249e+08 | H46: =$E$42*(1+$D46)^H$24 -> 1.9132394e+08 | I46: =$E$42*(1+$D46)^I$24 -> 1.9515042e+08 | J46: =$E$42*(1+$D46)^J$24 -> 1.9905343e+08 | K46: =$E$42*(1+$D46)^K$24 -> 2.0303449e+08
C47: (※2)特例なし、加点あり：4% | D47: 0.04 | G47: =$E$42*(1+$D47)^G$24 -> 1.9125038e+08 | H47: =$E$42*(1+$D47)^H$24 -> 1.989004e+08 | I47: =$E$42*(1+$D47)^I$24 -> 2.0685641e+08 | J47: =$E$42*(1+$D47)^J$24 -> 2.1513067e+08 | K47: =$E$42*(1+$D47)^K$24 -> 2.2373589e+08
C48: (※3)特例あり：6% | D48: 0.06 | G48: =$E$42*(1+$D48)^G$24 -> 1.9492827e+08 | H48: =$E$42*(1+$D48)^H$24 -> 2.0662397e+08 | I48: =$E$42*(1+$D48)^I$24 -> 2.1902141e+08 | J48: =$E$42*(1+$D48)^J$24 -> 2.3216269e+08 | K48: =$E$42*(1+$D48)^K$24 -> 2.4609245e+08
...

Sheet 【参考書式】達成すべき目標値の算出ツール（参考）
C1: (参考)
D3: 基準年 | E3: 1 | F3: 2 | G3: 3 | H3: 4 | I3: 5
C4: 増加率 | E4: 0.02 | F4: =(1+$E4)^$F3-1 -> 0.0404 | G4: =(1+$E4)^G3-1 -> 0.061208 | H4: =(1+$E4)^H3-1 -> 0.08243216 | I4: =(1+$E4)^I3-1 -> 0.1040808
D5: 1000 | E5: =$D5*((1+$E4)^E3) -> 1020 | F5: =$D5*((1+$E4)^F3) -> 1040.4 | G5: =$D5*((1+$E4)^G3) -> 1061.208 | H5: =$D5*((1+$E4)^H3) -> 1082.4322 | I5: =$D5*((1+$E4)^I3) -> 1104.0808
E6: 0.04 | F6: =(1+$E6)^F3-1 -> 0.0816 | G6: =(1+$E6)^G3-1 -> 0.124864 | H6: =(1+$E6)^H3-1 -> 0.16985856 | I6: =(1+$E6)^I3-1 -> 0.2166529
E7: 0.05 | F7: =(1+$E7)^F3-1 -> 0.1025 | G7: =(1+$E7)^G3-1 -> 0.157625 | H7: =(1+$E7)^H3-1 -> 0.21550625 | I7: =(1+$E7)^I3-1 -> 0.27628156
E8: 0.06 | F8: =(1+$E8)^F3-1 -> 0.1236 | G8: =(1+$E8)^G3-1 -> 0.191016 | H8: =(1+$E8)^H3-1 -> 0.26247696 | I8: =(1+$E8)^I3-1 -> 0.33822558
E9: 0.07 | F9: =(1+$E9)^F3-1 -> 0.1449 | G9: =(1+$E9)^G3-1 -> 0.225043 | H9: =(1+$E9)^H3-1 -> 0.31079601 | I9: =(1+$E9)^I3-1 -> 0.40255173
E10: 0.08 | F10: =(1+$E10)^F3-1 -> 0.1664 | G10: =(1+$E10)^G3-1 -> 0.259712 | H10: =(1+$E10)^H3-1 -> 0.36048896 | I10: =(1+$E10)^I3-1 -> 0.46932808
E11: 0.09 | F11: =(1+$E11)^F3-1 -> 0.1881 | G11: =(1+$E11)^G3-1 -> 0.295029 | H11: =(1+$E11)^H3-1 -> 0.41158161 | I11: =(1+$E11)^I3-1 -> 0.53862395
D13: 基準年 | E13: １年目 | F13: ２年目 | G13: ３年目 | H13: ４年目 | I13: ５年目
C14: 増加率 | E14: 0.02 | F14: =(1+$E14)^F3-1 -> 0.0404 | G14: =(1+$E14)^G3-1 -> 0.061208 | H14: =(1+$E14)^H3-1 -> 0.08243216 | I14: =(1+$E14)^I3-1 -> 0.1040808
C15: 目標値 | D15: 4500000 | E15: =ROUNDUP($D$15*((1+$E14)^E3),3) -> 4590000 | F15: =$D$15*((1+$E14)^F3) -> 4681800 | G15: =$D15*((1+$E14)^G3) -> 4775436 | H15: =$D15*((1+$E14)^H3) -> 4870944.7 | I15: =$D15*((1+$E14)^I3) -> 4968363.6
C16: 年平均成長率 | E16: =ROUNDDOWN(((E15/$D$15)^(1/E3)-1),5) -> 0.02 | F16: =ROUNDDOWN(((F15/$D$15)^(1/F3)-1),5) -> 0.02 | G16: =ROUNDDOWN(((G15/$D$15)^(1/G3)-1),5) -> 0.02 | H16: =ROUNDDOWN(((H15/$D$15)^(1/H3)-1),5) -> 0.02 | I16: =ROUNDDOWN(((I15/$D$15)^(1/I3)-1),5) -> 0.02
