Workbook
Name サブタイトル: [1]更新履歴!$L$3
Name タイトル: [1]更新履歴!$D$3
Name 作成日: [1]更新履歴!$U$2
Name 所属: #REF!

Sheet 【指定様式】事業計画書（その3）
A1: 【指定様式】事業計画書（その３）
B2: 事業者名
B3: 株式会社ニッポンジーン
B4: 本事業計画における会社全体の事業計画（数値計画）を記載してください。
A5: 記載数値：「省力化指数」「付加価値額」「労働生産性」「1人当たり給与支給総額」「投資回収期間」
B7: 【１】省力化指数
B8: ='（別紙１）省力化計算シート'!M3 -> 0.85769231
B9: ※「（別紙１）省力化計算シート」より算出。
B10: ※「（別紙２）省力化業務プロセス図」も作成し省力化指数の詳細を説明してください。
B12: 【２】会社全体の事業計画（表）
B53: 【事業計画年数（３～５年）】
B54: 3 | D54: 年
B56: 【算定根拠】算定の根拠となる計算式等をそれぞれ記載ください。
B57: また、計画最終年の年平均成長率を転記してください。（事業者の目標値となります。）
B59: ①付加価値額 | H59: 最終年の年平均成長率 | I59: 8.69 | J59: ％
B60: 付加価値額（営業利益＋人件費＋減価償却費）は、基準年度916,124,358円→3年目1,176,621,540円（＋260,497,182円、年平均成長率8.69％）と推移する。 ①新製品売上：一般市場向けの新製品（呼吸器系イムノクロマト検査薬・ハウジング製品・卸値250円/テスト）を、1年目40万テスト＝100,000,000円→3年目100万テスト＝250,000,000円上乗せする。 ②既存売上の回復：主力の体外診断薬・研究用試薬はコロナ特需の反動で第45期（1,787,102,045円）を底としたが回復局面にあり、テストストリップ包装ラインの省力化で創出した工数を高付加価値業務へ再配置しつつ、第43期実績（2,036百万円）の範囲内で1年目1,940百万円→3年目2,008百万円へ回復させる。 ③利益率改善：省力化設備の稼働初年度（1年目）から、4mm幅化の取り数増と歩留まり改善で材料費率を18.73％→17.90％、スケールメリットで販管費率を12.9％→12.50％へ改善する。 ④人件費：既存従業員の年約4.1％賃上げに加え、省力化で創出した工数の再配置と、2年目以降に計画するバイオ領域の高度専門人材（研究開発・品質保証・製造技術・薬事）の段階的な増員分を織り込み、825,028,990円→3年目1,031,543,717円。 ⑤減価償却費：新設備165,564,000円（機械装置・耐用8年・200％定率法）の償却費（1年目41,391,000円→3年目23,282,438円）を既存分59,474,279円に加算。
B65: ②労働生産性 | H65: 最終年の年平均成長率 | I65: 4.15 | J65: ％
B66: 労働生産性＝付加価値額÷（役員9名＋常勤従業員数）。常勤従業員は基準年度130名・申請時点145名を基礎とし、省力化で創出した延べ139.4時間/日の工数を新製品の量産・開発・品質管理等の高付加価値業務へ再配置して付加価値を高める。ここで生まれた事業拡大と収益改善を原資に、2年目以降はバイオ領域の高度専門人材（研究開発・品質保証・製造技術・薬事）を各年2名ずつ計画的に増員し、常勤従業員数は1年目145名→2年目147名→3年目149名へ段階的に拡大する。付加価値額の増加が人員増を上回るため、労働生産性は基準年度6,590,822円→1年目6,882,882円（＋4.43％）→2年目7,155,364円（年平均+4.19％）→3年目7,446,972円（年平均+4.15％）と、事業計画期間を通じて毎年4.0％以上を満たす。
B72: ③1人当たり給与支給総額 | H72: 最終年の年平均成長率 | I72: 3.65 | J72: ％
B73: 全月分の給与支給を受けた従業員は、基準年度123名→1年目138名→2年目139名→3年目141名と、常勤従業員数の増加に合わせて段階的に増える。既存従業員を年約4.1％賃上げしつつ、2年目以降に採用する高度専門人材（想定年収600万円）が加わることで、1人当たり給与支給総額は基準年度4,683,168円→3年目5,216,402円（年平均成長率3.65％）となり、必須要件「年平均＋3.5％以上」を満たす。省力化による収益改善と新製品売上・既存事業の回復を賃上げ原資とし、従業員へ賃上げを表明して確実に実行する。
B78: 【３】投資回収期間
B79: ='（別紙３）投資回収期間計算シート'!C3 -> 0.47154696 | D79: 年
B80: ※「（別紙３）投資回収期間計算シート」より算出（自動反映）。

Sheet （別紙１）省力化計算シート
B1: （別紙１）省力化計算シート
C3: 設備導入により削減される 業務に要していた時間 | D3: =(SUMIF(C11:C40,"<>",D11:D40)-SUMIF(E11:E40,"<>-",D11:D40)-SUMIF(F11:F40,"<0"))/60 -> 162.5 | G3: 時間 | I3: 設備導入後に発生する 業務に要する時間 | J3: =(SUMIF(I11:I40,"<>",J11:J40)-SUMIF(N11:N40,"<>-",J11:J40)+SUMIF(N11:N40,">0"))/60 -> 23.125 | K3: 時間 | L3: 省力化指数 | M3: =IF(D3=0,0,IF((D3-J3)/D3<0,0,(D3-J3)/D3)) -> 0.85769231
B5: ■設備導入前の業務プロセス・作業工程 | H5: ■設備導入後の業務プロセス・作業工程
C7: 設備導入前の作業時間合計 | D7: =SUMIF(C11:C40,"<>",D11:D40)/60 -> 200.425 | G7: 時間 | I7: 設備導入後の作業時間合計 | J7: =SUMIF(I11:I40,"<>",J11:J40)/60 -> 61.05 | K7: 時間
B10: No. | C10: 工程名・作業名 | D10: 作業時間（分） | E10: 対応する導入後の 業務プロセスNo | F10: 同工程差分時間（分） | H10: No. | I10: 工程名・作業名 | J10: 作業時間（分） | K10: 作業種別 | L10: 対応する設備導入前の 業務プロセスNo. | N10: 同工程差分時間（分） | P10: 作業種別選択肢
B11: 1 | C11: ラミネート位置移動 | D11: 45 | E11: =IF(OR(C11="",D11=""),"-",IF(IFERROR(MATCH(B11,L$11:L$40,0),"")="","-",IF(OR(INDEX(I$11:I$40,MATCH(B11,L$11:L$40,0))="",INDEX(J$11:J$40,MATCH(B11,L$11:L$40,0))="",INDEX(K$11:K$40,MATCH(B11,L$11:L$40,0))<>"内容は変化しない作業"),"-",MATCH(B11,L$11:L$40,0)))) -> 1 | F11: {=IF(E11="-","-",IF(AND(C11<>"",D11>0,INDEX(K$11:K$40,E11)="内容は変化しない作業",AND(E11<>"-",E11<>""),INDEX(I$11:I$40,E11)<>"",INDEX(J$11:J$40,E11)<>""),INDEX(J$11:J$40,E11)-D11,"-"))} -> 0 | H11: 1 | I11: ラミネート位置移動 | J11: 45 | K11: 内容は変化しない作業 | L11: 1 | N11: {=IF(AND(I11<>"",J11>0,K11="内容は変化しない作業",L11>0,INDEX(C$11:C$40,L11)<>"",INDEX(D$11:D$40,L11)<>""),J11-INDEX(D$11:D$40,L11),"-")} -> 0 | P11: 新たに追加される作業
B12: 2 | C12: ラミネート準備 | D12: 30 | E12: =IF(OR(C12="",D12=""),"-",IF(IFERROR(MATCH(B12,L$11:L$40,0),"")="","-",IF(OR(INDEX(I$11:I$40,MATCH(B12,L$11:L$40,0))="",INDEX(J$11:J$40,MATCH(B12,L$11:L$40,0))="",INDEX(K$11:K$40,MATCH(B12,L$11:L$40,0))<>"内容は変化しない作業"),"-",MATCH(B12,L$11:L$40,0)))) -> 2 | F12: {=IF(E12="-","-",IF(AND(C12<>"",D12>0,INDEX(K$11:K$40,E12)="内容は変化しない作業",AND(E12<>"-",E12<>""),INDEX(I$11:I$40,E12)<>"",INDEX(J$11:J$40,E12)<>""),INDEX(J$11:J$40,E12)-D12,"-"))} -> 0 | H12: 2 | I12: ラミネート準備 | J12: 30 | K12: 内容は変化しない作業 | L12: 2 | N12: {=IF(AND(I12<>"",J12>0,K12="内容は変化しない作業",L12>0,INDEX(C$11:C$40,L12)<>"",INDEX(D$11:D$40,L12)<>""),J12-INDEX(D$11:D$40,L12),"-")} -> 0 | P12: 内容は変化しない作業
B13: 3 | C13: 短冊ラミネート作業（5mm幅・約12,500本にカット） | D13: 150 | E13: =IF(OR(C13="",D13=""),"-",IF(IFERROR(MATCH(B13,L$11:L$40,0),"")="","-",IF(OR(INDEX(I$11:I$40,MATCH(B13,L$11:L$40,0))="",INDEX(J$11:J$40,MATCH(B13,L$11:L$40,0))="",INDEX(K$11:K$40,MATCH(B13,L$11:L$40,0))<>"内容は変化しない作業"),"-",MATCH(B13,L$11:L$40,0)))) -> - | F13: {=IF(E13="-","-",IF(AND(C13<>"",D13>0,INDEX(K$11:K$40,E13)="内容は変化しない作業",AND(E13<>"-",E13<>""),INDEX(I$11:I$40,E13)<>"",INDEX(J$11:J$40,E13)<>""),INDEX(J$11:J$40,E13)-D13,"-"))} -> - | H13: 3 | I13: シートラミネート作業（50cm幅にカット・カット回数減） | J13: 90 | K13: 新たに追加される作業 | N13: {=IF(AND(I13<>"",J13>0,K13="内容は変化しない作業",L13>0,INDEX(C$11:C$40,L13)<>"",INDEX(D$11:D$40,L13)<>""),J13-INDEX(D$11:D$40,L13),"-")} -> -
B14: 4 | C14: ラミネート片付け・記録作成 | D14: 45 | E14: =IF(OR(C14="",D14=""),"-",IF(IFERROR(MATCH(B14,L$11:L$40,0),"")="","-",IF(OR(INDEX(I$11:I$40,MATCH(B14,L$11:L$40,0))="",INDEX(J$11:J$40,MATCH(B14,L$11:L$40,0))="",INDEX(K$11:K$40,MATCH(B14,L$11:L$40,0))<>"内容は変化しない作業"),"-",MATCH(B14,L$11:L$40,0)))) -> 4 | F14: {=IF(E14="-","-",IF(AND(C14<>"",D14>0,INDEX(K$11:K$40,E14)="内容は変化しない作業",AND(E14<>"-",E14<>""),INDEX(I$11:I$40,E14)<>"",INDEX(J$11:J$40,E14)<>""),INDEX(J$11:J$40,E14)-D14,"-"))} -> 0 | H14: 4 | I14: ラミネート片付け・記録作成 | J14: 45 | K14: 内容は変化しない作業 | L14: 4 | N14: {=IF(AND(I14<>"",J14>0,K14="内容は変化しない作業",L14>0,INDEX(C$11:C$40,L14)<>"",INDEX(D$11:D$40,L14)<>""),J14-INDEX(D$11:D$40,L14),"-")} -> 0
B15: 5 | C15: ストリップ検品・検数（短冊を1本ずつ検品） | D15: 1950 | E15: =IF(OR(C15="",D15=""),"-",IF(IFERROR(MATCH(B15,L$11:L$40,0),"")="","-",IF(OR(INDEX(I$11:I$40,MATCH(B15,L$11:L$40,0))="",INDEX(J$11:J$40,MATCH(B15,L$11:L$40,0))="",INDEX(K$11:K$40,MATCH(B15,L$11:L$40,0))<>"内容は変化しない作業"),"-",MATCH(B15,L$11:L$40,0)))) -> - | F15: {=IF(E15="-","-",IF(AND(C15<>"",D15>0,INDEX(K$11:K$40,E15)="内容は変化しない作業",AND(E15<>"-",E15<>""),INDEX(I$11:I$40,E15)<>"",INDEX(J$11:J$40,E15)<>""),INDEX(J$11:J$40,E15)-D15,"-"))} -> - | H15: 5 | I15: シート検品（シートラミネートの検品） | J15: 60 | K15: 新たに追加される作業 | N15: {=IF(AND(I15<>"",J15>0,K15="内容は変化しない作業",L15>0,INDEX(C$11:C$40,L15)<>"",INDEX(D$11:D$40,L15)<>""),J15-INDEX(D$11:D$40,L15),"-")} -> -
B16: 6 | C16: 嵌合・検品・照合（手作業でハウジングを嵌合） | D16: 3000 | E16: =IF(OR(C16="",D16=""),"-",IF(IFERROR(MATCH(B16,L$11:L$40,0),"")="","-",IF(OR(INDEX(I$11:I$40,MATCH(B16,L$11:L$40,0))="",INDEX(J$11:J$40,MATCH(B16,L$11:L$40,0))="",INDEX(K$11:K$40,MATCH(B16,L$11:L$40,0))<>"内容は変化しない作業"),"-",MATCH(B16,L$11:L$40,0)))) -> - | F16: {=IF(E16="-","-",IF(AND(C16<>"",D16>0,INDEX(K$11:K$40,E16)="内容は変化しない作業",AND(E16<>"-",E16<>""),INDEX(I$11:I$40,E16)<>"",INDEX(J$11:J$40,E16)<>""),INDEX(J$11:J$40,E16)-D16,"-"))} -> - | H16: 6 | I16: 嵌合機 段取り替え（部品交換・仕様変更） | J16: 90 | K16: 新たに追加される作業 | N16: {=IF(AND(I16<>"",J16>0,K16="内容は変化しない作業",L16>0,INDEX(C$11:C$40,L16)<>"",INDEX(D$11:D$40,L16)<>""),J16-INDEX(D$11:D$40,L16),"-")} -> -
B17: 7 | C17: ピロー包装機 段取り替え | D17: 45 | E17: =IF(OR(C17="",D17=""),"-",IF(IFERROR(MATCH(B17,L$11:L$40,0),"")="","-",IF(OR(INDEX(I$11:I$40,MATCH(B17,L$11:L$40,0))="",INDEX(J$11:J$40,MATCH(B17,L$11:L$40,0))="",INDEX(K$11:K$40,MATCH(B17,L$11:L$40,0))<>"内容は変化しない作業"),"-",MATCH(B17,L$11:L$40,0)))) -> 10 | F17: {=IF(E17="-","-",IF(AND(C17<>"",D17>0,INDEX(K$11:K$40,E17)="内容は変化しない作業",AND(E17<>"-",E17<>""),INDEX(I$11:I$40,E17)<>"",INDEX(J$11:J$40,E17)<>""),INDEX(J$11:J$40,E17)-D17,"-"))} -> 0 | H17: 7 | I17: アセンブラー オペレート（シート供給・マガジン交換） | J17: 195 | K17: 新たに追加される作業 | N17: {=IF(AND(I17<>"",J17>0,K17="内容は変化しない作業",L17>0,INDEX(C$11:C$40,L17)<>"",INDEX(D$11:D$40,L17)<>""),J17-INDEX(D$11:D$40,L17),"-")} -> -
B18: 8 | C18: ピロー包装（既存機への手供給・立ち合い） | D18: 1350 | E18: =IF(OR(C18="",D18=""),"-",IF(IFERROR(MATCH(B18,L$11:L$40,0),"")="","-",IF(OR(INDEX(I$11:I$40,MATCH(B18,L$11:L$40,0))="",INDEX(J$11:J$40,MATCH(B18,L$11:L$40,0))="",INDEX(K$11:K$40,MATCH(B18,L$11:L$40,0))<>"内容は変化しない作業"),"-",MATCH(B18,L$11:L$40,0)))) -> - | F18: {=IF(E18="-","-",IF(AND(C18<>"",D18>0,INDEX(K$11:K$40,E18)="内容は変化しない作業",AND(E18<>"-",E18<>""),INDEX(I$11:I$40,E18)<>"",INDEX(J$11:J$40,E18)<>""),INDEX(J$11:J$40,E18)-D18,"-"))} -> - | H18: 8 | I18: ケース検品・マガジン詰め・帯掛 | J18: 330 | K18: 新たに追加される作業 | N18: {=IF(AND(I18<>"",J18>0,K18="内容は変化しない作業",L18>0,INDEX(C$11:C$40,L18)<>"",INDEX(D$11:D$40,L18)<>""),J18-INDEX(D$11:D$40,L18),"-")} -> -
B19: 9 | C19: ピロー包装品 検品・帯掛 | D19: 1950 | E19: =IF(OR(C19="",D19=""),"-",IF(IFERROR(MATCH(B19,L$11:L$40,0),"")="","-",IF(OR(INDEX(I$11:I$40,MATCH(B19,L$11:L$40,0))="",INDEX(J$11:J$40,MATCH(B19,L$11:L$40,0))="",INDEX(K$11:K$40,MATCH(B19,L$11:L$40,0))<>"内容は変化しない作業"),"-",MATCH(B19,L$11:L$40,0)))) -> 11 | F19: {=IF(E19="-","-",IF(AND(C19<>"",D19>0,INDEX(K$11:K$40,E19)="内容は変化しない作業",AND(E19<>"-",E19<>""),INDEX(I$11:I$40,E19)<>"",INDEX(J$11:J$40,E19)<>""),INDEX(J$11:J$40,E19)-D19,"-"))} -> -1410 | H19: 9 | I19: 補充（ケース・ストリップ）・帯掛 | J19: 165 | K19: 新たに追加される作業 | N19: {=IF(AND(I19<>"",J19>0,K19="内容は変化しない作業",L19>0,INDEX(C$11:C$40,L19)<>"",INDEX(D$11:D$40,L19)<>""),J19-INDEX(D$11:D$40,L19),"-")} -> -
B20: 10 | C20: 箱詰め | D20: 300 | E20: =IF(OR(C20="",D20=""),"-",IF(IFERROR(MATCH(B20,L$11:L$40,0),"")="","-",IF(OR(INDEX(I$11:I$40,MATCH(B20,L$11:L$40,0))="",INDEX(J$11:J$40,MATCH(B20,L$11:L$40,0))="",INDEX(K$11:K$40,MATCH(B20,L$11:L$40,0))<>"内容は変化しない作業"),"-",MATCH(B20,L$11:L$40,0)))) -> 12 | F20: {=IF(E20="-","-",IF(AND(C20<>"",D20>0,INDEX(K$11:K$40,E20)="内容は変化しない作業",AND(E20<>"-",E20<>""),INDEX(I$11:I$40,E20)<>"",INDEX(J$11:J$40,E20)<>""),INDEX(J$11:J$40,E20)-D20,"-"))} -> 0 | H20: 10 | I20: ピロー包装機 段取り替え | J20: 45 | K20: 内容は変化しない作業 | L20: 7 | N20: {=IF(AND(I20<>"",J20>0,K20="内容は変化しない作業",L20>0,INDEX(C$11:C$40,L20)<>"",INDEX(D$11:D$40,L20)<>""),J20-INDEX(D$11:D$40,L20),"-")} -> 0
B21: 11 | E21: =IF(OR(C21="",D21=""),"-",IF(IFERROR(MATCH(B21,L$11:L$40,0),"")="","-",IF(OR(INDEX(I$11:I$40,MATCH(B21,L$11:L$40,0))="",INDEX(J$11:J$40,MATCH(B21,L$11:L$40,0))="",INDEX(K$11:K$40,MATCH(B21,L$11:L$40,0))<>"内容は変化しない作業"),"-",MATCH(B21,L$11:L$40,0)))) -> - | F21: {=IF(E21="-","-",IF(AND(C21<>"",D21>0,INDEX(K$11:K$40,E21)="内容は変化しない作業",AND(E21<>"-",E21<>""),INDEX(I$11:I$40,E21)<>"",INDEX(J$11:J$40,E21)<>""),INDEX(J$11:J$40,E21)-D21,"-"))} -> - | H21: 11 | I21: ピロー包装品 検品・帯掛 | J21: 540 | K21: 内容は変化しない作業 | L21: 9 | N21: {=IF(AND(I21<>"",J21>0,K21="内容は変化しない作業",L21>0,INDEX(C$11:C$40,L21)<>"",INDEX(D$11:D$40,L21)<>""),J21-INDEX(D$11:D$40,L21),"-")} -> -1410
B22: 12 | E22: =IF(OR(C22="",D22=""),"-",IF(IFERROR(MATCH(B22,L$11:L$40,0),"")="","-",IF(OR(INDEX(I$11:I$40,MATCH(B22,L$11:L$40,0))="",INDEX(J$11:J$40,MATCH(B22,L$11:L$40,0))="",INDEX(K$11:K$40,MATCH(B22,L$11:L$40,0))<>"内容は変化しない作業"),"-",MATCH(B22,L$11:L$40,0)))) -> - | F22: {=IF(E22="-","-",IF(AND(C22<>"",D22>0,INDEX(K$11:K$40,E22)="内容は変化しない作業",AND(E22<>"-",E22<>""),INDEX(I$11:I$40,E22)<>"",INDEX(J$11:J$40,E22)<>""),INDEX(J$11:J$40,E22)-D22,"-"))} -> - | H22: 12 | I22: 箱詰め | J22: 300 | K22: 内容は変化しない作業 | L22: 10 | N22: {=IF(AND(I22<>"",J22>0,K22="内容は変化しない作業",L22>0,INDEX(C$11:C$40,L22)<>"",INDEX(D$11:D$40,L22)<>""),J22-INDEX(D$11:D$40,L22),"-")} -> 0
B23: 13 | E23: =IF(OR(C23="",D23=""),"-",IF(IFERROR(MATCH(B23,L$11:L$40,0),"")="","-",IF(OR(INDEX(I$11:I$40,MATCH(B23,L$11:L$40,0))="",INDEX(J$11:J$40,MATCH(B23,L$11:L$40,0))="",INDEX(K$11:K$40,MATCH(B23,L$11:L$40,0))<>"内容は変化しない作業"),"-",MATCH(B23,L$11:L$40,0)))) -> - | F23: {=IF(E23="-","-",IF(AND(C23<>"",D23>0,INDEX(K$11:K$40,E23)="内容は変化しない作業",AND(E23<>"-",E23<>""),INDEX(I$11:I$40,E23)<>"",INDEX(J$11:J$40,E23)<>""),INDEX(J$11:J$40,E23)-D23,"-"))} -> - | H23: 13 | N23: {=IF(AND(I23<>"",J23>0,K23="内容は変化しない作業",L23>0,INDEX(C$11:C$40,L23)<>"",INDEX(D$11:D$40,L23)<>""),J23-INDEX(D$11:D$40,L23),"-")} -> -
B24: 14 | C24: テストストリップ 検品・検数 | D24: 750 | E24: =IF(OR(C24="",D24=""),"-",IF(IFERROR(MATCH(B24,L$11:L$40,0),"")="","-",IF(OR(INDEX(I$11:I$40,MATCH(B24,L$11:L$40,0))="",INDEX(J$11:J$40,MATCH(B24,L$11:L$40,0))="",INDEX(K$11:K$40,MATCH(B24,L$11:L$40,0))<>"内容は変化しない作業"),"-",MATCH(B24,L$11:L$40,0)))) -> 14 | F24: {=IF(E24="-","-",IF(AND(C24<>"",D24>0,INDEX(K$11:K$40,E24)="内容は変化しない作業",AND(E24<>"-",E24<>""),INDEX(I$11:I$40,E24)<>"",INDEX(J$11:J$40,E24)<>""),INDEX(J$11:J$40,E24)-D24,"-"))} -> 0 | H24: 14 | I24: テストストリップ 検品・検数 | J24: 750 | K24: 内容は変化しない作業 | L24: 14 | N24: {=IF(AND(I24<>"",J24>0,K24="内容は変化しない作業",L24>0,INDEX(C$11:C$40,L24)<>"",INDEX(D$11:D$40,L24)<>""),J24-INDEX(D$11:D$40,L24),"-")} -> 0
B25: 15 | C25: アルミ袋 検品・検数 | D25: 75 | E25: =IF(OR(C25="",D25=""),"-",IF(IFERROR(MATCH(B25,L$11:L$40,0),"")="","-",IF(OR(INDEX(I$11:I$40,MATCH(B25,L$11:L$40,0))="",INDEX(J$11:J$40,MATCH(B25,L$11:L$40,0))="",INDEX(K$11:K$40,MATCH(B25,L$11:L$40,0))<>"内容は変化しない作業"),"-",MATCH(B25,L$11:L$40,0)))) -> 15 | F25: {=IF(E25="-","-",IF(AND(C25<>"",D25>0,INDEX(K$11:K$40,E25)="内容は変化しない作業",AND(E25<>"-",E25<>""),INDEX(I$11:I$40,E25)<>"",INDEX(J$11:J$40,E25)<>""),INDEX(J$11:J$40,E25)-D25,"-"))} -> 0 | H25: 15 | I25: アルミ袋 検品・検数 | J25: 75 | K25: 内容は変化しない作業 | L25: 15 | N25: {=IF(AND(I25<>"",J25>0,K25="内容は変化しない作業",L25>0,INDEX(C$11:C$40,L25)<>"",INDEX(D$11:D$40,L25)<>""),J25-INDEX(D$11:D$40,L25),"-")} -> 0
B26: 16 | C26: 乾燥剤 検品・検数（手作業で20個ずつ数える） | D26: 270 | E26: =IF(OR(C26="",D26=""),"-",IF(IFERROR(MATCH(B26,L$11:L$40,0),"")="","-",IF(OR(INDEX(I$11:I$40,MATCH(B26,L$11:L$40,0))="",INDEX(J$11:J$40,MATCH(B26,L$11:L$40,0))="",INDEX(K$11:K$40,MATCH(B26,L$11:L$40,0))<>"内容は変化しない作業"),"-",MATCH(B26,L$11:L$40,0)))) -> - | F26: {=IF(E26="-","-",IF(AND(C26<>"",D26>0,INDEX(K$11:K$40,E26)="内容は変化しない作業",AND(E26<>"-",E26<>""),INDEX(I$11:I$40,E26)<>"",INDEX(J$11:J$40,E26)<>""),INDEX(J$11:J$40,E26)-D26,"-"))} -> - | H26: 16 | I26: アルミ袋に事前印字（印字後に画像検査機で全数検査） | J26: 60 | K26: 新たに追加される作業 | N26: {=IF(AND(I26<>"",J26>0,K26="内容は変化しない作業",L26>0,INDEX(C$11:C$40,L26)<>"",INDEX(D$11:D$40,L26)<>""),J26-INDEX(D$11:D$40,L26),"-")} -> -
B27: 17 | C27: 製造前準備 | D27: 37.5 | E27: =IF(OR(C27="",D27=""),"-",IF(IFERROR(MATCH(B27,L$11:L$40,0),"")="","-",IF(OR(INDEX(I$11:I$40,MATCH(B27,L$11:L$40,0))="",INDEX(J$11:J$40,MATCH(B27,L$11:L$40,0))="",INDEX(K$11:K$40,MATCH(B27,L$11:L$40,0))<>"内容は変化しない作業"),"-",MATCH(B27,L$11:L$40,0)))) -> 17 | F27: {=IF(E27="-","-",IF(AND(C27<>"",D27>0,INDEX(K$11:K$40,E27)="内容は変化しない作業",AND(E27<>"-",E27<>""),INDEX(I$11:I$40,E27)<>"",INDEX(J$11:J$40,E27)<>""),INDEX(J$11:J$40,E27)-D27,"-"))} -> 0 | H27: 17 | I27: 製造前準備 | J27: 37.5 | K27: 内容は変化しない作業 | L27: 17 | N27: {=IF(AND(I27<>"",J27>0,K27="内容は変化しない作業",L27>0,INDEX(C$11:C$40,L27)<>"",INDEX(D$11:D$40,L27)<>""),J27-INDEX(D$11:D$40,L27),"-")} -> 0
B28: 18 | C28: シーラー機 作業前点検 | D28: 7.5 | E28: =IF(OR(C28="",D28=""),"-",IF(IFERROR(MATCH(B28,L$11:L$40,0),"")="","-",IF(OR(INDEX(I$11:I$40,MATCH(B28,L$11:L$40,0))="",INDEX(J$11:J$40,MATCH(B28,L$11:L$40,0))="",INDEX(K$11:K$40,MATCH(B28,L$11:L$40,0))<>"内容は変化しない作業"),"-",MATCH(B28,L$11:L$40,0)))) -> - | F28: {=IF(E28="-","-",IF(AND(C28<>"",D28>0,INDEX(K$11:K$40,E28)="内容は変化しない作業",AND(E28<>"-",E28<>""),INDEX(I$11:I$40,E28)<>"",INDEX(J$11:J$40,E28)<>""),INDEX(J$11:J$40,E28)-D28,"-"))} -> - | H28: 18 | I28: 印字機・半自動機 作業前点検 | J28: 7.5 | K28: 新たに追加される作業 | N28: {=IF(AND(I28<>"",J28>0,K28="内容は変化しない作業",L28>0,INDEX(C$11:C$40,L28)<>"",INDEX(D$11:D$40,L28)<>""),J28-INDEX(D$11:D$40,L28),"-")} -> -
B29: 19 | C29: 手作業：アルミ袋詰め（テスト材・乾燥剤を1組ずつ袋詰め） | D29: 1350 | E29: =IF(OR(C29="",D29=""),"-",IF(IFERROR(MATCH(B29,L$11:L$40,0),"")="","-",IF(OR(INDEX(I$11:I$40,MATCH(B29,L$11:L$40,0))="",INDEX(J$11:J$40,MATCH(B29,L$11:L$40,0))="",INDEX(K$11:K$40,MATCH(B29,L$11:L$40,0))<>"内容は変化しない作業"),"-",MATCH(B29,L$11:L$40,0)))) -> - | F29: {=IF(E29="-","-",IF(AND(C29<>"",D29>0,INDEX(K$11:K$40,E29)="内容は変化しない作業",AND(E29<>"-",E29<>""),INDEX(I$11:I$40,E29)<>"",INDEX(J$11:J$40,E29)<>""),INDEX(J$11:J$40,E29)-D29,"-"))} -> - | H29: 19 | I29: マガジン詰め（アルミ袋・乾燥剤） | J29: 75 | K29: 新たに追加される作業 | N29: {=IF(AND(I29<>"",J29>0,K29="内容は変化しない作業",L29>0,INDEX(C$11:C$40,L29)<>"",INDEX(D$11:D$40,L29)<>""),J29-INDEX(D$11:D$40,L29),"-")} -> -
B30: 20 | C30: 手作業：シール・印字 | D30: 262.5 | E30: =IF(OR(C30="",D30=""),"-",IF(IFERROR(MATCH(B30,L$11:L$40,0),"")="","-",IF(OR(INDEX(I$11:I$40,MATCH(B30,L$11:L$40,0))="",INDEX(J$11:J$40,MATCH(B30,L$11:L$40,0))="",INDEX(K$11:K$40,MATCH(B30,L$11:L$40,0))<>"内容は変化しない作業"),"-",MATCH(B30,L$11:L$40,0)))) -> - | F30: {=IF(E30="-","-",IF(AND(C30<>"",D30>0,INDEX(K$11:K$40,E30)="内容は変化しない作業",AND(E30<>"-",E30<>""),INDEX(I$11:I$40,E30)<>"",INDEX(J$11:J$40,E30)<>""),INDEX(J$11:J$40,E30)-D30,"-"))} -> - | H30: 20 | I30: 装置オペレート・マガジン補充 | J30: 75 | K30: 新たに追加される作業 | N30: {=IF(AND(I30<>"",J30>0,K30="内容は変化しない作業",L30>0,INDEX(C$11:C$40,L30)<>"",INDEX(D$11:D$40,L30)<>""),J30-INDEX(D$11:D$40,L30),"-")} -> -
B31: 21 | C31: 包装品 検品・検数 | D31: 375 | E31: =IF(OR(C31="",D31=""),"-",IF(IFERROR(MATCH(B31,L$11:L$40,0),"")="","-",IF(OR(INDEX(I$11:I$40,MATCH(B31,L$11:L$40,0))="",INDEX(J$11:J$40,MATCH(B31,L$11:L$40,0))="",INDEX(K$11:K$40,MATCH(B31,L$11:L$40,0))<>"内容は変化しない作業"),"-",MATCH(B31,L$11:L$40,0)))) -> 23 | F31: {=IF(E31="-","-",IF(AND(C31<>"",D31>0,INDEX(K$11:K$40,E31)="内容は変化しない作業",AND(E31<>"-",E31<>""),INDEX(I$11:I$40,E31)<>"",INDEX(J$11:J$40,E31)<>""),INDEX(J$11:J$40,E31)-D31,"-"))} -> 0 | H31: 21 | I31: テストストリップ供給 | J31: 135 | K31: 新たに追加される作業 | N31: {=IF(AND(I31<>"",J31>0,K31="内容は変化しない作業",L31>0,INDEX(C$11:C$40,L31)<>"",INDEX(D$11:D$40,L31)<>""),J31-INDEX(D$11:D$40,L31),"-")} -> -
B32: 22 | C32: 清掃・片付け・作業記録作成 | D32: 33 | E32: =IF(OR(C32="",D32=""),"-",IF(IFERROR(MATCH(B32,L$11:L$40,0),"")="","-",IF(OR(INDEX(I$11:I$40,MATCH(B32,L$11:L$40,0))="",INDEX(J$11:J$40,MATCH(B32,L$11:L$40,0))="",INDEX(K$11:K$40,MATCH(B32,L$11:L$40,0))<>"内容は変化しない作業"),"-",MATCH(B32,L$11:L$40,0)))) -> 24 | F32: {=IF(E32="-","-",IF(AND(C32<>"",D32>0,INDEX(K$11:K$40,E32)="内容は変化しない作業",AND(E32<>"-",E32<>""),INDEX(I$11:I$40,E32)<>"",INDEX(J$11:J$40,E32)<>""),INDEX(J$11:J$40,E32)-D32,"-"))} -> 0 | H32: 22 | I32: 包装品排出口（取り出し・立ち合い） | J32: 105 | K32: 新たに追加される作業 | N32: {=IF(AND(I32<>"",J32>0,K32="内容は変化しない作業",L32>0,INDEX(C$11:C$40,L32)<>"",INDEX(D$11:D$40,L32)<>""),J32-INDEX(D$11:D$40,L32),"-")} -> -
B33: 23 | E33: =IF(OR(C33="",D33=""),"-",IF(IFERROR(MATCH(B33,L$11:L$40,0),"")="","-",IF(OR(INDEX(I$11:I$40,MATCH(B33,L$11:L$40,0))="",INDEX(J$11:J$40,MATCH(B33,L$11:L$40,0))="",INDEX(K$11:K$40,MATCH(B33,L$11:L$40,0))<>"内容は変化しない作業"),"-",MATCH(B33,L$11:L$40,0)))) -> - | F33: {=IF(E33="-","-",IF(AND(C33<>"",D33>0,INDEX(K$11:K$40,E33)="内容は変化しない作業",AND(E33<>"-",E33<>""),INDEX(I$11:I$40,E33)<>"",INDEX(J$11:J$40,E33)<>""),INDEX(J$11:J$40,E33)-D33,"-"))} -> - | H33: 23 | I33: 包装品 検品・検数 | J33: 375 | K33: 内容は変化しない作業 | L33: 21 | N33: {=IF(AND(I33<>"",J33>0,K33="内容は変化しない作業",L33>0,INDEX(C$11:C$40,L33)<>"",INDEX(D$11:D$40,L33)<>""),J33-INDEX(D$11:D$40,L33),"-")} -> 0
B34: 24 | E34: =IF(OR(C34="",D34=""),"-",IF(IFERROR(MATCH(B34,L$11:L$40,0),"")="","-",IF(OR(INDEX(I$11:I$40,MATCH(B34,L$11:L$40,0))="",INDEX(J$11:J$40,MATCH(B34,L$11:L$40,0))="",INDEX(K$11:K$40,MATCH(B34,L$11:L$40,0))<>"内容は変化しない作業"),"-",MATCH(B34,L$11:L$40,0)))) -> - | F34: {=IF(E34="-","-",IF(AND(C34<>"",D34>0,INDEX(K$11:K$40,E34)="内容は変化しない作業",AND(E34<>"-",E34<>""),INDEX(I$11:I$40,E34)<>"",INDEX(J$11:J$40,E34)<>""),INDEX(J$11:J$40,E34)-D34,"-"))} -> - | H34: 24 | I34: 清掃・片付け・作業記録作成 | J34: 33 | K34: 内容は変化しない作業 | L34: 22 | N34: {=IF(AND(I34<>"",J34>0,K34="内容は変化しない作業",L34>0,INDEX(C$11:C$40,L34)<>"",INDEX(D$11:D$40,L34)<>""),J34-INDEX(D$11:D$40,L34),"-")} -> 0
B35: 25 | E35: =IF(OR(C35="",D35=""),"-",IF(IFERROR(MATCH(B35,L$11:L$40,0),"")="","-",IF(OR(INDEX(I$11:I$40,MATCH(B35,L$11:L$40,0))="",INDEX(J$11:J$40,MATCH(B35,L$11:L$40,0))="",INDEX(K$11:K$40,MATCH(B35,L$11:L$40,0))<>"内容は変化しない作業"),"-",MATCH(B35,L$11:L$40,0)))) -> - | F35: {=IF(E35="-","-",IF(AND(C35<>"",D35>0,INDEX(K$11:K$40,E35)="内容は変化しない作業",AND(E35<>"-",E35<>""),INDEX(I$11:I$40,E35)<>"",INDEX(J$11:J$40,E35)<>""),INDEX(J$11:J$40,E35)-D35,"-"))} -> - | H35: 25 | N35: {=IF(AND(I35<>"",J35>0,K35="内容は変化しない作業",L35>0,INDEX(C$11:C$40,L35)<>"",INDEX(D$11:D$40,L35)<>""),J35-INDEX(D$11:D$40,L35),"-")} -> -
B36: 26 | E36: =IF(OR(C36="",D36=""),"-",IF(IFERROR(MATCH(B36,L$11:L$40,0),"")="","-",IF(OR(INDEX(I$11:I$40,MATCH(B36,L$11:L$40,0))="",INDEX(J$11:J$40,MATCH(B36,L$11:L$40,0))="",INDEX(K$11:K$40,MATCH(B36,L$11:L$40,0))<>"内容は変化しない作業"),"-",MATCH(B36,L$11:L$40,0)))) -> - | F36: {=IF(E36="-","-",IF(AND(C36<>"",D36>0,INDEX(K$11:K$40,E36)="内容は変化しない作業",AND(E36<>"-",E36<>""),INDEX(I$11:I$40,E36)<>"",INDEX(J$11:J$40,E36)<>""),INDEX(J$11:J$40,E36)-D36,"-"))} -> - | H36: 26 | N36: {=IF(AND(I36<>"",J36>0,K36="内容は変化しない作業",L36>0,INDEX(C$11:C$40,L36)<>"",INDEX(D$11:D$40,L36)<>""),J36-INDEX(D$11:D$40,L36),"-")} -> -
B37: 27 | E37: =IF(OR(C37="",D37=""),"-",IF(IFERROR(MATCH(B37,L$11:L$40,0),"")="","-",IF(OR(INDEX(I$11:I$40,MATCH(B37,L$11:L$40,0))="",INDEX(J$11:J$40,MATCH(B37,L$11:L$40,0))="",INDEX(K$11:K$40,MATCH(B37,L$11:L$40,0))<>"内容は変化しない作業"),"-",MATCH(B37,L$11:L$40,0)))) -> - | F37: {=IF(E37="-","-",IF(AND(C37<>"",D37>0,INDEX(K$11:K$40,E37)="内容は変化しない作業",AND(E37<>"-",E37<>""),INDEX(I$11:I$40,E37)<>"",INDEX(J$11:J$40,E37)<>""),INDEX(J$11:J$40,E37)-D37,"-"))} -> - | H37: 27 | N37: {=IF(AND(I37<>"",J37>0,K37="内容は変化しない作業",L37>0,INDEX(C$11:C$40,L37)<>"",INDEX(D$11:D$40,L37)<>""),J37-INDEX(D$11:D$40,L37),"-")} -> -
B38: 28 | E38: =IF(OR(C38="",D38=""),"-",IF(IFERROR(MATCH(B38,L$11:L$40,0),"")="","-",IF(OR(INDEX(I$11:I$40,MATCH(B38,L$11:L$40,0))="",INDEX(J$11:J$40,MATCH(B38,L$11:L$40,0))="",INDEX(K$11:K$40,MATCH(B38,L$11:L$40,0))<>"内容は変化しない作業"),"-",MATCH(B38,L$11:L$40,0)))) -> - | F38: {=IF(E38="-","-",IF(AND(C38<>"",D38>0,INDEX(K$11:K$40,E38)="内容は変化しない作業",AND(E38<>"-",E38<>""),INDEX(I$11:I$40,E38)<>"",INDEX(J$11:J$40,E38)<>""),INDEX(J$11:J$40,E38)-D38,"-"))} -> - | H38: 28 | N38: {=IF(AND(I38<>"",J38>0,K38="内容は変化しない作業",L38>0,INDEX(C$11:C$40,L38)<>"",INDEX(D$11:D$40,L38)<>""),J38-INDEX(D$11:D$40,L38),"-")} -> -
B39: 29 | E39: =IF(OR(C39="",D39=""),"-",IF(IFERROR(MATCH(B39,L$11:L$40,0),"")="","-",IF(OR(INDEX(I$11:I$40,MATCH(B39,L$11:L$40,0))="",INDEX(J$11:J$40,MATCH(B39,L$11:L$40,0))="",INDEX(K$11:K$40,MATCH(B39,L$11:L$40,0))<>"内容は変化しない作業"),"-",MATCH(B39,L$11:L$40,0)))) -> - | F39: {=IF(E39="-","-",IF(AND(C39<>"",D39>0,INDEX(K$11:K$40,E39)="内容は変化しない作業",AND(E39<>"-",E39<>""),INDEX(I$11:I$40,E39)<>"",INDEX(J$11:J$40,E39)<>""),INDEX(J$11:J$40,E39)-D39,"-"))} -> - | H39: 29 | N39: {=IF(AND(I39<>"",J39>0,K39="内容は変化しない作業",L39>0,INDEX(C$11:C$40,L39)<>"",INDEX(D$11:D$40,L39)<>""),J39-INDEX(D$11:D$40,L39),"-")} -> -
B40: 30 | E40: =IF(OR(C40="",D40=""),"-",IF(IFERROR(MATCH(B40,L$11:L$40,0),"")="","-",IF(OR(INDEX(I$11:I$40,MATCH(B40,L$11:L$40,0))="",INDEX(J$11:J$40,MATCH(B40,L$11:L$40,0))="",INDEX(K$11:K$40,MATCH(B40,L$11:L$40,0))<>"内容は変化しない作業"),"-",MATCH(B40,L$11:L$40,0)))) -> - | F40: {=IF(E40="-","-",IF(AND(C40<>"",D40>0,INDEX(K$11:K$40,E40)="内容は変化しない作業",AND(E40<>"-",E40<>""),INDEX(I$11:I$40,E40)<>"",INDEX(J$11:J$40,E40)<>""),INDEX(J$11:J$40,E40)-D40,"-"))} -> - | H40: 30 | N40: {=IF(AND(I40<>"",J40>0,K40="内容は変化しない作業",L40>0,INDEX(C$11:C$40,L40)<>"",INDEX(D$11:D$40,L40)<>""),J40-INDEX(D$11:D$40,L40),"-")} -> -

Sheet （別紙２）省力化業務プロセス図
B1: （別紙２）省力化業務プロセス図 ※（別紙1）で入れた業務プロセス・作業工程がフロー図として表示されます。
O3: 省力化指数 | S3: ='（別紙１）省力化計算シート'!M3 -> 0.85769231
C5: ■設備導入前の業務プロセス・作業工程 （BEFORE） | O5: 設備導入による削減時間 | S5: ='（別紙１）省力化計算シート'!D3 -> 162.5 | T5: 時間
C8: ='（別紙１）省力化計算シート'!C11 -> ラミネート位置移動 | E8: > | G8: ='（別紙１）省力化計算シート'!C12 -> ラミネート準備 | I8: > | K8: ='（別紙１）省力化計算シート'!C13 -> 短冊ラミネート作業（5mm幅・約12,500本にカット） | M8: > | O8: ='（別紙１）省力化計算シート'!C14 -> ラミネート片付け・記録作成 | Q8: > | S8: ='（別紙１）省力化計算シート'!C15 -> ストリップ検品・検数（短冊を1本ずつ検品） | U8: > | X8: 削減される作業
C9: =IF('（別紙１）省力化計算シート'!D11="","",IF(OR('（別紙１）省力化計算シート'!F11="-",'（別紙１）省力化計算シート'!F11=0),'（別紙１）省力化計算シート'!D11&"分",'（別紙１）省力化計算シート'!D11&"分"&" (→"&'（別紙１）省力化計算シート'!D11+'（別紙１）省力化計算シート'!F11&"分）")) -> 45分 | G9: =IF('（別紙１）省力化計算シート'!D12="","",IF(OR('（別紙１）省力化計算シート'!F12="-",'（別紙１）省力化計算シート'!F12=0),'（別紙１）省力化計算シート'!D12&"分",'（別紙１）省力化計算シート'!D12&"分"&" (→"&'（別紙１）省力化計算シート'!D12+'（別紙１）省力化計算シート'!F12&"分）")) -> 30分 | K9: =IF('（別紙１）省力化計算シート'!D13="","",IF(OR('（別紙１）省力化計算シート'!F13="-",'（別紙１）省力化計算シート'!F13=0),'（別紙１）省力化計算シート'!D13&"分",'（別紙１）省力化計算シート'!D13&"分"&" (→"&'（別紙１）省力化計算シート'!D13+'（別紙１）省力化計算シート'!F13&"分）")) -> 150分 | O9: =IF('（別紙１）省力化計算シート'!D14="","",IF(OR('（別紙１）省力化計算シート'!F14="-",'（別紙１）省力化計算シート'!F14=0),'（別紙１）省力化計算シート'!D14&"分",'（別紙１）省力化計算シート'!D14&"分"&" (→"&'（別紙１）省力化計算シート'!D14+'（別紙１）省力化計算シート'!F14&"分）")) -> 45分 | S9: =IF('（別紙１）省力化計算シート'!D15="","",IF(OR('（別紙１）省力化計算シート'!F15="-",'（別紙１）省力化計算シート'!F15=0),'（別紙１）省力化計算シート'!D15&"分",'（別紙１）省力化計算シート'!D15&"分"&" (→"&'（別紙１）省力化計算シート'!D15+'（別紙１）省力化計算シート'!F15&"分）")) -> 1950分
X11: 時間が削減される作業
C15: ='（別紙１）省力化計算シート'!C16 -> 嵌合・検品・照合（手作業でハウジングを嵌合） | E15: > | G15: ='（別紙１）省力化計算シート'!C17 -> ピロー包装機 段取り替え | I15: > | K15: ='（別紙１）省力化計算シート'!C18 -> ピロー包装（既存機への手供給・立ち合い） | M15: > | O15: ='（別紙１）省力化計算シート'!C19 -> ピロー包装品 検品・帯掛 | Q15: > | S15: ='（別紙１）省力化計算シート'!C20 -> 箱詰め | U15: > | X15: 導入前後で同様の作業
C16: =IF('（別紙１）省力化計算シート'!D16="","",IF(OR('（別紙１）省力化計算シート'!F16="-",'（別紙１）省力化計算シート'!F16=0),'（別紙１）省力化計算シート'!D16&"分",'（別紙１）省力化計算シート'!D16&"分"&" (→"&'（別紙１）省力化計算シート'!D16+'（別紙１）省力化計算シート'!F16&"分）")) -> 3000分 | G16: =IF('（別紙１）省力化計算シート'!D17="","",IF(OR('（別紙１）省力化計算シート'!F17="-",'（別紙１）省力化計算シート'!F17=0),'（別紙１）省力化計算シート'!D17&"分",'（別紙１）省力化計算シート'!D17&"分"&" (→"&'（別紙１）省力化計算シート'!D17+'（別紙１）省力化計算シート'!F17&"分）")) -> 45分 | K16: =IF('（別紙１）省力化計算シート'!D18="","",IF(OR('（別紙１）省力化計算シート'!F18="-",'（別紙１）省力化計算シート'!F18=0),'（別紙１）省力化計算シート'!D18&"分",'（別紙１）省力化計算シート'!D18&"分"&" (→"&'（別紙１）省力化計算シート'!D18+'（別紙１）省力化計算シート'!F18&"分）")) -> 1350分 | O16: =IF('（別紙１）省力化計算シート'!D19="","",IF(OR('（別紙１）省力化計算シート'!F19="-",'（別紙１）省力化計算シート'!F19=0),'（別紙１）省力化計算シート'!D19&"分",'（別紙１）省力化計算シート'!D19&"分"&" (→"&'（別紙１）省力化計算シート'!D19+'（別紙１）省力化計算シート'!F19&"分）")) -> 1950分 (→540分） | S16: =IF('（別紙１）省力化計算シート'!D20="","",IF(OR('（別紙１）省力化計算シート'!F20="-",'（別紙１）省力化計算シート'!F20=0),'（別紙１）省力化計算シート'!D20&"分",'（別紙１）省力化計算シート'!D20&"分"&" (→"&'（別紙１）省力化計算シート'!D20+'（別紙１）省力化計算シート'!F20&"分）")) -> 300分
X17: 作業内容の説明 入力欄
C22: ='（別紙１）省力化計算シート'!C21 -> 0 | E22: > | G22: ='（別紙１）省力化計算シート'!C22 -> 0 | I22: > | K22: ='（別紙１）省力化計算シート'!C23 -> 0 | M22: > | O22: ='（別紙１）省力化計算シート'!C24 -> テストストリップ 検品・検数 | Q22: > | S22: ='（別紙１）省力化計算シート'!C25 -> アルミ袋 検品・検数 | U22: >
C23: =IF('（別紙１）省力化計算シート'!D21="","",IF(OR('（別紙１）省力化計算シート'!F21="-",'（別紙１）省力化計算シート'!F21=0),'（別紙１）省力化計算シート'!D21&"分",'（別紙１）省力化計算シート'!D21&"分"&" (→"&'（別紙１）省力化計算シート'!D21+'（別紙１）省力化計算シート'!F21&"分）")) | G23: =IF('（別紙１）省力化計算シート'!D22="","",IF(OR('（別紙１）省力化計算シート'!F22="-",'（別紙１）省力化計算シート'!F22=0),'（別紙１）省力化計算シート'!D22&"分",'（別紙１）省力化計算シート'!D22&"分"&" (→"&'（別紙１）省力化計算シート'!D22+'（別紙１）省力化計算シート'!F22&"分）")) | K23: =IF('（別紙１）省力化計算シート'!D23="","",IF(OR('（別紙１）省力化計算シート'!F23="-",'（別紙１）省力化計算シート'!F23=0),'（別紙１）省力化計算シート'!D23&"分",'（別紙１）省力化計算シート'!D23&"分"&" (→"&'（別紙１）省力化計算シート'!D23+'（別紙１）省力化計算シート'!F23&"分）")) | O23: =IF('（別紙１）省力化計算シート'!D24="","",IF(OR('（別紙１）省力化計算シート'!F24="-",'（別紙１）省力化計算シート'!F24=0),'（別紙１）省力化計算シート'!D24&"分",'（別紙１）省力化計算シート'!D24&"分"&" (→"&'（別紙１）省力化計算シート'!D24+'（別紙１）省力化計算シート'!F24&"分）")) -> 750分 | S23: =IF('（別紙１）省力化計算シート'!D25="","",IF(OR('（別紙１）省力化計算シート'!F25="-",'（別紙１）省力化計算シート'!F25=0),'（別紙１）省力化計算シート'!D25&"分",'（別紙１）省力化計算シート'!D25&"分"&" (→"&'（別紙１）省力化計算シート'!D25+'（別紙１）省力化計算シート'!F25&"分）")) -> 75分
C29: ='（別紙１）省力化計算シート'!C26 -> 乾燥剤 検品・検数（手作業で20個ずつ数える） | E29: > | G29: ='（別紙１）省力化計算シート'!C27 -> 製造前準備 | I29: > | K29: ='（別紙１）省力化計算シート'!C28 -> シーラー機 作業前点検 | M29: > | O29: ='（別紙１）省力化計算シート'!C29 -> 手作業：アルミ袋詰め（テスト材・乾燥剤を1組ずつ袋詰め） | Q29: > | S29: ='（別紙１）省力化計算シート'!C30 -> 手作業：シール・印字 | U29: >
C30: =IF('（別紙１）省力化計算シート'!D26="","",IF(OR('（別紙１）省力化計算シート'!F26="-",'（別紙１）省力化計算シート'!F26=0),'（別紙１）省力化計算シート'!D26&"分",'（別紙１）省力化計算シート'!D26&"分"&" (→"&'（別紙１）省力化計算シート'!D26+'（別紙１）省力化計算シート'!F26&"分）")) -> 270分 | G30: =IF('（別紙１）省力化計算シート'!D27="","",IF(OR('（別紙１）省力化計算シート'!F27="-",'（別紙１）省力化計算シート'!F27=0),'（別紙１）省力化計算シート'!D27&"分",'（別紙１）省力化計算シート'!D27&"分"&" (→"&'（別紙１）省力化計算シート'!D27+'（別紙１）省力化計算シート'!F27&"分）")) -> 37.5分 | K30: =IF('（別紙１）省力化計算シート'!D28="","",IF(OR('（別紙１）省力化計算シート'!F28="-",'（別紙１）省力化計算シート'!F28=0),'（別紙１）省力化計算シート'!D28&"分",'（別紙１）省力化計算シート'!D28&"分"&" (→"&'（別紙１）省力化計算シート'!D28+'（別紙１）省力化計算シート'!F28&"分）")) -> 7.5分 | O30: =IF('（別紙１）省力化計算シート'!D29="","",IF(OR('（別紙１）省力化計算シート'!F29="-",'（別紙１）省力化計算シート'!F29=0),'（別紙１）省力化計算シート'!D29&"分",'（別紙１）省力化計算シート'!D29&"分"&" (→"&'（別紙１）省力化計算シート'!D29+'（別紙１）省力化計算シート'!F29&"分）")) -> 1350分 | S30: =IF('（別紙１）省力化計算シート'!D30="","",IF(OR('（別紙１）省力化計算シート'!F30="-",'（別紙１）省力化計算シート'!F30=0),'（別紙１）省力化計算シート'!D30&"分",'（別紙１）省力化計算シート'!D30&"分"&" (→"&'（別紙１）省力化計算シート'!D30+'（別紙１）省力化計算シート'!F30&"分）")) -> 262.5分
C36: ='（別紙１）省力化計算シート'!C31 -> 包装品 検品・検数 | E36: > | G36: ='（別紙１）省力化計算シート'!C32 -> 清掃・片付け・作業記録作成 | I36: > | K36: ='（別紙１）省力化計算シート'!C33 -> 0 | M36: > | O36: ='（別紙１）省力化計算シート'!C34 -> 0 | Q36: > | S36: ='（別紙１）省力化計算シート'!C35 -> 0 | U36: >
C37: =IF('（別紙１）省力化計算シート'!D31="","",IF(OR('（別紙１）省力化計算シート'!F31="-",'（別紙１）省力化計算シート'!F31=0),'（別紙１）省力化計算シート'!D31&"分",'（別紙１）省力化計算シート'!D31&"分"&" (→"&'（別紙１）省力化計算シート'!D31+'（別紙１）省力化計算シート'!F31&"分）")) -> 375分 | G37: =IF('（別紙１）省力化計算シート'!D32="","",IF(OR('（別紙１）省力化計算シート'!F32="-",'（別紙１）省力化計算シート'!F32=0),'（別紙１）省力化計算シート'!D32&"分",'（別紙１）省力化計算シート'!D32&"分"&" (→"&'（別紙１）省力化計算シート'!D32+'（別紙１）省力化計算シート'!F32&"分）")) -> 33分 | K37: =IF('（別紙１）省力化計算シート'!D33="","",IF(OR('（別紙１）省力化計算シート'!F33="-",'（別紙１）省力化計算シート'!F33=0),'（別紙１）省力化計算シート'!D33&"分",'（別紙１）省力化計算シート'!D33&"分"&" (→"&'（別紙１）省力化計算シート'!D33+'（別紙１）省力化計算シート'!F33&"分）")) | O37: =IF('（別紙１）省力化計算シート'!D34="","",IF(OR('（別紙１）省力化計算シート'!F34="-",'（別紙１）省力化計算シート'!F34=0),'（別紙１）省力化計算シート'!D34&"分",'（別紙１）省力化計算シート'!D34&"分"&" (→"&'（別紙１）省力化計算シート'!D34+'（別紙１）省力化計算シート'!F34&"分）")) | S37: =IF('（別紙１）省力化計算シート'!D35="","",IF(OR('（別紙１）省力化計算シート'!F35="-",'（別紙１）省力化計算シート'!F35=0),'（別紙１）省力化計算シート'!D35&"分",'（別紙１）省力化計算シート'!D35&"分"&" (→"&'（別紙１）省力化計算シート'!D35+'（別紙１）省力化計算シート'!F35&"分）"))
C43: ='（別紙１）省力化計算シート'!C36 -> 0 | E43: > | G43: ='（別紙１）省力化計算シート'!C37 -> 0 | I43: > | K43: ='（別紙１）省力化計算シート'!C38 -> 0 | M43: > | O43: ='（別紙１）省力化計算シート'!C39 -> 0 | Q43: > | S43: ='（別紙１）省力化計算シート'!C40 -> 0
C44: =IF('（別紙１）省力化計算シート'!D36="","",IF(OR('（別紙１）省力化計算シート'!F36="-",'（別紙１）省力化計算シート'!F36=0),'（別紙１）省力化計算シート'!D36&"分",'（別紙１）省力化計算シート'!D36&"分"&" (→"&'（別紙１）省力化計算シート'!D36+'（別紙１）省力化計算シート'!F36&"分）")) | G44: =IF('（別紙１）省力化計算シート'!D37="","",IF(OR('（別紙１）省力化計算シート'!F37="-",'（別紙１）省力化計算シート'!F37=0),'（別紙１）省力化計算シート'!D37&"分",'（別紙１）省力化計算シート'!D37&"分"&" (→"&'（別紙１）省力化計算シート'!D37+'（別紙１）省力化計算シート'!F37&"分）")) | K44: =IF('（別紙１）省力化計算シート'!D38="","",IF(OR('（別紙１）省力化計算シート'!F38="-",'（別紙１）省力化計算シート'!F38=0),'（別紙１）省力化計算シート'!D38&"分",'（別紙１）省力化計算シート'!D38&"分"&" (→"&'（別紙１）省力化計算シート'!D38+'（別紙１）省力化計算シート'!F38&"分）")) | O44: =IF('（別紙１）省力化計算シート'!D39="","",IF(OR('（別紙１）省力化計算シート'!F39="-",'（別紙１）省力化計算シート'!F39=0),'（別紙１）省力化計算シート'!D39&"分",'（別紙１）省力化計算シート'!D39&"分"&" (→"&'（別紙１）省力化計算シート'!D39+'（別紙１）省力化計算シート'!F39&"分）")) | S44: =IF('（別紙１）省力化計算シート'!D40="","",IF(OR('（別紙１）省力化計算シート'!F40="-",'（別紙１）省力化計算シート'!F40=0),'（別紙１）省力化計算シート'!D40&"分",'（別紙１）省力化計算シート'!D40&"分"&" (→"&'（別紙１）省力化計算シート'!D40+'（別紙１）省力化計算シート'!F40&"分）"))
A48: =IF(COUNTA('（別紙１）省力化計算シート'!C26:C40)<>0,"← 非表示エリアに記載があります。[＋]をクリックして表示してください。[-]の場合は、すべて表示されています。","") -> ← 非表示エリアに記載があります。[＋]をクリックして表示してください。[-]の場合は、すべて表示されています。
C50: ■設備導入後の業務プロセス・作業工程 （AFTER） | O50: 設備導入による増加時間 | S50: ='（別紙１）省力化計算シート'!J3 -> 23.125 | T50: 時間
C53: ='（別紙１）省力化計算シート'!I11 -> ラミネート位置移動 | E53: > | G53: ='（別紙１）省力化計算シート'!I12 -> ラミネート準備 | I53: > | K53: ='（別紙１）省力化計算シート'!I13 -> シートラミネート作業（50cm幅にカット・カット回数減） | M53: > | O53: ='（別紙１）省力化計算シート'!I14 -> ラミネート片付け・記録作成 | Q53: > | S53: ='（別紙１）省力化計算シート'!I15 -> シート検品（シートラミネートの検品） | U53: > | X53: 新たに追加される作業
C54: =IF('（別紙１）省力化計算シート'!J11="","",IF(OR('（別紙１）省力化計算シート'!N11="-",'（別紙１）省力化計算シート'!N11=0),'（別紙１）省力化計算シート'!J11&"分","("&'（別紙１）省力化計算シート'!J11-'（別紙１）省力化計算シート'!N11&"分→）"&'（別紙１）省力化計算シート'!J11&"分")) -> 45分 | G54: =IF('（別紙１）省力化計算シート'!J12="","",IF(OR('（別紙１）省力化計算シート'!N12="-",'（別紙１）省力化計算シート'!N12=0),'（別紙１）省力化計算シート'!J12&"分","("&'（別紙１）省力化計算シート'!J12-'（別紙１）省力化計算シート'!N12&"分→）"&'（別紙１）省力化計算シート'!J12&"分")) -> 30分 | K54: =IF('（別紙１）省力化計算シート'!J13="","",IF(OR('（別紙１）省力化計算シート'!N13="-",'（別紙１）省力化計算シート'!N13=0),'（別紙１）省力化計算シート'!J13&"分","("&'（別紙１）省力化計算シート'!J13-'（別紙１）省力化計算シート'!N13&"分→）"&'（別紙１）省力化計算シート'!J13&"分")) -> 90分 | O54: =IF('（別紙１）省力化計算シート'!J14="","",IF(OR('（別紙１）省力化計算シート'!N14="-",'（別紙１）省力化計算シート'!N14=0),'（別紙１）省力化計算シート'!J14&"分","("&'（別紙１）省力化計算シート'!J14-'（別紙１）省力化計算シート'!N14&"分→）"&'（別紙１）省力化計算シート'!J14&"分")) -> 45分 | S54: =IF('（別紙１）省力化計算シート'!J15="","",IF(OR('（別紙１）省力化計算シート'!N15="-",'（別紙１）省力化計算シート'!N15=0),'（別紙１）省力化計算シート'!J15&"分","("&'（別紙１）省力化計算シート'!J15-'（別紙１）省力化計算シート'!N15&"分→）"&'（別紙１）省力化計算シート'!J15&"分")) -> 60分
X56: 時間が増加する作業
C60: ='（別紙１）省力化計算シート'!I16 -> 嵌合機 段取り替え（部品交換・仕様変更） | E60: > | G60: ='（別紙１）省力化計算シート'!I17 -> アセンブラー オペレート（シート供給・マガジン交換） | I60: > | K60: ='（別紙１）省力化計算シート'!I18 -> ケース検品・マガジン詰め・帯掛 | M60: > | O60: ='（別紙１）省力化計算シート'!I19 -> 補充（ケース・ストリップ）・帯掛 | Q60: > | S60: ='（別紙１）省力化計算シート'!I20 -> ピロー包装機 段取り替え | U60: > | X60: 導入前後で同様の作業
C61: =IF('（別紙１）省力化計算シート'!J16="","",IF(OR('（別紙１）省力化計算シート'!N16="-",'（別紙１）省力化計算シート'!N16=0),'（別紙１）省力化計算シート'!J16&"分","("&'（別紙１）省力化計算シート'!J16-'（別紙１）省力化計算シート'!N16&"分→）"&'（別紙１）省力化計算シート'!J16&"分")) -> 90分 | G61: =IF('（別紙１）省力化計算シート'!J17="","",IF(OR('（別紙１）省力化計算シート'!N17="-",'（別紙１）省力化計算シート'!N17=0),'（別紙１）省力化計算シート'!J17&"分","("&'（別紙１）省力化計算シート'!J17-'（別紙１）省力化計算シート'!N17&"分→）"&'（別紙１）省力化計算シート'!J17&"分")) -> 195分 | K61: =IF('（別紙１）省力化計算シート'!J18="","",IF(OR('（別紙１）省力化計算シート'!N18="-",'（別紙１）省力化計算シート'!N18=0),'（別紙１）省力化計算シート'!J18&"分","("&'（別紙１）省力化計算シート'!J18-'（別紙１）省力化計算シート'!N18&"分→）"&'（別紙１）省力化計算シート'!J18&"分")) -> 330分 | O61: =IF('（別紙１）省力化計算シート'!J19="","",IF(OR('（別紙１）省力化計算シート'!N19="-",'（別紙１）省力化計算シート'!N19=0),'（別紙１）省力化計算シート'!J19&"分","("&'（別紙１）省力化計算シート'!J19-'（別紙１）省力化計算シート'!N19&"分→）"&'（別紙１）省力化計算シート'!J19&"分")) -> 165分 | S61: =IF('（別紙１）省力化計算シート'!J20="","",IF(OR('（別紙１）省力化計算シート'!N20="-",'（別紙１）省力化計算シート'!N20=0),'（別紙１）省力化計算シート'!J20&"分","("&'（別紙１）省力化計算シート'!J20-'（別紙１）省力化計算シート'!N20&"分→）"&'（別紙１）省力化計算シート'!J20&"分")) -> 45分
X62: 作業内容の説明 入力欄
C67: ='（別紙１）省力化計算シート'!I21 -> ピロー包装品 検品・帯掛 | E67: > | G67: ='（別紙１）省力化計算シート'!I22 -> 箱詰め | I67: > | K67: ='（別紙１）省力化計算シート'!I23 -> 0 | M67: > | O67: ='（別紙１）省力化計算シート'!I24 -> テストストリップ 検品・検数 | Q67: > | S67: ='（別紙１）省力化計算シート'!I25 -> アルミ袋 検品・検数 | U67: >
C68: =IF('（別紙１）省力化計算シート'!J21="","",IF(OR('（別紙１）省力化計算シート'!N21="-",'（別紙１）省力化計算シート'!N21=0),'（別紙１）省力化計算シート'!J21&"分","("&'（別紙１）省力化計算シート'!J21-'（別紙１）省力化計算シート'!N21&"分→）"&'（別紙１）省力化計算シート'!J21&"分")) -> (1950分→）540分 | G68: =IF('（別紙１）省力化計算シート'!J22="","",IF(OR('（別紙１）省力化計算シート'!N22="-",'（別紙１）省力化計算シート'!N22=0),'（別紙１）省力化計算シート'!J22&"分","("&'（別紙１）省力化計算シート'!J22-'（別紙１）省力化計算シート'!N22&"分→）"&'（別紙１）省力化計算シート'!J22&"分")) -> 300分 | K68: =IF('（別紙１）省力化計算シート'!J23="","",IF(OR('（別紙１）省力化計算シート'!N23="-",'（別紙１）省力化計算シート'!N23=0),'（別紙１）省力化計算シート'!J23&"分","("&'（別紙１）省力化計算シート'!J23-'（別紙１）省力化計算シート'!N23&"分→）"&'（別紙１）省力化計算シート'!J23&"分")) | O68: =IF('（別紙１）省力化計算シート'!J24="","",IF(OR('（別紙１）省力化計算シート'!N24="-",'（別紙１）省力化計算シート'!N24=0),'（別紙１）省力化計算シート'!J24&"分","("&'（別紙１）省力化計算シート'!J24-'（別紙１）省力化計算シート'!N24&"分→）"&'（別紙１）省力化計算シート'!J24&"分")) -> 750分 | S68: =IF('（別紙１）省力化計算シート'!J25="","",IF(OR('（別紙１）省力化計算シート'!N25="-",'（別紙１）省力化計算シート'!N25=0),'（別紙１）省力化計算シート'!J25&"分","("&'（別紙１）省力化計算シート'!J25-'（別紙１）省力化計算シート'!N25&"分→）"&'（別紙１）省力化計算シート'!J25&"分")) -> 75分
C74: ='（別紙１）省力化計算シート'!I26 -> アルミ袋に事前印字（印字後に画像検査機で全数検査） | E74: > | G74: ='（別紙１）省力化計算シート'!I27 -> 製造前準備 | I74: > | K74: ='（別紙１）省力化計算シート'!I28 -> 印字機・半自動機 作業前点検 | M74: > | O74: ='（別紙１）省力化計算シート'!I29 -> マガジン詰め（アルミ袋・乾燥剤） | Q74: > | S74: ='（別紙１）省力化計算シート'!I30 -> 装置オペレート・マガジン補充 | U74: >
C75: =IF('（別紙１）省力化計算シート'!J26="","",IF(OR('（別紙１）省力化計算シート'!N26="-",'（別紙１）省力化計算シート'!N26=0),'（別紙１）省力化計算シート'!J26&"分","("&'（別紙１）省力化計算シート'!J26-'（別紙１）省力化計算シート'!N26&"分→）"&'（別紙１）省力化計算シート'!J26&"分")) -> 60分 | G75: =IF('（別紙１）省力化計算シート'!J27="","",IF(OR('（別紙１）省力化計算シート'!N27="-",'（別紙１）省力化計算シート'!N27=0),'（別紙１）省力化計算シート'!J27&"分","("&'（別紙１）省力化計算シート'!J27-'（別紙１）省力化計算シート'!N27&"分→）"&'（別紙１）省力化計算シート'!J27&"分")) -> 37.5分 | K75: =IF('（別紙１）省力化計算シート'!J28="","",IF(OR('（別紙１）省力化計算シート'!N28="-",'（別紙１）省力化計算シート'!N28=0),'（別紙１）省力化計算シート'!J28&"分","("&'（別紙１）省力化計算シート'!J28-'（別紙１）省力化計算シート'!N28&"分→）"&'（別紙１）省力化計算シート'!J28&"分")) -> 7.5分 | O75: =IF('（別紙１）省力化計算シート'!J29="","",IF(OR('（別紙１）省力化計算シート'!N29="-",'（別紙１）省力化計算シート'!N29=0),'（別紙１）省力化計算シート'!J29&"分","("&'（別紙１）省力化計算シート'!J29-'（別紙１）省力化計算シート'!N29&"分→）"&'（別紙１）省力化計算シート'!J29&"分")) -> 75分 | S75: =IF('（別紙１）省力化計算シート'!J30="","",IF(OR('（別紙１）省力化計算シート'!N30="-",'（別紙１）省力化計算シート'!N30=0),'（別紙１）省力化計算シート'!J30&"分","("&'（別紙１）省力化計算シート'!J30-'（別紙１）省力化計算シート'!N30&"分→）"&'（別紙１）省力化計算シート'!J30&"分")) -> 75分
C81: ='（別紙１）省力化計算シート'!I31 -> テストストリップ供給 | E81: > | G81: ='（別紙１）省力化計算シート'!I32 -> 包装品排出口（取り出し・立ち合い） | I81: > | K81: ='（別紙１）省力化計算シート'!I33 -> 包装品 検品・検数 | M81: > | O81: ='（別紙１）省力化計算シート'!I34 -> 清掃・片付け・作業記録作成 | Q81: > | S81: ='（別紙１）省力化計算シート'!I35 -> 0 | U81: >
C82: =IF('（別紙１）省力化計算シート'!J31="","",IF(OR('（別紙１）省力化計算シート'!N31="-",'（別紙１）省力化計算シート'!N31=0),'（別紙１）省力化計算シート'!J31&"分","("&'（別紙１）省力化計算シート'!J31-'（別紙１）省力化計算シート'!N31&"分→）"&'（別紙１）省力化計算シート'!J31&"分")) -> 135分 | G82: =IF('（別紙１）省力化計算シート'!J32="","",IF(OR('（別紙１）省力化計算シート'!N32="-",'（別紙１）省力化計算シート'!N32=0),'（別紙１）省力化計算シート'!J32&"分","("&'（別紙１）省力化計算シート'!J32-'（別紙１）省力化計算シート'!N32&"分→）"&'（別紙１）省力化計算シート'!J32&"分")) -> 105分 | K82: =IF('（別紙１）省力化計算シート'!J33="","",IF(OR('（別紙１）省力化計算シート'!N33="-",'（別紙１）省力化計算シート'!N33=0),'（別紙１）省力化計算シート'!J33&"分","("&'（別紙１）省力化計算シート'!J33-'（別紙１）省力化計算シート'!N33&"分→）"&'（別紙１）省力化計算シート'!J33&"分")) -> 375分 | O82: =IF('（別紙１）省力化計算シート'!J34="","",IF(OR('（別紙１）省力化計算シート'!N34="-",'（別紙１）省力化計算シート'!N34=0),'（別紙１）省力化計算シート'!J34&"分","("&'（別紙１）省力化計算シート'!J34-'（別紙１）省力化計算シート'!N34&"分→）"&'（別紙１）省力化計算シート'!J34&"分")) -> 33分 | S82: =IF('（別紙１）省力化計算シート'!J35="","",IF(OR('（別紙１）省力化計算シート'!N35="-",'（別紙１）省力化計算シート'!N35=0),'（別紙１）省力化計算シート'!J35&"分","("&'（別紙１）省力化計算シート'!J35-'（別紙１）省力化計算シート'!N35&"分→）"&'（別紙１）省力化計算シート'!J35&"分"))
C88: ='（別紙１）省力化計算シート'!I36 -> 0 | E88: > | G88: ='（別紙１）省力化計算シート'!I37 -> 0 | I88: > | K88: ='（別紙１）省力化計算シート'!I38 -> 0 | M88: > | O88: ='（別紙１）省力化計算シート'!I39 -> 0 | Q88: > | S88: ='（別紙１）省力化計算シート'!I40 -> 0
C89: =IF('（別紙１）省力化計算シート'!J36="","",IF(OR('（別紙１）省力化計算シート'!N36="-",'（別紙１）省力化計算シート'!N36=0),'（別紙１）省力化計算シート'!J36&"分","("&'（別紙１）省力化計算シート'!J36-'（別紙１）省力化計算シート'!N36&"分→）"&'（別紙１）省力化計算シート'!J36&"分")) | G89: =IF('（別紙１）省力化計算シート'!J37="","",IF(OR('（別紙１）省力化計算シート'!N37="-",'（別紙１）省力化計算シート'!N37=0),'（別紙１）省力化計算シート'!J37&"分","("&'（別紙１）省力化計算シート'!J37-'（別紙１）省力化計算シート'!N37&"分→）"&'（別紙１）省力化計算シート'!J37&"分")) | K89: =IF('（別紙１）省力化計算シート'!J38="","",IF(OR('（別紙１）省力化計算シート'!N38="-",'（別紙１）省力化計算シート'!N38=0),'（別紙１）省力化計算シート'!J38&"分","("&'（別紙１）省力化計算シート'!J38-'（別紙１）省力化計算シート'!N38&"分→）"&'（別紙１）省力化計算シート'!J38&"分")) | O89: =IF('（別紙１）省力化計算シート'!J39="","",IF(OR('（別紙１）省力化計算シート'!N39="-",'（別紙１）省力化計算シート'!N39=0),'（別紙１）省力化計算シート'!J39&"分","("&'（別紙１）省力化計算シート'!J39-'（別紙１）省力化計算シート'!N39&"分→）"&'（別紙１）省力化計算シート'!J39&"分")) | S89: =IF('（別紙１）省力化計算シート'!J40="","",IF(OR('（別紙１）省力化計算シート'!N40="-",'（別紙１）省力化計算シート'!N40=0),'（別紙１）省力化計算シート'!J40&"分","("&'（別紙１）省力化計算シート'!J40-'（別紙１）省力化計算シート'!N40&"分→）"&'（別紙１）省力化計算シート'!J40&"分"))
A93: =IF(COUNTA('（別紙１）省力化計算シート'!I26:I40)<>0,"← 非表示エリアに記載があります。[＋]をクリックして表示してください。[-]の場合は、すべて表示されています。","") -> ← 非表示エリアに記載があります。[＋]をクリックして表示してください。[-]の場合は、すべて表示されています。

Sheet （別紙３）投資回収期間計算シート
B1: （別紙３）投資回収期間計算シート
B3: 投資回収期間 | C3: =IF(AND(O4=FALSE,OR(C6="",H6="",J6="",L6="")),"",IF(AND(O4=TRUE,OR(C6="",L6="")),"",IF(C6/(F6*H6*J6+L6)<=0,"",C6/(F6*H6*J6+L6)))) -> 0.47154696 | D3: 年 | O3: パラメータ（公開時に非表示）
O4: FALSE
C5: 投資総額（円） | F5: 削減工数(時間) | H5: 年間稼働日数（日） | J5: 人件費単価（円/時） | L5: 増加した付加価値額（円） | O5: =IF($O$4=TRUE,"※新規事業の場合、削減工数（時間）は0と見なします。","※ 省力化計算シートより自動入力されます。") -> ※ 省力化計算シートより自動入力されます。
C6: 182120400 | D6: / | E6: （ | F6: =IF($O$4=TRUE,0,'（別紙１）省力化計算シート'!D3-'（別紙１）省力化計算シート'!J3) -> 139.375 | G6: × | H6: 240 | I6: × | J6: 3758.5 | K6: ＋ | L6: 260497182 | M6: ）
C12: 【算定根拠】算定の根拠となる計算式等の説明があれば記載してください。
C13: ・投資総額182,120,400円＝機械装置費165,564,000円（税抜）×消費税10％。 ・削減工数139.375時間/日＝別紙１より算出 ・年間稼働日数240日＝当社製造拠点（医薬品富山工場・診断薬事業所）の年間稼働日数。 ・人件費単価3,758.5円/時＝従業員・役員の時給平均額（人件費825,028,990円÷総労働時間219,509時間）。 ・増加した付加価値額260,497,182円＝3年目付加価値額1,176,621,540円−基準年度916,124,358円。 →投資回収期間＝182,120,400÷（139.375×240×3,758.5＋260,497,182）≒0.47年。

Sheet 【参考書式】事業計画目標値算出シート（参考）
B1: ◆◆◆ 参考書式をご利用になる際のご注意点 ◆◆◆
B2: ・自動計算項目については、参考値となります。 | N2: （参考サイト：写真をタッチでリンクに飛びます）
B3: ・入力値(営業利益が大幅にマイナスの場合など)によっては、申請システムの計算値と異なる可能性があります。
B4: ・イメージがわかるよう入力値に数値をいれてありますが、上書きしてご活用ください。また、以下の機構ツールもぜひご活用ください。
B5: 「経営自己診断システム」「価格転嫁検討ツール」「儲かる経営キヅク君」→印刷枠外にリンクあります。
B6: ・申請システムへの入力は、この表の一部（緑字のセル）を転記していただくことになりますが、本事業における売上・収益計画等
B7: を立てるにあたっての参考にお使いください。（初めに直近決算書の実績数値を入れて、数値シミュレーションにもお使いください。）
B8: ・あくまでシステムに入力いただいた数値を正しいものとして審査します。（提出時に本シートは削除しなくて結構です。）
B9: 申請に係る要件の確認は、必ず申請システム上でご確認ください。
E11: 緑字 | F11: 申請システムへ転記する数字 | H11: 入力するとシミュレーションできます
E14: 青字 | F14: 成長率（自動計算）
E16: 黒字 | F16: 自動計算
B19: 【参考書式】事業計画目標値算出シート
B21: 労働生産性の算定シート
E22: 基準年度 | G22: 1 | H22: 2 | I22: 3 | J22: 4 | K22: 5
E23: 直近の決算年月 | G23: 年目計画 | H23: 年目計画 | I23: 年目計画 | J23: 年目計画 | K23: 年目計画
E24: 2026年1月期 | G24: 2029年1月期 | H24: 2030年1月期 | I24: 2031年1月期 | J24: 2032年1月期 | K24: 2033年1月期
B26: 売上高 | E26: 1787102045 | G26: 2040000000 | H26: 2145000000 | I26: 2258000000 | J26: 2395000000 | K26: 2532000000
B27: 売上原価 | E27: 1131714965 | G27: 1345046964 | H27: 1406210853 | I27: 1473557430 | J27: 1553315664 | K27: 1635471280
B28: 売上総利益 | E28: =E26-E27 -> 655387080 | G28: =G26-G27 -> 694953036 | H28: =H26-H27 -> 738789147 | I28: =I26-I27 -> 784442570 | J28: =J26-J27 -> 841684336 | K28: =K26-K27 -> 896528720
B29: 販売費及び一般管理費 | E29: 623765991 | G29: 664860019 | H29: 692598059 | I29: 722121464 | J29: 755722794 | K29: 789999653
B30: ① 営業利益 | E30: =E28-E29 -> 31621089 | G30: =G28-G29 -> 30093017 | H30: =H28-H29 -> 46191088 | I30: =I28-I29 -> 62321106 | J30: =J28-J29 -> 85961542 | K30: =K28-K29 -> 106529067
B31: ② 人件費 （注１） | E31: 825028990 | G31: 929005593 | H31: 979528237 | I31: 1031543717 | J31: 1085113240 | K31: 1140300521
B32: ③ 減価償却費 | E32: =E33+E34 -> 59474279 | G32: =G33+G34 -> 100865279 | H32: =H33+H34 -> 90517529 | I32: =I33+I34 -> 82756717 | J32: =J33+J34 -> 76936107 | K32: =K33+K34 -> 72570650
B33: （内訳）既存設備の減価償却費 | E33: 59474279 | G33: 59474279 | H33: 59474279 | I33: 59474279 | J33: 59474279 | K33: 59474279
B34: 本補助金で導入する設備の減価償却費 | G34: 41391000 | H34: 31043250 | I34: 23282438 | J34: 17461828 | K34: 13096371
B35: ④付加価値額（①+②+③） | E35: =E30+E31+E32 -> 916124358 | G35: =G30+G31+G32 -> 1059963889 | H35: =H30+H31+H32 -> 1116236854 | I35: =I30+I31+I32 -> 1176621540 | J35: =J30+J31+J32 -> 1248010889 | K35: =K30+K31+K32 -> 1319400238
B36: 付加価値額の年平均成長率（％） | G36: =ROUNDDOWN(((G35/$E$35)^(1/G22)-1)*100,2) -> 15.7 | H36: =ROUNDDOWN(((H35/$E$35)^(1/H22)-1)*100,2) -> 10.38 | I36: =ROUNDDOWN(((I35/$E$35)^(1/I22)-1)*100,2) -> 8.69 | J36: =ROUNDDOWN(((J35/$E$35)^(1/J22)-1)*100,2) -> 8.03 | K36: =ROUNDDOWN(((K35/$E$35)^(1/K22)-1)*100,2) -> 7.56
B37: ⑤労働者数のうち役員数（人） | E37: 9 | G37: 9 | H37: 9 | I37: 9 | J37: 9 | K37: 9
B38: ⑥労働者数のうち常勤従業員数（人） （注２） | E38: 130 | G38: 145 | H38: 147 | I38: 149 | J38: 151 | K38: 153
B39: 労働生産性(＝１人あたり付加価値額)（④÷(⑤＋⑥)） | E39: =IF(E35<0,ROUNDUP((E35/(E37+E38)),2),ROUNDDOWN((E35/(E37+E38)),2)) -> 6590822.7 | G39: =IF(G35<0,ROUNDUP((G35/(G37+G38)),2),ROUNDDOWN((G35/(G37+G38)),2)) -> 6882882.4 | H39: =IF(H35<0,ROUNDUP((H35/(H37+H38)),2),ROUNDDOWN((H35/(H37+H38)),2)) -> 7155364.4 | I39: =IF(I35<0,ROUNDUP((I35/(I37+I38)),2),ROUNDDOWN((I35/(I37+I38)),2)) -> 7446971.8 | J39: =IF(J35<0,ROUNDUP((J35/(J37+J38)),2),ROUNDDOWN((J35/(J37+J38)),2)) -> 7800068 | K39: =IF(K35<0,ROUNDUP((K35/(K37+K38)),2),ROUNDDOWN((K35/(K37+K38)),2)) -> 8144445.9
B40: 労働生産性の目標値 （年平均成長率４％ずつ上げる場合） | G40: =IFERROR(IF($E$35>=0,ROUNDUP(((ABS($E$35)*1.04^G22-(ABS($E$35)))+$E$35)/($E$37+$E$38),2),ROUNDDOWN(((ABS($E$35)*1.04^G22-(ABS($E$35)))+$E$35)/($E$37+$E$38),2)),0) -> 6854455.6 | H40: =IFERROR(IF($E$35>=0,ROUNDUP(((ABS($E$35)*1.04^H22-(ABS($E$35)))+$E$35)/($E$37+$E$38),2),ROUNDDOWN(((ABS($E$35)*1.04^H22-(ABS($E$35)))+$E$35)/($E$37+$E$38),2)),0) -> 7128633.9 | I40: =IFERROR(IF($E$35>=0,ROUNDUP(((ABS($E$35)*1.04^I22-(ABS($E$35)))+$E$35)/($E$37+$E$38),2),ROUNDDOWN(((ABS($E$35)*1.04^I22-(ABS($E$35)))+$E$35)/($E$37+$E$38),2)),0) -> 7413779.2 | J40: =IFERROR(IF($E$35>=0,ROUNDUP(((ABS($E$35)*1.04^J22-(ABS($E$35)))+$E$35)/($E$37+$E$38),2),ROUNDDOWN(((ABS($E$35)*1.04^J22-(ABS($E$35)))+$E$35)/($E$37+$E$38),2)),0) -> 7710330.4 | K40: =IFERROR(IF($E$35>=0,ROUNDUP(((ABS($E$35)*1.04^K22-(ABS($E$35)))+$E$35)/($E$37+$E$38),2),ROUNDDOWN(((ABS($E$35)*1.04^K22-(ABS($E$35)))+$E$35)/($E$37+$E$38),2)),0) -> 8018743.6
B41: 労働生産性の年平均成長率（％）（注３） | G41: =ROUNDDOWN(((G39/$E$39)^(1/G22)-1)*100,2) -> 4.43 | H41: =ROUNDDOWN(((H39/$E$39)^(1/H22)-1)*100,2) -> 4.19 | I41: =ROUNDDOWN(((I39/$E$39)^(1/I22)-1)*100,2) -> 4.15 | J41: =ROUNDDOWN(((J39/$E$39)^(1/J22)-1)*100,2) -> 4.3 | K41: =ROUNDDOWN(((K39/$E$39)^(1/K22)-1)*100,2) -> 4.32
B43: １人当たり給与支給総額の算定シート
B44: ⑦全月分の給与等の支給を受けた従業員の給与支給総額 （注４） | E44: 576029692 | G44: 662106909 | H44: 695253293 | I44: 735512678 | J44: 776930697 | K44: 819554856
B45: ⑧全月分の給与等の支給を受けた従業員数（人）（注４） | E45: 123 | G45: 138 | H45: 139 | I45: 141 | J45: 143 | K45: 145
B46: １人当たり給与支給総額 | C46: （⑦÷⑧） | E46: =ROUNDDOWN(E44/E45,2) -> 4683168.2 | G46: =ROUNDDOWN(G44/G45,2) -> 4797876.2 | H46: =ROUNDDOWN(H44/H45,2) -> 5001822.2 | I46: =ROUNDDOWN(I44/I45,2) -> 5216402 | J46: =ROUNDDOWN(J44/J45,2) -> 5433081.8 | K46: =ROUNDDOWN(K44/K45,2) -> 5652102.5
B47: 従業員1人当たり給与支給総額の目標値 | C47: 【特例無し】3.5％ | G47: =ROUNDUP(($E$44+(ABS($E$44)*1.035^G22-ABS($E$44)))/($E$45),0) -> 4847080 | H47: =ROUNDUP(($E$44+(ABS($E$44)*1.035^H22-ABS($E$44)))/($E$45),0) -> 5016727 | I47: =ROUNDUP(($E$44+(ABS($E$44)*1.035^I22-ABS($E$44)))/($E$45),0) -> 5192313 | J47: =ROUNDUP(($E$44+(ABS($E$44)*1.035^J22-ABS($E$44)))/($E$45),0) -> 5374044 | K47: =ROUNDUP(($E$44+(ABS($E$44)*1.035^K22-ABS($E$44)))/($E$45),0) -> 5562135
C48: 【大幅な賃上げ特例】6.0％ | G48: =ROUNDUP(($E$44+(ABS($E$44)*1.06^G22-ABS($E$44)))/($E$45),0) -> 4964159 | H48: =ROUNDUP(($E$44+(ABS($E$44)*1.06^H22-ABS($E$44)))/($E$45),0) -> 5262008 | I48: =ROUNDUP(($E$44+(ABS($E$44)*1.06^I22-ABS($E$44)))/($E$45),0) -> 5577729 | J48: =ROUNDUP(($E$44+(ABS($E$44)*1.06^J22-ABS($E$44)))/($E$45),0) -> 5912392 | K48: =ROUNDUP(($E$44+(ABS($E$44)*1.06^K22-ABS($E$44)))/($E$45),0) -> 6267136
B49: 従業員１人当たり給与支給総額の年平均成長率（％） （注３） | G49: =IFERROR(IF(G$46>=$E$46,ROUNDDOWN(((G46/$E$46)^(1/G22)-1)*100,2),ROUNDUP(((G46/$E$46)^(1/G22)-1)*100,2)),0) -> 2.44 | H49: =IFERROR(IF(H$46>=$E$46,ROUNDDOWN(((H46/$E$46)^(1/H22)-1)*100,2),ROUNDUP(((H46/$E$46)^(1/H22)-1)*100,2)),0) -> 3.34 | I49: =IFERROR(IF(I$46>=$E$46,ROUNDDOWN(((I46/$E$46)^(1/I22)-1)*100,2),ROUNDUP(((I46/$E$46)^(1/I22)-1)*100,2)),0) -> 3.65 | J49: =IFERROR(IF(J$46>=$E$46,ROUNDDOWN(((J46/$E$46)^(1/J22)-1)*100,2),ROUNDUP(((J46/$E$46)^(1/J22)-1)*100,2)),0) -> 3.78 | K49: =IFERROR(IF(K$46>=$E$46,ROUNDDOWN(((K46/$E$46)^(1/K22)-1)*100,2),ROUNDUP(((K46/$E$46)^(1/K22)-1)*100,2)),0) -> 3.83
...

Sheet 【参考書式】達成すべき目標値の算出ツール（参考）
C1: (参考)
D3: 基準年 | E3: 1 | F3: 2 | G3: 3 | H3: 4 | I3: 5
C4: 増加率 | E4: 0.02 | F4: =(1+$E4)^$F3-1 -> 0.0404 | G4: =(1+$E4)^G3-1 -> 0.061208 | H4: =(1+$E4)^H3-1 -> 0.08243216 | I4: =(1+$E4)^I3-1 -> 0.1040808
D5: 1000 | E5: =$D5*((1+$E4)^E3) -> 1020 | F5: =$D5*((1+$E4)^F3) -> 1040.4 | G5: =$D5*((1+$E4)^G3) -> 1061.208 | H5: =$D5*((1+$E4)^H3) -> 1082.4322 | I5: =$D5*((1+$E4)^I3) -> 1104.0808
E6: 0.04 | F6: =(1+$E6)^F3-1 -> 0.0816 | G6: =(1+$E6)^G3-1 -> 0.124864 | H6: =(1+$E6)^H3-1 -> 0.16985856 | I6: =(1+$E6)^I3-1 -> 0.2166529
E7: 0.05 | F7: =(1+$E7)^F3-1 -> 0.1025 | G7: =(1+$E7)^G3-1 -> 0.157625 | H7: =(1+$E7)^H3-1 -> 0.21550625 | I7: =(1+$E7)^I3-1 -> 0.27628156
E8: 0.06 | F8: =(1+$E8)^F3-1 -> 0.1236 | G8: =(1+$E8)^G3-1 -> 0.191016 | H8: =(1+$E8)^H3-1 -> 0.26247696 | I8: =(1+$E8)^I3-1 -> 0.33822558
E9: 0.07 | F9: =(1+$E9)^F3-1 -> 0.1449 | G9: =(1+$E9)^G3-1 -> 0.225043 | H9: =(1+$E9)^H3-1 -> 0.31079601 | I9: =(1+$E9)^I3-1 -> 0.40255173
E10: 0.08 | F10: =(1+$E10)^F3-1 -> 0.1664 | G10: =(1+$E10)^G3-1 -> 0.259712 | H10: =(1+$E10)^H3-1 -> 0.36048896 | I10: =(1+$E10)^I3-1 -> 0.46932808
E11: 0.09 | F11: =(1+$E11)^F3-1 -> 0.1881 | G11: =(1+$E11)^G3-1 -> 0.295029 | H11: =(1+$E11)^H3-1 -> 0.41158161 | I11: =(1+$E11)^I3-1 -> 0.53862395
D13: 基準年 | E13: １年目 | F13: ２年目 | G13: ３年目 | H13: ４年目 | I13: ５年目
C14: 増加率 | E14: 0.035 | F14: =(1+$E14)^F3-1 -> 0.071225 | G14: =(1+$E14)^G3-1 -> 0.10871787 | H14: =(1+$E14)^H3-1 -> 0.147523 | I14: =(1+$E14)^I3-1 -> 0.18768631
C15: 目標値 | D15: 4683168.2 | E15: =ROUNDUP($D$15*((1+$E14)^E3),3) -> 4847079.1 | F15: =$D$15*((1+$E14)^F3) -> 5016726.9 | G15: =$D15*((1+$E14)^G3) -> 5192312.3 | H15: =$D15*((1+$E14)^H3) -> 5374043.2 | I15: =$D15*((1+$E14)^I3) -> 5562134.8
C16: 年平均成長率 | E16: =ROUNDDOWN(((E15/$D$15)^(1/E3)-1),5) -> 0.035 | F16: =ROUNDDOWN(((F15/$D$15)^(1/F3)-1),5) -> 0.03499 | G16: =ROUNDDOWN(((G15/$D$15)^(1/G3)-1),5) -> 0.03499 | H16: =ROUNDDOWN(((H15/$D$15)^(1/H3)-1),5) -> 0.03499 | I16: =ROUNDDOWN(((I15/$D$15)^(1/I3)-1),5) -> 0.03499
