Workbook

Sheet 【指定様式】事業計画書（その3）
A1: 【指定様式】事業計画書（その３）
A2: 本事業計画における会社全体の事業計画（数値計画）を記載してください。
A3: 記載数値：「省力化指数」「付加価値額」「労働生産性」「給与支給総額」「一人当たり給与支給総額」「投資回収期間」
B5: 【１】省力化指数
B6: ='（別紙１）省力化計算シート'!M3 -> 1
B7: ※「（別紙１）省力化計算シート」より算出。
B8: ※「（別紙２）省力化業務プロセス図」も作成し省力化指数の詳細を説明してください。
B10: 【２】会社全体の事業計画（表）
B49: 【算定根拠】算定の根拠となる計算式等を記載ください。
B50: ①付加価値額
B51: 生産量が、設備導入直後に48ton/週から、50ton/週に増加。その後、2年目以降も顧客からの要望に沿って、毎年期末までに2ton/週増えていく。これに伴って当社全ての売上高が生産量比率に沿って増加する。1年目+25,849千円、2年目+206,794千円、3年目移行+155,095千円ずつ増加。 変動費がそれに伴って増加。変動比率は維持する。 人件費は、基準年度以降毎年5%ずつ増加。設備保守のための修繕費は、毎年20万円を計上。減価償却費は本設備を定額法にて処理し、毎年+4,000千円ずつ増加する。それ以外の減価償却費は横ばいを想定。
B56: ②労働生産性
B57: これまで作業者の手作業で行っていた、「尾切」と「魚体選別」を機械化・自動化できる設備を導入する。これにより、「尾切」では2名作業を1名作業に省人化、「魚体選別」では6名作業を3名作業に省人化できる。省人化によって生まれる4名は、機械化が難しい「骨取り」と「最終出荷」の工程に配置。これにより、労働者数を増やすことなく、増加する生産量に対応することができる人員配置が可能となる。
B62: ③給与支給総額
B63: 労働者数を増やすことなく、生産量増加に対応できることで、従業員一人当たりの付加価値が増加。直近年度では、6,796千円の従業員一人当たりの付加価値額が、基準年度では6,983千円、1年後では7,454千円、2年後7,810千円、3年後8,166千円、4年後8,522千円、5年後8,878千円と増加する。労働分配率を維持したまま、高い給与支給総額の増加に対応できることを計画している。
B68: ④一人当たり給与支給総額
B69: 労働者数を増やすことなく、生産量増加に対応でき、毎年5%の給与支給総額を増加していける。そのため、一人当たり給与支給総額も高い水準で増加させることが可能となる。
B74: 【３】投資回収期間
B75: ='（別紙３）投資回収期間計算シート'!C3 -> 0.45873255 | D75: 年
B76: ※「（別紙３）投資回収期間計算シート」より算出。

Sheet （別紙１）省力化計算シート
B1: （別紙１）省力化計算シート
C3: 設備導入により削減される 業務に要していた時間 | D3: =(SUMIF(C11:C40,"<>",D11:D40)-SUMIF(E11:E40,"<>-",D11:D40)-SUMIF(F11:F40,"<0"))/60 -> 48 | G3: 時間 | I3: 設備導入後に発生する 業務に要する時間 | J3: =(SUMIF(I11:I40,"<>",J11:J40)-SUMIF(N11:N40,"<>-",J11:J40)+SUMIF(N11:N40,">0"))/60 -> 0 | K3: 時間 | L3: 省力化指数 | M3: =IF(D3=0,0,IF((D3-J3)/D3<0,0,(D3-J3)/D3)) -> 1
B5: ■設備導入前の業務プロセス・作業工程 | H5: ■設備導入後の業務プロセス・作業工程
C7: 設備導入前の作業時間合計 | D7: =SUMIF(C11:C40,"<>",D11:D40)/60 -> 64 | G7: 時間 | I7: 設備導入後の作業時間合計 | J7: =SUMIF(I11:I40,"<>",J11:J40)/60 -> 16 | K7: 時間
D9: １日あたりの人手による作業時間を入力してください。 | J9: １日あたりの人手による 作業時間を入力してください。
B10: No. | C10: 工程名・作業名 | D10: 作業時間（分） | E10: 対応する導入後の 業務プロセスNo | F10: 同工程差分時間（分） | H10: No. | I10: 工程名・作業名 | J10: 作業時間（分） | K10: 作業種別 | L10: 対応する設備導入前の 業務プロセスNo. | N10: 同工程差分時間（分） | P10: 作業種別選択肢
B11: 1 | C11: 尻尾切り | D11: 960 | E11: =IF(OR(C11="",D11=""),"-",IF(IFERROR(MATCH(B11,L$11:L$40,0),"")="","-",IF(OR(INDEX(I$11:I$40,MATCH(B11,L$11:L$40,0))="",INDEX(J$11:J$40,MATCH(B11,L$11:L$40,0))="",INDEX(K$11:K$40,MATCH(B11,L$11:L$40,0))<>"内容は変化しない作業"),"-",MATCH(B11,L$11:L$40,0)))) -> 1 | F11: {=IF(E11="-","-",IF(AND(C11<>"",D11>0,INDEX(K$11:K$40,E11)="内容は変化しない作業",AND(E11<>"-",E11<>""),INDEX(I$11:I$40,E11)<>"",INDEX(J$11:J$40,E11)<>""),INDEX(J$11:J$40,E11)-D11,"-"))} -> -720 | H11: 1 | I11: 尻尾切り | J11: 240 | K11: 内容は変化しない作業 | L11: 1 | N11: {=IF(AND(I11<>"",J11>0,K11="内容は変化しない作業",L11>0,INDEX(C$11:C$40,L11)<>"",INDEX(D$11:D$40,L11)<>""),J11-INDEX(D$11:D$40,L11),"-")} -> -720 | P11: 新たに追加される作業
B12: 2 | C12: 魚体選別 | D12: 2880 | E12: =IF(OR(C12="",D12=""),"-",IF(IFERROR(MATCH(B12,L$11:L$40,0),"")="","-",IF(OR(INDEX(I$11:I$40,MATCH(B12,L$11:L$40,0))="",INDEX(J$11:J$40,MATCH(B12,L$11:L$40,0))="",INDEX(K$11:K$40,MATCH(B12,L$11:L$40,0))<>"内容は変化しない作業"),"-",MATCH(B12,L$11:L$40,0)))) -> 2 | F12: {=IF(E12="-","-",IF(AND(C12<>"",D12>0,INDEX(K$11:K$40,E12)="内容は変化しない作業",AND(E12<>"-",E12<>""),INDEX(I$11:I$40,E12)<>"",INDEX(J$11:J$40,E12)<>""),INDEX(J$11:J$40,E12)-D12,"-"))} -> -2160 | H12: 2 | I12: 魚体選別 | J12: 720 | K12: 内容は変化しない作業 | L12: 2 | N12: {=IF(AND(I12<>"",J12>0,K12="内容は変化しない作業",L12>0,INDEX(C$11:C$40,L12)<>"",INDEX(D$11:D$40,L12)<>""),J12-INDEX(D$11:D$40,L12),"-")} -> -2160 | P12: 内容は変化しない作業
B13: 3 | E13: =IF(OR(C13="",D13=""),"-",IF(IFERROR(MATCH(B13,L$11:L$40,0),"")="","-",IF(OR(INDEX(I$11:I$40,MATCH(B13,L$11:L$40,0))="",INDEX(J$11:J$40,MATCH(B13,L$11:L$40,0))="",INDEX(K$11:K$40,MATCH(B13,L$11:L$40,0))<>"内容は変化しない作業"),"-",MATCH(B13,L$11:L$40,0)))) -> - | F13: {=IF(E13="-","-",IF(AND(C13<>"",D13>0,INDEX(K$11:K$40,E13)="内容は変化しない作業",AND(E13<>"-",E13<>""),INDEX(I$11:I$40,E13)<>"",INDEX(J$11:J$40,E13)<>""),INDEX(J$11:J$40,E13)-D13,"-"))} -> - | H13: 3 | N13: {=IF(AND(I13<>"",J13>0,K13="内容は変化しない作業",L13>0,INDEX(C$11:C$40,L13)<>"",INDEX(D$11:D$40,L13)<>""),J13-INDEX(D$11:D$40,L13),"-")} -> -
B14: 4 | E14: =IF(OR(C14="",D14=""),"-",IF(IFERROR(MATCH(B14,L$11:L$40,0),"")="","-",IF(OR(INDEX(I$11:I$40,MATCH(B14,L$11:L$40,0))="",INDEX(J$11:J$40,MATCH(B14,L$11:L$40,0))="",INDEX(K$11:K$40,MATCH(B14,L$11:L$40,0))<>"内容は変化しない作業"),"-",MATCH(B14,L$11:L$40,0)))) -> - | F14: {=IF(E14="-","-",IF(AND(C14<>"",D14>0,INDEX(K$11:K$40,E14)="内容は変化しない作業",AND(E14<>"-",E14<>""),INDEX(I$11:I$40,E14)<>"",INDEX(J$11:J$40,E14)<>""),INDEX(J$11:J$40,E14)-D14,"-"))} -> - | H14: 4 | N14: {=IF(AND(I14<>"",J14>0,K14="内容は変化しない作業",L14>0,INDEX(C$11:C$40,L14)<>"",INDEX(D$11:D$40,L14)<>""),J14-INDEX(D$11:D$40,L14),"-")} -> -
B15: 5 | E15: =IF(OR(C15="",D15=""),"-",IF(IFERROR(MATCH(B15,L$11:L$40,0),"")="","-",IF(OR(INDEX(I$11:I$40,MATCH(B15,L$11:L$40,0))="",INDEX(J$11:J$40,MATCH(B15,L$11:L$40,0))="",INDEX(K$11:K$40,MATCH(B15,L$11:L$40,0))<>"内容は変化しない作業"),"-",MATCH(B15,L$11:L$40,0)))) -> - | F15: {=IF(E15="-","-",IF(AND(C15<>"",D15>0,INDEX(K$11:K$40,E15)="内容は変化しない作業",AND(E15<>"-",E15<>""),INDEX(I$11:I$40,E15)<>"",INDEX(J$11:J$40,E15)<>""),INDEX(J$11:J$40,E15)-D15,"-"))} -> - | H15: 5 | N15: {=IF(AND(I15<>"",J15>0,K15="内容は変化しない作業",L15>0,INDEX(C$11:C$40,L15)<>"",INDEX(D$11:D$40,L15)<>""),J15-INDEX(D$11:D$40,L15),"-")} -> -
B16: 6 | E16: =IF(OR(C16="",D16=""),"-",IF(IFERROR(MATCH(B16,L$11:L$40,0),"")="","-",IF(OR(INDEX(I$11:I$40,MATCH(B16,L$11:L$40,0))="",INDEX(J$11:J$40,MATCH(B16,L$11:L$40,0))="",INDEX(K$11:K$40,MATCH(B16,L$11:L$40,0))<>"内容は変化しない作業"),"-",MATCH(B16,L$11:L$40,0)))) -> - | F16: {=IF(E16="-","-",IF(AND(C16<>"",D16>0,INDEX(K$11:K$40,E16)="内容は変化しない作業",AND(E16<>"-",E16<>""),INDEX(I$11:I$40,E16)<>"",INDEX(J$11:J$40,E16)<>""),INDEX(J$11:J$40,E16)-D16,"-"))} -> - | H16: 6 | N16: {=IF(AND(I16<>"",J16>0,K16="内容は変化しない作業",L16>0,INDEX(C$11:C$40,L16)<>"",INDEX(D$11:D$40,L16)<>""),J16-INDEX(D$11:D$40,L16),"-")} -> -
B17: 7 | E17: =IF(OR(C17="",D17=""),"-",IF(IFERROR(MATCH(B17,L$11:L$40,0),"")="","-",IF(OR(INDEX(I$11:I$40,MATCH(B17,L$11:L$40,0))="",INDEX(J$11:J$40,MATCH(B17,L$11:L$40,0))="",INDEX(K$11:K$40,MATCH(B17,L$11:L$40,0))<>"内容は変化しない作業"),"-",MATCH(B17,L$11:L$40,0)))) -> - | F17: {=IF(E17="-","-",IF(AND(C17<>"",D17>0,INDEX(K$11:K$40,E17)="内容は変化しない作業",AND(E17<>"-",E17<>""),INDEX(I$11:I$40,E17)<>"",INDEX(J$11:J$40,E17)<>""),INDEX(J$11:J$40,E17)-D17,"-"))} -> - | H17: 7 | N17: {=IF(AND(I17<>"",J17>0,K17="内容は変化しない作業",L17>0,INDEX(C$11:C$40,L17)<>"",INDEX(D$11:D$40,L17)<>""),J17-INDEX(D$11:D$40,L17),"-")} -> -
B18: 8 | E18: =IF(OR(C18="",D18=""),"-",IF(IFERROR(MATCH(B18,L$11:L$40,0),"")="","-",IF(OR(INDEX(I$11:I$40,MATCH(B18,L$11:L$40,0))="",INDEX(J$11:J$40,MATCH(B18,L$11:L$40,0))="",INDEX(K$11:K$40,MATCH(B18,L$11:L$40,0))<>"内容は変化しない作業"),"-",MATCH(B18,L$11:L$40,0)))) -> - | F18: {=IF(E18="-","-",IF(AND(C18<>"",D18>0,INDEX(K$11:K$40,E18)="内容は変化しない作業",AND(E18<>"-",E18<>""),INDEX(I$11:I$40,E18)<>"",INDEX(J$11:J$40,E18)<>""),INDEX(J$11:J$40,E18)-D18,"-"))} -> - | H18: 8 | N18: {=IF(AND(I18<>"",J18>0,K18="内容は変化しない作業",L18>0,INDEX(C$11:C$40,L18)<>"",INDEX(D$11:D$40,L18)<>""),J18-INDEX(D$11:D$40,L18),"-")} -> -
B19: 9 | E19: =IF(OR(C19="",D19=""),"-",IF(IFERROR(MATCH(B19,L$11:L$40,0),"")="","-",IF(OR(INDEX(I$11:I$40,MATCH(B19,L$11:L$40,0))="",INDEX(J$11:J$40,MATCH(B19,L$11:L$40,0))="",INDEX(K$11:K$40,MATCH(B19,L$11:L$40,0))<>"内容は変化しない作業"),"-",MATCH(B19,L$11:L$40,0)))) -> - | F19: {=IF(E19="-","-",IF(AND(C19<>"",D19>0,INDEX(K$11:K$40,E19)="内容は変化しない作業",AND(E19<>"-",E19<>""),INDEX(I$11:I$40,E19)<>"",INDEX(J$11:J$40,E19)<>""),INDEX(J$11:J$40,E19)-D19,"-"))} -> - | H19: 9 | N19: {=IF(AND(I19<>"",J19>0,K19="内容は変化しない作業",L19>0,INDEX(C$11:C$40,L19)<>"",INDEX(D$11:D$40,L19)<>""),J19-INDEX(D$11:D$40,L19),"-")} -> -
B20: 10 | E20: =IF(OR(C20="",D20=""),"-",IF(IFERROR(MATCH(B20,L$11:L$40,0),"")="","-",IF(OR(INDEX(I$11:I$40,MATCH(B20,L$11:L$40,0))="",INDEX(J$11:J$40,MATCH(B20,L$11:L$40,0))="",INDEX(K$11:K$40,MATCH(B20,L$11:L$40,0))<>"内容は変化しない作業"),"-",MATCH(B20,L$11:L$40,0)))) -> - | F20: {=IF(E20="-","-",IF(AND(C20<>"",D20>0,INDEX(K$11:K$40,E20)="内容は変化しない作業",AND(E20<>"-",E20<>""),INDEX(I$11:I$40,E20)<>"",INDEX(J$11:J$40,E20)<>""),INDEX(J$11:J$40,E20)-D20,"-"))} -> - | H20: 10 | N20: {=IF(AND(I20<>"",J20>0,K20="内容は変化しない作業",L20>0,INDEX(C$11:C$40,L20)<>"",INDEX(D$11:D$40,L20)<>""),J20-INDEX(D$11:D$40,L20),"-")} -> -
B21: 11 | E21: =IF(OR(C21="",D21=""),"-",IF(IFERROR(MATCH(B21,L$11:L$40,0),"")="","-",IF(OR(INDEX(I$11:I$40,MATCH(B21,L$11:L$40,0))="",INDEX(J$11:J$40,MATCH(B21,L$11:L$40,0))="",INDEX(K$11:K$40,MATCH(B21,L$11:L$40,0))<>"内容は変化しない作業"),"-",MATCH(B21,L$11:L$40,0)))) -> - | F21: {=IF(E21="-","-",IF(AND(C21<>"",D21>0,INDEX(K$11:K$40,E21)="内容は変化しない作業",AND(E21<>"-",E21<>""),INDEX(I$11:I$40,E21)<>"",INDEX(J$11:J$40,E21)<>""),INDEX(J$11:J$40,E21)-D21,"-"))} -> - | H21: 11 | N21: {=IF(AND(I21<>"",J21>0,K21="内容は変化しない作業",L21>0,INDEX(C$11:C$40,L21)<>"",INDEX(D$11:D$40,L21)<>""),J21-INDEX(D$11:D$40,L21),"-")} -> -
B22: 12 | E22: =IF(OR(C22="",D22=""),"-",IF(IFERROR(MATCH(B22,L$11:L$40,0),"")="","-",IF(OR(INDEX(I$11:I$40,MATCH(B22,L$11:L$40,0))="",INDEX(J$11:J$40,MATCH(B22,L$11:L$40,0))="",INDEX(K$11:K$40,MATCH(B22,L$11:L$40,0))<>"内容は変化しない作業"),"-",MATCH(B22,L$11:L$40,0)))) -> - | F22: {=IF(E22="-","-",IF(AND(C22<>"",D22>0,INDEX(K$11:K$40,E22)="内容は変化しない作業",AND(E22<>"-",E22<>""),INDEX(I$11:I$40,E22)<>"",INDEX(J$11:J$40,E22)<>""),INDEX(J$11:J$40,E22)-D22,"-"))} -> - | H22: 12 | N22: {=IF(AND(I22<>"",J22>0,K22="内容は変化しない作業",L22>0,INDEX(C$11:C$40,L22)<>"",INDEX(D$11:D$40,L22)<>""),J22-INDEX(D$11:D$40,L22),"-")} -> -
B23: 13 | E23: =IF(OR(C23="",D23=""),"-",IF(IFERROR(MATCH(B23,L$11:L$40,0),"")="","-",IF(OR(INDEX(I$11:I$40,MATCH(B23,L$11:L$40,0))="",INDEX(J$11:J$40,MATCH(B23,L$11:L$40,0))="",INDEX(K$11:K$40,MATCH(B23,L$11:L$40,0))<>"内容は変化しない作業"),"-",MATCH(B23,L$11:L$40,0)))) -> - | F23: {=IF(E23="-","-",IF(AND(C23<>"",D23>0,INDEX(K$11:K$40,E23)="内容は変化しない作業",AND(E23<>"-",E23<>""),INDEX(I$11:I$40,E23)<>"",INDEX(J$11:J$40,E23)<>""),INDEX(J$11:J$40,E23)-D23,"-"))} -> - | H23: 13 | N23: {=IF(AND(I23<>"",J23>0,K23="内容は変化しない作業",L23>0,INDEX(C$11:C$40,L23)<>"",INDEX(D$11:D$40,L23)<>""),J23-INDEX(D$11:D$40,L23),"-")} -> -
B24: 14 | E24: =IF(OR(C24="",D24=""),"-",IF(IFERROR(MATCH(B24,L$11:L$40,0),"")="","-",IF(OR(INDEX(I$11:I$40,MATCH(B24,L$11:L$40,0))="",INDEX(J$11:J$40,MATCH(B24,L$11:L$40,0))="",INDEX(K$11:K$40,MATCH(B24,L$11:L$40,0))<>"内容は変化しない作業"),"-",MATCH(B24,L$11:L$40,0)))) -> - | F24: {=IF(E24="-","-",IF(AND(C24<>"",D24>0,INDEX(K$11:K$40,E24)="内容は変化しない作業",AND(E24<>"-",E24<>""),INDEX(I$11:I$40,E24)<>"",INDEX(J$11:J$40,E24)<>""),INDEX(J$11:J$40,E24)-D24,"-"))} -> - | H24: 14 | N24: {=IF(AND(I24<>"",J24>0,K24="内容は変化しない作業",L24>0,INDEX(C$11:C$40,L24)<>"",INDEX(D$11:D$40,L24)<>""),J24-INDEX(D$11:D$40,L24),"-")} -> -
... B40: 30 | E40: =IF(OR(C40="",D40=""),"-",IF(IFERROR(MATCH(B40,L$11:L$40,0),"")="","-",IF(OR(INDEX(I$11:I$40,MATCH(B40,L$11:L$40,0))="",INDEX(J$11:J$40,MATCH(B40,L$11:L$40,0))="",INDEX(K$11:K$40,MATCH(B40,L$11:L$40,0))<>"内容は変化しない作業"),"-",MATCH(B40,L$11:L$40,0)))) -> - | F40: {=IF(E40="-","-",IF(AND(C40<>"",D40>0,INDEX(K$11:K$40,E40)="内容は変化しない作業",AND(E40<>"-",E40<>""),INDEX(I$11:I$40,E40)<>"",INDEX(J$11:J$40,E40)<>""),INDEX(J$11:J$40,E40)-D40,"-"))} -> - | H40: 30 | N40: {=IF(AND(I40<>"",J40>0,K40="内容は変化しない作業",L40>0,INDEX(C$11:C$40,L40)<>"",INDEX(D$11:D$40,L40)<>""),J40-INDEX(D$11:D$40,L40),"-")} -> -

Sheet （別紙２）省力化業務プロセス図
B1: （別紙２）省力化業務プロセス図 ※（別紙1）で入れた業務プロセス・作業工程がフロー図として表示されます。
O3: 省力化指数 | S3: ='（別紙１）省力化計算シート'!M3 -> 1
C5: ■設備導入前の業務プロセス・作業工程 （BEFORE） | O5: 設備導入による削減時間 | S5: ='（別紙１）省力化計算シート'!D3 -> 48 | T5: 時間
C8: ='（別紙１）省力化計算シート'!C11 -> 尻尾切り | E8: > | G8: ='（別紙１）省力化計算シート'!C12 -> 魚体選別 | I8: > | K8: ='（別紙１）省力化計算シート'!C13 -> 0 | M8: > | O8: ='（別紙１）省力化計算シート'!C14 -> 0 | Q8: > | S8: ='（別紙１）省力化計算シート'!C15 -> 0 | U8: > | X8: 削減される作業
C9: =IF('（別紙１）省力化計算シート'!D11="","",IF(OR('（別紙１）省力化計算シート'!F11="-",'（別紙１）省力化計算シート'!F11=0),'（別紙１）省力化計算シート'!D11&"分",'（別紙１）省力化計算シート'!D11&"分"&" (→"&'（別紙１）省力化計算シート'!D11+'（別紙１）省力化計算シート'!F11&"分）")) -> 960分 (→240分） | G9: =IF('（別紙１）省力化計算シート'!D12="","",IF(OR('（別紙１）省力化計算シート'!F12="-",'（別紙１）省力化計算シート'!F12=0),'（別紙１）省力化計算シート'!D12&"分",'（別紙１）省力化計算シート'!D12&"分"&" (→"&'（別紙１）省力化計算シート'!D12+'（別紙１）省力化計算シート'!F12&"分）")) -> 2880分 (→720分） | K9: =IF('（別紙１）省力化計算シート'!D13="","",IF(OR('（別紙１）省力化計算シート'!F13="-",'（別紙１）省力化計算シート'!F13=0),'（別紙１）省力化計算シート'!D13&"分",'（別紙１）省力化計算シート'!D13&"分"&" (→"&'（別紙１）省力化計算シート'!D13+'（別紙１）省力化計算シート'!F13&"分）")) | O9: =IF('（別紙１）省力化計算シート'!D14="","",IF(OR('（別紙１）省力化計算シート'!F14="-",'（別紙１）省力化計算シート'!F14=0),'（別紙１）省力化計算シート'!D14&"分",'（別紙１）省力化計算シート'!D14&"分"&" (→"&'（別紙１）省力化計算シート'!D14+'（別紙１）省力化計算シート'!F14&"分）")) | S9: =IF('（別紙１）省力化計算シート'!D15="","",IF(OR('（別紙１）省力化計算シート'!F15="-",'（別紙１）省力化計算シート'!F15=0),'（別紙１）省力化計算シート'!D15&"分",'（別紙１）省力化計算シート'!D15&"分"&" (→"&'（別紙１）省力化計算シート'!D15+'（別紙１）省力化計算シート'!F15&"分）"))
X11: 時間が削減される作業
C15: ='（別紙１）省力化計算シート'!C16 -> 0 | E15: > | G15: ='（別紙１）省力化計算シート'!C17 -> 0 | I15: > | K15: ='（別紙１）省力化計算シート'!C18 -> 0 | M15: > | O15: ='（別紙１）省力化計算シート'!C19 -> 0 | Q15: > | S15: ='（別紙１）省力化計算シート'!C20 -> 0 | U15: > | X15: 導入前後で同様の作業
C16: =IF('（別紙１）省力化計算シート'!D16="","",IF(OR('（別紙１）省力化計算シート'!F16="-",'（別紙１）省力化計算シート'!F16=0),'（別紙１）省力化計算シート'!D16&"分",'（別紙１）省力化計算シート'!D16&"分"&" (→"&'（別紙１）省力化計算シート'!D16+'（別紙１）省力化計算シート'!F16&"分）")) | G16: =IF('（別紙１）省力化計算シート'!D17="","",IF(OR('（別紙１）省力化計算シート'!F17="-",'（別紙１）省力化計算シート'!F17=0),'（別紙１）省力化計算シート'!D17&"分",'（別紙１）省力化計算シート'!D17&"分"&" (→"&'（別紙１）省力化計算シート'!D17+'（別紙１）省力化計算シート'!F17&"分）")) | K16: =IF('（別紙１）省力化計算シート'!D18="","",IF(OR('（別紙１）省力化計算シート'!F18="-",'（別紙１）省力化計算シート'!F18=0),'（別紙１）省力化計算シート'!D18&"分",'（別紙１）省力化計算シート'!D18&"分"&" (→"&'（別紙１）省力化計算シート'!D18+'（別紙１）省力化計算シート'!F18&"分）")) | O16: =IF('（別紙１）省力化計算シート'!D19="","",IF(OR('（別紙１）省力化計算シート'!F19="-",'（別紙１）省力化計算シート'!F19=0),'（別紙１）省力化計算シート'!D19&"分",'（別紙１）省力化計算シート'!D19&"分"&" (→"&'（別紙１）省力化計算シート'!D19+'（別紙１）省力化計算シート'!F19&"分）")) | S16: =IF('（別紙１）省力化計算シート'!D20="","",IF(OR('（別紙１）省力化計算シート'!F20="-",'（別紙１）省力化計算シート'!F20=0),'（別紙１）省力化計算シート'!D20&"分",'（別紙１）省力化計算シート'!D20&"分"&" (→"&'（別紙１）省力化計算シート'!D20+'（別紙１）省力化計算シート'!F20&"分）"))
X17: 作業内容の説明 入力欄
C22: ='（別紙１）省力化計算シート'!C21 -> 0 | E22: > | G22: ='（別紙１）省力化計算シート'!C22 -> 0 | I22: > | K22: ='（別紙１）省力化計算シート'!C23 -> 0 | M22: > | O22: ='（別紙１）省力化計算シート'!C24 -> 0 | Q22: > | S22: ='（別紙１）省力化計算シート'!C25 -> 0 | U22: >
C23: =IF('（別紙１）省力化計算シート'!D21="","",IF(OR('（別紙１）省力化計算シート'!F21="-",'（別紙１）省力化計算シート'!F21=0),'（別紙１）省力化計算シート'!D21&"分",'（別紙１）省力化計算シート'!D21&"分"&" (→"&'（別紙１）省力化計算シート'!D21+'（別紙１）省力化計算シート'!F21&"分）")) | G23: =IF('（別紙１）省力化計算シート'!D22="","",IF(OR('（別紙１）省力化計算シート'!F22="-",'（別紙１）省力化計算シート'!F22=0),'（別紙１）省力化計算シート'!D22&"分",'（別紙１）省力化計算シート'!D22&"分"&" (→"&'（別紙１）省力化計算シート'!D22+'（別紙１）省力化計算シート'!F22&"分）")) | K23: =IF('（別紙１）省力化計算シート'!D23="","",IF(OR('（別紙１）省力化計算シート'!F23="-",'（別紙１）省力化計算シート'!F23=0),'（別紙１）省力化計算シート'!D23&"分",'（別紙１）省力化計算シート'!D23&"分"&" (→"&'（別紙１）省力化計算シート'!D23+'（別紙１）省力化計算シート'!F23&"分）")) | O23: =IF('（別紙１）省力化計算シート'!D24="","",IF(OR('（別紙１）省力化計算シート'!F24="-",'（別紙１）省力化計算シート'!F24=0),'（別紙１）省力化計算シート'!D24&"分",'（別紙１）省力化計算シート'!D24&"分"&" (→"&'（別紙１）省力化計算シート'!D24+'（別紙１）省力化計算シート'!F24&"分）")) | S23: =IF('（別紙１）省力化計算シート'!D25="","",IF(OR('（別紙１）省力化計算シート'!F25="-",'（別紙１）省力化計算シート'!F25=0),'（別紙１）省力化計算シート'!D25&"分",'（別紙１）省力化計算シート'!D25&"分"&" (→"&'（別紙１）省力化計算シート'!D25+'（別紙１）省力化計算シート'!F25&"分）"))
C29: ='（別紙１）省力化計算シート'!C26 -> 0 | E29: > | G29: ='（別紙１）省力化計算シート'!C27 -> 0 | I29: > | K29: ='（別紙１）省力化計算シート'!C28 -> 0 | M29: > | O29: ='（別紙１）省力化計算シート'!C29 -> 0 | Q29: > | S29: ='（別紙１）省力化計算シート'!C30 -> 0 | U29: >
C30: =IF('（別紙１）省力化計算シート'!D26="","",IF(OR('（別紙１）省力化計算シート'!F26="-",'（別紙１）省力化計算シート'!F26=0),'（別紙１）省力化計算シート'!D26&"分",'（別紙１）省力化計算シート'!D26&"分"&" (→"&'（別紙１）省力化計算シート'!D26+'（別紙１）省力化計算シート'!F26&"分）")) | G30: =IF('（別紙１）省力化計算シート'!D27="","",IF(OR('（別紙１）省力化計算シート'!F27="-",'（別紙１）省力化計算シート'!F27=0),'（別紙１）省力化計算シート'!D27&"分",'（別紙１）省力化計算シート'!D27&"分"&" (→"&'（別紙１）省力化計算シート'!D27+'（別紙１）省力化計算シート'!F27&"分）")) | K30: =IF('（別紙１）省力化計算シート'!D28="","",IF(OR('（別紙１）省力化計算シート'!F28="-",'（別紙１）省力化計算シート'!F28=0),'（別紙１）省力化計算シート'!D28&"分",'（別紙１）省力化計算シート'!D28&"分"&" (→"&'（別紙１）省力化計算シート'!D28+'（別紙１）省力化計算シート'!F28&"分）")) | O30: =IF('（別紙１）省力化計算シート'!D29="","",IF(OR('（別紙１）省力化計算シート'!F29="-",'（別紙１）省力化計算シート'!F29=0),'（別紙１）省力化計算シート'!D29&"分",'（別紙１）省力化計算シート'!D29&"分"&" (→"&'（別紙１）省力化計算シート'!D29+'（別紙１）省力化計算シート'!F29&"分）")) | S30: =IF('（別紙１）省力化計算シート'!D30="","",IF(OR('（別紙１）省力化計算シート'!F30="-",'（別紙１）省力化計算シート'!F30=0),'（別紙１）省力化計算シート'!D30&"分",'（別紙１）省力化計算シート'!D30&"分"&" (→"&'（別紙１）省力化計算シート'!D30+'（別紙１）省力化計算シート'!F30&"分）"))
C36: ='（別紙１）省力化計算シート'!C31 -> 0 | E36: > | G36: ='（別紙１）省力化計算シート'!C32 -> 0 | I36: > | K36: ='（別紙１）省力化計算シート'!C33 -> 0 | M36: > | O36: ='（別紙１）省力化計算シート'!C34 -> 0 | Q36: > | S36: ='（別紙１）省力化計算シート'!C35 -> 0 | U36: >
C37: =IF('（別紙１）省力化計算シート'!D31="","",IF(OR('（別紙１）省力化計算シート'!F31="-",'（別紙１）省力化計算シート'!F31=0),'（別紙１）省力化計算シート'!D31&"分",'（別紙１）省力化計算シート'!D31&"分"&" (→"&'（別紙１）省力化計算シート'!D31+'（別紙１）省力化計算シート'!F31&"分）")) | G37: =IF('（別紙１）省力化計算シート'!D32="","",IF(OR('（別紙１）省力化計算シート'!F32="-",'（別紙１）省力化計算シート'!F32=0),'（別紙１）省力化計算シート'!D32&"分",'（別紙１）省力化計算シート'!D32&"分"&" (→"&'（別紙１）省力化計算シート'!D32+'（別紙１）省力化計算シート'!F32&"分）")) | K37: =IF('（別紙１）省力化計算シート'!D33="","",IF(OR('（別紙１）省力化計算シート'!F33="-",'（別紙１）省力化計算シート'!F33=0),'（別紙１）省力化計算シート'!D33&"分",'（別紙１）省力化計算シート'!D33&"分"&" (→"&'（別紙１）省力化計算シート'!D33+'（別紙１）省力化計算シート'!F33&"分）")) | O37: =IF('（別紙１）省力化計算シート'!D34="","",IF(OR('（別紙１）省力化計算シート'!F34="-",'（別紙１）省力化計算シート'!F34=0),'（別紙１）省力化計算シート'!D34&"分",'（別紙１）省力化計算シート'!D34&"分"&" (→"&'（別紙１）省力化計算シート'!D34+'（別紙１）省力化計算シート'!F34&"分）")) | S37: =IF('（別紙１）省力化計算シート'!D35="","",IF(OR('（別紙１）省力化計算シート'!F35="-",'（別紙１）省力化計算シート'!F35=0),'（別紙１）省力化計算シート'!D35&"分",'（別紙１）省力化計算シート'!D35&"分"&" (→"&'（別紙１）省力化計算シート'!D35+'（別紙１）省力化計算シート'!F35&"分）"))
C43: ='（別紙１）省力化計算シート'!C36 -> 0 | E43: > | G43: ='（別紙１）省力化計算シート'!C37 -> 0 | I43: > | K43: ='（別紙１）省力化計算シート'!C38 -> 0 | M43: > | O43: ='（別紙１）省力化計算シート'!C39 -> 0 | Q43: > | S43: ='（別紙１）省力化計算シート'!C40 -> 0
C44: =IF('（別紙１）省力化計算シート'!D36="","",IF(OR('（別紙１）省力化計算シート'!F36="-",'（別紙１）省力化計算シート'!F36=0),'（別紙１）省力化計算シート'!D36&"分",'（別紙１）省力化計算シート'!D36&"分"&" (→"&'（別紙１）省力化計算シート'!D36+'（別紙１）省力化計算シート'!F36&"分）")) | G44: =IF('（別紙１）省力化計算シート'!D37="","",IF(OR('（別紙１）省力化計算シート'!F37="-",'（別紙１）省力化計算シート'!F37=0),'（別紙１）省力化計算シート'!D37&"分",'（別紙１）省力化計算シート'!D37&"分"&" (→"&'（別紙１）省力化計算シート'!D37+'（別紙１）省力化計算シート'!F37&"分）")) | K44: =IF('（別紙１）省力化計算シート'!D38="","",IF(OR('（別紙１）省力化計算シート'!F38="-",'（別紙１）省力化計算シート'!F38=0),'（別紙１）省力化計算シート'!D38&"分",'（別紙１）省力化計算シート'!D38&"分"&" (→"&'（別紙１）省力化計算シート'!D38+'（別紙１）省力化計算シート'!F38&"分）")) | O44: =IF('（別紙１）省力化計算シート'!D39="","",IF(OR('（別紙１）省力化計算シート'!F39="-",'（別紙１）省力化計算シート'!F39=0),'（別紙１）省力化計算シート'!D39&"分",'（別紙１）省力化計算シート'!D39&"分"&" (→"&'（別紙１）省力化計算シート'!D39+'（別紙１）省力化計算シート'!F39&"分）")) | S44: =IF('（別紙１）省力化計算シート'!D40="","",IF(OR('（別紙１）省力化計算シート'!F40="-",'（別紙１）省力化計算シート'!F40=0),'（別紙１）省力化計算シート'!D40&"分",'（別紙１）省力化計算シート'!D40&"分"&" (→"&'（別紙１）省力化計算シート'!D40+'（別紙１）省力化計算シート'!F40&"分）"))
A48: =IF(COUNTA('（別紙１）省力化計算シート'!C26:C40)<>0,"← 非表示エリアに記載があります。[＋]をクリックして表示してください。[-]の場合は、すべて表示されています。","")
C50: ■設備導入後の業務プロセス・作業工程 （AFTER） | O50: 設備導入による増加時間 | S50: ='（別紙１）省力化計算シート'!J3 -> 0 | T50: 時間
C53: ='（別紙１）省力化計算シート'!I11 -> 尻尾切り | E53: > | G53: ='（別紙１）省力化計算シート'!I12 -> 魚体選別 | I53: > | K53: ='（別紙１）省力化計算シート'!I13 -> 0 | M53: > | O53: ='（別紙１）省力化計算シート'!I14 -> 0 | Q53: > | S53: ='（別紙１）省力化計算シート'!I15 -> 0 | U53: > | X53: 新たに追加される作業
C54: =IF('（別紙１）省力化計算シート'!J11="","",IF(OR('（別紙１）省力化計算シート'!N11="-",'（別紙１）省力化計算シート'!N11=0),'（別紙１）省力化計算シート'!J11&"分","("&'（別紙１）省力化計算シート'!J11-'（別紙１）省力化計算シート'!N11&"分→）"&'（別紙１）省力化計算シート'!J11&"分")) -> (960分→）240分 | G54: =IF('（別紙１）省力化計算シート'!J12="","",IF(OR('（別紙１）省力化計算シート'!N12="-",'（別紙１）省力化計算シート'!N12=0),'（別紙１）省力化計算シート'!J12&"分","("&'（別紙１）省力化計算シート'!J12-'（別紙１）省力化計算シート'!N12&"分→）"&'（別紙１）省力化計算シート'!J12&"分")) -> (2880分→）720分 | K54: =IF('（別紙１）省力化計算シート'!J13="","",IF(OR('（別紙１）省力化計算シート'!N13="-",'（別紙１）省力化計算シート'!N13=0),'（別紙１）省力化計算シート'!J13&"分","("&'（別紙１）省力化計算シート'!J13-'（別紙１）省力化計算シート'!N13&"分→）"&'（別紙１）省力化計算シート'!J13&"分")) | O54: =IF('（別紙１）省力化計算シート'!J14="","",IF(OR('（別紙１）省力化計算シート'!N14="-",'（別紙１）省力化計算シート'!N14=0),'（別紙１）省力化計算シート'!J14&"分","("&'（別紙１）省力化計算シート'!J14-'（別紙１）省力化計算シート'!N14&"分→）"&'（別紙１）省力化計算シート'!J14&"分")) | S54: =IF('（別紙１）省力化計算シート'!J15="","",IF(OR('（別紙１）省力化計算シート'!N15="-",'（別紙１）省力化計算シート'!N15=0),'（別紙１）省力化計算シート'!J15&"分","("&'（別紙１）省力化計算シート'!J15-'（別紙１）省力化計算シート'!N15&"分→）"&'（別紙１）省力化計算シート'!J15&"分"))
X56: 時間が増加する作業
C60: ='（別紙１）省力化計算シート'!I16 -> 0 | E60: > | G60: ='（別紙１）省力化計算シート'!I17 -> 0 | I60: > | K60: ='（別紙１）省力化計算シート'!I18 -> 0 | M60: > | O60: ='（別紙１）省力化計算シート'!I19 -> 0 | Q60: > | S60: ='（別紙１）省力化計算シート'!I20 -> 0 | U60: > | X60: 導入前後で同様の作業
C61: =IF('（別紙１）省力化計算シート'!J16="","",IF(OR('（別紙１）省力化計算シート'!N16="-",'（別紙１）省力化計算シート'!N16=0),'（別紙１）省力化計算シート'!J16&"分","("&'（別紙１）省力化計算シート'!J16-'（別紙１）省力化計算シート'!N16&"分→）"&'（別紙１）省力化計算シート'!J16&"分")) | G61: =IF('（別紙１）省力化計算シート'!J17="","",IF(OR('（別紙１）省力化計算シート'!N17="-",'（別紙１）省力化計算シート'!N17=0),'（別紙１）省力化計算シート'!J17&"分","("&'（別紙１）省力化計算シート'!J17-'（別紙１）省力化計算シート'!N17&"分→）"&'（別紙１）省力化計算シート'!J17&"分")) | K61: =IF('（別紙１）省力化計算シート'!J18="","",IF(OR('（別紙１）省力化計算シート'!N18="-",'（別紙１）省力化計算シート'!N18=0),'（別紙１）省力化計算シート'!J18&"分","("&'（別紙１）省力化計算シート'!J18-'（別紙１）省力化計算シート'!N18&"分→）"&'（別紙１）省力化計算シート'!J18&"分")) | O61: =IF('（別紙１）省力化計算シート'!J19="","",IF(OR('（別紙１）省力化計算シート'!N19="-",'（別紙１）省力化計算シート'!N19=0),'（別紙１）省力化計算シート'!J19&"分","("&'（別紙１）省力化計算シート'!J19-'（別紙１）省力化計算シート'!N19&"分→）"&'（別紙１）省力化計算シート'!J19&"分")) | S61: =IF('（別紙１）省力化計算シート'!J20="","",IF(OR('（別紙１）省力化計算シート'!N20="-",'（別紙１）省力化計算シート'!N20=0),'（別紙１）省力化計算シート'!J20&"分","("&'（別紙１）省力化計算シート'!J20-'（別紙１）省力化計算シート'!N20&"分→）"&'（別紙１）省力化計算シート'!J20&"分"))
X62: 作業内容の説明 入力欄
C67: ='（別紙１）省力化計算シート'!I21 -> 0 | E67: > | G67: ='（別紙１）省力化計算シート'!I22 -> 0 | I67: > | K67: ='（別紙１）省力化計算シート'!I23 -> 0 | M67: > | O67: ='（別紙１）省力化計算シート'!I24 -> 0 | Q67: > | S67: ='（別紙１）省力化計算シート'!I25 -> 0 | U67: >
C68: =IF('（別紙１）省力化計算シート'!J21="","",IF(OR('（別紙１）省力化計算シート'!N21="-",'（別紙１）省力化計算シート'!N21=0),'（別紙１）省力化計算シート'!J21&"分","("&'（別紙１）省力化計算シート'!J21-'（別紙１）省力化計算シート'!N21&"分→）"&'（別紙１）省力化計算シート'!J21&"分")) | G68: =IF('（別紙１）省力化計算シート'!J22="","",IF(OR('（別紙１）省力化計算シート'!N22="-",'（別紙１）省力化計算シート'!N22=0),'（別紙１）省力化計算シート'!J22&"分","("&'（別紙１）省力化計算シート'!J22-'（別紙１）省力化計算シート'!N22&"分→）"&'（別紙１）省力化計算シート'!J22&"分")) | K68: =IF('（別紙１）省力化計算シート'!J23="","",IF(OR('（別紙１）省力化計算シート'!N23="-",'（別紙１）省力化計算シート'!N23=0),'（別紙１）省力化計算シート'!J23&"分","("&'（別紙１）省力化計算シート'!J23-'（別紙１）省力化計算シート'!N23&"分→）"&'（別紙１）省力化計算シート'!J23&"分")) | O68: =IF('（別紙１）省力化計算シート'!J24="","",IF(OR('（別紙１）省力化計算シート'!N24="-",'（別紙１）省力化計算シート'!N24=0),'（別紙１）省力化計算シート'!J24&"分","("&'（別紙１）省力化計算シート'!J24-'（別紙１）省力化計算シート'!N24&"分→）"&'（別紙１）省力化計算シート'!J24&"分")) | S68: =IF('（別紙１）省力化計算シート'!J25="","",IF(OR('（別紙１）省力化計算シート'!N25="-",'（別紙１）省力化計算シート'!N25=0),'（別紙１）省力化計算シート'!J25&"分","("&'（別紙１）省力化計算シート'!J25-'（別紙１）省力化計算シート'!N25&"分→）"&'（別紙１）省力化計算シート'!J25&"分"))
C74: ='（別紙１）省力化計算シート'!I26 -> 0 | E74: > | G74: ='（別紙１）省力化計算シート'!I27 -> 0 | I74: > | K74: ='（別紙１）省力化計算シート'!I28 -> 0 | M74: > | O74: ='（別紙１）省力化計算シート'!I29 -> 0 | Q74: > | S74: ='（別紙１）省力化計算シート'!I30 -> 0 | U74: >
C75: =IF('（別紙１）省力化計算シート'!J26="","",IF(OR('（別紙１）省力化計算シート'!N26="-",'（別紙１）省力化計算シート'!N26=0),'（別紙１）省力化計算シート'!J26&"分","("&'（別紙１）省力化計算シート'!J26-'（別紙１）省力化計算シート'!N26&"分→）"&'（別紙１）省力化計算シート'!J26&"分")) | G75: =IF('（別紙１）省力化計算シート'!J27="","",IF(OR('（別紙１）省力化計算シート'!N27="-",'（別紙１）省力化計算シート'!N27=0),'（別紙１）省力化計算シート'!J27&"分","("&'（別紙１）省力化計算シート'!J27-'（別紙１）省力化計算シート'!N27&"分→）"&'（別紙１）省力化計算シート'!J27&"分")) | K75: =IF('（別紙１）省力化計算シート'!J28="","",IF(OR('（別紙１）省力化計算シート'!N28="-",'（別紙１）省力化計算シート'!N28=0),'（別紙１）省力化計算シート'!J28&"分","("&'（別紙１）省力化計算シート'!J28-'（別紙１）省力化計算シート'!N28&"分→）"&'（別紙１）省力化計算シート'!J28&"分")) | O75: =IF('（別紙１）省力化計算シート'!J29="","",IF(OR('（別紙１）省力化計算シート'!N29="-",'（別紙１）省力化計算シート'!N29=0),'（別紙１）省力化計算シート'!J29&"分","("&'（別紙１）省力化計算シート'!J29-'（別紙１）省力化計算シート'!N29&"分→）"&'（別紙１）省力化計算シート'!J29&"分")) | S75: =IF('（別紙１）省力化計算シート'!J30="","",IF(OR('（別紙１）省力化計算シート'!N30="-",'（別紙１）省力化計算シート'!N30=0),'（別紙１）省力化計算シート'!J30&"分","("&'（別紙１）省力化計算シート'!J30-'（別紙１）省力化計算シート'!N30&"分→）"&'（別紙１）省力化計算シート'!J30&"分"))
C81: ='（別紙１）省力化計算シート'!I31 -> 0 | E81: > | G81: ='（別紙１）省力化計算シート'!I32 -> 0 | I81: > | K81: ='（別紙１）省力化計算シート'!I33 -> 0 | M81: > | O81: ='（別紙１）省力化計算シート'!I34 -> 0 | Q81: > | S81: ='（別紙１）省力化計算シート'!I35 -> 0 | U81: >
C82: =IF('（別紙１）省力化計算シート'!J31="","",IF(OR('（別紙１）省力化計算シート'!N31="-",'（別紙１）省力化計算シート'!N31=0),'（別紙１）省力化計算シート'!J31&"分","("&'（別紙１）省力化計算シート'!J31-'（別紙１）省力化計算シート'!N31&"分→）"&'（別紙１）省力化計算シート'!J31&"分")) | G82: =IF('（別紙１）省力化計算シート'!J32="","",IF(OR('（別紙１）省力化計算シート'!N32="-",'（別紙１）省力化計算シート'!N32=0),'（別紙１）省力化計算シート'!J32&"分","("&'（別紙１）省力化計算シート'!J32-'（別紙１）省力化計算シート'!N32&"分→）"&'（別紙１）省力化計算シート'!J32&"分")) | K82: =IF('（別紙１）省力化計算シート'!J33="","",IF(OR('（別紙１）省力化計算シート'!N33="-",'（別紙１）省力化計算シート'!N33=0),'（別紙１）省力化計算シート'!J33&"分","("&'（別紙１）省力化計算シート'!J33-'（別紙１）省力化計算シート'!N33&"分→）"&'（別紙１）省力化計算シート'!J33&"分")) | O82: =IF('（別紙１）省力化計算シート'!J34="","",IF(OR('（別紙１）省力化計算シート'!N34="-",'（別紙１）省力化計算シート'!N34=0),'（別紙１）省力化計算シート'!J34&"分","("&'（別紙１）省力化計算シート'!J34-'（別紙１）省力化計算シート'!N34&"分→）"&'（別紙１）省力化計算シート'!J34&"分")) | S82: =IF('（別紙１）省力化計算シート'!J35="","",IF(OR('（別紙１）省力化計算シート'!N35="-",'（別紙１）省力化計算シート'!N35=0),'（別紙１）省力化計算シート'!J35&"分","("&'（別紙１）省力化計算シート'!J35-'（別紙１）省力化計算シート'!N35&"分→）"&'（別紙１）省力化計算シート'!J35&"分"))
C88: ='（別紙１）省力化計算シート'!I36 -> 0 | E88: > | G88: ='（別紙１）省力化計算シート'!I37 -> 0 | I88: > | K88: ='（別紙１）省力化計算シート'!I38 -> 0 | M88: > | O88: ='（別紙１）省力化計算シート'!I39 -> 0 | Q88: > | S88: ='（別紙１）省力化計算シート'!I40 -> 0
C89: =IF('（別紙１）省力化計算シート'!J36="","",IF(OR('（別紙１）省力化計算シート'!N36="-",'（別紙１）省力化計算シート'!N36=0),'（別紙１）省力化計算シート'!J36&"分","("&'（別紙１）省力化計算シート'!J36-'（別紙１）省力化計算シート'!N36&"分→）"&'（別紙１）省力化計算シート'!J36&"分")) | G89: =IF('（別紙１）省力化計算シート'!J37="","",IF(OR('（別紙１）省力化計算シート'!N37="-",'（別紙１）省力化計算シート'!N37=0),'（別紙１）省力化計算シート'!J37&"分","("&'（別紙１）省力化計算シート'!J37-'（別紙１）省力化計算シート'!N37&"分→）"&'（別紙１）省力化計算シート'!J37&"分")) | K89: =IF('（別紙１）省力化計算シート'!J38="","",IF(OR('（別紙１）省力化計算シート'!N38="-",'（別紙１）省力化計算シート'!N38=0),'（別紙１）省力化計算シート'!J38&"分","("&'（別紙１）省力化計算シート'!J38-'（別紙１）省力化計算シート'!N38&"分→）"&'（別紙１）省力化計算シート'!J38&"分")) | O89: =IF('（別紙１）省力化計算シート'!J39="","",IF(OR('（別紙１）省力化計算シート'!N39="-",'（別紙１）省力化計算シート'!N39=0),'（別紙１）省力化計算シート'!J39&"分","("&'（別紙１）省力化計算シート'!J39-'（別紙１）省力化計算シート'!N39&"分→）"&'（別紙１）省力化計算シート'!J39&"分")) | S89: =IF('（別紙１）省力化計算シート'!J40="","",IF(OR('（別紙１）省力化計算シート'!N40="-",'（別紙１）省力化計算シート'!N40=0),'（別紙１）省力化計算シート'!J40&"分","("&'（別紙１）省力化計算シート'!J40-'（別紙１）省力化計算シート'!N40&"分→）"&'（別紙１）省力化計算シート'!J40&"分"))
A93: =IF(COUNTA('（別紙１）省力化計算シート'!I26:I40)<>0,"← 非表示エリアに記載があります。[＋]をクリックして表示してください。[-]の場合は、すべて表示されています。","")

Sheet （別紙３）投資回収期間計算シート
B1: （別紙３）投資回収期間計算シート
B3: 投資回収期間 | C3: =IF(OR(C6="",H6="",J6="",L6=""),"",IF(C6/(F6*H6*J6+L6)<=0,"",C6/(F6*H6*J6+L6))) -> 0.45873255 | D3: 年
C5: 投資総額（円） | F5: 削減工数(時間) | H5: 年間稼働日数（日） | J5: 人件費単価（円/時） | L5: 増加した付加価値額（円）
C6: 39900000 | D6: / | E6: （ | F6: ='（別紙１）省力化計算シート'!D3-'（別紙１）省力化計算シート'!J3 -> 48 | G6: × | H6: 245 | I6: × | J6: 1150 | K6: ＋ | L6: 73454786 | M6: ）
F7: ※ 省力化計算シートより
C12: 【算定根拠】算定の根拠となる計算式等の説明があれば記載してください。
C13: 【削減工数】：尻尾切り工程 ： 2名×480分/日 → 1名×240分/日（全自動化により魚体の取り回しが不要となるため） 魚体選別工程 ： 6名×480分/日 → 3名×240分/日（選別作業が自動化され、取り出しと収納容器への投入のみとなるため） 【年間稼働日数】：245日/年 【人件費単価】：「内臓除去＋魚体選別」工程の6名と「尻尾切り」工程の2名の平均給与÷（245日×8時間） 【増加した付加価値額】：基準年度（2023年度）の付加価値額 315,087,360円 5年目（2029年度）の付加価値額 353,070,832円

Sheet 【参考書式】事業計画目標値算出シート（参考）
B1: ◆◆◆ 参考書式をご利用になる際のご注意点 ◆◆◆
B2: ・自動計算項目については、参考値となります。
B3: ・入力値(営業利益が大幅にマイナスの場合など)によっては、申請システムの計算値と異なる可能性があります。
B4: ・イメージがわかるよう入力値に数値をいれてありますが、上書きしてご活用ください。
B5: ・申請システムへの入力は、この表の一部（黄色のセル）を転記していただくことになりますが、本事業における売上・収益計画等
B6: を立てるにあたっての参考にお使いください。（初めに直近決算書の実績数値を入れて、数値シミュレーションにもお使いください。）
B7: ・あくまでシステムに入力いただいた数値を正しいものとして審査します。（提出時には本シートもそのままお出しください。）
B8: ・労働生産性および給与支給総額の計画値が、目標額を上回っていることの確認、
B9: および、事業実施都道府県における最低賃金の直近5年間の年平均成長率の要件を充たしていることの確認 等、
B10: 申請に係る要件の確認は、必ず申請システム上でご確認ください。
F12: 申請システムへ転記する数字
E14: 緑字 | F14: 入力するとシミュレーションできます
E16: 青字 | F16: 成長率 | H16: 紫字 | I16: 計算式が不適当な場合適宜直接手入力してください
E18: その他 | F18: 自動計算 | I18: （基準年の販管費に人件費増加分と新設備減価償却費を加味）
B21: 【参考書式】事業計画目標値算出シート
E23: 直近の決算年月 （基準年度） ２０２４年９月 | G23: 1 | H23: 2 | I23: 3 | J23: 4 | K23: 5
G24: 年目計画 | H24: 年目計画 | I24: 年目計画 | J24: 年目計画 | K24: 年目計画
B27: 売上高 | E27: 3722290631 | G27: 4.0324815e+09 | H27: 4.3038985e+09 | I27: 4.5365417e+09 | J27: 4.730411e+09 | K27: 4.8079587e+09
B28: 売上原価 | E28: 3551996445 | G28: 3.8474223e+09 | H28: 4.0959242e+09 | I28: 4.3108729e+09 | J28: 4.4922936e+09 | K28: 4.5720968e+09
B29: 売上総利益 | E29: =E27-E28 -> 170294186 | G29: =G27-G28 -> 1.8505922e+08 | H29: =H27-H28 -> 2.0797434e+08 | I29: =I27-I28 -> 2.2566883e+08 | J29: =J27-J28 -> 2.3811744e+08 | K29: =K27-K28 -> 2.3586198e+08
B30: 販管費及び一般管理費（人件費・減価償却費も含む） | E30: 133040506 | G30: =$E$30+G35+(G41-$E$41) -> 1.4480206e+08 | H30: =$E$30+H35+(H41-$E$41) -> 1.5977844e+08 | I30: =$E$30+I35+(I41-$E$41) -> 1.7201239e+08 | J30: =$E$30+J35+(J41-$E$41) -> 1.8485804e+08 | K30: =$E$30+K35+(K41-$E$41) -> 1.9834597e+08
B31: ① 営業利益 | E31: =E29-E30 -> 37253680 | G31: =G29-G30 -> 40257158 | H31: =H29-H30 -> 48195901 | I31: =I29-I30 -> 53656437 | J31: =J29-J30 -> 53259399 | K31: =K29-K30 -> 37516007
B32: ② 人件費 (販管費及び一般管理費のうち) （注１） | E32: 257050265 | G32: 2.6990278e+08 | H32: 2.8297663e+08 | I32: 2.9670418e+08 | J32: 3.111181e+08 | K32: 3.2625272e+08
B33: ③ 減価償却費 (販管費及び一般管理費のうち) | E33: =E34+E35 -> 20783415 | G33: =G34+G35 -> 21448415 | H33: =H34+H35 -> 24773415 | I33: =I34+I35 -> 24773415 | J33: =J34+J35 -> 24773415 | K33: =K34+K35 -> 24773415
B34: （内訳）既存設備の減価償却費 | E34: 20783415 | G34: 20783415 | H34: 20783415 | I34: 20783415 | J34: 20783415 | K34: 20783415
B35: 本補助金で導入する設備の減価償却費 | E35: 0 | G35: 665000 | H35: 3990000 | I35: 3990000 | J35: 3990000 | K35: 3990000
B36: ④付加価値額（①+②+③） | E36: =E31+E32+E33 -> 315087360 | G36: =G31+G32+G33 -> 3.3160835e+08 | H36: =H31+H32+H33 -> 3.5594595e+08 | I36: =I31+I32+I33 -> 3.7513403e+08 | J36: =J31+J32+J33 -> 3.8915092e+08 | K36: =K31+K32+K33 -> 3.8854215e+08
B37: 付加価値額の年平均成長率（％） | G37: =ROUNDDOWN(((G36/$E$36)^(1/G23)-1)*100,2) -> 5.24 | H37: =ROUNDDOWN(((H36/$E$36)^(1/H23)-1)*100,2) -> 6.28 | I37: =ROUNDDOWN(((I36/$E$36)^(1/I23)-1)*100,2) -> 5.98 | J37: =ROUNDDOWN(((J36/$E$36)^(1/J23)-1)*100,2) -> 5.41 | K37: =ROUNDDOWN(((K36/$E$36)^(1/K23)-1)*100,2) -> 4.28
B38: 労働生産性(＝１人あたり付加価値額) | E38: =ROUNDUP((E36/(E48+E49)),2) -> 5527848.4 | G38: =ROUNDUP((G36/(G48+G49)),2) -> 5817690.4 | H38: =ROUNDUP((H36/(H48+H49)),2) -> 6244665.8 | I38: =ROUNDUP((I36/(I48+I49)),2) -> 6581298.8 | J38: =ROUNDUP((J36/(J48+J49)),2) -> 6827209.1 | K38: =ROUNDUP((K36/(K48+K49)),2) -> 6816528.9
B39: 労働生産性の目標値 （年平均成長率４％ずつ上げる場合） | G39: =ROUNDUP(($E$36+(ABS($E$36)*1.04^G23-ABS($E$36)))/($E$48+$E$49),0) -> 5748963 | H39: =ROUNDUP(($E$36+(ABS($E$36)*1.04^H23-ABS($E$36)))/($E$48+$E$49),0) -> 5978921 | I39: =ROUNDUP(($E$36+(ABS($E$36)*1.04^I23-ABS($E$36)))/($E$48+$E$49),0) -> 6218078 | J39: =ROUNDUP(($E$36+(ABS($E$36)*1.04^J23-ABS($E$36)))/($E$48+$E$49),0) -> 6466801 | K39: =ROUNDUP(($E$36+(ABS($E$36)*1.04^K23-ABS($E$36)))/($E$48+$E$49),0) -> 6725473
B40: 労働生産性の年平均成長率（％） | G40: =ROUNDDOWN(((G38/$E$38)^(1/G23)-1)*100,2) -> 5.24 | H40: =ROUNDDOWN(((H38/$E$38)^(1/H23)-1)*100,2) -> 6.28 | I40: =ROUNDDOWN(((I38/$E$38)^(1/I23)-1)*100,2) -> 5.98 | J40: =ROUNDDOWN(((J38/$E$38)^(1/J23)-1)*100,2) -> 5.41 | K40: =ROUNDDOWN(((K38/$E$38)^(1/K23)-1)*100,2) -> 4.28
B41: ⑤給与支給総額（⑥+⑦） (注２) | E41: =E42+E43 -> 221931081 | G41: =G42+G43 -> 2.3302764e+08 | H41: =H42+H43 -> 2.4467902e+08 | I41: =I42+I43 -> 2.5691297e+08 | J41: =J42+J43 -> 2.6975862e+08 | K41: =K42+K43 -> 2.8324655e+08
B42: ⑥ ⑤のうち、役員報酬 | E42: 55200000 | G42: 57960000 | H42: 60858000 | I42: 63900900 | J42: 67095945 | K42: 70450742
B43: ⑦ ⑤のうち、従業員の給与支給総額 | E43: 166731081 | G43: 1.7506764e+08 | H43: 1.8382102e+08 | I43: 1.9301207e+08 | J43: 2.0266267e+08 | K43: 2.127958e+08
B44: 給与支給総額の年平均成長率（％）（※５） | G44: =ROUNDDOWN(((G41/$E$41)^(1/G23)-1)*100,2) -> 4.99 | H44: =ROUNDDOWN(((H41/$E$41)^(1/H23)-1)*100,2) -> 5 | I44: =ROUNDDOWN(((I41/$E$41)^(1/I23)-1)*100,2) -> 5 | J44: =ROUNDDOWN(((J41/$E$41)^(1/J23)-1)*100,2) -> 5 | K44: =ROUNDDOWN(((K41/$E$41)^(1/K23)-1)*100,2) -> 5
B45: 給与支給総額の目標額 | C45: (※1)特例なし、加点なし：2% | D45: 0.02 | G45: =$E$41*(1+$D45)^G$23 -> 2.263697e+08 | H45: =$E$41*(1+$D45)^H$23 -> 2.308971e+08 | I45: =$E$41*(1+$D45)^I$23 -> 2.3551504e+08 | J45: =$E$41*(1+$D45)^J$23 -> 2.4022534e+08 | K45: =$E$41*(1+$D45)^K$23 -> 2.4502985e+08
C46: (※2)特例なし、加点あり：4% | D46: 0.04 | G46: =$E$41*(1+$D46)^G$23 -> 2.3080832e+08 | H46: =$E$41*(1+$D46)^H$23 -> 2.4004066e+08 | I46: =$E$41*(1+$D46)^I$23 -> 2.4964228e+08 | J46: =$E$41*(1+$D46)^J$23 -> 2.5962797e+08 | K46: =$E$41*(1+$D46)^K$23 -> 2.7001309e+08
C47: (※3)特例あり：6% | D47: 0.06 | G47: =$E$41*(1+$D47)^G$23 -> 2.3524695e+08 | H47: =$E$41*(1+$D47)^H$23 -> 2.4936176e+08 | I47: =$E$41*(1+$D47)^I$23 -> 2.6432347e+08 | J47: =$E$41*(1+$D47)^J$23 -> 2.8018288e+08 | K47: =$E$41*(1+$D47)^K$23 -> 2.9699385e+08
B48: ⑧役員数（人） | E48: 3 | G48: 3 | H48: 3 | I48: 3 | J48: 3 | K48: 3
B49: ⑨従業員数（人） （注２） | E49: 54 | G49: 54 | H49: 54 | I49: 54 | J49: 54 | K49: 54
...

Sheet 【参考書式】達成すべき目標値の算出ツール（参考）
C1: (参考)
D3: 基準年 | E3: 1 | F3: 2 | G3: 3 | H3: 4 | I3: 5
C4: 増加率 | E4: 0.02 | F4: =(1+$E4)^$F3-1 -> 0.0404 | G4: =(1+$E4)^G3-1 -> 0.061208 | H4: =(1+$E4)^H3-1 -> 0.08243216 | I4: =(1+$E4)^I3-1 -> 0.1040808
D5: 1000 | E5: =$D5*((1+$E4)^E3) -> 1020 | F5: =$D5*((1+$E4)^F3) -> 1040.4 | G5: =$D5*((1+$E4)^G3) -> 1061.208 | H5: =$D5*((1+$E4)^H3) -> 1082.4322 | I5: =$D5*((1+$E4)^I3) -> 1104.0808
E6: 0.04 | F6: =(1+$E6)^F3-1 -> 0.0816 | G6: =(1+$E6)^G3-1 -> 0.124864 | H6: =(1+$E6)^H3-1 -> 0.16985856 | I6: =(1+$E6)^I3-1 -> 0.2166529
E7: 0.05 | F7: =(1+$E7)^F3-1 -> 0.1025 | G7: =(1+$E7)^G3-1 -> 0.157625 | H7: =(1+$E7)^H3-1 -> 0.21550625 | I7: =(1+$E7)^I3-1 -> 0.27628156
E8: 0.06 | F8: =(1+$E8)^F3-1 -> 0.1236 | G8: =(1+$E8)^G3-1 -> 0.191016 | H8: =(1+$E8)^H3-1 -> 0.26247696 | I8: =(1+$E8)^I3-1 -> 0.33822558
E9: 0.07 | F9: =(1+$E9)^F3-1 -> 0.1449 | G9: =(1+$E9)^G3-1 -> 0.225043 | H9: =(1+$E9)^H3-1 -> 0.31079601 | I9: =(1+$E9)^I3-1 -> 0.40255173
E10: 0.08 | F10: =(1+$E10)^F3-1 -> 0.1664 | G10: =(1+$E10)^G3-1 -> 0.259712 | H10: =(1+$E10)^H3-1 -> 0.36048896 | I10: =(1+$E10)^I3-1 -> 0.46932808
E11: 0.09 | F11: =(1+$E11)^F3-1 -> 0.1881 | G11: =(1+$E11)^G3-1 -> 0.295029 | H11: =(1+$E11)^H3-1 -> 0.41158161 | I11: =(1+$E11)^I3-1 -> 0.53862395
D13: 基準年 | E13: １年目 | F13: ２年目 | G13: ３年目 | H13: ４年目 | I13: ５年目
C14: 増加率 | E14: 0.02 | F14: =(1+$E14)^F3-1 -> 0.0404 | G14: =(1+$E14)^G3-1 -> 0.061208 | H14: =(1+$E14)^H3-1 -> 0.08243216 | I14: =(1+$E14)^I3-1 -> 0.1040808
C15: 目標値 | D15: 4500000 | E15: =ROUNDUP($D$15*((1+$E14)^E3),3) -> 4590000 | F15: =$D$15*((1+$E14)^F3) -> 4681800 | G15: =$D15*((1+$E14)^G3) -> 4775436 | H15: =$D15*((1+$E14)^H3) -> 4870944.7 | I15: =$D15*((1+$E14)^I3) -> 4968363.6
C16: 年平均成長率 | E16: =ROUNDDOWN(((E15/$D$15)^(1/E3)-1),5) -> 0.02 | F16: =ROUNDDOWN(((F15/$D$15)^(1/F3)-1),5) -> 0.02 | G16: =ROUNDDOWN(((G15/$D$15)^(1/G3)-1),5) -> 0.02 | H16: =ROUNDDOWN(((H15/$D$15)^(1/H3)-1),5) -> 0.02 | I16: =ROUNDDOWN(((I15/$D$15)^(1/I3)-1),5) -> 0.02
